Workbook

Sheet Resumen Consolidado Dirección
B2: CODIAGRO · RESUMEN DIRECCIÓN: REVISIÓN DE PREVISIONES Q4 2026
B3: Consolidado de Desviaciones de Septiembre y Previsiones hasta Final de Año (Octubre a Diciembre) | Cierre Sep: 01/10/2026
B5: INFORMACIÓN COMERCIAL | D5: CIERRE SEPTIEMBRE 2026 (REAL vs PREVISTO) | H5: PREVISIÓN CARTERA HASTA FINAL DE AÑO (Q4 2026) | L5: VALIDACIÓN
B6: Comercial | C6: Clientes Activos | D6: Sep Previsto (u) | E6: Sep Real (u) | F6: Desv. Sep (u) | G6: % Consec. | H6: Oct Previsto (u) | I6: Nov Previsto (u) | J6: Dic Previsto (u) | K6: Total Q4 Previsto (u) | L6: Estado Cierre Sep
B7: Alfonso | C7: 29 | D7: ='Alfonso'!F44 | E7: ='Alfonso'!G44 | F7: ='Alfonso'!H44 | G7: ='Alfonso'!I44 | H7: ='Alfonso'!L44 | I7: ='Alfonso'!N44 | J7: ='Alfonso'!P44 | K7: ='Alfonso'!R44 | L7: =IF(G7>=1.0, "Superado (+)", IF(G7>=0.7, "En Rango", "Revisar"))
B8: García | C8: 24 | D8: ='García'!F128 | E8: ='García'!G128 | F8: ='García'!H128 | G8: ='García'!I128 | H8: ='García'!L128 | I8: ='García'!N128 | J8: ='García'!P128 | K8: ='García'!R128 | L8: =IF(G8>=1.0, "Superado (+)", IF(G8>=0.7, "En Rango", "Revisar"))
B9: Irene | C9: 6 | D9: ='Irene'!F74 | E9: ='Irene'!G74 | F9: ='Irene'!H74 | G9: ='Irene'!I74 | H9: ='Irene'!L74 | I9: ='Irene'!N74 | J9: ='Irene'!P74 | K9: ='Irene'!R74 | L9: =IF(G9>=1.0, "Superado (+)", IF(G9>=0.7, "En Rango", "Revisar"))
B10: Javier | C10: 5 | D10: ='Javier'!F82 | E10: ='Javier'!G82 | F10: ='Javier'!H82 | G10: ='Javier'!I82 | H10: ='Javier'!L82 | I10: ='Javier'!N82 | J10: ='Javier'!P82 | K10: ='Javier'!R82 | L10: =IF(G10>=1.0, "Superado (+)", IF(G10>=0.7, "En Rango", "Revisar"))
B11: Mehmet | C11: 5 | D11: ='Mehmet'!F48 | E11: ='Mehmet'!G48 | F11: ='Mehmet'!H48 | G11: ='Mehmet'!I48 | H11: ='Mehmet'!L48 | I11: ='Mehmet'!N48 | J11: ='Mehmet'!P48 | K11: ='Mehmet'!R48 | L11: =IF(G11>=1.0, "Superado (+)", IF(G11>=0.7, "En Rango", "Revisar"))
B12: Pedro | C12: 3 | D12: ='Pedro'!F52 | E12: ='Pedro'!G52 | F12: ='Pedro'!H52 | G12: ='Pedro'!I52 | H12: ='Pedro'!L52 | I12: ='Pedro'!N52 | J12: ='Pedro'!P52 | K12: ='Pedro'!R52 | L12: =IF(G12>=1.0, "Superado (+)", IF(G12>=0.7, "En Rango", "Revisar"))
B13: Ricardo | C13: 11 | D13: ='Ricardo'!F111 | E13: ='Ricardo'!G111 | F13: ='Ricardo'!H111 | G13: ='Ricardo'!I111 | H13: ='Ricardo'!L111 | I13: ='Ricardo'!N111 | J13: ='Ricardo'!P111 | K13: ='Ricardo'!R111 | L13: =IF(G13>=1.0, "Superado (+)", IF(G13>=0.7, "En Rango", "Revisar"))
B14: TOTAL CODIAGRO | C14: =SUM(C7:C13) | D14: =SUM(D7:D13) | E14: =SUM(E7:E13) | F14: =SUM(F7:F13) | G14: =E14/D14 | H14: =SUM(H7:H13) | I14: =SUM(I7:I13) | J14: =SUM(J7:J13) | K14: =SUM(K7:K13) | L14: CONSOLIDADO

Sheet Alfonso
B2: CODIAGRO · ACTUALIZACIÓN DE PREVISIONES COMERCIALES Q4 2026 (OCTUBRE - DICIEMBRE)
B3: DELEGADO COMERCIAL: ALFONSO | Cierre Septiembre Oficial (01/10/2026) vs Previsiones a Final de Año | Generado: 01/10/2026 14:16
B4: 📌 INSTRUCCIONES: 1) Revise el bloque de SEPTIEMBRE (Previsto, Real, Desviación en Valor Absoluto y % Consecución) e indique en col. J el motivo de la desviación (adelanto, atraso, extra). 2) En las columnas verdes (L, N, P), revise y actualice las cantidades estimadas de Octubre, Noviembre y Diciembre si prevé cambios. 3) Comente en col. T cualquier nota de campaña.
B5: PREVISTO SEP 2026 (U) | E5: REAL PEDIDOS SEP 2026 (U) | H5: % CONSECUCIÓN SEP | K5: PREVISIÓN INICIAL Q4 (U) | N5: PREVISIÓN REVISADA Q4 (U) | Q5: VARIACIÓN NETA Q4 (U)
B6: =F44 | E6: =G44 | H6: =I44 | K6: =Q44 | N6: =R44 | Q6: =S44
B8: DATOS CLIENTE Y ARTÍCULO | F8: CIERRE SEPTIEMBRE 2026 (CALIBRACIÓN Y ANÁLISIS) | K8: REVISIÓN PREVISIONES MES A MES (HASTA FINAL DE AÑO 2026) | Q8: IMPACTO Q4 Y JUSTIFICACIÓN
B9: País | C9: Cliente | D9: Cód. SKU | E9: Descripción Artículo | F9: Sep Previsto (u) | G9: Sep Real (u) | H9: Desv. Sep (u) | I9: % Consec. | J9: Comentario Sep (¿Adelanto/Atraso/Extra?) | K9: Oct Anterior (u) | L9: Oct Revisado (u) | M9: Nov Anterior (u) | N9: Nov Revisado (u) | O9: Dic Anterior (u) | P9: Dic Revisado (u) | Q9: Total Q4 Ant (u) | R9: Total Q4 Rev (u) | S9: Dif Q4 (u) | T9: Comentarios / Justificación Q4
B10: ESPAÑA | C10: ACTIV. PRODUC. Y COMERC. LA VEGUILLA, SL | D10: BIO0020 | E10: BIORAD-20, 20 L | F10: 960 | G10: 1280 | H10: =ABS(G10-F10) | I10: =IF(F10>0, G10/F10, IF(G10>0, 1.0, 0.0)) | K10: 960 | L10: 960 | M10: 0 | N10: 0 | O10: 960 | P10: 960 | Q10: =K10+M10+O10 | R10: =L10+N10+P10 | S10: =R10-Q10
B11: ESPAÑA | C11: ACTIV. PRODUC. Y COMERC. LA VEGUILLA, SL | D11: BROTA0020 | E11: BROTAMEC, 20 L | F11: 960 | G11: 1920 | H11: =ABS(G11-F11) | I11: =IF(F11>0, G11/F11, IF(G11>0, 1.0, 0.0)) | K11: 920 | L11: 920 | M11: 0 | N11: 0 | O11: 960 | P11: 960 | Q11: =K11+M11+O11 | R11: =L11+N11+P11 | S11: =R11-Q11
B12: ESPAÑA | C12: AGRICOLA DEL JUCAR DE CUENCA, S.L. | D12: C-CU0020 | E12: CODICOBRE, 20 L | F12: 0 | G12: 100 | H12: =ABS(G12-F12) | I12: =IF(F12>0, G12/F12, IF(G12>0, 1.0, 0.0)) | J12: Pedido extra no previsto | K12: 0 | L12: 0 | M12: 0 | N12: 0 | O12: 0 | P12: 0 | Q12: =K12+M12+O12 | R12: =L12+N12+P12 | S12: =R12-Q12
B13: ESPAÑA | C13: AGRICOLA DEL JUCAR DE CUENCA, S.L. | D13: C-L0020 | E13: CODIBOR-L, 20 L | F13: 0 | G13: 200 | H13: =ABS(G13-F13) | I13: =IF(F13>0, G13/F13, IF(G13>0, 1.0, 0.0)) | J13: Pedido extra no previsto | K13: 0 | L13: 0 | M13: 0 | N13: 0 | O13: 0 | P13: 0 | Q13: =K13+M13+O13 | R13: =L13+N13+P13 | S13: =R13-Q13
B14: ESPAÑA | C14: AGROTÉCNICA DEL NORTE, S.L | D14: A-50(2)0005 | E14: CODIORGAN-A50, 5 KG | F14: 0 | G14: 500 | H14: =ABS(G14-F14) | I14: =IF(F14>0, G14/F14, IF(G14>0, 1.0, 0.0)) | J14: Pedido extra no previsto | K14: 0 | L14: 0 | M14: 0 | N14: 0 | O14: 0 | P14: 0 | Q14: =K14+M14+O14 | R14: =L14+N14+P14 | S14: =R14-Q14
B15: ESPAÑA | C15: AGROTÉCNICA DEL NORTE, S.L | D15: AGRMG0005 | E15: AGROXIGREEN-MG, 5 L | F15: 0 | G15: 300 | H15: =ABS(G15-F15) | I15: =IF(F15>0, G15/F15, IF(G15>0, 1.0, 0.0)) | J15: Pedido extra no previsto | K15: 0 | L15: 0 | M15: 0 | N15: 0 | O15: 0 | P15: 0 | Q15: =K15+M15+O15 | R15: =L15+N15+P15 | S15: =R15-Q15
B16: ESPAÑA | C16: AGROTÉCNICA DEL NORTE, S.L | D16: PT0005 | E16: AGROPOTASION, 5 L | F16: 0 | G16: 400 | H16: =ABS(G16-F16) | I16: =IF(F16>0, G16/F16, IF(G16>0, 1.0, 0.0)) | J16: Pedido extra no previsto | K16: 0 | L16: 0 | M16: 0 | N16: 0 | O16: 0 | P16: 0 | Q16: =K16+M16+O16 | R16: =L16+N16+P16 | S16: =R16-Q16
B17: ESPAÑA | C17: AGROVEYCA,S.L | D17: A-50(2)0005 | E17: CODIORGAN-A50, 5 KG | F17: 0 | G17: 400 | H17: =ABS(G17-F17) | I17: =IF(F17>0, G17/F17, IF(G17>0, 1.0, 0.0)) | J17: Pedido extra no previsto | K17: 0 | L17: 0 | M17: 0 | N17: 0 | O17: 0 | P17: 0 | Q17: =K17+M17+O17 | R17: =L17+N17+P17 | S17: =R17-Q17
B18: ESPAÑA | C18: AGROVEYCA,S.L | D18: BIO0020 | E18: BIORAD-20, 20 L | F18: 400 | G18: 320 | H18: =ABS(G18-F18) | I18: =IF(F18>0, G18/F18, IF(G18>0, 1.0, 0.0)) | K18: 300 | L18: 300 | M18: 400 | N18: 400 | O18: 0 | P18: 0 | Q18: =K18+M18+O18 | R18: =L18+N18+P18 | S18: =R18-Q18
B19: ESPAÑA | C19: AGROVEYCA,S.L | D19: BROTA0020 | E19: BROTAMEC, 20 L | F19: 0 | G19: 0 | H19: =ABS(G19-F19) | I19: =IF(F19>0, G19/F19, IF(G19>0, 1.0, 0.0)) | K19: 640 | L19: 640 | M19: 0 | N19: 0 | O19: 0 | P19: 0 | Q19: =K19+M19+O19 | R19: =L19+N19+P19 | S19: =R19-Q19
B20: ESPAÑA | C20: ASOC. HORTICULTORES DE VILLA DEL PRADO | D20: A-50(2)0005 | E20: CODIORGAN A-50, 5 KG | F20: 0 | G20: 50 | H20: =ABS(G20-F20) | I20: =IF(F20>0, G20/F20, IF(G20>0, 1.0, 0.0)) | J20: Pedido extra no previsto | K20: 0 | L20: 0 | M20: 0 | N20: 0 | O20: 0 | P20: 0 | Q20: =K20+M20+O20 | R20: =L20+N20+P20 | S20: =R20-Q20
B21: ESPAÑA | C21: ASOC. HORTICULTORES DE VILLA DEL PRADO | D21: AVAN0005 | E21: FLORAMEC AVANCE, 5 L | F21: 0 | G21: 100 | H21: =ABS(G21-F21) | I21: =IF(F21>0, G21/F21, IF(G21>0, 1.0, 0.0)) | J21: Pedido extra no previsto | K21: 0 | L21: 0 | M21: 0 | N21: 0 | O21: 0 | P21: 0 | Q21: =K21+M21+O21 | R21: =L21+N21+P21 | S21: =R21-Q21
B22: ESPAÑA | C22: ASOC. HORTICULTORES DE VILLA DEL PRADO | D22: C-CU0005 | E22: CODICOBRE, 5 L | F22: 0 | G22: 20 | H22: =ABS(G22-F22) | I22: =IF(F22>0, G22/F22, IF(G22>0, 1.0, 0.0)) | J22: Pedido extra no previsto | K22: 0 | L22: 0 | M22: 0 | N22: 0 | O22: 0 | P22: 0 | Q22: =K22+M22+O22 | R22: =L22+N22+P22 | S22: =R22-Q22
B23: ESPAÑA | C23: ASOC. HORTICULTORES DE VILLA DEL PRADO | D23: S0020 | E23: SALWAX STAR, 20 L | F23: 0 | G23: 40 | H23: =ABS(G23-F23) | I23: =IF(F23>0, G23/F23, IF(G23>0, 1.0, 0.0)) | J23: Pedido extra no previsto | K23: 0 | L23: 0 | M23: 0 | N23: 0 | O23: 0 | P23: 0 | Q23: =K23+M23+O23 | R23: =L23+N23+P23 | S23: =R23-Q23
B24: ESPAÑA | C24: BARDENAS COMERCIAL, S.L. | D24: AGRMG0005 | E24: AGROXIGREEN-MG, 5 L | F24: 0 | G24: 300 | H24: =ABS(G24-F24) | I24: =IF(F24>0, G24/F24, IF(G24>0, 1.0, 0.0)) | J24: Pedido extra no previsto | K24: 0 | L24: 0 | M24: 0 | N24: 0 | O24: 0 | P24: 0 | Q24: =K24+M24+O24 | R24: =L24+N24+P24 | S24: =R24-Q24
B25: ESPAÑA | C25: BARDENAS COMERCIAL, S.L. | D25: PT0005 | E25: AGROPOTASION, 5 L | F25: 0 | G25: 300 | H25: =ABS(G25-F25) | I25: =IF(F25>0, G25/F25, IF(G25>0, 1.0, 0.0)) | J25: Pedido extra no previsto | K25: 0 | L25: 0 | M25: 0 | N25: 0 | O25: 0 | P25: 0 | Q25: =K25+M25+O25 | R25: =L25+N25+P25 | S25: =R25-Q25
B26: ESPAÑA | C26: COMERCIAL NORTE AGROCAMPO, S.L. | D26: A-50(2)0020 | E26: CODIORGAN-A50, 20 KG | F26: 0 | G26: 40 | H26: =ABS(G26-F26) | I26: =IF(F26>0, G26/F26, IF(G26>0, 1.0, 0.0)) | J26: Pedido extra no previsto | K26: 0 | L26: 0 | M26: 0 | N26: 0 | O26: 0 | P26: 0 | Q26: =K26+M26+O26 | R26: =L26+N26+P26 | S26: =R26-Q26
B27: ESPAÑA | C27: COMERCIAL NORTE AGROCAMPO, S.L. | D27: AN0005 | E27: ALCAPLANT NEW, 5 KG | F27: 0 | G27: 20 | H27: =ABS(G27-F27) | I27: =IF(F27>0, G27/F27, IF(G27>0, 1.0, 0.0)) | J27: Pedido extra no previsto | K27: 0 | L27: 0 | M27: 0 | N27: 0 | O27: 0 | P27: 0 | Q27: =K27+M27+O27 | R27: =L27+N27+P27 | S27: =R27-Q27
B28: ESPAÑA | C28: COMERCIAL NORTE AGROCAMPO, S.L. | D28: BR-590005 | E28: BR-59, 5 KG | F28: 0 | G28: 60 | H28: =ABS(G28-F28) | I28: =IF(F28>0, G28/F28, IF(G28>0, 1.0, 0.0)) | J28: Pedido extra no previsto | K28: 0 | L28: 0 | M28: 0 | N28: 0 | O28: 0 | P28: 0 | Q28: =K28+M28+O28 | R28: =L28+N28+P28 | S28: =R28-Q28
B29: ESPAÑA | C29: COMERCIAL NORTE AGROCAMPO, S.L. | D29: BROTA0020 | E29: BROTAMEC, 20 L | F29: 0 | G29: 20 | H29: =ABS(G29-F29) | I29: =IF(F29>0, G29/F29, IF(G29>0, 1.0, 0.0)) | J29: Pedido extra no previsto | K29: 0 | L29: 0 | M29: 0 | N29: 0 | O29: 0 | P29: 0 | Q29: =K29+M29+O29 | R29: =L29+N29+P29 | S29: =R29-Q29
B30: ESPAÑA | C30: COMERCIAL NORTE AGROCAMPO, S.L. | D30: C-CU0005 | E30: CODICOBRE, 5 L | F30: 0 | G30: 20 | H30: =ABS(G30-F30) | I30: =IF(F30>0, G30/F30, IF(G30>0, 1.0, 0.0)) | J30: Pedido extra no previsto | K30: 0 | L30: 0 | M30: 0 | N30: 0 | O30: 0 | P30: 0 | Q30: =K30+M30+O30 | R30: =L30+N30+P30 | S30: =R30-Q30
B31: ESPAÑA | C31: COMERCIAL NORTE AGROCAMPO, S.L. | D31: PT0020 | E31: AGROPOTASION, 20 L | F31: 0 | G31: 20 | H31: =ABS(G31-F31) | I31: =IF(F31>0, G31/F31, IF(G31>0, 1.0, 0.0)) | J31: Pedido extra no previsto | K31: 0 | L31: 0 | M31: 0 | N31: 0 | O31: 0 | P31: 0 | Q31: =K31+M31+O31 | R31: =L31+N31+P31 | S31: =R31-Q31
... B40: ESPAÑA | C40: T.J AGRICULTURA S.L. | D40: SS0020 | E40: SALWAX-CA, 20 KG | F40: 0 | G40: 500 | H40: =ABS(G40-F40) | I40: =IF(F40>0, G40/F40, IF(G40>0, 1.0, 0.0)) | J40: Pedido extra no previsto | K40: 0 | L40: 0 | M40: 0 | N40: 0 | O40: 0 | P40: 0 | Q40: =K40+M40+O40 | R40: =L40+N40+P40 | S40: =R40-Q40
B41: ESPAÑA | C41: VILLALTA SATIVUM, S.L. | D41: BIO0020 | E41: BIORAD-20, 20 L | F41: 0 | G41: 0 | H41: =ABS(G41-F41) | I41: =IF(F41>0, G41/F41, IF(G41>0, 1.0, 0.0)) | K41: 300 | L41: 300 | M41: 0 | N41: 0 | O41: 0 | P41: 0 | Q41: =K41+M41+O41 | R41: =L41+N41+P41 | S41: =R41-Q41
B42: ESPAÑA | C42: VILLALTA SATIVUM, S.L. | D42: BROTA0020 | E42: BROTAMEC, 20 L | F42: 0 | G42: 0 | H42: =ABS(G42-F42) | I42: =IF(F42>0, G42/F42, IF(G42>0, 1.0, 0.0)) | K42: 640 | L42: 640 | M42: 0 | N42: 0 | O42: 0 | P42: 0 | Q42: =K42+M42+O42 | R42: =L42+N42+P42 | S42: =R42-Q42
B43: ESPAÑA | C43: VILLALTA SATIVUM, S.L. | D43: WHITE0020 | E43: AGROWHITE, 20 KG | F43: 0 | G43: 3460 | H43: =ABS(G43-F43) | I43: =IF(F43>0, G43/F43, IF(G43>0, 1.0, 0.0)) | J43: Pedido extra no previsto | K43: 0 | L43: 0 | M43: 0 | N43: 0 | O43: 0 | P43: 0 | Q43: =K43+M43+O43 | R43: =L43+N43+P43 | S43: =R43-Q43
B44: TOTAL CONSOLIDADO - ALFONSO (UNIDADES) | F44: =SUM(F10:F43) | G44: =SUM(G10:G43) | H44: =SUM(H10:H43) | I44: =IF(F44>0, G44/F44, 1.0) | K44: =SUM(K10:K43) | L44: =SUM(L10:L43) | M44: =SUM(M10:M43) | N44: =SUM(N10:N43) | O44: =SUM(O10:O43) | P44: =SUM(P10:P43) | Q44: =SUM(Q10:Q43) | R44: =SUM(R10:R43) | S44: =SUM(S10:S43)

Sheet García
B2: CODIAGRO · ACTUALIZACIÓN DE PREVISIONES COMERCIALES Q4 2026 (OCTUBRE - DICIEMBRE)
B3: DELEGADO COMERCIAL: GARCÍA | Cierre Septiembre Oficial (01/10/2026) vs Previsiones a Final de Año | Generado: 01/10/2026 14:17
B4: 📌 INSTRUCCIONES: 1) Revise el bloque de SEPTIEMBRE (Previsto, Real, Desviación en Valor Absoluto y % Consecución) e indique en col. J el motivo de la desviación (adelanto, atraso, extra). 2) En las columnas verdes (L, N, P), revise y actualice las cantidades estimadas de Octubre, Noviembre y Diciembre si prevé cambios. 3) Comente en col. T cualquier nota de campaña.
B5: PREVISTO SEP 2026 (U) | E5: REAL PEDIDOS SEP 2026 (U) | H5: % CONSECUCIÓN SEP | K5: PREVISIÓN INICIAL Q4 (U) | N5: PREVISIÓN REVISADA Q4 (U) | Q5: VARIACIÓN NETA Q4 (U)
B6: =F128 | E6: =G128 | H6: =I128 | K6: =Q128 | N6: =R128 | Q6: =S128
B8: DATOS CLIENTE Y ARTÍCULO | F8: CIERRE SEPTIEMBRE 2026 (CALIBRACIÓN Y ANÁLISIS) | K8: REVISIÓN PREVISIONES MES A MES (HASTA FINAL DE AÑO 2026) | Q8: IMPACTO Q4 Y JUSTIFICACIÓN
B9: País | C9: Cliente | D9: Cód. SKU | E9: Descripción Artículo | F9: Sep Previsto (u) | G9: Sep Real (u) | H9: Desv. Sep (u) | I9: % Consec. | J9: Comentario Sep (¿Adelanto/Atraso/Extra?) | K9: Oct Anterior (u) | L9: Oct Revisado (u) | M9: Nov Anterior (u) | N9: Nov Revisado (u) | O9: Dic Anterior (u) | P9: Dic Revisado (u) | Q9: Total Q4 Ant (u) | R9: Total Q4 Rev (u) | S9: Dif Q4 (u) | T9: Comentarios / Justificación Q4
B10: ESPAÑA | C10: AGROGIMEDEL, S.L.U. | D10: AGZNP0005 | E10: AGROXILATO ZN PLUS, 5 KG | F10: 700 | G10: 0 | H10: =ABS(G10-F10) | I10: =IF(F10>0, G10/F10, IF(G10>0, 1.0, 0.0)) | K10: 0 | L10: 0 | M10: 0 | N10: 0 | O10: 200 | P10: 200 | Q10: =K10+M10+O10 | R10: =L10+N10+P10 | S10: =R10-Q10
B11: ESPAÑA | C11: AGRONEW FITO, S.L. | D11: AGXK0020 | E11: AGROXILATO-K, 20 L | F11: 0 | G11: 0 | H11: =ABS(G11-F11) | I11: =IF(F11>0, G11/F11, IF(G11>0, 1.0, 0.0)) | K11: 0 | L11: 0 | M11: 1280 | N11: 1280 | O11: 0 | P11: 0 | Q11: =K11+M11+O11 | R11: =L11+N11+P11 | S11: =R11-Q11
B12: ESPAÑA | C12: AGRONEW FITO, S.L. | D12: AGXK1000 | E12: AGROXILATO-K, 1000 L | F12: 2000 | G12: 0 | H12: =ABS(G12-F12) | I12: =IF(F12>0, G12/F12, IF(G12>0, 1.0, 0.0)) | K12: 0 | L12: 0 | M12: 2000 | N12: 2000 | O12: 0 | P12: 0 | Q12: =K12+M12+O12 | R12: =L12+N12+P12 | S12: =R12-Q12
B13: ESPAÑA | C13: AGRONEW FITO, S.L. | D13: AGZ-M0005 | E13: AGROXILATO-ZN-MN, 5 KG | F13: 300 | G13: 0 | H13: =ABS(G13-F13) | I13: =IF(F13>0, G13/F13, IF(G13>0, 1.0, 0.0)) | K13: 0 | L13: 0 | M13: 0 | N13: 0 | O13: 0 | P13: 0 | Q13: =K13+M13+O13 | R13: =L13+N13+P13 | S13: =R13-Q13
B14: ESPAÑA | C14: AGRONEW FITO, S.L. | D14: AGZNP0005 | E14: AGROXILATO-ZN PLUS, 5 KG | F14: 0 | G14: 100 | H14: =ABS(G14-F14) | I14: =IF(F14>0, G14/F14, IF(G14>0, 1.0, 0.0)) | J14: Pedido extra no previsto | K14: 0 | L14: 0 | M14: 0 | N14: 0 | O14: 0 | P14: 0 | Q14: =K14+M14+O14 | R14: =L14+N14+P14 | S14: =R14-Q14
B15: ESPAÑA | C15: AGRONEW FITO, S.L. | D15: AN0020 | E15: ALCAPLANT NEW, 20 KG | F15: 0 | G15: 0 | H15: =ABS(G15-F15) | I15: =IF(F15>0, G15/F15, IF(G15>0, 1.0, 0.0)) | K15: 0 | L15: 0 | M15: 600 | N15: 600 | O15: 0 | P15: 0 | Q15: =K15+M15+O15 | R15: =L15+N15+P15 | S15: =R15-Q15
B16: ESPAÑA | C16: AGRONEW FITO, S.L. | D16: ANAE0020 | E16: ALCAPLANT NEW AE, 20 KG | F16: 2200 | G16: 1100 | H16: =ABS(G16-F16) | I16: =IF(F16>0, G16/F16, IF(G16>0, 1.0, 0.0)) | K16: 1100 | L16: 1100 | M16: 0 | N16: 0 | O16: 0 | P16: 0 | Q16: =K16+M16+O16 | R16: =L16+N16+P16 | S16: =R16-Q16
B17: ESPAÑA | C17: AGRONEW FITO, S.L. | D17: PT0020 | E17: AGROPOTASION, 20 L | F17: 1920 | G17: 1280 | H17: =ABS(G17-F17) | I17: =IF(F17>0, G17/F17, IF(G17>0, 1.0, 0.0)) | K17: 0 | L17: 0 | M17: 1280 | N17: 1280 | O17: 0 | P17: 0 | Q17: =K17+M17+O17 | R17: =L17+N17+P17 | S17: =R17-Q17
B18: ESPAÑA | C18: AGRONEW FITO, S.L. | D18: S1000 | E18: SAL-WAX STAR, 1000 L | F18: 5000 | G18: 1000 | H18: =ABS(G18-F18) | I18: =IF(F18>0, G18/F18, IF(G18>0, 1.0, 0.0)) | K18: 5000 | L18: 5000 | M18: 5000 | N18: 5000 | O18: 0 | P18: 0 | Q18: =K18+M18+O18 | R18: =L18+N18+P18 | S18: =R18-Q18
B19: ESPAÑA | C19: AGROREBOLLO, S.L. | D19: AGZNP0005 | E19: AGROXILATO ZN PLUS, 5 KG | F19: 500 | G19: 0 | H19: =ABS(G19-F19) | I19: =IF(F19>0, G19/F19, IF(G19>0, 1.0, 0.0)) | K19: 0 | L19: 0 | M19: 0 | N19: 0 | O19: 750 | P19: 750 | Q19: =K19+M19+O19 | R19: =L19+N19+P19 | S19: =R19-Q19
B20: ESPAÑA | C20: AGROSER BERNARDINO, S.L. | D20: AN0020 | E20: ALCAPLANT NEW, 20 KG | F20: 1100 | G20: 1100 | H20: =ABS(G20-F20) | I20: =IF(F20>0, G20/F20, IF(G20>0, 1.0, 0.0)) | K20: 2200 | L20: 2200 | M20: 3300 | N20: 3300 | O20: 1100 | P20: 1100 | Q20: =K20+M20+O20 | R20: =L20+N20+P20 | S20: =R20-Q20
B21: ESPAÑA | C21: AGROSER BERNARDINO, S.L. | D21: BIO0020 | E21: BIORAD-20, 20 L | F21: 0 | G21: 0 | H21: =ABS(G21-F21) | I21: =IF(F21>0, G21/F21, IF(G21>0, 1.0, 0.0)) | K21: 1280 | L21: 1280 | M21: 640 | N21: 640 | O21: 640 | P21: 640 | Q21: =K21+M21+O21 | R21: =L21+N21+P21 | S21: =R21-Q21
B22: ESPAÑA | C22: AGROSER BERNARDINO, S.L. | D22: BIO1000 | E22: BIORAD-20, 1000 L | F22: 0 | G22: 0 | H22: =ABS(G22-F22) | I22: =IF(F22>0, G22/F22, IF(G22>0, 1.0, 0.0)) | K22: 2000 | L22: 2000 | M22: 2000 | N22: 2000 | O22: 0 | P22: 0 | Q22: =K22+M22+O22 | R22: =L22+N22+P22 | S22: =R22-Q22
B23: ESPAÑA | C23: AGROSER BERNARDINO, S.L. | D23: C-CU0005 | E23: CODICOBRE, 5 L | F23: 0 | G23: 0 | H23: =ABS(G23-F23) | I23: =IF(F23>0, G23/F23, IF(G23>0, 1.0, 0.0)) | K23: 600 | L23: 600 | M23: 0 | N23: 0 | O23: 0 | P23: 0 | Q23: =K23+M23+O23 | R23: =L23+N23+P23 | S23: =R23-Q23
B24: ESPAÑA | C24: AGROSER BERNARDINO, S.L. | D24: FROST-P0020 | E24: CODIFROST PLUS, 20 L | F24: 0 | G24: 0 | H24: =ABS(G24-F24) | I24: =IF(F24>0, G24/F24, IF(G24>0, 1.0, 0.0)) | K24: 0 | L24: 0 | M24: 200 | N24: 200 | O24: 200 | P24: 200 | Q24: =K24+M24+O24 | R24: =L24+N24+P24 | S24: =R24-Q24
B25: ESPAÑA | C25: AGROSER BERNARDINO, S.L. | D25: PT0020 | E25: AGROPOTASION, 20 L | F25: 0 | G25: 0 | H25: =ABS(G25-F25) | I25: =IF(F25>0, G25/F25, IF(G25>0, 1.0, 0.0)) | K25: 640 | L25: 640 | M25: 640 | N25: 640 | O25: 0 | P25: 0 | Q25: =K25+M25+O25 | R25: =L25+N25+P25 | S25: =R25-Q25
B26: ESPAÑA | C26: AGROTRAPICHE, S.L.U | D26: A-50(2)0020 | E26: CODIORGAN-A50, 20 KG | F26: 200 | G26: 0 | H26: =ABS(G26-F26) | I26: =IF(F26>0, G26/F26, IF(G26>0, 1.0, 0.0)) | K26: 0 | L26: 0 | M26: 0 | N26: 0 | O26: 0 | P26: 0 | Q26: =K26+M26+O26 | R26: =L26+N26+P26 | S26: =R26-Q26
... B47: EGIPTO | C47: DOTRA CHEMICALS | D47: SSEG0020 | E47: SAL-WAX Ca | F47: 0 | G47: 0 | H47: =ABS(G47-F47) | I47: =IF(F47>0, G47/F47, IF(G47>0, 1.0, 0.0)) | K47: 0 | L47: 0 | M47: 10000 | N47: 10000 | O47: 0 | P47: 0 | Q47: =K47+M47+O47 | R47: =L47+N47+P47 | S47: =R47-Q47
B48: ARABIA SAUDÍ | C48: DOTRA GULF TRADING COMPANY | D48: AQUOMAR0005 | E48: AQUOM ARABIA, 5 L | F48: 0 | G48: 400 | H48: =ABS(G48-F48) | I48: =IF(F48>0, G48/F48, IF(G48>0, 1.0, 0.0)) | J48: Pedido extra no previsto | K48: 0 | L48: 0 | M48: 0 | N48: 0 | O48: 0 | P48: 0 | Q48: =K48+M48+O48 | R48: =L48+N48+P48 | S48: =R48-Q48
B49: ESPAÑA | C49: DOTRA GULF TRADING COMPANY | D49: AVAN0001 | E49: FLORAMEC AVANCE, 1 L | F49: 0 | G49: 504 | H49: =ABS(G49-F49) | I49: =IF(F49>0, G49/F49, IF(G49>0, 1.0, 0.0)) | J49: Pedido extra no previsto | K49: 0 | L49: 0 | M49: 0 | N49: 0 | O49: 0 | P49: 0 | Q49: =K49+M49+O49 | R49: =L49+N49+P49 | S49: =R49-Q49
B50: ARABIA SAUDÍ | C50: DOTRA GULF TRADING COMPANY | D50: BIO0005 | E50: BIORAD-20, 5L | F50: 0 | G50: 800 | H50: =ABS(G50-F50) | I50: =IF(F50>0, G50/F50, IF(G50>0, 1.0, 0.0)) | J50: Pedido extra no previsto | K50: 0 | L50: 0 | M50: 0 | N50: 0 | O50: 0 | P50: 0 | Q50: =K50+M50+O50 | R50: =L50+N50+P50 | S50: =R50-Q50
B51: ARABIA SAUDÍ | C51: DOTRA GULF TRADING COMPANY | D51: SPAR0001 | E51: SPRINTENE ARABIA, 1 L | F51: 0 | G51: 1080 | H51: =ABS(G51-F51) | I51: =IF(F51>0, G51/F51, IF(G51>0, 1.0, 0.0)) | J51: Pedido extra no previsto | K51: 0 | L51: 0 | M51: 0 | N51: 0 | O51: 0 | P51: 0 | Q51: =K51+M51+O51 | R51: =L51+N51+P51 | S51: =R51-Q51
B52: ARABIA SAUDÍ | C52: DOTRA GULF TRADING COMPANY | D52: SSEG0005 | E52: SALWAX CALCIO EGIPTO, 5 KG | F52: 0 | G52: 17500 | H52: =ABS(G52-F52) | I52: =IF(F52>0, G52/F52, IF(G52>0, 1.0, 0.0)) | J52: Pedido extra no previsto | K52: 0 | L52: 0 | M52: 0 | N52: 0 | O52: 0 | P52: 0 | Q52: =K52+M52+O52 | R52: =L52+N52+P52 | S52: =R52-Q52
B53: ESPAÑA | C53: ECO-PONIENTE, S.L.U. | D53: AGXKAE0020 | E53: BIOCULTURE POTASIO, 20 L | F53: 0 | G53: 0 | H53: =ABS(G53-F53) | I53: =IF(F53>0, G53/F53, IF(G53>0, 1.0, 0.0)) | K53: 0 | L53: 0 | M53: 0 | N53: 0 | O53: 640 | P53: 640 | Q53: =K53+M53+O53 | R53: =L53+N53+P53 | S53: =R53-Q53
B54: ESPAÑA | C54: EL PINAR BERRIES, S.L. | D54: AN0005 | E54: ALCAPLANT NEW, 5 KG | F54: 0 | G54: 1100 | H54: =ABS(G54-F54) | I54: =IF(F54>0, G54/F54, IF(G54>0, 1.0, 0.0)) | J54: Pedido extra no previsto | K54: 0 | L54: 0 | M54: 0 | N54: 0 | O54: 0 | P54: 0 | Q54: =K54+M54+O54 | R54: =L54+N54+P54 | S54: =R54-Q54
B55: GRECIA | C55: EMPHYTON SERVICE P.C. | D55: GRE10001 | E55: TONAZ | F55: 0 | G55: 0 | H55: =ABS(G55-F55) | I55: =IF(F55>0, G55/F55, IF(G55>0, 1.0, 0.0)) | K55: 0 | L55: 0 | M55: 0 | N55: 0 | O55: 8000 | P55: 8000 | Q55: =K55+M55+O55 | R55: =L55+N55+P55 | S55: =R55-Q55
B56: GRECIA | C56: EMPHYTON SERVICE P.C. | D56: GRE10005 | E56: TONAZ | F56: 0 | G56: 0 | H56: =ABS(G56-F56) | I56: =IF(F56>0, G56/F56, IF(G56>0, 1.0, 0.0)) | K56: 0 | L56: 0 | M56: 0 | N56: 0 | O56: 4000 | P56: 4000 | Q56: =K56+M56+O56 | R56: =L56+N56+P56 | S56: =R56-Q56
B57: GRECIA | C57: EMPHYTON SERVICE P.C. | D57: VITA0001 | E57: VITA-S | F57: 0 | G57: 0 | H57: =ABS(G57-F57) | I57: =IF(F57>0, G57/F57, IF(G57>0, 1.0, 0.0)) | K57: 0 | L57: 0 | M57: 0 | N57: 0 | O57: 10000 | P57: 10000 | Q57: =K57+M57+O57 | R57: =L57+N57+P57 | S57: =R57-Q57
B58: GRECIA | C58: EMPHYTON SERVICE P.C. | D58: VITA0005 | E58: VITA-S | F58: 0 | G58: 0 | H58: =ABS(G58-F58) | I58: =IF(F58>0, G58/F58, IF(G58>0, 1.0, 0.0)) | K58: 0 | L58: 0 | M58: 0 | N58: 0 | O58: 10000 | P58: 10000 | Q58: =K58+M58+O58 | R58: =L58+N58+P58 | S58: =R58-Q58
B59: GRECIA | C59: GEORGIOS POULTSIDIS | D59: GRE20005 | E59: EGERSIS, 5 L | F59: 0 | G59: 0 | H59: =ABS(G59-F59) | I59: =IF(F59>0, G59/F59, IF(G59>0, 1.0, 0.0)) | K59: 0 | L59: 0 | M59: 0 | N59: 0 | O59: 2000 | P59: 2000 | Q59: =K59+M59+O59 | R59: =L59+N59+P59 | S59: =R59-Q59
B60: ESPAÑA | C60: HORTOFRUTICOLA COSTA DE ALMERÍA, S.L. | D60: AGXK0020 | E60: AGROXILATO-K, 20 L | F60: 0 | G60: 0 | H60: =ABS(G60-F60) | I60: =IF(F60>0, G60/F60, IF(G60>0, 1.0, 0.0)) | K60: 0 | L60: 0 | M60: 0 | N60: 0 | O60: 1280 | P60: 1280 | Q60: =K60+M60+O60 | R60: =L60+N60+P60 | S60: =R60-Q60
B61: ESPAÑA | C61: INIESTA DEL PINO DISTRIBUCIONES S.L.U | D61: A-50(2)0005 | E61: CODIORGAN-A50, 5 KG | F61: 0 | G61: 0 | H61: =ABS(G61-F61) | I61: =IF(F61>0, G61/F61, IF(G61>0, 1.0, 0.0)) | K61: 0 | L61: 0 | M61: 0 | N61: 0 | O61: 25 | P61: 25 | Q61: =K61+M61+O61 | R61: =L61+N61+P61 | S61: =R61-Q61
B62: ESPAÑA | C62: INIESTA DEL PINO DISTRIBUCIONES S.L.U | D62: AGXK0020 | E62: AGROXILATO-K, 20 L | F62: 640 | G62: 0 | H62: =ABS(G62-F62) | I62: =IF(F62>0, G62/F62, IF(G62>0, 1.0, 0.0)) | K62: 1920 | L62: 1920 | M62: 0 | N62: 0 | O62: 0 | P62: 0 | Q62: =K62+M62+O62 | R62: =L62+N62+P62 | S62: =R62-Q62
...

Sheet Irene
B2: CODIAGRO · ACTUALIZACIÓN DE PREVISIONES COMERCIALES Q4 2026 (OCTUBRE - DICIEMBRE)
B3: DELEGADO COMERCIAL: IRENE | Cierre Septiembre Oficial (01/10/2026) vs Previsiones a Final de Año | Generado: 01/10/2026 14:17
B4: 📌 INSTRUCCIONES: 1) Revise el bloque de SEPTIEMBRE (Previsto, Real, Desviación en Valor Absoluto y % Consecución) e indique en col. J el motivo de la desviación (adelanto, atraso, extra). 2) En las columnas verdes (L, N, P), revise y actualice las cantidades estimadas de Octubre, Noviembre y Diciembre si prevé cambios. 3) Comente en col. T cualquier nota de campaña.
B5: PREVISTO SEP 2026 (U) | E5: REAL PEDIDOS SEP 2026 (U) | H5: % CONSECUCIÓN SEP | K5: PREVISIÓN INICIAL Q4 (U) | N5: PREVISIÓN REVISADA Q4 (U) | Q5: VARIACIÓN NETA Q4 (U)
B6: =F74 | E6: =G74 | H6: =I74 | K6: =Q74 | N6: =R74 | Q6: =S74
B8: DATOS CLIENTE Y ARTÍCULO | F8: CIERRE SEPTIEMBRE 2026 (CALIBRACIÓN Y ANÁLISIS) | K8: REVISIÓN PREVISIONES MES A MES (HASTA FINAL DE AÑO 2026) | Q8: IMPACTO Q4 Y JUSTIFICACIÓN
B9: País | C9: Cliente | D9: Cód. SKU | E9: Descripción Artículo | F9: Sep Previsto (u) | G9: Sep Real (u) | H9: Desv. Sep (u) | I9: % Consec. | J9: Comentario Sep (¿Adelanto/Atraso/Extra?) | K9: Oct Anterior (u) | L9: Oct Revisado (u) | M9: Nov Anterior (u) | N9: Nov Revisado (u) | O9: Dic Anterior (u) | P9: Dic Revisado (u) | Q9: Total Q4 Ant (u) | R9: Total Q4 Rev (u) | S9: Dif Q4 (u) | T9: Comentarios / Justificación Q4
B10: ESPAÑA | C10: CAMPOEJIDO S.C.A. | D10: A-50(2)0005 | E10: CODIORGAN-A50, 5 KG | F10: 200 | G10: 100 | H10: =ABS(G10-F10) | I10: =IF(F10>0, G10/F10, IF(G10>0, 1.0, 0.0)) | K10: 0 | L10: 0 | M10: 0 | N10: 0 | O10: 200 | P10: 200 | Q10: =K10+M10+O10 | R10: =L10+N10+P10 | S10: =R10-Q10
B11: ESPAÑA | C11: CAMPOEJIDO S.C.A. | D11: AGN0005 | E11: AGROXILATO N, 5 L | F11: 0 | G11: 20 | H11: =ABS(G11-F11) | I11: =IF(F11>0, G11/F11, IF(G11>0, 1.0, 0.0)) | J11: Pedido extra no previsto | K11: 0 | L11: 0 | M11: 0 | N11: 0 | O11: 0 | P11: 0 | Q11: =K11+M11+O11 | R11: =L11+N11+P11 | S11: =R11-Q11
B12: ESPAÑA | C12: CAMPOEJIDO S.C.A. | D12: AGXK0020 | E12: AGROXILATO-K, 20 L | F12: 1920 | G12: 640 | H12: =ABS(G12-F12) | I12: =IF(F12>0, G12/F12, IF(G12>0, 1.0, 0.0)) | K12: 5060 | L12: 5060 | M12: 1920 | N12: 1920 | O12: 3200 | P12: 3200 | Q12: =K12+M12+O12 | R12: =L12+N12+P12 | S12: =R12-Q12
B13: ESPAÑA | C13: CAMPOEJIDO S.C.A. | D13: AVAN0005 | E13: FLORAMEC AVANCE, 5 L | F13: 300 | G13: 0 | H13: =ABS(G13-F13) | I13: =IF(F13>0, G13/F13, IF(G13>0, 1.0, 0.0)) | K13: 300 | L13: 300 | M13: 0 | N13: 0 | O13: 300 | P13: 300 | Q13: =K13+M13+O13 | R13: =L13+N13+P13 | S13: =R13-Q13
B14: ESPAÑA | C14: CAMPOEJIDO S.C.A. | D14: AVAN0020 | E14: FLORAMEC AVANCE, 20 L | F14: 960 | G14: 2560 | H14: =ABS(G14-F14) | I14: =IF(F14>0, G14/F14, IF(G14>0, 1.0, 0.0)) | K14: 640 | L14: 640 | M14: 960 | N14: 960 | O14: 1280 | P14: 1280 | Q14: =K14+M14+O14 | R14: =L14+N14+P14 | S14: =R14-Q14
B15: ESPAÑA | C15: CAMPOEJIDO S.C.A. | D15: B0001 | E15: BOROCAL,1 L | F15: 0 | G15: 0 | H15: =ABS(G15-F15) | I15: =IF(F15>0, G15/F15, IF(G15>0, 1.0, 0.0)) | K15: 0 | L15: 0 | M15: 0 | N15: 0 | O15: 36 | P15: 36 | Q15: =K15+M15+O15 | R15: =L15+N15+P15 | S15: =R15-Q15
B16: ESPAÑA | C16: CAMPOEJIDO S.C.A. | D16: B0005 | E16: BOROCAL, 5 L | F16: 0 | G16: 0 | H16: =ABS(G16-F16) | I16: =IF(F16>0, G16/F16, IF(G16>0, 1.0, 0.0)) | K16: 100 | L16: 100 | M16: 0 | N16: 0 | O16: 100 | P16: 100 | Q16: =K16+M16+O16 | R16: =L16+N16+P16 | S16: =R16-Q16
B17: ESPAÑA | C17: CAMPOEJIDO S.C.A. | D17: BIO0020 | E17: BIORAD-20, 20 L | F17: 640 | G17: 640 | H17: =ABS(G17-F17) | I17: =IF(F17>0, G17/F17, IF(G17>0, 1.0, 0.0)) | K17: 640 | L17: 640 | M17: 640 | N17: 640 | O17: 640 | P17: 640 | Q17: =K17+M17+O17 | R17: =L17+N17+P17 | S17: =R17-Q17
B18: ESPAÑA | C18: CAMPOEJIDO S.C.A. | D18: BROTA0005 | E18: BROTAMEC, 5 L | F18: 0 | G18: 0 | H18: =ABS(G18-F18) | I18: =IF(F18>0, G18/F18, IF(G18>0, 1.0, 0.0)) | K18: 200 | L18: 200 | M18: 100 | N18: 100 | O18: 100 | P18: 100 | Q18: =K18+M18+O18 | R18: =L18+N18+P18 | S18: =R18-Q18
B19: ESPAÑA | C19: CAMPOEJIDO S.C.A. | D19: C-CUAE0005 | E19: CUPRAMEC, 5 L | F19: 0 | G19: 0 | H19: =ABS(G19-F19) | I19: =IF(F19>0, G19/F19, IF(G19>0, 1.0, 0.0)) | K19: 0 | L19: 0 | M19: 600 | N19: 600 | O19: 300 | P19: 300 | Q19: =K19+M19+O19 | R19: =L19+N19+P19 | S19: =R19-Q19
B20: ESPAÑA | C20: CAMPOEJIDO S.C.A. | D20: C-GLB0001 | E20: CODIORGAN GLB, 1 KG | F20: 60 | G20: 0 | H20: =ABS(G20-F20) | I20: =IF(F20>0, G20/F20, IF(G20>0, 1.0, 0.0)) | K20: 120 | L20: 120 | M20: 108 | N20: 108 | O20: 108 | P20: 108 | Q20: =K20+M20+O20 | R20: =L20+N20+P20 | S20: =R20-Q20
B21: ESPAÑA | C21: CAMPOEJIDO S.C.A. | D21: C-L0005 | E21: CODIBOR-L, 5 L | F21: 300 | G21: 0 | H21: =ABS(G21-F21) | I21: =IF(F21>0, G21/F21, IF(G21>0, 1.0, 0.0)) | K21: 0 | L21: 0 | M21: 400 | N21: 400 | O21: 300 | P21: 300 | Q21: =K21+M21+O21 | R21: =L21+N21+P21 | S21: =R21-Q21
B22: ESPAÑA | C22: CAMPOEJIDO S.C.A. | D22: C-MB0001 | E22: CODIFOL-MB, 1 L | F22: 48 | G22: 36 | H22: =ABS(G22-F22) | I22: =IF(F22>0, G22/F22, IF(G22>0, 1.0, 0.0)) | K22: 0 | L22: 0 | M22: 0 | N22: 0 | O22: 0 | P22: 0 | Q22: =K22+M22+O22 | R22: =L22+N22+P22 | S22: =R22-Q22
B23: ESPAÑA | C23: CAMPOEJIDO S.C.A. | D23: C-MB0005 | E23: CODIFOL-MB, 5 L | F23: 400 | G23: 1300 | H23: =ABS(G23-F23) | I23: =IF(F23>0, G23/F23, IF(G23>0, 1.0, 0.0)) | K23: 120 | L23: 120 | M23: 200 | N23: 200 | O23: 300 | P23: 300 | Q23: =K23+M23+O23 | R23: =L23+N23+P23 | S23: =R23-Q23
... B27: ESPAÑA | C27: CAMPOEJIDO S.C.A. | D27: HST0005 | E27: HIDROSTRESS, 5 L | F27: 0 | G27: 0 | H27: =ABS(G27-F27) | I27: =IF(F27>0, G27/F27, IF(G27>0, 1.0, 0.0)) | K27: 0 | L27: 0 | M27: 0 | N27: 0 | O27: 100 | P27: 100 | Q27: =K27+M27+O27 | R27: =L27+N27+P27 | S27: =R27-Q27
B28: ESPAÑA | C28: CAMPOEJIDO S.C.A. | D28: PHD0001 | E28: PH-DOWNER, 1 L | F28: 0 | G28: 48 | H28: =ABS(G28-F28) | I28: =IF(F28>0, G28/F28, IF(G28>0, 1.0, 0.0)) | J28: Pedido extra no previsto | K28: 0 | L28: 0 | M28: 0 | N28: 0 | O28: 0 | P28: 0 | Q28: =K28+M28+O28 | R28: =L28+N28+P28 | S28: =R28-Q28
B29: ESPAÑA | C29: CAMPOEJIDO S.C.A. | D29: PHD0005 | E29: PH-DOWNER, 5 L | F29: 100 | G29: 300 | H29: =ABS(G29-F29) | I29: =IF(F29>0, G29/F29, IF(G29>0, 1.0, 0.0)) | K29: 0 | L29: 0 | M29: 100 | N29: 100 | O29: 0 | P29: 0 | Q29: =K29+M29+O29 | R29: =L29+N29+P29 | S29: =R29-Q29
B30: ESPAÑA | C30: CAMPOEJIDO S.C.A. | D30: PIV0020 | E30: PGR IV, 20 L | F30: 3200 | G30: 640 | H30: =ABS(G30-F30) | I30: =IF(F30>0, G30/F30, IF(G30>0, 1.0, 0.0)) | K30: 1280 | L30: 1280 | M30: 1920 | N30: 1920 | O30: 640 | P30: 640 | Q30: =K30+M30+O30 | R30: =L30+N30+P30 | S30: =R30-Q30
B31: ESPAÑA | C31: CAMPOEJIDO S.C.A. | D31: PT0005 | E31: AGROPOTASION, 5 L | F31: 0 | G31: 0 | H31: =ABS(G31-F31) | I31: =IF(F31>0, G31/F31, IF(G31>0, 1.0, 0.0)) | K31: 100 | L31: 100 | M31: 0 | N31: 0 | O31: 100 | P31: 100 | Q31: =K31+M31+O31 | R31: =L31+N31+P31 | S31: =R31-Q31
B32: ESPAÑA | C32: CAMPOEJIDO S.C.A. | D32: S0020 | E32: SAL-WAX STAR, 20 L | F32: 640 | G32: 0 | H32: =ABS(G32-F32) | I32: =IF(F32>0, G32/F32, IF(G32>0, 1.0, 0.0)) | K32: 0 | L32: 0 | M32: 0 | N32: 0 | O32: 0 | P32: 0 | Q32: =K32+M32+O32 | R32: =L32+N32+P32 | S32: =R32-Q32
B33: ESPAÑA | C33: CAMPOEJIDO S.C.A. | D33: TRI0001 | E33: TRIFENO-94, 1 L | F33: 0 | G33: 0 | H33: =ABS(G33-F33) | I33: =IF(F33>0, G33/F33, IF(G33>0, 1.0, 0.0)) | K33: 0 | L33: 0 | M33: 0 | N33: 0 | O33: 108 | P33: 108 | Q33: =K33+M33+O33 | R33: =L33+N33+P33 | S33: =R33-Q33
B34: ESPAÑA | C34: CAMPOEJIDO S.C.A. | D34: TRI0005 | E34: TRIFENO-94, 5L | F34: 100 | G34: 100 | H34: =ABS(G34-F34) | I34: =IF(F34>0, G34/F34, IF(G34>0, 1.0, 0.0)) | K34: 100 | L34: 100 | M34: 100 | N34: 100 | O34: 200 | P34: 200 | Q34: =K34+M34+O34 | R34: =L34+N34+P34 | S34: =R34-Q34
B35: ESPAÑA | C35: COOP.AGRIC. SAN ISIDRO S.C.A. | D35: A-50(2)0005 | E35: CODIORGAN-A50, 5 KG | F35: 0 | G35: 0 | H35: =ABS(G35-F35) | I35: =IF(F35>0, G35/F35, IF(G35>0, 1.0, 0.0)) | K35: 0 | L35: 0 | M35: 0 | N35: 0 | O35: 200 | P35: 200 | Q35: =K35+M35+O35 | R35: =L35+N35+P35 | S35: =R35-Q35
B36: ESPAÑA | C36: COOP.AGRIC. SAN ISIDRO S.C.A. | D36: AGXK0020 | E36: AGROXILATO-K, 20 L | F36: 3200 | G36: 0 | H36: =ABS(G36-F36) | I36: =IF(F36>0, G36/F36, IF(G36>0, 1.0, 0.0)) | K36: 5120 | L36: 5120 | M36: 3840 | N36: 3840 | O36: 7040 | P36: 7040 | Q36: =K36+M36+O36 | R36: =L36+N36+P36 | S36: =R36-Q36
B37: ESPAÑA | C37: COOP.AGRIC. SAN ISIDRO S.C.A. | D37: AGXK0200 | E37: AGROXILATO-K, 200 L | F37: 400 | G37: 0 | H37: =ABS(G37-F37) | I37: =IF(F37>0, G37/F37, IF(G37>0, 1.0, 0.0)) | K37: 0 | L37: 0 | M37: 0 | N37: 0 | O37: 0 | P37: 0 | Q37: =K37+M37+O37 | R37: =L37+N37+P37 | S37: =R37-Q37
B38: ESPAÑA | C38: COOP.AGRIC. SAN ISIDRO S.C.A. | D38: AGZ-M0001 | E38: AGROXILATO-ZN-MN, 1 KG | F38: 0 | G38: 0 | H38: =ABS(G38-F38) | I38: =IF(F38>0, G38/F38, IF(G38>0, 1.0, 0.0)) | K38: 0 | L38: 0 | M38: 112 | N38: 112 | O38: 0 | P38: 0 | Q38: =K38+M38+O38 | R38: =L38+N38+P38 | S38: =R38-Q38
B39: ESPAÑA | C39: COOP.AGRIC. SAN ISIDRO S.C.A. | D39: AGZ-M0005 | E39: AGROXILATO-ZN-MN, 5 KG | F39: 0 | G39: 0 | H39: =ABS(G39-F39) | I39: =IF(F39>0, G39/F39, IF(G39>0, 1.0, 0.0)) | K39: 0 | L39: 0 | M39: 0 | N39: 0 | O39: 200 | P39: 200 | Q39: =K39+M39+O39 | R39: =L39+N39+P39 | S39: =R39-Q39
B40: ESPAÑA | C40: COOP.AGRIC. SAN ISIDRO S.C.A. | D40: AMIMG0020 | E40: AMINOSOIL MG, 20 L | F40: 0 | G40: 0 | H40: =ABS(G40-F40) | I40: =IF(F40>0, G40/F40, IF(G40>0, 1.0, 0.0)) | K40: 0 | L40: 0 | M40: 640 | N40: 640 | O40: 300 | P40: 300 | Q40: =K40+M40+O40 | R40: =L40+N40+P40 | S40: =R40-Q40
... B54: ESPAÑA | C54: GUIVARTO AGRICOLA, S.L. | D54: AGXK0020 | E54: AGROXILATO-K, 20 L | F54: 1240 | G54: 0 | H54: =ABS(G54-F54) | I54: =IF(F54>0, G54/F54, IF(G54>0, 1.0, 0.0)) | K54: 2480 | L54: 2480 | M54: 1240 | N54: 1240 | O54: 1960 | P54: 1960 | Q54: =K54+M54+O54 | R54: =L54+N54+P54 | S54: =R54-Q54
B55: ESPAÑA | C55: GUIVARTO AGRICOLA, S.L. | D55: AGXK1000 | E55: AGROXILATO-K, 1000 L | F55: 0 | G55: 8000 | H55: =ABS(G55-F55) | I55: =IF(F55>0, G55/F55, IF(G55>0, 1.0, 0.0)) | J55: Pedido extra no previsto | K55: 0 | L55: 0 | M55: 1000 | N55: 1000 | O55: 0 | P55: 0 | Q55: =K55+M55+O55 | R55: =L55+N55+P55 | S55: =R55-Q55
B56: ESPAÑA | C56: GUIVARTO AGRICOLA, S.L. | D56: AGZNP0005 | E56: AGROXILATO-ZN PLUS, 5 KG | F56: 50 | G56: 50 | H56: =ABS(G56-F56) | I56: =IF(F56>0, G56/F56, IF(G56>0, 1.0, 0.0)) | K56: 0 | L56: 0 | M56: 0 | N56: 0 | O56: 0 | P56: 0 | Q56: =K56+M56+O56 | R56: =L56+N56+P56 | S56: =R56-Q56
B57: ESPAÑA | C57: GUIVARTO AGRICOLA, S.L. | D57: AQUOM0005 | E57: AQUOM, 5 L | F57: 200 | G57: 200 | H57: =ABS(G57-F57) | I57: =IF(F57>0, G57/F57, IF(G57>0, 1.0, 0.0)) | K57: 0 | L57: 0 | M57: 0 | N57: 0 | O57: 0 | P57: 0 | Q57: =K57+M57+O57 | R57: =L57+N57+P57 | S57: =R57-Q57
B58: ESPAÑA | C58: GUIVARTO AGRICOLA, S.L. | D58: AVAN0005 | E58: FLORAMEC AVANCE, 5 L | F58: 0 | G58: 0 | H58: =ABS(G58-F58) | I58: =IF(F58>0, G58/F58, IF(G58>0, 1.0, 0.0)) | K58: 300 | L58: 300 | M58: 300 | N58: 300 | O58: 300 | P58: 300 | Q58: =K58+M58+O58 | R58: =L58+N58+P58 | S58: =R58-Q58
...

Sheet Javier
B2: CODIAGRO · ACTUALIZACIÓN DE PREVISIONES COMERCIALES Q4 2026 (OCTUBRE - DICIEMBRE)
B3: DELEGADO COMERCIAL: JAVIER | Cierre Septiembre Oficial (01/10/2026) vs Previsiones a Final de Año | Generado: 01/10/2026 14:17
B4: 📌 INSTRUCCIONES: 1) Revise el bloque de SEPTIEMBRE (Previsto, Real, Desviación en Valor Absoluto y % Consecución) e indique en col. J el motivo de la desviación (adelanto, atraso, extra). 2) En las columnas verdes (L, N, P), revise y actualice las cantidades estimadas de Octubre, Noviembre y Diciembre si prevé cambios. 3) Comente en col. T cualquier nota de campaña.
B5: PREVISTO SEP 2026 (U) | E5: REAL PEDIDOS SEP 2026 (U) | H5: % CONSECUCIÓN SEP | K5: PREVISIÓN INICIAL Q4 (U) | N5: PREVISIÓN REVISADA Q4 (U) | Q5: VARIACIÓN NETA Q4 (U)
B6: =F82 | E6: =G82 | H6: =I82 | K6: =Q82 | N6: =R82 | Q6: =S82
B8: DATOS CLIENTE Y ARTÍCULO | F8: CIERRE SEPTIEMBRE 2026 (CALIBRACIÓN Y ANÁLISIS) | K8: REVISIÓN PREVISIONES MES A MES (HASTA FINAL DE AÑO 2026) | Q8: IMPACTO Q4 Y JUSTIFICACIÓN
B9: País | C9: Cliente | D9: Cód. SKU | E9: Descripción Artículo | F9: Sep Previsto (u) | G9: Sep Real (u) | H9: Desv. Sep (u) | I9: % Consec. | J9: Comentario Sep (¿Adelanto/Atraso/Extra?) | K9: Oct Anterior (u) | L9: Oct Revisado (u) | M9: Nov Anterior (u) | N9: Nov Revisado (u) | O9: Dic Anterior (u) | P9: Dic Revisado (u) | Q9: Total Q4 Ant (u) | R9: Total Q4 Rev (u) | S9: Dif Q4 (u) | T9: Comentarios / Justificación Q4
B10: ESPAÑA | C10: AGROQUIMICAS DRAGO S.L. | D10: AGXK0020 | E10: AGROXILATO-K, 20 L | F10: 0 | G10: 0 | H10: =ABS(G10-F10) | I10: =IF(F10>0, G10/F10, IF(G10>0, 1.0, 0.0)) | K10: 640 | L10: 640 | M10: 1280 | N10: 1280 | O10: 640 | P10: 640 | Q10: =K10+M10+O10 | R10: =L10+N10+P10 | S10: =R10-Q10
B11: ESPAÑA | C11: AGROQUIMICAS DRAGO S.L. | D11: AGXK0200 | E11: AGROXILATO-K, 200 L | F11: 1600 | G11: 3200 | H11: =ABS(G11-F11) | I11: =IF(F11>0, G11/F11, IF(G11>0, 1.0, 0.0)) | K11: 1600 | L11: 1600 | M11: 1600 | N11: 1600 | O11: 1600 | P11: 1600 | Q11: =K11+M11+O11 | R11: =L11+N11+P11 | S11: =R11-Q11
B12: ESPAÑA | C12: AGROQUIMICAS DRAGO S.L. | D12: AGXK1000 | E12: AGROXILATO-K, 1000 L | F12: 0 | G12: 1000 | H12: =ABS(G12-F12) | I12: =IF(F12>0, G12/F12, IF(G12>0, 1.0, 0.0)) | J12: Pedido extra no previsto | K12: 0 | L12: 0 | M12: 0 | N12: 0 | O12: 0 | P12: 0 | Q12: =K12+M12+O12 | R12: =L12+N12+P12 | S12: =R12-Q12
B13: ESPAÑA | C13: AGROQUIMICAS DRAGO S.L. | D13: AN0020 | E13: ALCAPLANT NEW, 20 KG | F13: 1100 | G13: 1100 | H13: =ABS(G13-F13) | I13: =IF(F13>0, G13/F13, IF(G13>0, 1.0, 0.0)) | K13: 2200 | L13: 2200 | M13: 1100 | N13: 1100 | O13: 0 | P13: 0 | Q13: =K13+M13+O13 | R13: =L13+N13+P13 | S13: =R13-Q13
B14: ESPAÑA | C14: AGROQUIMICAS DRAGO S.L. | D14: AVAN0020 | E14: FLORAMEC AVANCE, 20 L | F14: 0 | G14: 0 | H14: =ABS(G14-F14) | I14: =IF(F14>0, G14/F14, IF(G14>0, 1.0, 0.0)) | K14: 300 | L14: 300 | M14: 300 | N14: 300 | O14: 0 | P14: 0 | Q14: =K14+M14+O14 | R14: =L14+N14+P14 | S14: =R14-Q14
B15: ESPAÑA | C15: AGROQUIMICAS DRAGO S.L. | D15: B0005 | E15: BOROCAL, 5 L | F15: 0 | G15: 40 | H15: =ABS(G15-F15) | I15: =IF(F15>0, G15/F15, IF(G15>0, 1.0, 0.0)) | J15: Pedido extra no previsto | K15: 0 | L15: 0 | M15: 0 | N15: 0 | O15: 0 | P15: 0 | Q15: =K15+M15+O15 | R15: =L15+N15+P15 | S15: =R15-Q15
B16: ESPAÑA | C16: AGROQUIMICAS DRAGO S.L. | D16: B0020 | E16: BOROCAL, 20 L | F16: 0 | G16: 100 | H16: =ABS(G16-F16) | I16: =IF(F16>0, G16/F16, IF(G16>0, 1.0, 0.0)) | J16: Pedido extra no previsto | K16: 0 | L16: 0 | M16: 0 | N16: 0 | O16: 0 | P16: 0 | Q16: =K16+M16+O16 | R16: =L16+N16+P16 | S16: =R16-Q16
B17: ESPAÑA | C17: AGROQUIMICAS DRAGO S.L. | D17: BIO0020 | E17: BIORAD-20, 20 L | F17: 0 | G17: 0 | H17: =ABS(G17-F17) | I17: =IF(F17>0, G17/F17, IF(G17>0, 1.0, 0.0)) | K17: 640 | L17: 640 | M17: 640 | N17: 640 | O17: 0 | P17: 0 | Q17: =K17+M17+O17 | R17: =L17+N17+P17 | S17: =R17-Q17
B18: ESPAÑA | C18: AGROQUIMICAS DRAGO S.L. | D18: C-CU0005 | E18: CODICOBRE, 5 L | F18: 0 | G18: 0 | H18: =ABS(G18-F18) | I18: =IF(F18>0, G18/F18, IF(G18>0, 1.0, 0.0)) | K18: 100 | L18: 100 | M18: 300 | N18: 300 | O18: 0 | P18: 0 | Q18: =K18+M18+O18 | R18: =L18+N18+P18 | S18: =R18-Q18
B19: ESPAÑA | C19: AGROQUIMICAS DRAGO S.L. | D19: CALCIO0020 | E19: CALCIAMEC, 20 KG | F19: 0 | G19: 60 | H19: =ABS(G19-F19) | I19: =IF(F19>0, G19/F19, IF(G19>0, 1.0, 0.0)) | J19: Pedido extra no previsto | K19: 0 | L19: 0 | M19: 200 | N19: 200 | O19: 0 | P19: 0 | Q19: =K19+M19+O19 | R19: =L19+N19+P19 | S19: =R19-Q19
B20: ESPAÑA | C20: AGROQUIMICAS DRAGO S.L. | D20: CM3M0005 | E20: TENSOLINE-MAX, 5 L | F20: 0 | G20: 60 | H20: =ABS(G20-F20) | I20: =IF(F20>0, G20/F20, IF(G20>0, 1.0, 0.0)) | J20: Pedido extra no previsto | K20: 0 | L20: 0 | M20: 0 | N20: 0 | O20: 0 | P20: 0 | Q20: =K20+M20+O20 | R20: =L20+N20+P20 | S20: =R20-Q20
B21: ESPAÑA | C21: AGROQUIMICAS DRAGO S.L. | D21: CPLUS0020 | E21: CALCIPLUS, 20 L | F21: 0 | G21: 200 | H21: =ABS(G21-F21) | I21: =IF(F21>0, G21/F21, IF(G21>0, 1.0, 0.0)) | J21: Pedido extra no previsto | K21: 640 | L21: 640 | M21: 640 | N21: 640 | O21: 0 | P21: 0 | Q21: =K21+M21+O21 | R21: =L21+N21+P21 | S21: =R21-Q21
B22: ESPAÑA | C22: AGROQUIMICAS DRAGO S.L. | D22: CPLUS0200 | E22: CALCIPLUS, 200 L | F22: 0 | G22: 0 | H22: =ABS(G22-F22) | I22: =IF(F22>0, G22/F22, IF(G22>0, 1.0, 0.0)) | K22: 0 | L22: 0 | M22: 800 | N22: 800 | O22: 0 | P22: 0 | Q22: =K22+M22+O22 | R22: =L22+N22+P22 | S22: =R22-Q22
B23: ESPAÑA | C23: AGROQUIMICAS DRAGO S.L. | D23: CPLUS1000 | E23: CALCIPLUS, 1000 L | F23: 0 | G23: 0 | H23: =ABS(G23-F23) | I23: =IF(F23>0, G23/F23, IF(G23>0, 1.0, 0.0)) | K23: 2000 | L23: 2000 | M23: 2000 | N23: 2000 | O23: 0 | P23: 0 | Q23: =K23+M23+O23 | R23: =L23+N23+P23 | S23: =R23-Q23
B24: ESPAÑA | C24: AGROQUIMICAS DRAGO S.L. | D24: FLOR0200 | E24: FLORAMEC, 200 L | F24: 0 | G24: 0 | H24: =ABS(G24-F24) | I24: =IF(F24>0, G24/F24, IF(G24>0, 1.0, 0.0)) | K24: 200 | L24: 200 | M24: 0 | N24: 0 | O24: 0 | P24: 0 | Q24: =K24+M24+O24 | R24: =L24+N24+P24 | S24: =R24-Q24
B25: ESPAÑA | C25: AGROQUIMICAS DRAGO S.L. | D25: FTK0005 | E25: FITOKONTROL CA FLOW, 5 KG | F25: 0 | G25: 40 | H25: =ABS(G25-F25) | I25: =IF(F25>0, G25/F25, IF(G25>0, 1.0, 0.0)) | J25: Pedido extra no previsto | K25: 0 | L25: 0 | M25: 0 | N25: 0 | O25: 0 | P25: 0 | Q25: =K25+M25+O25 | R25: =L25+N25+P25 | S25: =R25-Q25
B26: ESPAÑA | C26: AGROQUIMICAS DRAGO S.L. | D26: JF0020 | E26: DRAGO-FOS, 20 L | F26: 0 | G26: 1280 | H26: =ABS(G26-F26) | I26: =IF(F26>0, G26/F26, IF(G26>0, 1.0, 0.0)) | J26: Pedido extra no previsto | K26: 0 | L26: 0 | M26: 640 | N26: 640 | O26: 0 | P26: 0 | Q26: =K26+M26+O26 | R26: =L26+N26+P26 | S26: =R26-Q26
B27: ESPAÑA | C27: AGROQUIMICAS DRAGO S.L. | D27: PHD0005 | E27: PH-DOWNER, 5 L | F27: 0 | G27: 40 | H27: =ABS(G27-F27) | I27: =IF(F27>0, G27/F27, IF(G27>0, 1.0, 0.0)) | J27: Pedido extra no previsto | K27: 0 | L27: 0 | M27: 0 | N27: 0 | O27: 0 | P27: 0 | Q27: =K27+M27+O27 | R27: =L27+N27+P27 | S27: =R27-Q27
B28: ESPAÑA | C28: AGROQUIMICAS DRAGO S.L. | D28: PT0020 | E28: AGROPOTASION, 20 L | F28: 0 | G28: 0 | H28: =ABS(G28-F28) | I28: =IF(F28>0, G28/F28, IF(G28>0, 1.0, 0.0)) | K28: 640 | L28: 640 | M28: 640 | N28: 640 | O28: 0 | P28: 0 | Q28: =K28+M28+O28 | R28: =L28+N28+P28 | S28: =R28-Q28
B29: ESPAÑA | C29: AGROQUIMICAS DRAGO S.L. | D29: PT0200 | E29: AGROPOTASION, 200 L | F29: 0 | G29: 0 | H29: =ABS(G29-F29) | I29: =IF(F29>0, G29/F29, IF(G29>0, 1.0, 0.0)) | K29: 200 | L29: 200 | M29: 200 | N29: 200 | O29: 0 | P29: 0 | Q29: =K29+M29+O29 | R29: =L29+N29+P29 | S29: =R29-Q29
B30: ESPAÑA | C30: AGROQUIMICAS DRAGO S.L. | D30: S0020 | E30: SAL-WAX STAR, 20 L | F30: 0 | G30: 1280 | H30: =ABS(G30-F30) | I30: =IF(F30>0, G30/F30, IF(G30>0, 1.0, 0.0)) | J30: Pedido extra no previsto | K30: 1280 | L30: 1280 | M30: 1280 | N30: 1280 | O30: 0 | P30: 0 | Q30: =K30+M30+O30 | R30: =L30+N30+P30 | S30: =R30-Q30
B31: ESPAÑA | C31: AGROQUIMICAS DRAGO S.L. | D31: S0200 | E31: SALWAX STAR, 200 L | F31: 0 | G31: 0 | H31: =ABS(G31-F31) | I31: =IF(F31>0, G31/F31, IF(G31>0, 1.0, 0.0)) | K31: 1200 | L31: 1200 | M31: 1200 | N31: 1200 | O31: 0 | P31: 0 | Q31: =K31+M31+O31 | R31: =L31+N31+P31 | S31: =R31-Q31
B32: ESPAÑA | C32: ALMENDRALIA IBÉRICA, S.L.U. | D32: AN0020 | E32: ALCAPLANT NEW, 20 KG | F32: 0 | G32: 1100 | H32: =ABS(G32-F32) | I32: =IF(F32>0, G32/F32, IF(G32>0, 1.0, 0.0)) | J32: Pedido extra no previsto | K32: 0 | L32: 0 | M32: 0 | N32: 0 | O32: 0 | P32: 0 | Q32: =K32+M32+O32 | R32: =L32+N32+P32 | S32: =R32-Q32
B33: ESPAÑA | C33: CABRERA MORALES FRANCISCO | D33: A-50(2)0005 | E33: CODIORGAN A-50, 5 KG | F33: 0 | G33: 625 | H33: =ABS(G33-F33) | I33: =IF(F33>0, G33/F33, IF(G33>0, 1.0, 0.0)) | J33: Pedido extra no previsto | K33: 0 | L33: 0 | M33: 750 | N33: 750 | O33: 0 | P33: 0 | Q33: =K33+M33+O33 | R33: =L33+N33+P33 | S33: =R33-Q33
B34: ESPAÑA | C34: CABRERA MORALES FRANCISCO | D34: A-50(2)0020 | E34: CODIORGAN A-50, 20 KG | F34: 0 | G34: 100 | H34: =ABS(G34-F34) | I34: =IF(F34>0, G34/F34, IF(G34>0, 1.0, 0.0)) | J34: Pedido extra no previsto | K34: 0 | L34: 0 | M34: 0 | N34: 0 | O34: 0 | P34: 0 | Q34: =K34+M34+O34 | R34: =L34+N34+P34 | S34: =R34-Q34
B35: ESPAÑA | C35: CABRERA MORALES FRANCISCO | D35: AGXK0005 | E35: AGROXILATO-K, 5 L | F35: 0 | G35: 0 | H35: =ABS(G35-F35) | I35: =IF(F35>0, G35/F35, IF(G35>0, 1.0, 0.0)) | K35: 0 | L35: 0 | M35: 1800 | N35: 1800 | O35: 0 | P35: 0 | Q35: =K35+M35+O35 | R35: =L35+N35+P35 | S35: =R35-Q35
B36: ESPAÑA | C36: CABRERA MORALES FRANCISCO | D36: AGXK0020 | E36: AGROXILATO-K, 20 L | F36: 0 | G36: 0 | H36: =ABS(G36-F36) | I36: =IF(F36>0, G36/F36, IF(G36>0, 1.0, 0.0)) | K36: 0 | L36: 0 | M36: 2560 | N36: 2560 | O36: 0 | P36: 0 | Q36: =K36+M36+O36 | R36: =L36+N36+P36 | S36: =R36-Q36
B37: ESPAÑA | C37: CABRERA MORALES FRANCISCO | D37: ANAE0005 | E37: ALCAPLANT NEW AE, 5 KG | F37: 6600 | G37: 6600 | H37: =ABS(G37-F37) | I37: =IF(F37>0, G37/F37, IF(G37>0, 1.0, 0.0)) | K37: 4400 | L37: 4400 | M37: 6600 | N37: 6600 | O37: 0 | P37: 0 | Q37: =K37+M37+O37 | R37: =L37+N37+P37 | S37: =R37-Q37
B38: ESPAÑA | C38: CABRERA MORALES FRANCISCO | D38: ANAE0020 | E38: ALCAPLANT NEW AE, 20 KG | F38: 0 | G38: 0 | H38: =ABS(G38-F38) | I38: =IF(F38>0, G38/F38, IF(G38>0, 1.0, 0.0)) | K38: 1100 | L38: 1100 | M38: 1100 | N38: 1100 | O38: 0 | P38: 0 | Q38: =K38+M38+O38 | R38: =L38+N38+P38 | S38: =R38-Q38
B39: ESPAÑA | C39: CABRERA MORALES FRANCISCO | D39: BIO0005 | E39: BIORAD-20, 5L | F39: 0 | G39: 600 | H39: =ABS(G39-F39) | I39: =IF(F39>0, G39/F39, IF(G39>0, 1.0, 0.0)) | J39: Pedido extra no previsto | K39: 1200 | L39: 1200 | M39: 1200 | N39: 1200 | O39: 0 | P39: 0 | Q39: =K39+M39+O39 | R39: =L39+N39+P39 | S39: =R39-Q39
B40: ESPAÑA | C40: CABRERA MORALES FRANCISCO | D40: BIO0020 | E40: BIORAD-20, 20 L | F40: 0 | G40: 1280 | H40: =ABS(G40-F40) | I40: =IF(F40>0, G40/F40, IF(G40>0, 1.0, 0.0)) | J40: Pedido extra no previsto | K40: 1280 | L40: 1280 | M40: 1280 | N40: 1280 | O40: 0 | P40: 0 | Q40: =K40+M40+O40 | R40: =L40+N40+P40 | S40: =R40-Q40
B41: ESPAÑA | C41: CABRERA MORALES FRANCISCO | D41: C-L0005 | E41: CODIBOR-L, 5 L | F41: 0 | G41: 400 | H41: =ABS(G41-F41) | I41: =IF(F41>0, G41/F41, IF(G41>0, 1.0, 0.0)) | J41: Pedido extra no previsto | K41: 0 | L41: 0 | M41: 0 | N41: 0 | O41: 0 | P41: 0 | Q41: =K41+M41+O41 | R41: =L41+N41+P41 | S41: =R41-Q41
B42: ESPAÑA | C42: CABRERA MORALES FRANCISCO | D42: CALCIO0020 | E42: CALCIAMEC, 20 KG | F42: 0 | G42: 0 | H42: =ABS(G42-F42) | I42: =IF(F42>0, G42/F42, IF(G42>0, 1.0, 0.0)) | K42: 0 | L42: 0 | M42: 800 | N42: 800 | O42: 0 | P42: 0 | Q42: =K42+M42+O42 | R42: =L42+N42+P42 | S42: =R42-Q42
...

Sheet Mehmet
B2: CODIAGRO · ACTUALIZACIÓN DE PREVISIONES COMERCIALES Q4 2026 (OCTUBRE - DICIEMBRE)
B3: DELEGADO COMERCIAL: MEHMET | Cierre Septiembre Oficial (01/10/2026) vs Previsiones a Final de Año | Generado: 01/10/2026 14:17
B4: 📌 INSTRUCCIONES: 1) Revise el bloque de SEPTIEMBRE (Previsto, Real, Desviación en Valor Absoluto y % Consecución) e indique en col. J el motivo de la desviación (adelanto, atraso, extra). 2) En las columnas verdes (L, N, P), revise y actualice las cantidades estimadas de Octubre, Noviembre y Diciembre si prevé cambios. 3) Comente en col. T cualquier nota de campaña.
B5: PREVISTO SEP 2026 (U) | E5: REAL PEDIDOS SEP 2026 (U) | H5: % CONSECUCIÓN SEP | K5: PREVISIÓN INICIAL Q4 (U) | N5: PREVISIÓN REVISADA Q4 (U) | Q5: VARIACIÓN NETA Q4 (U)
B6: =F48 | E6: =G48 | H6: =I48 | K6: =Q48 | N6: =R48 | Q6: =S48
B8: DATOS CLIENTE Y ARTÍCULO | F8: CIERRE SEPTIEMBRE 2026 (CALIBRACIÓN Y ANÁLISIS) | K8: REVISIÓN PREVISIONES MES A MES (HASTA FINAL DE AÑO 2026) | Q8: IMPACTO Q4 Y JUSTIFICACIÓN
B9: País | C9: Cliente | D9: Cód. SKU | E9: Descripción Artículo | F9: Sep Previsto (u) | G9: Sep Real (u) | H9: Desv. Sep (u) | I9: % Consec. | J9: Comentario Sep (¿Adelanto/Atraso/Extra?) | K9: Oct Anterior (u) | L9: Oct Revisado (u) | M9: Nov Anterior (u) | N9: Nov Revisado (u) | O9: Dic Anterior (u) | P9: Dic Revisado (u) | Q9: Total Q4 Ant (u) | R9: Total Q4 Rev (u) | S9: Dif Q4 (u) | T9: Comentarios / Justificación Q4
B10: GEORGIA | C10: BORN AGROCHEMISTRY, LLC | D10: A-500001 | E10: CODIORGAN A-50 | F10: 0 | G10: 0 | H10: =ABS(G10-F10) | I10: =IF(F10>0, G10/F10, IF(G10>0, 1.0, 0.0)) | K10: 0 | L10: 0 | M10: 0 | N10: 0 | O10: 1920 | P10: 1920 | Q10: =K10+M10+O10 | R10: =L10+N10+P10 | S10: =R10-Q10
B11: GEORGIA | C11: BORN AGROCHEMISTRY, LLC | D11: A-500005 | E11: CODIORGAN A-50 | F11: 0 | G11: 0 | H11: =ABS(G11-F11) | I11: =IF(F11>0, G11/F11, IF(G11>0, 1.0, 0.0)) | K11: 0 | L11: 0 | M11: 0 | N11: 0 | O11: 1000 | P11: 1000 | Q11: =K11+M11+O11 | R11: =L11+N11+P11 | S11: =R11-Q11
B12: GEORGIA | C12: BORN AGROCHEMISTRY, LLC | D12: AGXK0005 | E12: AGROXILATO-K, 5 L | F12: 0 | G12: 0 | H12: =ABS(G12-F12) | I12: =IF(F12>0, G12/F12, IF(G12>0, 1.0, 0.0)) | K12: 0 | L12: 0 | M12: 0 | N12: 0 | O12: 1000 | P12: 1000 | Q12: =K12+M12+O12 | R12: =L12+N12+P12 | S12: =R12-Q12
B13: GEORGIA | C13: BORN AGROCHEMISTRY, LLC | D13: AN0020 | E13: ALCAPLANT NEW | F13: 0 | G13: 0 | H13: =ABS(G13-F13) | I13: =IF(F13>0, G13/F13, IF(G13>0, 1.0, 0.0)) | K13: 0 | L13: 0 | M13: 0 | N13: 0 | O13: 6000 | P13: 6000 | Q13: =K13+M13+O13 | R13: =L13+N13+P13 | S13: =R13-Q13
B14: GEORGIA | C14: BORN AGROCHEMISTRY, LLC | D14: BIO0020 | E14: BIORAD-20 | F14: 0 | G14: 0 | H14: =ABS(G14-F14) | I14: =IF(F14>0, G14/F14, IF(G14>0, 1.0, 0.0)) | K14: 0 | L14: 0 | M14: 0 | N14: 0 | O14: 30000 | P14: 30000 | Q14: =K14+M14+O14 | R14: =L14+N14+P14 | S14: =R14-Q14
B15: GEORGIA | C15: BORN AGROCHEMISTRY, LLC | D15: C-CU0001 | E15: CODICOBRE | F15: 0 | G15: 0 | H15: =ABS(G15-F15) | I15: =IF(F15>0, G15/F15, IF(G15>0, 1.0, 0.0)) | K15: 0 | L15: 0 | M15: 0 | N15: 0 | O15: 960 | P15: 960 | Q15: =K15+M15+O15 | R15: =L15+N15+P15 | S15: =R15-Q15
B16: GEORGIA | C16: BORN AGROCHEMISTRY, LLC | D16: C-CU0005 | E16: CODICOBRE, 5 L | F16: 0 | G16: 0 | H16: =ABS(G16-F16) | I16: =IF(F16>0, G16/F16, IF(G16>0, 1.0, 0.0)) | K16: 0 | L16: 0 | M16: 0 | N16: 0 | O16: 1000 | P16: 1000 | Q16: =K16+M16+O16 | R16: =L16+N16+P16 | S16: =R16-Q16
B17: GEORGIA | C17: BORN AGROCHEMISTRY, LLC | D17: CM30005 | E17: TENSOLINE, 5 L | F17: 0 | G17: 0 | H17: =ABS(G17-F17) | I17: =IF(F17>0, G17/F17, IF(G17>0, 1.0, 0.0)) | K17: 0 | L17: 0 | M17: 0 | N17: 0 | O17: 1000 | P17: 1000 | Q17: =K17+M17+O17 | R17: =L17+N17+P17 | S17: =R17-Q17
B18: GEORGIA | C18: BORN AGROCHEMISTRY, LLC | D18: CZNMNES0001 | E18: CODIFOL ZN-MN, 1 KG | F18: 0 | G18: 0 | H18: =ABS(G18-F18) | I18: =IF(F18>0, G18/F18, IF(G18>0, 1.0, 0.0)) | K18: 0 | L18: 0 | M18: 0 | N18: 0 | O18: 1000 | P18: 1000 | Q18: =K18+M18+O18 | R18: =L18+N18+P18 | S18: =R18-Q18
B19: GEORGIA | C19: BORN AGROCHEMISTRY, LLC | D19: CZNMNES0005 | E19: CODIFOL ZN-MN | F19: 0 | G19: 0 | H19: =ABS(G19-F19) | I19: =IF(F19>0, G19/F19, IF(G19>0, 1.0, 0.0)) | K19: 0 | L19: 0 | M19: 0 | N19: 0 | O19: 1000 | P19: 1000 | Q19: =K19+M19+O19 | R19: =L19+N19+P19 | S19: =R19-Q19
B20: GEORGIA | C20: BORN AGROCHEMISTRY, LLC | D20: RUN0001 | E20: RUN STRESS | F20: 0 | G20: 0 | H20: =ABS(G20-F20) | I20: =IF(F20>0, G20/F20, IF(G20>0, 1.0, 0.0)) | K20: 0 | L20: 0 | M20: 0 | N20: 0 | O20: 960 | P20: 960 | Q20: =K20+M20+O20 | R20: =L20+N20+P20 | S20: =R20-Q20
B21: GEORGIA | C21: BORN AGROCHEMISTRY, LLC | D21: RUN0005 | E21: RUN STRESS | F21: 0 | G21: 0 | H21: =ABS(G21-F21) | I21: =IF(F21>0, G21/F21, IF(G21>0, 1.0, 0.0)) | K21: 0 | L21: 0 | M21: 0 | N21: 0 | O21: 1000 | P21: 1000 | Q21: =K21+M21+O21 | R21: =L21+N21+P21 | S21: =R21-Q21
... B35: TURQUÍA | C35: ÇITAR ÇIÇEK TARIM TIC. LTD. STI | D35: A-501000 | E35: CODIORGAN-A50, 1000 KG | F35: 0 | G35: 0 | H35: =ABS(G35-F35) | I35: =IF(F35>0, G35/F35, IF(G35>0, 1.0, 0.0)) | K35: 0 | L35: 0 | M35: 0 | N35: 0 | O35: 2000 | P35: 2000 | Q35: =K35+M35+O35 | R35: =L35+N35+P35 | S35: =R35-Q35
B36: TURQUÍA | C36: ÇITAR ÇIÇEK TARIM TIC. LTD. STI | D36: AN0005 | E36: ALCAPLANT NEW | F36: 0 | G36: 2200 | H36: =ABS(G36-F36) | I36: =IF(F36>0, G36/F36, IF(G36>0, 1.0, 0.0)) | J36: Pedido extra no previsto | K36: 0 | L36: 0 | M36: 0 | N36: 0 | O36: 0 | P36: 0 | Q36: =K36+M36+O36 | R36: =L36+N36+P36 | S36: =R36-Q36
B37: ESPAÑA | C37: ÇITAR ÇIÇEK TARIM TIC. LTD. STI | D37: BIO0020 | E37: BIORAD-20, 20 L | F37: 0 | G37: 10060 | H37: =ABS(G37-F37) | I37: =IF(F37>0, G37/F37, IF(G37>0, 1.0, 0.0)) | J37: Pedido extra no previsto | K37: 0 | L37: 0 | M37: 0 | N37: 0 | O37: 0 | P37: 0 | Q37: =K37+M37+O37 | R37: =L37+N37+P37 | S37: =R37-Q37
B38: ESPAÑA | C38: ÇITAR ÇIÇEK TARIM TIC. LTD. STI | D38: BIO1000 | E38: BIORAD-20, 1000 L | F38: 0 | G38: 11000 | H38: =ABS(G38-F38) | I38: =IF(F38>0, G38/F38, IF(G38>0, 1.0, 0.0)) | J38: Pedido extra no previsto | K38: 0 | L38: 0 | M38: 0 | N38: 0 | O38: 0 | P38: 0 | Q38: =K38+M38+O38 | R38: =L38+N38+P38 | S38: =R38-Q38
B39: ESPAÑA | C39: ÇITAR ÇIÇEK TARIM TIC. LTD. STI | D39: C-CU1000 | E39: CODICOBRE, 1000 L | F39: 0 | G39: 1000 | H39: =ABS(G39-F39) | I39: =IF(F39>0, G39/F39, IF(G39>0, 1.0, 0.0)) | J39: Pedido extra no previsto | K39: 0 | L39: 0 | M39: 0 | N39: 0 | O39: 0 | P39: 0 | Q39: =K39+M39+O39 | R39: =L39+N39+P39 | S39: =R39-Q39
B40: TURQUÍA | C40: ÇITAR ÇIÇEK TARIM TIC. LTD. STI | D40: FTK0005 | E40: FITOKONTROL CA FLOW, 5 KG | F40: 10000 | G40: 5500 | H40: =ABS(G40-F40) | I40: =IF(F40>0, G40/F40, IF(G40>0, 1.0, 0.0)) | K40: 0 | L40: 0 | M40: 0 | N40: 0 | O40: 10000 | P40: 10000 | Q40: =K40+M40+O40 | R40: =L40+N40+P40 | S40: =R40-Q40
B41: TURQUÍA | C41: ÇITAR ÇIÇEK TARIM TIC. LTD. STI | D41: FU1000 | E41: FULVIGIN, 1000 L | F41: 0 | G41: 1000 | H41: =ABS(G41-F41) | I41: =IF(F41>0, G41/F41, IF(G41>0, 1.0, 0.0)) | J41: Pedido extra no previsto | K41: 0 | L41: 0 | M41: 0 | N41: 0 | O41: 1000 | P41: 1000 | Q41: =K41+M41+O41 | R41: =L41+N41+P41 | S41: =R41-Q41
B42: TURQUÍA | C42: ÇITAR ÇIÇEK TARIM TIC. LTD. STI | D42: RUN0001 | E42: RUN STRESS, 1 L | F42: 1960 | G42: 1968 | H42: =ABS(G42-F42) | I42: =IF(F42>0, G42/F42, IF(G42>0, 1.0, 0.0)) | K42: 0 | L42: 0 | M42: 0 | N42: 0 | O42: 0 | P42: 0 | Q42: =K42+M42+O42 | R42: =L42+N42+P42 | S42: =R42-Q42
B43: TURQUÍA | C43: ÇİTAR ÇİÇEK TARIM TIC. LTD. STI | D43: AN0005 | E43: ALCAPLANT NEW, 5 KG | F43: 5500 | G43: 0 | H43: =ABS(G43-F43) | I43: =IF(F43>0, G43/F43, IF(G43>0, 1.0, 0.0)) | K43: 0 | L43: 0 | M43: 0 | N43: 0 | O43: 15000 | P43: 15000 | Q43: =K43+M43+O43 | R43: =L43+N43+P43 | S43: =R43-Q43
B44: TURQUÍA | C44: ÇİTAR ÇİÇEK TARIM TIC. LTD. STI | D44: BIO0020 | E44: BIORAD-20, 20 L | F44: 10000 | G44: 0 | H44: =ABS(G44-F44) | I44: =IF(F44>0, G44/F44, IF(G44>0, 1.0, 0.0)) | K44: 0 | L44: 0 | M44: 0 | N44: 0 | O44: 0 | P44: 0 | Q44: =K44+M44+O44 | R44: =L44+N44+P44 | S44: =R44-Q44
B45: TURQUÍA | C45: ÇİTAR ÇİÇEK TARIM TIC. LTD. STI | D45: BIO1000 | E45: BIORAD-20, 1000 L | F45: 10000 | G45: 0 | H45: =ABS(G45-F45) | I45: =IF(F45>0, G45/F45, IF(G45>0, 1.0, 0.0)) | K45: 0 | L45: 0 | M45: 0 | N45: 0 | O45: 0 | P45: 0 | Q45: =K45+M45+O45 | R45: =L45+N45+P45 | S45: =R45-Q45
B46: TURQUÍA | C46: ÇİTAR ÇİÇEK TARIM TIC. LTD. STI | D46: C-CU1000 | E46: CODICOBRE, 1000 L | F46: 2000 | G46: 0 | H46: =ABS(G46-F46) | I46: =IF(F46>0, G46/F46, IF(G46>0, 1.0, 0.0)) | K46: 0 | L46: 0 | M46: 0 | N46: 0 | O46: 0 | P46: 0 | Q46: =K46+M46+O46 | R46: =L46+N46+P46 | S46: =R46-Q46
B47: TURQUÍA | C47: ÇİTAR ÇİÇEK TARIM TIC. LTD. STI | D47: CZNMNES1000 | E47: CODIFOL ZN-MN, 1000 KG | F47: 0 | G47: 0 | H47: =ABS(G47-F47) | I47: =IF(F47>0, G47/F47, IF(G47>0, 1.0, 0.0)) | K47: 0 | L47: 0 | M47: 0 | N47: 0 | O47: 2000 | P47: 2000 | Q47: =K47+M47+O47 | R47: =L47+N47+P47 | S47: =R47-Q47
B48: TOTAL CONSOLIDADO - MEHMET (UNIDADES) | F48: =SUM(F10:F47) | G48: =SUM(G10:G47) | H48: =SUM(H10:H47) | I48: =IF(F48>0, G48/F48, 1.0) | K48: =SUM(K10:K47) | L48: =SUM(L10:L47) | M48: =SUM(M10:M47) | N48: =SUM(N10:N47) | O48: =SUM(O10:O47) | P48: =SUM(P10:P47) | Q48: =SUM(Q10:Q47) | R48: =SUM(R10:R47) | S48: =SUM(S10:S47)

Sheet Pedro
B2: CODIAGRO · ACTUALIZACIÓN DE PREVISIONES COMERCIALES Q4 2026 (OCTUBRE - DICIEMBRE)
B3: DELEGADO COMERCIAL: PEDRO | Cierre Septiembre Oficial (01/10/2026) vs Previsiones a Final de Año | Generado: 01/10/2026 14:17
B4: 📌 INSTRUCCIONES: 1) Revise el bloque de SEPTIEMBRE (Previsto, Real, Desviación en Valor Absoluto y % Consecución) e indique en col. J el motivo de la desviación (adelanto, atraso, extra). 2) En las columnas verdes (L, N, P), revise y actualice las cantidades estimadas de Octubre, Noviembre y Diciembre si prevé cambios. 3) Comente en col. T cualquier nota de campaña.
B5: PREVISTO SEP 2026 (U) | E5: REAL PEDIDOS SEP 2026 (U) | H5: % CONSECUCIÓN SEP | K5: PREVISIÓN INICIAL Q4 (U) | N5: PREVISIÓN REVISADA Q4 (U) | Q5: VARIACIÓN NETA Q4 (U)
B6: =F52 | E6: =G52 | H6: =I52 | K6: =Q52 | N6: =R52 | Q6: =S52
B8: DATOS CLIENTE Y ARTÍCULO | F8: CIERRE SEPTIEMBRE 2026 (CALIBRACIÓN Y ANÁLISIS) | K8: REVISIÓN PREVISIONES MES A MES (HASTA FINAL DE AÑO 2026) | Q8: IMPACTO Q4 Y JUSTIFICACIÓN
B9: País | C9: Cliente | D9: Cód. SKU | E9: Descripción Artículo | F9: Sep Previsto (u) | G9: Sep Real (u) | H9: Desv. Sep (u) | I9: % Consec. | J9: Comentario Sep (¿Adelanto/Atraso/Extra?) | K9: Oct Anterior (u) | L9: Oct Revisado (u) | M9: Nov Anterior (u) | N9: Nov Revisado (u) | O9: Dic Anterior (u) | P9: Dic Revisado (u) | Q9: Total Q4 Ant (u) | R9: Total Q4 Rev (u) | S9: Dif Q4 (u) | T9: Comentarios / Justificación Q4
B10: ESPAÑA | C10: ASESORAMIENTO TECNICO DE CULTIVOS, S.L. | D10: AGXK0020 | E10: AGROXILATO-K, 20 L | F10: 640 | G10: 0 | H10: =ABS(G10-F10) | I10: =IF(F10>0, G10/F10, IF(G10>0, 1.0, 0.0)) | K10: 640 | L10: 640 | M10: 0 | N10: 0 | O10: 0 | P10: 0 | Q10: =K10+M10+O10 | R10: =L10+N10+P10 | S10: =R10-Q10
B11: ESPAÑA | C11: ASESORAMIENTO TECNICO DE CULTIVOS, S.L. | D11: B0005 | E11: BOROCAL, 5 L | F11: 300 | G11: 0 | H11: =ABS(G11-F11) | I11: =IF(F11>0, G11/F11, IF(G11>0, 1.0, 0.0)) | K11: 0 | L11: 0 | M11: 0 | N11: 0 | O11: 0 | P11: 0 | Q11: =K11+M11+O11 | R11: =L11+N11+P11 | S11: =R11-Q11
B12: ESPAÑA | C12: ASESORAMIENTO TECNICO DE CULTIVOS, S.L. | D12: B0020 | E12: BOROCAL, 20 L | F12: 1280 | G12: 0 | H12: =ABS(G12-F12) | I12: =IF(F12>0, G12/F12, IF(G12>0, 1.0, 0.0)) | K12: 640 | L12: 640 | M12: 640 | N12: 640 | O12: 0 | P12: 0 | Q12: =K12+M12+O12 | R12: =L12+N12+P12 | S12: =R12-Q12
B13: ESPAÑA | C13: ASESORAMIENTO TECNICO DE CULTIVOS, S.L. | D13: C-CU0020 | E13: CODICOBRE, 20 L | F13: 1280 | G13: 0 | H13: =ABS(G13-F13) | I13: =IF(F13>0, G13/F13, IF(G13>0, 1.0, 0.0)) | K13: 640 | L13: 640 | M13: 1280 | N13: 1280 | O13: 0 | P13: 0 | Q13: =K13+M13+O13 | R13: =L13+N13+P13 | S13: =R13-Q13
B14: ESPAÑA | C14: ASESORAMIENTO TECNICO DE CULTIVOS, S.L. | D14: CBASI0005 | E14: BIOCULTURE BASI, 5 KG | F14: 0 | G14: 0 | H14: =ABS(G14-F14) | I14: =IF(F14>0, G14/F14, IF(G14>0, 1.0, 0.0)) | K14: 500 | L14: 500 | M14: 0 | N14: 0 | O14: 0 | P14: 0 | Q14: =K14+M14+O14 | R14: =L14+N14+P14 | S14: =R14-Q14
B15: ESPAÑA | C15: ASESORAMIENTO TECNICO DE CULTIVOS, S.L. | D15: PT0020 | E15: AGROPOTASION, 20 L | F15: 2560 | G15: 1920 | H15: =ABS(G15-F15) | I15: =IF(F15>0, G15/F15, IF(G15>0, 1.0, 0.0)) | K15: 1920 | L15: 1920 | M15: 1920 | N15: 1920 | O15: 0 | P15: 0 | Q15: =K15+M15+O15 | R15: =L15+N15+P15 | S15: =R15-Q15
B16: ESPAÑA | C16: COMERCIAL TÉCNICA FITOCARTHAGO, S.L. | D16: AGXK0200 | E16: AGROXILATO-K, 200 L | F16: 400 | G16: 0 | H16: =ABS(G16-F16) | I16: =IF(F16>0, G16/F16, IF(G16>0, 1.0, 0.0)) | K16: 800 | L16: 800 | M16: 0 | N16: 0 | O16: 0 | P16: 0 | Q16: =K16+M16+O16 | R16: =L16+N16+P16 | S16: =R16-Q16
B17: ESPAÑA | C17: COMERCIAL TÉCNICA FITOCARTHAGO, S.L. | D17: AGXK1000 | E17: AGROXILATO-K, 1000 L | F17: 2000 | G17: 0 | H17: =ABS(G17-F17) | I17: =IF(F17>0, G17/F17, IF(G17>0, 1.0, 0.0)) | K17: 3000 | L17: 3000 | M17: 1000 | N17: 1000 | O17: 0 | P17: 0 | Q17: =K17+M17+O17 | R17: =L17+N17+P17 | S17: =R17-Q17
B18: ESPAÑA | C18: COMERCIAL TÉCNICA FITOCARTHAGO, S.L. | D18: AN0020 | E18: ALCAPLANT NEW, 20 KG | F18: 2200 | G18: 2200 | H18: =ABS(G18-F18) | I18: =IF(F18>0, G18/F18, IF(G18>0, 1.0, 0.0)) | K18: 6500 | L18: 6500 | M18: 6500 | N18: 6500 | O18: 0 | P18: 0 | Q18: =K18+M18+O18 | R18: =L18+N18+P18 | S18: =R18-Q18
