Workbook
Name Datos: #REF!
Name Datos: #REF!

Sheet 2026
B2: Seleccionar las formulas de P&L YTD Mes anterior y de P&L YTD Actual y cambiar la referencia al mes anterior
C4: RELLENAR | L4: RELLENAR | U4: RELLENAR | AD4: RELLENAR | AM4: RELLENAR
B5: MES | C5: 9 | K5: MES | L5: 10 | T5: MES | U5: 11 | AC5: MES | AD5: 12 | AL5: MES | AM5: 12
B7: P&L Mensual | K7: P&L Mensual | T7: P&L Mensual | AC7: P&L Mensual | AL7: P&L Mensual
E8: Variación | H8: Variación | N8: Variación | Q8: Variación | W8: Variación | Z8: Variación | AF8: Variación | AI8: Variación | AO8: Variación | AR8: Variación
B9: € '000 | C9: 2026A | D9: 2025A | E9: EUR | F9: % | G9: 2026B | H9: EUR | I9: % | K9: € '000 | L9: 2026A | M9: 2025A | N9: EUR | O9: % | P9: 2026B | Q9: EUR | R9: % | T9: € '000 | U9: 2026A | V9: 2025A | W9: EUR | X9: % | Y9: 2026B | Z9: EUR | AA9: % | AC9: € '000 | AD9: 2026A | AE9: 2025A | AF9: EUR | AG9: % | AH9: 2026B | AI9: EUR | AJ9: % | AL9: € '000 | AM9: 2026A | AN9: 2025A | AO9: EUR | AP9: % | AQ9: 2026B | AR9: EUR | AS9: %
B10: Ventas | C10: =(GETPIVOTDATA("sep-26 ",TABLA!$B$3,"Nivel 4","1.- Importe neto de la cifra de negocios"))/1000 -> 483.08374 | D10: =VLOOKUP(B10,'P&L Mensualitzada 2025'!$A$5:$N$25,$C$5+1,0) -> 842.11579 | E10: =C10-D10 -> -359.03205 | F10: =+IF(IFERROR(C10/D10-1,"-")<300%,IFERROR(C10/D10-1,"-"),"n.a.") -> -0.42634523 | G10: =VLOOKUP(B10,'Budget26 sin EI'!$B:$O,$C$5+1,0) -> 1026.5685 | H10: =C10-G10 -> -543.48475 | I10: =+IF(IFERROR(C10/G10-1,"-")<300%,IFERROR(C10/G10-1,"-"),"n.a.") -> -0.52941889 | K10: Ventas | L10: =(GETPIVOTDATA("oct-26 ",TABLA!$B$3,"Nivel 4","1.- Importe neto de la cifra de negocios"))/1000 -> 912.05501 | M10: =VLOOKUP(K10,'P&L Mensualitzada 2025'!$A$5:$N$25,$L$5+1,0) -> 699.58345 | N10: =L10-M10 -> 212.47156 | O10: =+IF(IFERROR(L10/M10-1,"-")<300%,IFERROR(L10/M10-1,"-"),"n.a.") -> 0.30371153 | P10: =VLOOKUP(K10,'Budget26 sin EI'!$B:$O,$L$5+1,0) -> 798.56718 | Q10: =L10-P10 -> 113.48783 | R10: =+IF(IFERROR(L10/P10-1,"-")<300%,IFERROR(L10/P10-1,"-"),"n.a.") -> 0.14211431 | T10: Ventas | U10: =(GETPIVOTDATA("nov-26 ",TABLA!$B$3,"Nivel 4","1.- Importe neto de la cifra de negocios"))/1000 -> 1225.3218 | V10: =VLOOKUP(T10,'P&L Mensualitzada 2025'!$A$5:$N$25,$U$5+1,0) -> 749.69916 | W10: =U10-V10 -> 475.62262 | X10: =+IF(IFERROR(U10/V10-1,"-")<300%,IFERROR(U10/V10-1,"-"),"n.a.") -> 0.63441797 | Y10: =VLOOKUP(T10,'Budget26 sin EI'!$B:$O,$U$5+1,0) -> 1030.243 | Z10: =U10-Y10 -> 195.07877 | AA10: =+IF(IFERROR(U10/Y10-1,"-")<300%,IFERROR(U10/Y10-1,"-"),"n.a.") -> 0.18935219 | AC10: Ventas | AD10: =(GETPIVOTDATA("dic-26 ",TABLA!$B$3,"Nivel 4","1.- Importe neto de la cifra de negocios"))/1000 -> 1142.4074 | AE10: =VLOOKUP(AC10,'P&L Mensualitzada 2025'!$A$5:$N$25,$AD$5+1,0) -> 248.50601 | AF10: =AD10-AE10 -> 893.90137 | AG10: =+IF(IFERROR(AD10/AE10-1,"-")<300%,IFERROR(AD10/AE10-1,"-"),"n.a.") -> n.a. | AH10: =VLOOKUP(AC10,'Budget26 sin EI'!$B:$O,$AD$5+1,0) -> 659.94465 | AI10: =AD10-AH10 -> 482.46273 | AJ10: =+IF(IFERROR(AD10/AH10-1,"-")<300%,IFERROR(AD10/AH10-1,"-"),"n.a.") -> 0.73106544 | AL10: Ventas | AM10: =(GETPIVOTDATA("Total 2026 ",TABLA!$B$3,"Nivel 4","1.- Importe neto de la cifra de negocios"))/1000 -> 15180 | AN10: =VLOOKUP(AL10,'P&L Mensualitzada 2025'!$A$5:$N$25,$AD$5+1,0) -> 248.50601 | AO10: =AM10-AN10 -> 14931.494 | AP10: =+IF(IFERROR(AM10/AN10-1,"-")<300%,IFERROR(AM10/AN10-1,"-"),"n.a.") -> n.a. | AQ10: =VLOOKUP(AL10,'Budget26 sin EI'!$B:$O,$AD$5+1,0) -> 659.94465 | AR10: =AM10-AQ10 -> 14520.055 | AS10: =+IF(IFERROR(AM10/AQ10-1,"-")<300%,IFERROR(AM10/AQ10-1,"-"),"n.a.") -> n.a.
B11: COGS | C11: -80 | D11: =VLOOKUP(B11,'P&L Mensualitzada 2025'!$A$5:$N$25,$C$5+1,0) -> -265.37091 | E11: =C11-D11 -> 185.37091 | F11: =+IF(IFERROR(C11/D11-1,"-")<300%,IFERROR(C11/D11-1,"-"),"n.a.") -> -0.69853516 | G11: =VLOOKUP(B11,'Budget26 sin EI'!$B:$O,$C$5+1,0) -> -352.55893 | H11: =C11-G11 -> 272.55893 | I11: =+IF(IFERROR(C11/G11-1,"-")<300%,IFERROR(C11/G11-1,"-"),"n.a.") -> -0.77308758 | K11: COGS | L11: =(GETPIVOTDATA("oct-26 ",TABLA!$B$3,"Nivel 4","2.- Variación de existencias")+GETPIVOTDATA("oct-26 ",TABLA!$B$3,"Nivel 4","4.- Aprovisionamientos"))/1000 -> -302.10136 | M11: =VLOOKUP(K11,'P&L Mensualitzada 2025'!$A$5:$N$25,$L$5+1,0) -> -361.07371 | N11: =L11-M11 -> 58.97235 | O11: =+IF(IFERROR(L11/M11-1,"-")<300%,IFERROR(L11/M11-1,"-"),"n.a.") -> -0.16332496 | P11: =VLOOKUP(K11,'Budget26 sin EI'!$B:$O,$L$5+1,0) -> -274.25544 | Q11: =L11-P11 -> -27.84592 | R11: =+IF(IFERROR(L11/P11-1,"-")<300%,IFERROR(L11/P11-1,"-"),"n.a.") -> 0.10153279 | T11: COGS | U11: =(GETPIVOTDATA("nov-26 ",TABLA!$B$3,"Nivel 4","2.- Variación de existencias")+GETPIVOTDATA("nov-26 ",TABLA!$B$3,"Nivel 4","4.- Aprovisionamientos"))/1000 -> -404.42328 | V11: =VLOOKUP(T11,'P&L Mensualitzada 2025'!$A$5:$N$25,$U$5+1,0) -> -275.74654 | W11: =U11-V11 -> -128.67674 | X11: =+IF(IFERROR(U11/V11-1,"-")<300%,IFERROR(U11/V11-1,"-"),"n.a.") -> 0.46664861 | Y11: =VLOOKUP(T11,'Budget26 sin EI'!$B:$O,$U$5+1,0) -> -353.82089 | Z11: =U11-Y11 -> -50.602393 | AA11: =+IF(IFERROR(U11/Y11-1,"-")<300%,IFERROR(U11/Y11-1,"-"),"n.a.") -> 0.14301697 | AC11: COGS | AD11: =(GETPIVOTDATA("dic-26 ",TABLA!$B$3,"Nivel 4","2.- Variación de existencias")+GETPIVOTDATA("dic-26 ",TABLA!$B$3,"Nivel 4","4.- Aprovisionamientos"))/1000 -> -449.14533 | AE11: =VLOOKUP(AC11,'P&L Mensualitzada 2025'!$A$5:$N$25,$AD$5+1,0) -> -116.4287 | AF11: =AD11-AE11 -> -332.71663 | AG11: =+IF(IFERROR(AD11/AE11-1,"-")<300%,IFERROR(AD11/AE11-1,"-"),"n.a.") -> 2.8576857 | AH11: =VLOOKUP(AC11,'Budget26 sin EI'!$B:$O,$AD$5+1,0) -> -226.64682 | AI11: =AD11-AH11 -> -222.49851 | AJ11: =+IF(IFERROR(AD11/AH11-1,"-")<300%,IFERROR(AD11/AH11-1,"-"),"n.a.") -> 0.981697 | AL11: COGS | AM11: =(GETPIVOTDATA("Total 2026 ",TABLA!$B$3,"Nivel 4","2.- Variación de existencias")+GETPIVOTDATA("Total 2026 ",TABLA!$B$3,"Nivel 4","4.- Aprovisionamientos"))/1000 -> -5233.5328 | AN11: =VLOOKUP(AL11,'P&L Mensualitzada 2025'!$A$5:$N$25,$AD$5+1,0) -> -116.4287 | AO11: =AM11-AN11 -> -5117.1041 | AP11: =+IF(IFERROR(AM11/AN11-1,"-")<300%,IFERROR(AM11/AN11-1,"-"),"n.a.") -> n.a. | AQ11: =VLOOKUP(AL11,'Budget26 sin EI'!$B:$O,$AD$5+1,0) -> -226.64682 | AR11: =AM11-AQ11 -> -5006.886 | AS11: =+IF(IFERROR(AM11/AQ11-1,"-")<300%,IFERROR(AM11/AQ11-1,"-"),"n.a.") -> n.a.
B12: Gross Profit | C12: =C10+C11 -> 403.08374 | D12: =SUM(D10:D11) -> 576.74488 | E12: =C12-D12 -> -173.66114 | F12: =+IF(IFERROR(C12/D12-1,"-")<300%,IFERROR(C12/D12-1,"-"),"n.a.") -> -0.30110565 | G12: =SUM(G10:G11) -> 674.00956 | H12: =C12-G12 -> -270.92582 | I12: =+IF(IFERROR(C12/G12-1,"-")<300%,IFERROR(C12/G12-1,"-"),"n.a.") -> -0.40196139 | K12: Gross Profit | L12: =L10+L11 -> 609.95365 | M12: =SUM(M10:M11) -> 338.50974 | N12: =L12-M12 -> 271.44391 | O12: =+IF(IFERROR(L12/M12-1,"-")<300%,IFERROR(L12/M12-1,"-"),"n.a.") -> 0.80187917 | P12: =SUM(P10:P11) -> 524.31174 | Q12: =L12-P12 -> 85.641906 | R12: =+IF(IFERROR(L12/P12-1,"-")<300%,IFERROR(L12/P12-1,"-"),"n.a.") -> 0.16334157 | T12: Gross Profit | U12: =U10+U11 -> 820.8985 | V12: =SUM(V10:V11) -> 473.95262 | W12: =U12-V12 -> 346.94588 | X12: =+IF(IFERROR(U12/V12-1,"-")<300%,IFERROR(U12/V12-1,"-"),"n.a.") -> 0.73202651 | Y12: =SUM(Y10:Y11) -> 676.42212 | Z12: =U12-Y12 -> 144.47638 | AA12: =+IF(IFERROR(U12/Y12-1,"-")<300%,IFERROR(U12/Y12-1,"-"),"n.a.") -> 0.21358908 | AC12: Gross Profit | AD12: =AD10+AD11 -> 693.26205 | AE12: =SUM(AE10:AE11) -> 132.07731 | AF12: =AD12-AE12 -> 561.18474 | AG12: =+IF(IFERROR(AD12/AE12-1,"-")<300%,IFERROR(AD12/AE12-1,"-"),"n.a.") -> n.a. | AH12: =SUM(AH10:AH11) -> 433.29783 | AI12: =AD12-AH12 -> 259.96422 | AJ12: =+IF(IFERROR(AD12/AH12-1,"-")<300%,IFERROR(AD12/AH12-1,"-"),"n.a.") -> 0.59996659 | AL12: Gross Profit | AM12: =AM10+AM11 -> 9946.4672 | AN12: =SUM(AN10:AN11) -> 132.07731 | AO12: =AM12-AN12 -> 9814.3898 | AP12: =+IF(IFERROR(AM12/AN12-1,"-")<300%,IFERROR(AM12/AN12-1,"-"),"n.a.") -> n.a. | AQ12: =SUM(AQ10:AQ11) -> 433.29783 | AR12: =AM12-AQ12 -> 9513.1693 | AS12: =+IF(IFERROR(AM12/AQ12-1,"-")<300%,IFERROR(AM12/AQ12-1,"-"),"n.a.") -> n.a.
B13: % Gross Margin | C13: =C12/C10 -> 0.83439724 | D13: =D12/D10 -> 0.68487598 | G13: =G12/G10 -> 0.6565656 | K13: % Gross Margin | L13: =L12/L10 -> 0.66876849 | M13: =M12/M10 -> 0.48387328 | P13: =P12/P10 -> 0.6565656 | T13: % Gross Margin | U13: =U12/U10 -> 0.66994524 | V13: =V12/V10 -> 0.63219041 | Y13: =Y12/Y10 -> 0.6565656 | AC13: % Gross Margin | AD13: =AD12/AD10 -> 0.60684311 | AE13: =AE12/AE10 -> 0.53148538 | AH13: =AH12/AH10 -> 0.65656692 | AL13: % Gross Margin | AM13: =AM12/AM10 -> 0.65523499 | AN13: =AN12/AN10 -> 0.53148538 | AQ13: =AQ12/AQ10 -> 0.65656692
B15: Gastos de Personal | C15: =GETPIVOTDATA("sep-26 ",TABLA!$B$3,"Nivel 4","6.- Gastos de personal")/1000 -> -152.63279 | D15: =VLOOKUP(B15,'P&L Mensualitzada 2025'!$A$5:$N$25,$C$5+1,0) -> -133.7212 | E15: =C15-D15 -> -18.91159 | F15: =+IF(IFERROR(C15/D15-1,"-")<300%,IFERROR(C15/D15-1,"-"),"n.a.") -> 0.14142552 | G15: =VLOOKUP(B15,'Budget26 sin EI'!$B:$O,$C$5+1,0) -> -174.23 | H15: =C15-G15 -> 21.59721 | I15: =+IF(IFERROR(C15/G15-1,"-")<300%,IFERROR(C15/G15-1,"-"),"n.a.") -> -0.12395804 | K15: Gastos de Personal | L15: =GETPIVOTDATA("oct-26 ",TABLA!$B$3,"Nivel 4","6.- Gastos de personal")/1000 -> -152.63279 | M15: =VLOOKUP(K15,'P&L Mensualitzada 2025'!$A$5:$N$25,$L$5+1,0) -> -300.72411 | N15: =L15-M15 -> 148.09132 | O15: =+IF(IFERROR(L15/M15-1,"-")<300%,IFERROR(L15/M15-1,"-"),"n.a.") -> -0.49244911 | P15: =VLOOKUP(K15,'Budget26 sin EI'!$B:$O,$L$5+1,0) -> -174.23 | Q15: =L15-P15 -> 21.59721 | R15: =+IF(IFERROR(L15/P15-1,"-")<300%,IFERROR(L15/P15-1,"-"),"n.a.") -> -0.12395804 | T15: Gastos de Personal | U15: =GETPIVOTDATA("nov-26 ",TABLA!$B$3,"Nivel 4","6.- Gastos de personal")/1000 -> -152.63279 | V15: =VLOOKUP(T15,'P&L Mensualitzada 2025'!$A$5:$N$25,$U$5+1,0) -> -153.08435 | W15: =U15-V15 -> 0.45156 | X15: =+IF(IFERROR(U15/V15-1,"-")<300%,IFERROR(U15/V15-1,"-"),"n.a.") -> -0.0029497463 | Y15: =VLOOKUP(T15,'Budget26 sin EI'!$B:$O,$U$5+1,0) -> -174.23 | Z15: =U15-Y15 -> 21.59721 | AA15: =+IF(IFERROR(U15/Y15-1,"-")<300%,IFERROR(U15/Y15-1,"-"),"n.a.") -> -0.12395804 | AC15: Gastos de Personal | AD15: =GETPIVOTDATA("dic-26 ",TABLA!$B$3,"Nivel 4","6.- Gastos de personal")/1000 -> -431.63279 | AE15: =VLOOKUP(AC15,'P&L Mensualitzada 2025'!$A$5:$N$25,$AD$5+1,0) -> -172.01862 | AF15: =AD15-AE15 -> -259.61417 | AG15: =+IF(IFERROR(AD15/AE15-1,"-")<300%,IFERROR(AD15/AE15-1,"-"),"n.a.") -> 1.5092213 | AH15: =VLOOKUP(AC15,'Budget26 sin EI'!$B:$O,$AD$5+1,0) -> -306.97667 | AI15: =AD15-AH15 -> -124.65612 | AJ15: =+IF(IFERROR(AD15/AH15-1,"-")<300%,IFERROR(AD15/AH15-1,"-"),"n.a.") -> 0.40607687 | AL15: Gastos de Personal | AM15: =GETPIVOTDATA("Total 2026 ",TABLA!$B$3,"Nivel 4","6.- Gastos de personal")/1000 -> -2006.5026 | AN15: =VLOOKUP(AL15,'P&L Mensualitzada 2025'!$A$5:$N$25,$AD$5+1,0) -> -172.01862 | AO15: =AM15-AN15 -> -1834.484 | AP15: =+IF(IFERROR(AM15/AN15-1,"-")<300%,IFERROR(AM15/AN15-1,"-"),"n.a.") -> n.a. | AQ15: =VLOOKUP(AL15,'Budget26 sin EI'!$B:$O,$AD$5+1,0) -> -306.97667 | AR15: =AM15-AQ15 -> -1699.5259 | AS15: =+IF(IFERROR(AM15/AQ15-1,"-")<300%,IFERROR(AM15/AQ15-1,"-"),"n.a.") -> n.a.
B16: % of Revenue | C16: =C15/C10 -> -0.31595514 | D16: =D15/D10 -> -0.15879194 | G16: =G15/G10 -> -0.16972078 | K16: % of Revenue | L16: =L15/L10 -> -0.16735042 | M16: =M15/M10 -> -0.42986167 | P16: =P15/P10 -> -0.21817826 | T16: % of Revenue | U16: =U15/U10 -> -0.12456548 | V16: =V15/V10 -> -0.20419437 | Y16: =Y15/Y10 -> -0.16911544 | AC16: % of Revenue | AD16: =AD15/AD10 -> -0.37782738 | AE16: =AE15/AE10 -> -0.69221111 | AH16: =AH15/AH10 -> -0.46515517 | AL16: % of Revenue | AM16: =AM15/AM10 -> -0.13218067 | AN16: =AN15/AN10 -> -0.69221111 | AQ16: =AQ15/AQ10 -> -0.46515517
B18: Otros Ingresos Operativos | C18: =GETPIVOTDATA("sep-26 ",TABLA!$B$3,"Nivel 4","5.- Otros ingresos de explotación")/1000 -> 5.2862 | D18: =VLOOKUP(B18,'P&L Mensualitzada 2025'!$A$5:$N$25,$C$5+1,0) -> 0 | E18: =C18-D18 -> 5.2862 | F18: =+IF(IFERROR(C18/D18-1,"-")<300%,IFERROR(C18/D18-1,"-"),"n.a.") -> n.a. | G18: =VLOOKUP(B18,'Budget26 sin EI'!$B:$O,$C$5+1,0) -> 0 | H18: =C18-G18 -> 5.2862 | I18: =+IF(IFERROR(C18/G18-1,"-")<300%,IFERROR(C18/G18-1,"-"),"n.a.") -> n.a. | K18: Otros Ingresos Operativos | L18: =GETPIVOTDATA("oct-26 ",TABLA!$B$3,"Nivel 4","5.- Otros ingresos de explotación")/1000 -> 10.01367 | M18: =VLOOKUP(K18,'P&L Mensualitzada 2025'!$A$5:$N$25,$L$5+1,0) -> 1.80096 | N18: =L18-M18 -> 8.21271 | O18: =+IF(IFERROR(L18/M18-1,"-")<300%,IFERROR(L18/M18-1,"-"),"n.a.") -> n.a. | P18: =VLOOKUP(K18,'Budget26 sin EI'!$B:$O,$L$5+1,0) -> 0 | Q18: =L18-P18 -> 10.01367 | R18: =+IF(IFERROR(L18/P18-1,"-")<300%,IFERROR(L18/P18-1,"-"),"n.a.") -> n.a. | T18: Otros Ingresos Operativos | U18: =GETPIVOTDATA("nov-26 ",TABLA!$B$3,"Nivel 4","5.- Otros ingresos de explotación")/1000 -> 13.46183 | V18: =VLOOKUP(T18,'P&L Mensualitzada 2025'!$A$5:$N$25,$U$5+1,0) -> 0 | W18: =U18-V18 -> 13.46183 | X18: =+IF(IFERROR(U18/V18-1,"-")<300%,IFERROR(U18/V18-1,"-"),"n.a.") -> n.a. | Y18: =VLOOKUP(T18,'Budget26 sin EI'!$B:$O,$U$5+1,0) -> 0 | Z18: =U18-Y18 -> 13.46183 | AA18: =+IF(IFERROR(U18/Y18-1,"-")<300%,IFERROR(U18/Y18-1,"-"),"n.a.") -> n.a. | AC18: Otros Ingresos Operativos | AD18: =GETPIVOTDATA("dic-26 ",TABLA!$B$3,"Nivel 4","5.- Otros ingresos de explotación")/1000 -> 14.53394 | AE18: =VLOOKUP(AC18,'P&L Mensualitzada 2025'!$A$5:$N$25,$AD$5+1,0) -> 47.20436 | AF18: =AD18-AE18 -> -32.67042 | AG18: =+IF(IFERROR(AD18/AE18-1,"-")<300%,IFERROR(AD18/AE18-1,"-"),"n.a.") -> -0.69210598 | AH18: =VLOOKUP(AC18,'Budget26 sin EI'!$B:$O,$AD$5+1,0) -> 0 | AI18: =AD18-AH18 -> 14.53394 | AJ18: =+IF(IFERROR(AD18/AH18-1,"-")<300%,IFERROR(AD18/AH18-1,"-"),"n.a.") -> n.a. | AL18: Otros Ingresos Operativos | AM18: =GETPIVOTDATA("Total 2026 ",TABLA!$B$3,"Nivel 4","5.- Otros ingresos de explotación")/1000 -> 114.62098 | AN18: =VLOOKUP(AL18,'P&L Mensualitzada 2025'!$A$5:$N$25,$AD$5+1,0) -> 47.20436 | AO18: =AM18-AN18 -> 67.41662 | AP18: =+IF(IFERROR(AM18/AN18-1,"-")<300%,IFERROR(AM18/AN18-1,"-"),"n.a.") -> 1.4281863 | AQ18: =VLOOKUP(AL18,'Budget26 sin EI'!$B:$O,$AD$5+1,0) -> 0 | AR18: =AM18-AQ18 -> 114.62098 | AS18: =+IF(IFERROR(AM18/AQ18-1,"-")<300%,IFERROR(AM18/AQ18-1,"-"),"n.a.") -> n.a.
B19: Otros Gastos Operativos | C19: =-100 -> -100 | D19: =VLOOKUP(B19,'P&L Mensualitzada 2025'!$A$5:$N$25,$C$5+1,0) -> -73.91279 | E19: =C19-D19 -> -26.08721 | F19: =+IF(IFERROR(C19/D19-1,"-")<300%,IFERROR(C19/D19-1,"-"),"n.a.") -> 0.35294582 | G19: =VLOOKUP(B19,'Budget26 sin EI'!$B:$O,$C$5+1,0) -> -120.05333 | H19: =C19-G19 -> 20.053329 | I19: =+IF(IFERROR(C19/G19-1,"-")<300%,IFERROR(C19/G19-1,"-"),"n.a.") -> -0.16703684 | K19: Otros Gastos Operativos | L19: =GETPIVOTDATA("oct-26 ",TABLA!$B$3,"Nivel 4","7.- Otros gastos de explotación")/1000 -> -141.64847 | M19: =VLOOKUP(K19,'P&L Mensualitzada 2025'!$A$5:$N$25,$L$5+1,0) -> -122.16905 | N19: =L19-M19 -> -19.47942 | O19: =+IF(IFERROR(L19/M19-1,"-")<300%,IFERROR(L19/M19-1,"-"),"n.a.") -> 0.15944644 | P19: =VLOOKUP(K19,'Budget26 sin EI'!$B:$O,$L$5+1,0) -> -144.84269 | Q19: =L19-P19 -> 3.1942192 | R19: =+IF(IFERROR(L19/P19-1,"-")<300%,IFERROR(L19/P19-1,"-"),"n.a.") -> -0.022053023 | T19: Otros Gastos Operativos | U19: =GETPIVOTDATA("nov-26 ",TABLA!$B$3,"Nivel 4","7.- Otros gastos de explotación")/1000 -> -149.83612 | V19: =VLOOKUP(T19,'P&L Mensualitzada 2025'!$A$5:$N$25,$U$5+1,0) -> -68.32762 | W19: =U19-V19 -> -81.5085 | X19: =+IF(IFERROR(U19/V19-1,"-")<300%,IFERROR(U19/V19-1,"-"),"n.a.") -> 1.1929071 | Y19: =VLOOKUP(T19,'Budget26 sin EI'!$B:$O,$U$5+1,0) -> -148.99269 | Z19: =U19-Y19 -> -0.84343084 | AA19: =+IF(IFERROR(U19/Y19-1,"-")<300%,IFERROR(U19/Y19-1,"-"),"n.a.") -> 0.0056608874 | AC19: Otros Gastos Operativos | AD19: =GETPIVOTDATA("dic-26 ",TABLA!$B$3,"Nivel 4","7.- Otros gastos de explotación")/1000 -> -291.51097 | AE19: =VLOOKUP(AC19,'P&L Mensualitzada 2025'!$A$5:$N$25,$AD$5+1,0) -> -239.07332 | AF19: =AD19-AE19 -> -52.43765 | AG19: =+IF(IFERROR(AD19/AE19-1,"-")<300%,IFERROR(AD19/AE19-1,"-"),"n.a.") -> 0.21933711 | AH19: =VLOOKUP(AC19,'Budget26 sin EI'!$B:$O,$AD$5+1,0) -> -180.34269 | AI19: =AD19-AH19 -> -111.16828 | AJ19: =+IF(IFERROR(AD19/AH19-1,"-")<300%,IFERROR(AD19/AH19-1,"-"),"n.a.") -> 0.61642799 | AL19: Otros Gastos Operativos | AM19: =GETPIVOTDATA("Total 2026 ",TABLA!$B$3,"Nivel 4","7.- Otros gastos de explotación")/1000 -> -1678.4074 | AN19: =VLOOKUP(AL19,'P&L Mensualitzada 2025'!$A$5:$N$25,$AD$5+1,0) -> -239.07332 | AO19: =AM19-AN19 -> -1439.3341 | AP19: =+IF(IFERROR(AM19/AN19-1,"-")<300%,IFERROR(AM19/AN19-1,"-"),"n.a.") -> n.a. | AQ19: =VLOOKUP(AL19,'Budget26 sin EI'!$B:$O,$AD$5+1,0) -> -180.34269 | AR19: =AM19-AQ19 -> -1498.0647 | AS19: =+IF(IFERROR(AM19/AQ19-1,"-")<300%,IFERROR(AM19/AQ19-1,"-"),"n.a.") -> n.a.
B20: Operating Expenses | C20: =SUM(C18:C19) -> -94.7138 | D20: =SUM(D18:D19) -> -73.91279 | E20: =C20-D20 -> -20.80101 | F20: =+IF(IFERROR(C20/D20-1,"-")<300%,IFERROR(C20/D20-1,"-"),"n.a.") -> 0.28142639 | G20: =SUM(G18:G19) -> -120.05333 | H20: =C20-G20 -> 25.339529 | I20: =+IF(IFERROR(C20/G20-1,"-")<300%,IFERROR(C20/G20-1,"-"),"n.a.") -> -0.21106894 | K20: Operating Expenses | L20: =SUM(L18:L19) -> -131.6348 | M20: =SUM(M18:M19) -> -120.36809 | N20: =L20-M20 -> -11.26671 | O20: =+IF(IFERROR(L20/M20-1,"-")<300%,IFERROR(L20/M20-1,"-"),"n.a.") -> 0.093602133 | P20: =SUM(P18:P19) -> -144.84269 | Q20: =L20-P20 -> 13.207889 | R20: =+IF(IFERROR(L20/P20-1,"-")<300%,IFERROR(L20/P20-1,"-"),"n.a.") -> -0.091187821 | T20: Operating Expenses | U20: =SUM(U18:U19) -> -136.37429 | V20: =SUM(V18:V19) -> -68.32762 | W20: =U20-V20 -> -68.04667 | X20: =+IF(IFERROR(U20/V20-1,"-")<300%,IFERROR(U20/V20-1,"-"),"n.a.") -> 0.99588819 | Y20: =SUM(Y18:Y19) -> -148.99269 | Z20: =U20-Y20 -> 12.618399 | AA20: =+IF(IFERROR(U20/Y20-1,"-")<300%,IFERROR(U20/Y20-1,"-"),"n.a.") -> -0.084691398 | AC20: Operating Expenses | AD20: =SUM(AD18:AD19) -> -276.97703 | AE20: =SUM(AE18:AE19) -> -191.86896 | AF20: =AD20-AE20 -> -85.10807 | AG20: =+IF(IFERROR(AD20/AE20-1,"-")<300%,IFERROR(AD20/AE20-1,"-"),"n.a.") -> 0.44357394 | AH20: =SUM(AH18:AH19) -> -180.34269 | AI20: =AD20-AH20 -> -96.634341 | AJ20: =+IF(IFERROR(AD20/AH20-1,"-")<300%,IFERROR(AD20/AH20-1,"-"),"n.a.") -> 0.53583731 | AL20: Operating Expenses | AM20: =SUM(AM18:AM19) -> -1563.7865 | AN20: =SUM(AN18:AN19) -> -191.86896 | AO20: =AM20-AN20 -> -1371.9175 | AP20: =+IF(IFERROR(AM20/AN20-1,"-")<300%,IFERROR(AM20/AN20-1,"-"),"n.a.") -> n.a. | AQ20: =SUM(AQ18:AQ19) -> -180.34269 | AR20: =AM20-AQ20 -> -1383.4438 | AS20: =+IF(IFERROR(AM20/AQ20-1,"-")<300%,IFERROR(AM20/AQ20-1,"-"),"n.a.") -> n.a.
B21: % of Revenue | C21: =C20/C10 -> -0.19606083 | D21: =D20/D10 -> -0.087770341 | G21: =G20/G10 -> -0.11694624 | K21: % of Revenue | L21: =L20/L10 -> -0.1443277 | M21: =M20/M10 -> -0.1720568 | P21: =P20/P10 -> -0.18137821 | T21: % of Revenue | U21: =U20/U10 -> -0.11129672 | V21: =V20/V10 -> -0.091140051 | Y21: =Y20/Y10 -> -0.14461898 | AC21: % of Revenue | AD21: =AD20/AD10 -> -0.24245032 | AE21: =AE20/AE10 -> -0.77208982 | AH21: =AH20/AH10 -> -0.27326941 | AL21: % of Revenue | AM21: =AM20/AM10 -> -0.10301624 | AN21: =AN20/AN10 -> -0.77208982 | AQ21: =AQ20/AQ10 -> -0.27326941
B22: Gastos Fijos | C22: =C20+C15 -> -247.34659 | D22: =D20+D15 -> -207.63399 | E22: =C22-D22 -> -39.7126 | F22: =+IF(IFERROR(C22/D22-1,"-")<300%,IFERROR(C22/D22-1,"-"),"n.a.") -> 0.19126252 | G22: =G20+G15 -> -294.28333 | H22: =C22-G22 -> 46.936739 | I22: =+IF(IFERROR(C22/G22-1,"-")<300%,IFERROR(C22/G22-1,"-"),"n.a.") -> -0.15949507 | K22: Gastos Fijos | L22: =L20+L15 -> -284.26759 | M22: =M20+M15 -> -421.0922 | N22: =L22-M22 -> 136.82461 | O22: =+IF(IFERROR(L22/M22-1,"-")<300%,IFERROR(L22/M22-1,"-"),"n.a.") -> -0.32492791 | P22: =P20+P15 -> -319.07269 | Q22: =L22-P22 -> 34.805099 | R22: =+IF(IFERROR(L22/P22-1,"-")<300%,IFERROR(L22/P22-1,"-"),"n.a.") -> -0.10908204 | T22: Gastos Fijos | U22: =U20+U15 -> -289.00708 | V22: =V20+V15 -> -221.41197 | W22: =U22-V22 -> -67.59511 | X22: =+IF(IFERROR(U22/V22-1,"-")<300%,IFERROR(U22/V22-1,"-"),"n.a.") -> 0.30529113 | Y22: =Y20+Y15 -> -323.22269 | Z22: =U22-Y22 -> 34.215609 | AA22: =+IF(IFERROR(U22/Y22-1,"-")<300%,IFERROR(U22/Y22-1,"-"),"n.a.") -> -0.1058577 | AC22: Gastos Fijos | AD22: =AD20+AD15 -> -708.60982 | AE22: =AE20+AE15 -> -363.88758 | AF22: =AD22-AE22 -> -344.72224 | AG22: =+IF(IFERROR(AD22/AE22-1,"-")<300%,IFERROR(AD22/AE22-1,"-"),"n.a.") -> 0.9473317 | AH22: =AH20+AH15 -> -487.31936 | AI22: =AD22-AH22 -> -221.29046 | AJ22: =+IF(IFERROR(AD22/AH22-1,"-")<300%,IFERROR(AD22/AH22-1,"-"),"n.a.") -> 0.45409742 | AL22: Gastos Fijos | AM22: =AM20+AM15 -> -3570.289 | AN22: =AN20+AN15 -> -363.88758 | AO22: =AM22-AN22 -> -3206.4015 | AP22: =+IF(IFERROR(AM22/AN22-1,"-")<300%,IFERROR(AM22/AN22-1,"-"),"n.a.") -> n.a. | AQ22: =AQ20+AQ15 -> -487.31936 | AR22: =AM22-AQ22 -> -3082.9697 | AS22: =+IF(IFERROR(AM22/AQ22-1,"-")<300%,IFERROR(AM22/AQ22-1,"-"),"n.a.") -> n.a.
B23: % of Revenue | C23: =C22/C10 -> -0.51201597 | D23: =D22/D10 -> -0.24656228 | G23: =G22/G10 -> -0.28666702 | K23: % of Revenue | L23: =L22/L10 -> -0.31167812 | M23: =M22/M10 -> -0.60191847 | P23: =P22/P10 -> -0.39955648 | T23: % of Revenue | U23: =U22/U10 -> -0.23586219 | V23: =V22/V10 -> -0.29533442 | Y23: =Y22/Y10 -> -0.31373442 | AC23: % of Revenue | AD23: =AD22/AD10 -> -0.6202777 | AE23: =AE22/AE10 -> -1.4643009 | AH23: =AH22/AH10 -> -0.73842458 | AL23: % of Revenue | AM23: =AM22/AM10 -> -0.23519691 | AN23: =AN22/AN10 -> -1.4643009 | AQ23: =AQ22/AQ10 -> -0.73842458
B24: Adjusted EBITDA | C24: =C12+C22 -> 155.73715 | D24: =D12+D22 -> 369.11089 | E24: =C24-D24 -> -213.37374 | F24: =+IF(IFERROR(C24/D24-1,"-")<300%,IFERROR(C24/D24-1,"-"),"n.a.") -> -0.5780749 | G24: =G12+G22 -> 379.72623 | H24: =C24-G24 -> -223.98908 | I24: =+IF(IFERROR(C24/G24-1,"-")<300%,IFERROR(C24/G24-1,"-"),"n.a.") -> -0.58986992 | K24: Adjusted EBITDA | L24: =L12+L22 -> 325.68606 | M24: =M12+M22 -> -82.58246 | N24: =L24-M24 -> 408.26852 | O24: =+IF(IFERROR(L24/M24-1,"-")<300%,IFERROR(L24/M24-1,"-"),"n.a.") -> -4.943768 | P24: =P12+P22 -> 205.23905 | Q24: =L24-P24 -> 120.44701 | R24: =+IF(IFERROR(L24/P24-1,"-")<300%,IFERROR(L24/P24-1,"-"),"n.a.") -> 0.58686201 | T24: Adjusted EBITDA | U24: =U12+U22 -> 531.89142 | V24: =V12+V22 -> 252.54065 | W24: =U24-V24 -> 279.35077 | X24: =+IF(IFERROR(U24/V24-1,"-")<300%,IFERROR(U24/V24-1,"-"),"n.a.") -> 1.1061616 | Y24: =Y12+Y22 -> 353.19943 | Z24: =U24-Y24 -> 178.69199 | AA24: =+IF(IFERROR(U24/Y24-1,"-")<300%,IFERROR(U24/Y24-1,"-"),"n.a.") -> 0.50592377 | AC24: Adjusted EBITDA | AD24: =AD12+AD22 -> -15.34777 | AE24: =AE12+AE22 -> -231.81027 | AF24: =AD24-AE24 -> 216.4625 | AG24: =+IF(IFERROR(AD24/AE24-1,"-")<300%,IFERROR(AD24/AE24-1,"-"),"n.a.") -> -0.93379167 | AH24: =AH12+AH22 -> -54.021526 | AI24: =AD24-AH24 -> 38.673756 | AJ24: =+IF(IFERROR(AD24/AH24-1,"-")<300%,IFERROR(AD24/AH24-1,"-"),"n.a.") -> -0.71589529 | AL24: Adjusted EBITDA | AM24: =AM12+AM22 -> 6376.1781 | AN24: =AN12+AN22 -> -231.81027 | AO24: =AM24-AN24 -> 6607.9884 | AP24: =+IF(IFERROR(AM24/AN24-1,"-")<300%,IFERROR(AM24/AN24-1,"-"),"n.a.") -> -28.506021 | AQ24: =AQ12+AQ22 -> -54.021526 | AR24: =AM24-AQ24 -> 6430.1996 | AS24: =+IF(IFERROR(AM24/AQ24-1,"-")<300%,IFERROR(AM24/AQ24-1,"-"),"n.a.") -> -119.03032
B25: % Adj. EBITDA Margin | C25: =C24/C10 -> 0.32238127 | D25: =D24/D10 -> 0.4383137 | F25: =+IF(IFERROR(C25/D25-1,"-")<300%,IFERROR(C25/D25-1,"-"),"n.a.") -> -0.26449648 | G25: =G24/G10 -> 0.36989858 | K25: % Adj. EBITDA Margin | L25: =L24/L10 -> 0.35709037 | M25: =M24/M10 -> -0.11804519 | O25: =+IF(IFERROR(L25/M25-1,"-")<300%,IFERROR(L25/M25-1,"-"),"n.a.") -> -4.0250311 | P25: =P24/P10 -> 0.25700913 | T25: % Adj. EBITDA Margin | U25: =U24/U10 -> 0.43408305 | V25: =V24/V10 -> 0.33685599 | X25: =+IF(IFERROR(U25/V25-1,"-")<300%,IFERROR(U25/V25-1,"-"),"n.a.") -> 0.28863096 | Y25: =Y24/Y10 -> 0.34283119 | AC25: % Adj. EBITDA Margin | AD25: =AD24/AD10 -> -0.013434586 | AE25: =AE24/AE10 -> -0.93281555 | AG25: =+IF(IFERROR(AD25/AE25-1,"-")<300%,IFERROR(AD25/AE25-1,"-"),"n.a.") -> -0.98559781 | AH25: =AH24/AH10 -> -0.081857662 | AL25: % Adj. EBITDA Margin | AM25: =AM24/AM10 -> 0.42003808 | AN25: =AN24/AN10 -> -0.93281555 | AP25: =+IF(IFERROR(AM25/AN25-1,"-")<300%,IFERROR(AM25/AN25-1,"-"),"n.a.") -> -1.4502906 | AQ25: =AQ24/AQ10 -> -0.081857662
B27: D&A | C27: =GETPIVOTDATA("sep-26 ",TABLA!$B$3,"Nivel 4","8.- Amortización del inmovilizado")/1000 -> -19.22535 | D27: =VLOOKUP(B27,'P&L Mensualitzada 2025'!$A$5:$N$25,$C$5+1,0) -> 0 | E27: =C27-D27 -> -19.22535 | F27: =+IF(IFERROR(C27/D27-1,"-")<300%,IFERROR(C27/D27-1,"-"),"n.a.") -> n.a. | G27: =VLOOKUP(B27,'Budget26 sin EI'!$B:$O,$C$5+1,0) -> -20.833333 | H27: =C27-G27 -> 1.607983 | I27: =+IF(IFERROR(C27/G27-1,"-")<300%,IFERROR(C27/G27-1,"-"),"n.a.") -> -0.077183185 | K27: D&A | L27: =GETPIVOTDATA("oct-26 ",TABLA!$B$3,"Nivel 4","8.- Amortización del inmovilizado")/1000 -> -19.22535 | M27: =VLOOKUP(K27,'P&L Mensualitzada 2025'!$A$5:$N$25,$L$5+1,0) -> -194.71201 | N27: =L27-M27 -> 175.48666 | O27: =+IF(IFERROR(L27/M27-1,"-")<300%,IFERROR(L27/M27-1,"-"),"n.a.") -> -0.90126264 | P27: =VLOOKUP(K27,'Budget26 sin EI'!$B:$O,$L$5+1,0) -> -20.833333 | Q27: =L27-P27 -> 1.607983 | R27: =+IF(IFERROR(L27/P27-1,"-")<300%,IFERROR(L27/P27-1,"-"),"n.a.") -> -0.077183185 | T27: D&A | U27: =GETPIVOTDATA("nov-26 ",TABLA!$B$3,"Nivel 4","8.- Amortización del inmovilizado")/1000 -> -19.22535 | V27: =VLOOKUP(T27,'P&L Mensualitzada 2025'!$A$5:$N$25,$U$5+1,0) -> -19.4712 | W27: =U27-V27 -> 0.24585 | X27: =+IF(IFERROR(U27/V27-1,"-")<300%,IFERROR(U27/V27-1,"-"),"n.a.") -> -0.01262634 | Y27: =VLOOKUP(T27,'Budget26 sin EI'!$B:$O,$U$5+1,0) -> -20.833333 | Z27: =U27-Y27 -> 1.607983 | AA27: =+IF(IFERROR(U27/Y27-1,"-")<300%,IFERROR(U27/Y27-1,"-"),"n.a.") -> -0.077183185 | AC27: D&A | AD27: =GETPIVOTDATA("dic-26 ",TABLA!$B$3,"Nivel 4","8.- Amortización del inmovilizado")/1000 -> -19.22535 | AE27: =VLOOKUP(AC27,'P&L Mensualitzada 2025'!$A$5:$N$25,$AD$5+1,0) -> -34.07237 | AF27: =AD27-AE27 -> 14.84702 | AG27: =+IF(IFERROR(AD27/AE27-1,"-")<300%,IFERROR(AD27/AE27-1,"-"),"n.a.") -> -0.43574955 | AH27: =VLOOKUP(AC27,'Budget26 sin EI'!$B:$O,$AD$5+1,0) -> -20.833333 | AI27: =AD27-AH27 -> 1.607983 | AJ27: =+IF(IFERROR(AD27/AH27-1,"-")<300%,IFERROR(AD27/AH27-1,"-"),"n.a.") -> -0.077183185 | AL27: D&A | AM27: =GETPIVOTDATA("Total 2026 ",TABLA!$B$3,"Nivel 4","8.- Amortización del inmovilizado")/1000 -> -229.67475 | AN27: =VLOOKUP(AL27,'P&L Mensualitzada 2025'!$A$5:$N$25,$AD$5+1,0) -> -34.07237 | AO27: =AM27-AN27 -> -195.60238 | AP27: =+IF(IFERROR(AM27/AN27-1,"-")<300%,IFERROR(AM27/AN27-1,"-"),"n.a.") -> n.a. | AQ27: =VLOOKUP(AL27,'Budget26 sin EI'!$B:$O,$AD$5+1,0) -> -20.833333 | AR27: =AM27-AQ27 -> -208.84142 | AS27: =+IF(IFERROR(AM27/AQ27-1,"-")<300%,IFERROR(AM27/AQ27-1,"-"),"n.a.") -> n.a.
B28: Other Gains/Losses | C28: =GETPIVOTDATA("sep-26 ",TABLA!$B$3,"Nivel 4","13.- Otros resultados")+GETPIVOTDATA("ago-26 ",TABLA!$B$3,"Nivel 4","11.- Deterioro y resultado por enajenaciones del inmovilizado")/1000 -> 0 | D28: =VLOOKUP(B28,'P&L Mensualitzada 2025'!$A$5:$N$25,$C$5+1,0) -> -0.04064 | E28: =C28-D28 -> 0.04064 | F28: n.a. | G28: =VLOOKUP(B28,'Budget26 sin EI'!$B:$O,$C$5+1,0) -> 0 | H28: =C28-G28 -> 0 | I28: =+IF(IFERROR(C28/G28-1,"-")<300%,IFERROR(C28/G28-1,"-"),"n.a.") -> n.a. | K28: Other Gains/Losses | L28: =GETPIVOTDATA("oct-26 ",TABLA!$B$3,"Nivel 4","13.- Otros resultados")+GETPIVOTDATA("ago-26 ",TABLA!$B$3,"Nivel 4","11.- Deterioro y resultado por enajenaciones del inmovilizado")/1000 -> 0 | M28: =VLOOKUP(K28,'P&L Mensualitzada 2025'!$A$5:$N$25,$L$5+1,0) -> 0.81001 | N28: =L28-M28 -> -0.81001 | O28: n.a. | P28: =VLOOKUP(K28,'Budget26 sin EI'!$B:$O,$L$5+1,0) -> 0 | Q28: =L28-P28 -> 0 | R28: =+IF(IFERROR(L28/P28-1,"-")<300%,IFERROR(L28/P28-1,"-"),"n.a.") -> n.a. | T28: Other Gains/Losses | U28: =GETPIVOTDATA("nov-26 ",TABLA!$B$3,"Nivel 4","13.- Otros resultados")+GETPIVOTDATA("ago-26 ",TABLA!$B$3,"Nivel 4","11.- Deterioro y resultado por enajenaciones del inmovilizado")/1000 -> 0 | V28: =VLOOKUP(T28,'P&L Mensualitzada 2025'!$A$5:$N$25,$U$5+1,0) -> 0.00443 | W28: =U28-V28 -> -0.00443 | X28: n.a. | Y28: =VLOOKUP(T28,'Budget26 sin EI'!$B:$O,$U$5+1,0) -> 0 | Z28: =U28-Y28 -> 0 | AA28: =+IF(IFERROR(U28/Y28-1,"-")<300%,IFERROR(U28/Y28-1,"-"),"n.a.") -> n.a. | AC28: Other Gains/Losses | AD28: =GETPIVOTDATA("dic-26 ",TABLA!$B$3,"Nivel 4","13.- Otros resultados")+GETPIVOTDATA("ago-26 ",TABLA!$B$3,"Nivel 4","11.- Deterioro y resultado por enajenaciones del inmovilizado")/1000 -> 0 | AE28: =VLOOKUP(AC28,'P&L Mensualitzada 2025'!$A$5:$N$25,$AD$5+1,0) -> 0.15045 | AF28: =AD28-AE28 -> -0.15045 | AG28: n.a. | AH28: =VLOOKUP(AC28,'Budget26 sin EI'!$B:$O,$AD$5+1,0) -> 0 | AI28: =AD28-AH28 -> 0 | AJ28: =+IF(IFERROR(AD28/AH28-1,"-")<300%,IFERROR(AD28/AH28-1,"-"),"n.a.") -> n.a. | AL28: Other Gains/Losses | AM28: =GETPIVOTDATA("Total 2026 ",TABLA!$B$3,"Nivel 4","13.- Otros resultados")/1000+GETPIVOTDATA("ago-26 ",TABLA!$B$3,"Nivel 4","11.- Deterioro y resultado por enajenaciones del inmovilizado")/1000 -> 3.99994 | AN28: =VLOOKUP(AL28,'P&L Mensualitzada 2025'!$A$5:$N$25,$AD$5+1,0) -> 0.15045 | AO28: =AM28-AN28 -> 3.84949 | AP28: n.a. | AQ28: =VLOOKUP(AL28,'Budget26 sin EI'!$B:$O,$AD$5+1,0) -> 0 | AR28: =AM28-AQ28 -> 3.99994 | AS28: =+IF(IFERROR(AM28/AQ28-1,"-")<300%,IFERROR(AM28/AQ28-1,"-"),"n.a.") -> n.a.
B29: Adjusted EBIT | C29: =C24+C27+C28 -> 136.5118 | D29: =D24+D27+D28 -> 369.07025 | E29: =C29-D29 -> -232.55845 | F29: =+IF(IFERROR(C29/D29-1,"-")<300%,IFERROR(C29/D29-1,"-"),"n.a.") -> -0.63011974 | G29: =G24+G27+G28 -> 358.8929 | H29: =C29-G29 -> -222.3811 | I29: =+IF(IFERROR(C29/G29-1,"-")<300%,IFERROR(C29/G29-1,"-"),"n.a.") -> -0.61963081 | K29: Adjusted EBIT | L29: =L24+L27+L28 -> 306.46071 | M29: =M24+M27+M28 -> -276.48446 | N29: =L29-M29 -> 582.94517 | O29: =+IF(IFERROR(L29/M29-1,"-")<300%,IFERROR(L29/M29-1,"-"),"n.a.") -> -2.1084193 | P29: =P24+P27+P28 -> 184.40572 | Q29: =L29-P29 -> 122.05499 | R29: =+IF(IFERROR(L29/P29-1,"-")<300%,IFERROR(L29/P29-1,"-"),"n.a.") -> 0.66188287 | T29: Adjusted EBIT | U29: =U24+U27+U28 -> 512.66607 | V29: =V24+V27+V28 -> 233.07388 | W29: =U29-V29 -> 279.59219 | X29: =+IF(IFERROR(U29/V29-1,"-")<300%,IFERROR(U29/V29-1,"-"),"n.a.") -> 1.1995861 | Y29: =Y24+Y27+Y28 -> 332.3661 | Z29: =U29-Y29 -> 180.29997 | AA29: =+IF(IFERROR(U29/Y29-1,"-")<300%,IFERROR(U29/Y29-1,"-"),"n.a.") -> 0.54247401 | AC29: Adjusted EBIT | AD29: =AD24+AD27+AD28 -> -34.57312 | AE29: =AE24+AE27+AE28 -> -265.73219 | AF29: =AD29-AE29 -> 231.15907 | AG29: =+IF(IFERROR(AD29/AE29-1,"-")<300%,IFERROR(AD29/AE29-1,"-"),"n.a.") -> -0.86989487 | AH29: =AH24+AH27+AH28 -> -74.854859 | AI29: =AD29-AH29 -> 40.281739 | AJ29: =+IF(IFERROR(AD29/AH29-1,"-")<300%,IFERROR(AD29/AH29-1,"-"),"n.a.") -> -0.53813125 | AL29: Adjusted EBIT | AM29: =AM24+AM27+AM28 -> 6150.5033 | AN29: =AN24+AN27+AN28 -> -265.73219 | AO29: =AM29-AN29 -> 6416.2355 | AP29: =+IF(IFERROR(AM29/AN29-1,"-")<300%,IFERROR(AM29/AN29-1,"-"),"n.a.") -> -24.145496 | AQ29: =AQ24+AQ27+AQ28 -> -74.854859 | AR29: =AM29-AQ29 -> 6225.3582 | AS29: =+IF(IFERROR(AM29/AQ29-1,"-")<300%,IFERROR(AM29/AQ29-1,"-"),"n.a.") -> -83.165718
B30: % EBIT Margin | C30: =C29/C10 -> 0.28258413 | D30: =D29/D10 -> 0.43826544 | G30: =G29/G10 -> 0.34960443 | K30: % EBIT Margin | L30: =L29/L10 -> 0.33601121 | M30: =M29/M10 -> -0.39521298 | P30: =P29/P10 -> 0.23092074 | T30: % EBIT Margin | U30: =U29/U10 -> 0.41839301 | V30: =V29/V10 -> 0.31088988 | Y30: =Y29/Y10 -> 0.32260942 | AC30: % EBIT Margin | AD30: =AD29/AD10 -> -0.03026339 | AE30: =AE29/AE10 -> -1.069319 | AH30: =AH29/AH10 -> -0.11342597 | AL30: % EBIT Margin | AM30: =AM29/AM10 -> 0.4051715 | AN30: =AN29/AN10 -> -1.069319 | AQ30: =AQ29/AQ10 -> -0.11342597

Sheet TABLA
B1: Periodo | C1: 2026
B3: Detalle sin Ajustar | C3: ene-26 | D3: feb-26 | E3: mar-26 | F3: abr-26 | G3: may-26 | H3: jun-26 | I3: jul-26 | J3: ago-26 | K3: sep-26 | L3: oct-26 | M3: nov-26 | N3: dic-26 | O3: Total 2026
B4: 1.- Importe neto de la cifra de negocios | C4: 983817.13 | D4: 1470428.1 | E4: 1533789.4 | F4: 1462146.3 | G4: 1925929.9 | H4: 1962261.8 | I4: 1290654.2 | J4: 788105.15 | K4: 483083.74 | L4: 912055.01 | M4: 1225321.8 | N4: 1142407.4 | O4: 15180000
B5: 2.- Variación de existencias | C5: -84878.08 | D5: 50005.57 | E5: 83552.77 | F5: 8645.2 | G5: -30291.1 | H5: -90104.87 | I5: -6292.63 | J5: 6734.64 | K5: 0 | L5: 0 | M5: 0 | N5: 0 | O5: -62628.5
B6: 4.- Aprovisionamientos | C6: -417787.47 | D6: -406242.73 | E6: -469252.7 | F6: -514848.29 | G6: -593981.24 | H6: -653453.72 | I6: -519022.4 | J6: -278854.87 | K6: -161790.96 | L6: -302101.36 | M6: -404423.28 | N6: -449145.33 | O6: -5170904.3
B7: 6.- Gastos de personal | C7: -111532.01 | D7: -142927.2 | E7: -146233.31 | F7: -130047.67 | G7: -134992.52 | H7: -145072.28 | I7: -153533.65 | J7: -152632.79 | K7: -152632.79 | L7: -152632.79 | M7: -152632.79 | N7: -431632.79 | O7: -2006502.6
B8: 5.- Otros ingresos de explotación | C8: 0 | D8: 0 | E8: 0 | F8: 750.75 | G8: 25140.75 | H8: 22977.6 | I8: 11027.24 | J8: 11429 | K8: 5286.2 | L8: 10013.67 | M8: 13461.83 | N8: 14533.94 | O8: 114620.98
B9: 7.- Otros gastos de explotación | C9: -103451.76 | D9: -62498.88 | E9: -110606.27 | F9: -107706.65 | G9: -123392.08 | H9: -175013.76 | I9: -161051.74 | J9: -130060.66 | K9: -121630.07 | L9: -141648.47 | M9: -149836.12 | N9: -291510.97 | O9: -1678407.4
B10: 11.- Deterioro y resultado por enajenaciones del inmovilizado | C10: 0 | D10: 0 | E10: 2000 | F10: 0 | G10: 0 | H10: 0 | I10: 0 | J10: 0 | K10: 0 | L10: 0 | M10: 0 | N10: 0 | O10: 2000
B11: 8.- Amortización del inmovilizado | C11: -19132.87 | D11: -19132.87 | E11: -18903.55 | F11: -18903.55 | G11: -19189.68 | H11: -19060.25 | I11: -19225.29 | J11: -19225.29 | K11: -19225.35 | L11: -19225.35 | M11: -19225.35 | N11: -19225.35 | O11: -229674.75
B12: 13.- Otros resultados | C12: 3065.27 | D12: 0.02 | E12: -0.14 | F12: 1024.26 | G12: -1.43 | H12: 0 | I12: -88.03 | J12: -0.01 | K12: 0 | L12: 0 | M12: 0 | N12: 0 | O12: 3999.94
B13: 15.- Gastos financieros | C13: -52.82 | D13: 0 | E13: -79.37 | F13: -24483.47 | G13: -38651.64 | H13: -78497.33 | I13: -32604.18 | J13: -19768.43 | K13: -12975.21 | L13: -24579.01 | M13: -33042.67 | N13: -35674.22 | O13: -300408.35
B14: 17.- Diferencias de cambio | C14: 0 | D14: 78.79 | E14: 15.51 | F14: 0 | G14: 2879.75 | H14: 1665.7 | I14: 604.76 | J14: 0 | K14: 0 | L14: 0 | M14: 0 | N14: 0 | O14: 5244.51
B15: 14.- Ingresos financieros | C15: 0 | D15: 0 | E15: 0 | F15: 0 | G15: 0 | H15: 4495.93 | I15: 0 | J15: 0 | K15: 0 | L15: 0 | M15: 0 | N15: 0 | O15: 4495.93
B16: Total general | C16: 250047.39 | D16: 889710.85 | E16: 874282.35 | F16: 676576.86 | G16: 1013450.7 | H16: 830198.85 | I16: 410468.31 | J16: 205726.74 | K16: 20115.56 | L16: 281881.7 | M16: 479623.4 | N16: -70247.34 | O16: 5861835.4
B17: EBITDA | C17: =+SUM(C4:C9) -> 266167.81 | D17: =+SUM(D4:D9) -> 908764.91 | E17: =+SUM(E4:E9) -> 891249.9 | F17: =+SUM(F4:F9) -> 718939.62 | G17: =+SUM(G4:G9) -> 1068413.7 | H17: =+SUM(H4:H9) -> 921594.8 | I17: =+SUM(I4:I9) -> 461781.05 | J17: =+SUM(J4:J9) -> 244720.47 | ... O17: =+SUM(O4:O9) -> 6376178.1
B18: EBITDA % | C18: =C17/C4 -> 0.27054602 | D18: =D17/D4 -> 0.61802742 | E18: =E17/E4 -> 0.5810771 | F18: =F17/F4 -> 0.49170157 | G18: =G17/G4 -> 0.55475213 | H18: =H17/H4 -> 0.46965944 | I18: =I17/I4 -> 0.35778835 | J18: =J17/J4 -> 0.31051754 | ... O18: =O17/O4 -> 0.42003808
N19: Check | O19: =SUM(C16:N16)-O16 -> 0

Sheet PL Mensual 2026
K2: =SUBTOTAL(9,K4:K215) -> 250047.39 | L2: =SUBTOTAL(9,L4:L215) -> 889710.85 | M2: =SUBTOTAL(9,M4:M215) -> 874282.35 | N2: =SUBTOTAL(9,N4:N215) -> 676576.86 | O2: =SUBTOTAL(9,O4:O2027) -> 1013450.7 | P2: =SUBTOTAL(9,P4:P2027) -> 830198.85 | Q2: =SUBTOTAL(9,Q4:Q2096) -> 410468.31 | R2: =SUBTOTAL(9,R4:R2015) -> 205726.74 | S2: =SUBTOTAL(9,S4:S215) -> 20115.56 | T2: =SUBTOTAL(9,T4:T215) -> 281881.7 | U2: =SUBTOTAL(9,U4:U215) -> 479623.4 | V2: =SUBTOTAL(9,V4:V215) -> -70247.34 | W2: =SUBTOTAL(9,W4:W2036) -> 5861835.4
B3: Periodo | C3: Empresa | D3: Nivel 1 | E3: Nivel 2 | F3: Nivel 3 | G3: Nivel 4 | H3: Nivel 5 | I3: Cuenta | J3: Grupo Ext Item | K3: 46023 | L3: 46054 | M3: 46082 | N3: 46113 | O3: 46143 | P3: 46174 | Q3: 46204 | R3: 46235 | S3: 46266 | T3: 46296 | U3: 46327 | V3: 46357 | W3: Total 2026
B4: 2026 | C4: Codiagro | D4: RESULTADO DEL EJERCICIO | E4: RESULTADO ANTES DE IMPUESTOS | F4: RESULTADO DE LA EXPLOTACION | G4: 1.- Importe neto de la cifra de negocios | H4: (700) Ventas | I4: 700000000 - Ventas de mercaderías | J4: - | K4: 993280.49 | L4: 1607538 | M4: 1536177.9 | N4: 1217250.4 | O4: 2029267 | P4: 2009948.7 | Q4: 1288443.6 | R4: 802410.56 | S4: 480563.3 | T4: 910333.55 | U4: 1223802.8 | V4: 1321267.5 | W4: 15420284 | X4: Presupuesto de Ventas 2026 ajustado para cuadrar la Cifra Neta de Negocios en 15.180.000,00 € exactos tras considerar la provisión anual de rappels (333k€) y gestión de envases.
B5: 2026 | C5: Codiagro | D5: RESULTADO DEL EJERCICIO | E5: RESULTADO ANTES DE IMPUESTOS | F5: RESULTADO DE LA EXPLOTACION | G5: 1.- Importe neto de la cifra de negocios | H5: (700) Ventas | I5: 700000001 - VENTA MERCADERIAS POR ANTICIPO | J5: - | K5: 0 | L5: 0 | M5: 0 | N5: 106250.17 | O5: -106250.17 | P5: - | Q5: 0 | R5: 0 | S5: 0 | T5: 0 | U5: 0 | V5: 0 | W5: 0 | X5: Cuenta sin saldo en el ejercicio. Sin previsión de movimientos.
B6: 2026 | C6: Codiagro | D6: RESULTADO DEL EJERCICIO | E6: RESULTADO ANTES DE IMPUESTOS | F6: RESULTADO DE LA EXPLOTACION | G6: 1.- Importe neto de la cifra de negocios | H6: (700) Ventas | I6: 700000624 - VENTA POR TRANSP. REP. AL CLIENTE | J6: - | K6: 17921.38 | L6: 12025.38 | M6: 8455.55 | N6: 0 | O6: 0 | P6: - | Q6: 0 | R6: 0 | S6: 0 | T6: 0 | U6: 0 | V6: 0 | W6: 38402.31 | X6: Partida puntual / no recurrente en el periodo enero-agosto. Sin movimiento adicional proyectado para el último cuatrimestre.
B7: 2026 | C7: Codiagro | D7: RESULTADO DEL EJERCICIO | E7: RESULTADO ANTES DE IMPUESTOS | F7: RESULTADO DE LA EXPLOTACION | G7: 5.- Otros ingresos de explotación | H7: (700) Ventas | I7: 700001624 - VENTA POR TRANSPORTE REP. AL CLIENTE DEFINITIVO | J7: - | K7: 0 | L7: 0 | M7: 0 | N7: 750.75 | O7: 25140.75 | P7: 22977.6 | Q7: 11027.24 | R7: 11429 | S7: 5286.2 | T7: 10013.67 | U7: 13461.83 | V7: 14533.94 | W7: 114620.98 | X7: Coste/Ingreso variable según volumen de ventas y fletes repercutidos al cliente (ratio histórico 1,10% s/ventas) + inflación de fletes.
B8: 2026 | C8: Codiagro | D8: RESULTADO DEL EJERCICIO | E8: RESULTADO ANTES DE IMPUESTOS | F8: RESULTADO DE LA EXPLOTACION | G8: 1.- Importe neto de la cifra de negocios | H8: (700) Ventas | I8: 700000769 - INGRESOS POR RETRASOS DE COBRO Y ACTUALIZACION | J8: - | K8: 5635.79 | L8: 202.81 | M8: 178.05 | N8: 0 | O8: - | P8: - | Q8: 0 | R8: 0 | S8: 0 | T8: 0 | U8: 0 | V8: 0 | W8: 6016.65 | X8: Partida puntual / no recurrente en el periodo enero-agosto. Sin movimiento adicional proyectado para el último cuatrimestre.
B9: 2026 | C9: Codiagro | D9: RESULTADO DEL EJERCICIO | E9: RESULTADO ANTES DE IMPUESTOS | F9: RESULTADO FINANCIERO | G9: 14.- Ingresos financieros | H9: (700) Ventas | I9: 700000769 - INGRESOS POR RETRASOS DE COBRO Y ACTUALIZACION | J9: - | K9: 0 | L9: 0 | M9: 0 | N9: 0 | O9: - | P9: - | Q9: 0 | R9: 0 | S9: 0 | T9: 0 | U9: 0 | V9: 0 | W9: 0 | X9: Cuenta sin saldo en el ejercicio. Sin previsión de movimientos.
B10: 2026 | C10: Codiagro | D10: RESULTADO DEL EJERCICIO | E10: RESULTADO ANTES DE IMPUESTOS | F10: RESULTADO DE LA EXPLOTACION | G10: 1.- Importe neto de la cifra de negocios | H10: (702) Ventas de productos semiterminados | I10: 702000000 - Ventas de productos semiterminados | J10: - | K10: 0 | L10: 0 | M10: 0 | N10: 51164.86 | R10: 0 | S10: 0 | T10: 0 | U10: 0 | V10: 0 | W10: 51164.86 | X10: Partida puntual / no recurrente en el periodo enero-agosto. Sin movimiento adicional proyectado para el último cuatrimestre.
B11: 2026 | C11: Codiagro | D11: RESULTADO DEL EJERCICIO | E11: RESULTADO ANTES DE IMPUESTOS | F11: RESULTADO DE LA EXPLOTACION | G11: 1.- Importe neto de la cifra de negocios | H11: (703) Ventas por subproductos y residuos | I11: 703000000 - Ventas de subproductos y residuos | J11: - | K11: 0 | L11: 0 | M11: 26.26 | N11: 0 | O11: - | P11: - | Q11: 0 | R11: 0 | S11: 0 | T11: 0 | U11: 0 | V11: 0 | W11: 26.26 | X11: Partida puntual / no recurrente en el periodo enero-agosto. Sin movimiento adicional proyectado para el último cuatrimestre.
B12: 2026 | C12: Codiagro | D12: RESULTADO DEL EJERCICIO | E12: RESULTADO ANTES DE IMPUESTOS | F12: RESULTADO DE LA EXPLOTACION | G12: 1.- Importe neto de la cifra de negocios | H12: (704) Venta de envases y embalajes | I12: 704000000 - Ventas de envases y embalajes | J12: - | K12: 0 | L12: 4500 | M12: 13500 | N12: 35533.66 | O12: 0 | P12: 0 | Q12: 0 | R12: 0 | S12: 0 | T12: 0 | U12: 0 | V12: 0 | W12: 53533.66 | X12: Partida puntual / no recurrente en el periodo enero-agosto. Sin movimiento adicional proyectado para el último cuatrimestre.
B13: 2026 | C13: Codiagro | D13: RESULTADO DEL EJERCICIO | E13: RESULTADO ANTES DE IMPUESTOS | F13: RESULTADO DE LA EXPLOTACION | G13: 1.- Importe neto de la cifra de negocios | H13: (705) Prestación de servicios | I13: 705000000 - Prestaciones de servicios | J13: - | K13: 0 | L13: 0 | M13: 0 | N13: 48700.8 | R13: 0 | S13: 0 | T13: 0 | U13: 0 | V13: 0 | W13: 48700.8 | X13: Partida puntual / no recurrente en el periodo enero-agosto. Sin movimiento adicional proyectado para el último cuatrimestre.
B14: 2026 | C14: Codiagro | D14: RESULTADO DEL EJERCICIO | E14: RESULTADO ANTES DE IMPUESTOS | F14: RESULTADO DE LA EXPLOTACION | G14: 1.- Importe neto de la cifra de negocios | H14: (705) Prestación de servicios | I14: 705000001 - INGRESO POR GESTIÓN DE ENVASES | J14: - | K14: 1295.63 | L14: 6097.12 | M14: -1420.15 | N14: 3246.37 | O14: 2913.09 | P14: 2313.16 | Q14: 2210.59 | R14: 1694.59 | S14: 2520.44 | T14: 1721.46 | U14: 1519.01 | V14: 5378.56 | W14: 29489.87 | X14: Modelo de gestión de envases (Envases y transportes.xlsx): histórico 2025 ajustado por +12,35% en unidades y +4,5% en tarifas (factor 1,1685).
B15: 2026 | C15: Codiagro | D15: RESULTADO DEL EJERCICIO | E15: RESULTADO ANTES DE IMPUESTOS | F15: RESULTADO DE LA EXPLOTACION | G15: 1.- Importe neto de la cifra de negocios | H15: (706) Dto. s/vtas p.p. | I15: 706000000 - Dtos. ventas por pronto pago mercaderías | J15: - | K15: -34316.16 | L15: -77173.86 | M15: -22849.78 | N15: 0 | O15: 0 | P15: - | Q15: 0 | R15: 0 | S15: 0 | T15: 0 | U15: 0 | V15: 0 | W15: -134339.8 | X15: Partida puntual / no recurrente en el periodo enero-agosto. Sin movimiento adicional proyectado para el último cuatrimestre.
B16: 2026 | C16: Codiagro | D16: RESULTADO DEL EJERCICIO | E16: RESULTADO ANTES DE IMPUESTOS | F16: RESULTADO DE LA EXPLOTACION | G16: 1.- Importe neto de la cifra de negocios | H16: (709) Bonificaciones s/ventas | I16: 709000000 - «Rappels» ventas de mercaderías | J16: - | K16: 0 | L16: 0 | M16: -278.38 | N16: 0 | O16: - | P16: - | Q16: 0 | R16: 0 | S16: 0 | T16: 0 | U16: 0 | V16: 0 | W16: -278.38 | X16: Partida puntual / no recurrente en el periodo enero-agosto. Sin movimiento adicional proyectado para el último cuatrimestre.
B17: 2026 | C17: Codiagro | D17: RESULTADO DEL EJERCICIO | E17: RESULTADO ANTES DE IMPUESTOS | F17: RESULTADO DE LA EXPLOTACION | G17: 1.- Importe neto de la cifra de negocios | H17: (709) Bonificaciones s/ventas | I17: 709000001 - PROVISION RAPPELS | J17: - | K17: 0 | L17: -82761.28 | M17: 0 | N17: 0 | O17: - | P17: -50000 | Q17: 0 | R17: -16000 | S17: 0 | T17: 0 | U17: 0 | V17: -184238.72 | W17: -333000 | X17: Provisión por rappels comerciales ajustada para alcanzar el objetivo anual exacto de 333.000,00 € (-148.761,28 € reales Ene-Ago + -184.238,72 € provisión Dic).
B18: 2026 | C18: Codiagro | D18: RESULTADO DEL EJERCICIO | E18: RESULTADO ANTES DE IMPUESTOS | F18: RESULTADO DE LA EXPLOTACION | G18: 11.- Deterioro y resultado por enajenaciones del inmovilizado | H18: (771) Beneficios procedentes IM | I18: 771000000 - Beneficios del inmovilizado material | J18: - | K18: 0 | L18: 0 | M18: 2000 | N18: 0 | O18: - | P18: - | Q18: 0 | R18: 0 | S18: 0 | T18: 0 | U18: 0 | V18: 0 | W18: 2000 | X18: Partida puntual / no recurrente en el periodo enero-agosto. Sin movimiento adicional proyectado para el último cuatrimestre.
B19: 2026 | C19: Codiagro | D19: RESULTADO DEL EJERCICIO | E19: RESULTADO ANTES DE IMPUESTOS | F19: RESULTADO DE LA EXPLOTACION | G19: 13.- Otros resultados | H19: (678) Gastos excepcionales PGC 2008 | I19: 678000000 - Gastos excepcionales | J19: - | K19: -0.2 | L19: 0 | M19: -0.14 | N19: -93.18 | O19: -1.43 | P19: - | Q19: -88.03 | R19: -0.02 | S19: 0 | T19: 0 | U19: 0 | V19: 0 | W19: -183 | X19: Partida puntual / no recurrente en el periodo enero-agosto. Sin movimiento adicional proyectado para el último cuatrimestre.
B20: 2026 | C20: Codiagro | D20: RESULTADO DEL EJERCICIO | E20: RESULTADO ANTES DE IMPUESTOS | F20: RESULTADO DE LA EXPLOTACION | G20: 13.- Otros resultados | H20: (778) Ingresos excepcionales PGC 2008 | I20: 778000000 - Ingresos excepcionales | J20: - | K20: 3065.47 | L20: 0.02 | M20: 0 | N20: 1117.44 | O20: - | P20: - | Q20: 0 | R20: 0.01 | S20: 0 | T20: 0 | U20: 0 | V20: 0 | W20: 4182.94 | X20: Partida puntual / no recurrente en el periodo enero-agosto. Sin movimiento adicional proyectado para el último cuatrimestre.
B21: 2026 | C21: Codiagro | D21: RESULTADO DEL EJERCICIO | E21: RESULTADO ANTES DE IMPUESTOS | F21: RESULTADO DE LA EXPLOTACION | G21: 2.- Variación de existencias | H21: (711) Variación de existencias de productos semiterminados | I21: 711000000 - Variación existencias de prod. semiterminados | J21: - | K21: 1191.85 | L21: -20400.17 | M21: -3284.66 | N21: 15429.21 | O21: 4436.02 | P21: -12387.42 | Q21: -48438.2 | R21: 27557.62 | S21: 0 | T21: 0 | U21: 0 | V21: 0 | W21: -35895.75 | X21: Ajuste previsional de variación de existencias para regularización de inventarios a cierre de ejercicio.
B22: 2026 | C22: Codiagro | D22: RESULTADO DEL EJERCICIO | E22: RESULTADO ANTES DE IMPUESTOS | F22: RESULTADO DE LA EXPLOTACION | G22: 2.- Variación de existencias | H22: (712) Variación de existencias producto terminado | I22: 712000000 - Variación existencias de prod. terminados | J22: - | K22: -86069.93 | L22: 70405.74 | M22: 86837.43 | N22: -6784.01 | O22: -34727.12 | P22: -77717.45 | Q22: 42145.57 | R22: -20822.98 | S22: 0 | T22: 0 | U22: 0 | V22: 0 | W22: -26732.75 | X22: Ajuste previsional de variación de existencias para regularización de inventarios a cierre de ejercicio.
B23: 2026 | C23: Codiagro | D23: RESULTADO DEL EJERCICIO | E23: RESULTADO ANTES DE IMPUESTOS | F23: RESULTADO DE LA EXPLOTACION | G23: 4.- Aprovisionamientos | H23: (601) Compras de materias primas | I23: 601000000 - Compras de materias primas | J23: - | K23: -372155.73 | L23: -457091.9 | M23: -457890.87 | N23: -391545.47 | O23: -423709.63 | P23: -393937.01 | Q23: -362186.44 | R23: -189242.44 | S23: -124233.67 | T23: -235336.47 | U23: -316373.51 | V23: -341569.79 | W23: -4065272.9 | X23: Coste variable directo: volumen según presupuesto ajustado (ratio histórico 25,85% s/ventas sin incremento de inflación en 2026; la inflación del +4,5% se aplica solo en 2027).
B24: 2026 | C24: Codiagro | D24: RESULTADO DEL EJERCICIO | E24: RESULTADO ANTES DE IMPUESTOS | F24: RESULTADO DE LA EXPLOTACION | G24: 4.- Aprovisionamientos | H24: (602) Compras de otros aprovisionamientos | I24: 602000001 - COMPRA DE ENVASES Y EMBALAJES | J24: - | K24: -103817.84 | L24: -62983.5 | M24: -55812.27 | N24: -92652.34 | O24: -30193.15 | P24: -119472.15 | Q24: -145291.05 | R24: -8606.04 | S24: -25894.98 | T24: -49053 | U24: -65944.18 | V24: -71196.03 | W24: -830916.53 | X24: Coste variable por envases y embalajes: incluye saldo de junio traspasado de la 602000000 (-30.306,17 €). Estimación unificada según ratio histórico 5,39% s/ventas ajustadas (sin inflación en 2026; aplicable en 2027).
B25: 2026 | C25: Codiagro | D25: RESULTADO DEL EJERCICIO | E25: RESULTADO ANTES DE IMPUESTOS | F25: RESULTADO DE LA EXPLOTACION | G25: 4.- Aprovisionamientos | H25: (602) Compras de otros aprovisionamientos | I25: 602000000 - Compras de otros aprovisionamientos | J25: - | P25: 0 | Q25: 0 | R25: 0 | S25: 0 | T25: 0 | U25: 0 | V25: 0 | W25: 0 | X25: Cuenta fusionada con 602000001. Su saldo real de junio (-30.306,17 €) se ha traspasado a la 602000001. Sin previsión en sep-dic ni en 2027.
B26: 2026 | C26: Codiagro | D26: RESULTADO DEL EJERCICIO | E26: RESULTADO ANTES DE IMPUESTOS | F26: RESULTADO DE LA EXPLOTACION | G26: 4.- Aprovisionamientos | H26: (602) Compras de otros aprovisionamientos | I26: 602000002 - COMPRA DE ETIQUETAS | J26: - | K26: -12617.31 | L26: -5458.67 | M26: -15267.33 | N26: -9307.32 | O26: -2784.91 | P26: -5867.49 | Q26: -10270.19 | R26: -2886.68 | S26: -2625.86 | T26: -4974.16 | U26: -6687 | V26: -7219.56 | W26: -85966.48 | X26: Coste variable de etiquetas: ratio s/ventas ajustadas sin ajuste de precios de imprenta por inflación en 2026 (solo en 2027).
B27: 2026 | C27: Codiagro | D27: RESULTADO DEL EJERCICIO | E27: RESULTADO ANTES DE IMPUESTOS | F27: RESULTADO DE LA EXPLOTACION | G27: 4.- Aprovisionamientos | H27: (602) Compras de otros aprovisionamientos | I27: 602000003 - COMPRA DE PALETS | J27: - | K27: -7425.6 | L27: -3712.8 | M27: -4331.6 | N27: -12608.05 | O27: -17326.4 | P27: -12994.8 | Q27: -4331.6 | R27: -4331.6 | S27: -2731.63 | T27: -5174.53 | U27: -6956.35 | V27: -7510.36 | W27: -89435.32 | X27: Coste variable de palets: ratio s/ventas ajustadas sin inflación de suministros logísticos en 2026 (aplicable en 2027).
B28: 2026 | C28: Codiagro | D28: RESULTADO DEL EJERCICIO | E28: RESULTADO ANTES DE IMPUESTOS | F28: RESULTADO DE LA EXPLOTACION | G28: 4.- Aprovisionamientos | H28: (602) Compras de otros aprovisionamientos | I28: 602000004 - COMPRA MATERIAL DE LIMPIEZA | J28: - | K28: -131.92 | L28: 0 | M28: 0 | N28: 0 | O28: - | P28: - | Q28: 0 | R28: 0 | S28: -131.92 | T28: -131.92 | U28: -131.92 | V28: -131.92 | W28: -659.6 | X28: Coste operativo menor de planta: proyección basada en el promedio mensual histórico de reposición.
B29: 2026 | C29: Codiagro | D29: RESULTADO DEL EJERCICIO | E29: RESULTADO ANTES DE IMPUESTOS | F29: RESULTADO DE LA EXPLOTACION | G29: 4.- Aprovisionamientos | H29: (602) Compras de otros aprovisionamientos | I29: 602000005 - COMPRA MATERIAL DE OFICINA | J29: - | K29: -95.3 | L29: -136 | M29: 0 | N29: -380.75 | O29: - | P29: - | Q29: 0 | R29: 0 | S29: -204.02 | T29: -204.02 | U29: -204.02 | V29: -204.02 | W29: -1428.13 | X29: Coste operativo menor de planta: proyección basada en el promedio mensual histórico de reposición.
B30: 2026 | C30: Codiagro | D30: RESULTADO DEL EJERCICIO | E30: RESULTADO ANTES DE IMPUESTOS | F30: RESULTADO DE LA EXPLOTACION | G30: 4.- Aprovisionamientos | H30: (602) Compras de otros aprovisionamientos | I30: 602000006 - COMPRA TAPONES DE ENVASES | J30: - | K30: -3578.65 | L30: 0 | M30: -5949 | N30: -5353 | O30: - | P30: -3337.38 | Q30: -5826.6 | R30: -1108.8 | S30: -1071.66 | T30: -2030.04 | U30: -2729.08 | V30: -2946.43 | W30: -33930.64 | X30: Coste variable directamente proporcional al número de unidades/tapones envasados (0,22% s/ventas ajustadas).
B31: 2026 | C31: Codiagro | D31: RESULTADO DEL EJERCICIO | E31: RESULTADO ANTES DE IMPUESTOS | F31: RESULTADO DE LA EXPLOTACION | G31: 4.- Aprovisionamientos | H31: (602) Compras de otros aprovisionamientos | I31: 602000007 - COMPRAS LABORATORIO | J31: - | K31: 0 | L31: 0 | M31: 0 | N31: 0 | O31: 0 | P31: - | Q31: 0 | R31: 0 | S31: 0 | T31: 0 | U31: 0 | V31: 0 | W31: 0 | X31: Cuenta inactiva / sin saldo en el ejercicio. Sin previsión de movimientos.
B32: 2026 | C32: Codiagro | D32: RESULTADO DEL EJERCICIO | E32: RESULTADO ANTES DE IMPUESTOS | F32: RESULTADO DE LA EXPLOTACION | G32: 4.- Aprovisionamientos | H32: (602) Compras de otros aprovisionamientos | I32: 602000008 - RESPUESTOS PLANTA | J32: - | K32: 0 | L32: 0 | M32: 0 | N32: 0 | O32: 0 | P32: - | Q32: 0 | R32: 0 | S32: 0 | T32: 0 | U32: 0 | V32: 0 | W32: 0 | X32: Cuenta inactiva / sin saldo en el ejercicio. Sin previsión de movimientos.
B33: 2026 | C33: Codiagro | D33: RESULTADO DEL EJERCICIO | E33: RESULTADO ANTES DE IMPUESTOS | F33: RESULTADO DE LA EXPLOTACION | G33: 4.- Aprovisionamientos | H33: (602) Compras de otros aprovisionamientos | I33: 602000010 - COMPRA RIBBON | J33: - | K33: 0 | L33: 0 | M33: 0 | N33: 0 | O33: 0 | P33: - | Q33: 0 | R33: 0 | S33: 0 | T33: 0 | U33: 0 | V33: 0 | W33: 0 | X33: Cuenta inactiva / sin saldo en el ejercicio. Sin previsión de movimientos.
B34: 2026 | C34: Codiagro | D34: RESULTADO DEL EJERCICIO | E34: RESULTADO ANTES DE IMPUESTOS | F34: RESULTADO DE LA EXPLOTACION | G34: 4.- Aprovisionamientos | H34: (602) Compras de otros aprovisionamientos | I34: 602000011 - COMPRAS VARIAS PLANTA | J34: - | K34: 0 | L34: -1575 | M34: 0 | N34: 0 | O34: - | P34: -1735.41 | Q34: -175.92 | R34: -371.23 | S34: -964.39 | T34: -964.39 | U34: -964.39 | V34: -964.39 | W34: -7715.12 | X34: Coste operativo menor de planta: proyección basada en el promedio mensual histórico de reposición.
B35: 2026 | C35: Codiagro | D35: RESULTADO DEL EJERCICIO | E35: RESULTADO ANTES DE IMPUESTOS | F35: RESULTADO DE LA EXPLOTACION | G35: 4.- Aprovisionamientos | H35: (602) Compras de otros aprovisionamientos | I35: 602000012 - REPUESTOS INFORMATICOS | J35: - | K35: 0 | L35: -1887.21 | M35: 0 | N35: 0 | O35: - | P35: - | Q35: -1232.05 | R35: 0 | S35: -1559.63 | T35: -1559.63 | U35: -1559.63 | V35: -1559.63 | W35: -9357.78 | X35: Coste operativo menor de planta: proyección basada en el promedio mensual histórico de reposición.
B36: 2026 | C36: Codiagro | D36: RESULTADO DEL EJERCICIO | E36: RESULTADO ANTES DE IMPUESTOS | F36: RESULTADO DE LA EXPLOTACION | G36: 4.- Aprovisionamientos | H36: (602) Compras de otros aprovisionamientos | I36: 602000013 - COMPRA TINTA INPRESORA ETIQUETAS | J36: - | K36: -157 | L36: -2350.16 | M36: 0 | N36: -2676.19 | O36: -480.84 | P36: -2604.97 | Q36: -2809.41 | R36: -2557.66 | S36: -2190 | T36: -2490 | U36: -2690 | V36: -2690 | W36: -23696.23 | X36: Coste semi-variable de consumibles de marcaje y codificación en planta vinculado al volumen de producción envasado.
B37: 2026 | C37: Codiagro | D37: RESULTADO DEL EJERCICIO | E37: RESULTADO ANTES DE IMPUESTOS | F37: RESULTADO DE LA EXPLOTACION | G37: 4.- Aprovisionamientos | H37: (602) Compras de otros aprovisionamientos | I37: 602000100 - ENVASES Y EMBALAJES A DEVOLVER | J37: - | K37: -1200.4 | L37: -562 | M37: -363 | N37: 67 | O37: 1124 | P37: -1708 | Q37: 1360 | R37: 0 | S37: -183.2 | T37: -183.2 | U37: -183.2 | V37: -183.2 | W37: -2015.2 | X37: Coste operativo menor de planta: proyección basada en el promedio mensual histórico de reposición.
B38: 2026 | C38: Codiagro | D38: RESULTADO DEL EJERCICIO | E38: RESULTADO ANTES DE IMPUESTOS | F38: RESULTADO DE LA EXPLOTACION | G38: 4.- Aprovisionamientos | H38: (607) Trabajos realizados por otras empresas | I38: 607000000 - Trabajos realizados por otras empresas | J38: - | K38: -4010 | L38: -8438.96 | M38: -10901.61 | N38: -20866.93 | O38: -3540 | P38: 0.72 | Q38: -3900 | R38: -6131.31 | S38: 0 | T38: 0 | U38: 0 | V38: -7970 | W38: -65758.09 | X38: Coste variable de subcontratación fabril: eliminadas previsiones de sep a nov, dejando únicamente diciembre (-7.970,00 €) por refuerzo a cierre de ejercicio según indicación.
B39: 2026 | C39: Codiagro | D39: RESULTADO DEL EJERCICIO | E39: RESULTADO ANTES DE IMPUESTOS | F39: RESULTADO DE LA EXPLOTACION | G39: 4.- Aprovisionamientos | H39: (611) Variación de existencias de materias primas | I39: 611000000 - Variación de existencias de materias primas | J39: - | K39: 25970.74 | L39: 149437.84 | M39: 81262.98 | N39: -23562.66 | O39: -43504.89 | P39: -145710 | Q39: 649.67 | R39: -59037.03 | S39: 0 | T39: 0 | U39: 0 | V39: -15000 | W39: -29493.35 | X39: Ajuste previsional de variación de existencias para regularización de inventarios a cierre de ejercicio.
B40: 2026 | C40: Codiagro | D40: RESULTADO DEL EJERCICIO | E40: RESULTADO ANTES DE IMPUESTOS | F40: RESULTADO DE LA EXPLOTACION | G40: 4.- Aprovisionamientos | H40: (612) Variación de existencias envases/etiquetas | I40: 612000000 - Variación de existencias otros aprovisionamientos | J40: - | K40: 61431.54 | L40: -11484.37 | M40: 0 | N40: 44037.42 | O40: -73565.42 | P40: 33912.77 | Q40: 14991.19 | R40: -4582.08 | S40: 0 | T40: 0 | U40: 0 | V40: 10000 | W40: 74741.05 | X40: Ajuste previsional de variación de existencias para regularización de inventarios a cierre de ejercicio.
B41: 2026 | C41: Codiagro | D41: RESULTADO DEL EJERCICIO | E41: RESULTADO ANTES DE IMPUESTOS | F41: RESULTADO DE LA EXPLOTACION | G41: 5.- Otros ingresos de explotación | H41: (759) Otros ingresos de gestión | I41: 759000000 - Ingresos por servicios diversos | J41: - | K41: 0 | L41: 0 | M41: 0 | N41: 0 | O41: 0 | P41: - | Q41: 0 | R41: 0 | S41: 0 | T41: 0 | U41: 0 | V41: 0 | W41: 0 | X41: Cuenta inactiva / sin saldo en el ejercicio. Sin previsión de movimientos.
...

Sheet Ginger
A1: Cuenta | B1: Grupo Ext Item | C1: 46023 | D1: 46054 | E1: 46082 | F1: 46113 | G1: 46143 | H1: Comprobación | I1: Dif
A2: 700000000 - Ventas de mercaderías | B2: - | G2: 2029267 | H2: =VLOOKUP(A2,'PL Mensual 2026'!I:O,7,0) -> 2029267 | I2: =G2-H2 -> 0
A3: 700000001 - VENTA MERCADERIAS POR ANTICIPO | B3: - | G3: -106250.17 | H3: =VLOOKUP(A3,'PL Mensual 2026'!I:O,7,0) -> -106250.17 | I3: =G3-H3 -> 0
A4: 700000624 - VENTA POR TRANSP. REP. AL CLIENTE | B4: - | G4: - | H4: =VLOOKUP(A4,'PL Mensual 2026'!I:O,7,0) -> 0
A5: 700000769 - INGRESOS POR RETRASOS DE COBRO Y ACTUALIZACION | B5: - | G5: - | H5: =VLOOKUP(A5,'PL Mensual 2026'!I:O,7,0) -> -
A6: 700001624 - VENTA POR TRANSPORTE REP. AL CLIENTE DEFINITIVO | B6: - | G6: 25140.75 | H6: =VLOOKUP(A6,'PL Mensual 2026'!I:O,7,0) -> 25140.75 | I6: =G6-H6 -> 0
A7: 702000000 - Ventas de productos semiterminados | B7: - | G7: 101865.8 | H7: =VLOOKUP(A7,'PL Mensual 2026'!I:O,7,0) -> 0 | I7: =G7-H7 -> 101865.8
A8: 703000000 - Ventas de subproductos y residuos | B8: - | G8: - | H8: =VLOOKUP(A8,'PL Mensual 2026'!I:O,7,0) -> -
A9: 704000000 - Ventas de envases y embalajes | B9: - | G9: 80917.99 | H9: =VLOOKUP(A9,'PL Mensual 2026'!I:O,7,0) -> 0 | I9: =G9-H9 -> 80917.99
A10: 705000000 - Prestaciones de servicios | B10: - | G10: 111557.6 | H10: =VLOOKUP(A10,'PL Mensual 2026'!I:O,7,0) -> 0 | I10: =G10-H10 -> 111557.6
A11: - - | B11: Maquila | G11: -111557.6 | H11: =VLOOKUP(A11,'PL Mensual 2026'!I:O,7,0) -> #N/A | I11: =G11-H11 -> #N/A
A12: 705000001 - INGRESO POR GESTIÓN DE ENVASES | B12: - | G12: 2913.09 | H12: =VLOOKUP(A12,'PL Mensual 2026'!I:O,7,0) -> 2913.09 | I12: =G12-H12 -> 0
A13: 706000000 - Dtos. ventas por pronto pago mercaderías | B13: - | G13: - | H13: =VLOOKUP(A13,'PL Mensual 2026'!I:O,7,0) -> 0
A14: 706000001 - DESCUENTO POR PRONTO PAGO DEFINITIVO | B14: - | G14: -38633.95 | H14: =VLOOKUP(A14,'PL Mensual 2026'!I:O,7,0) -> -38633.95 | I14: =G14-H14 -> 0
A15: 709000000 - «Rappels» ventas de mercaderías | B15: - | G15: - | H15: =VLOOKUP(A15,'PL Mensual 2026'!I:O,7,0) -> -
A16: 709000001 - PROVISION RAPPELS | B16: - | G16: - | H16: =VLOOKUP(A16,'PL Mensual 2026'!I:O,7,0) -> -
A17: 709001500 - RAPPEL BONIFICACIONES POR PMK DEFINITIVO | B17: - | G17: -1350 | H17: =VLOOKUP(A17,'PL Mensual 2026'!I:O,7,0) -> -1350 | I17: =G17-H17 -> 0
A18: 711000000 - Variación existencias de prod. semiterminados | B18: - | G18: 4436.02 | H18: =VLOOKUP(A18,'PL Mensual 2026'!I:O,7,0) -> 4436.02 | I18: =G18-H18 -> 0
A19: 712000000 - Variación existencias de prod. terminados | B19: - | G19: -34727.12 | H19: =VLOOKUP(A19,'PL Mensual 2026'!I:O,7,0) -> -34727.12 | I19: =G19-H19 -> 0
A20: 601000000 - Compras de materias primas | B20: - | G20: -417425.43 | H20: =VLOOKUP(A20,'PL Mensual 2026'!I:O,7,0) -> -423709.63 | I20: =G20-H20 -> 6284.2
A21: 601000001 - COMPRAS MAT. PRIMAS INTRACOMUNITARIAS | B21: - | G21: -108150 | H21: =VLOOKUP(A21,'PL Mensual 2026'!I:O,7,0) -> #N/A | I21: =G21-H21 -> #N/A
