Workbook
Name Datos: #REF!
Name Datos: #REF!

Sheet 2026
C2: RELLENAR | L2: RELLENAR | U2: RELLENAR | AD2: RELLENAR | AM2: RELLENAR | AV2: RELLENAR | BE2: RELLENAR | BN2: RELLENAR | BW2: RELLENAR | CF2: RELLENAR | CO2: RELLENAR | CX2: RELLENAR | DG2: RELLENAR
B3: MES | C3: 1 | K3: MES | L3: 2 | T3: MES | U3: 3 | AC3: MES | AD3: 4 | AL3: MES | AM3: 5 | AU3: MES | AV3: 6 | BD3: MES | BE3: 7 | BM3: MES | BN3: 8 | BV3: MES | BW3: 9 | CE3: MES | CF3: 10 | CN3: MES | CO3: 11 | CW3: MES | CX3: 12 | DF3: MES | DG3: 12 | DH3: YTD
B5: P&L Mensual | K5: P&L Mensual | T5: P&L Mensual | AC5: P&L Mensual | AL5: P&L Mensual | AU5: P&L Mensual | BD5: P&L Mensual | BM5: P&L Mensual | BV5: P&L Mensual | CE5: P&L Mensual | CN5: P&L Mensual | CW5: P&L Mensual | DF5: P&L YTD
E6: Variación | H6: Variación | N6: Variación | Q6: Variación | W6: Variación | Z6: Variación | AF6: Variación | AI6: Variación | AO6: Variación | AR6: Variación | AX6: Variación | BA6: Variación | BG6: Variación | BJ6: Variación | BP6: Variación | BS6: Variación | BY6: Variación | CB6: Variación | CH6: Variación | CK6: Variación | CQ6: Variación | CT6: Variación | CZ6: Variación | DC6: Variación | DI6: Variación | DL6: Variación
B7: € '000 | C7: 2026A | D7: 2025A | E7: EUR | F7: % | G7: 2026B | H7: EUR | I7: % | K7: € '000 | L7: 2026A | M7: 2025A | N7: EUR | O7: % | P7: 2026B | Q7: EUR | R7: % | T7: € '000 | U7: 2026A | V7: 2025A | W7: EUR | X7: % | Y7: 2026B | Z7: EUR | AA7: % | AC7: € '000 | AD7: 2026A | AE7: 2025A | AF7: EUR | AG7: % | AH7: 2026B | AI7: EUR | AJ7: % | AL7: € '000 | AM7: 2026A | AN7: 2025A | AO7: EUR | AP7: % | AQ7: 2026B | AR7: EUR | AS7: % | AU7: € '000 | AV7: 2026A | AW7: 2025A | AX7: EUR | AY7: % | AZ7: 2026B | BA7: EUR | BB7: % | BD7: € '000 | BE7: 2026A | BF7: 2025A | BG7: EUR | BH7: % | BI7: 2026B | BJ7: EUR | BK7: % | BM7: € '000 | BN7: 2026A | BO7: 2025A | BP7: EUR | BQ7: % | BR7: 2026B | BS7: EUR | BT7: % | BV7: € '000 | BW7: 2026A | BX7: 2025A | BY7: EUR | BZ7: % | CA7: 2026B | CB7: EUR | CC7: % | CE7: € '000 | CF7: 2026A | CG7: 2025A | CH7: EUR | CI7: % | CJ7: 2026B | CK7: EUR | CL7: % | CN7: € '000 | CO7: 2026A | CP7: 2025A | CQ7: EUR | CR7: % | CS7: 2026B | CT7: EUR | CU7: % | CW7: € '000 | CX7: 2026A | CY7: 2025A | CZ7: EUR | DA7: % | DB7: 2026B | DC7: EUR | DD7: % | DF7: € '000 | DG7: 2026A | DH7: 2025A | DI7: EUR | DJ7: % | DK7: 2026B | DL7: EUR | DM7: %
B8: Ventas | C8: 983.81713 | D8: 622.28714 | E8: 361.52999 | F8: 0.58096973 | G8: 805.69363 | H8: 178.1235 | I8: 0.22108094 | K8: Ventas | L8: 1470.4281 | M8: 1062.4411 | N8: 407.98706 | O8: 0.38400911 | P8: 1513.248 | Q8: -42.819833 | R8: -0.02829664 | T8: Ventas | U8: 1533.7894 | V8: 1795.147 | W8: -261.35762 | X8: -0.14559121 | Y8: 2302.2173 | Z8: -768.4279 | AA8: -0.33377731 | AC8: Ventas | AD8: 1462.1463 | AE8: 1534.3509 | AF8: -72.20461 | AG8: -0.047058734 | AH8: 1891.2553 | AI8: -429.10904 | AJ8: -0.22689112 | AL8: Ventas | AM8: 1925.9299 | AN8: 1483.9152 | AO8: 442.01472 | AP8: 0.29787061 | AQ8: 1636.9092 | AR8: 289.0207 | AS8: 0.17656489 | AU8: Ventas | AV8: 1962.2618 | AW8: 1760.942 | AX8: 201.31983 | AY8: 0.11432508 | AZ8: 2150.2566 | BA8: -187.99474 | BB8: -0.087428981 | BD8: Ventas | BE8: 1290.6542 | BF8: 1314.5645 | BG8: -23.91025 | BH8: -0.018188724 | BI8: 1348.021 | BJ8: -57.366798 | BK8: -0.042556308 | BM8: Ventas | BN8: 788.10515 | BO8: 664.49694 | BP8: 123.60821 | BQ8: 0.18601773 | BR8: 776.07561 | BS8: 12.029536 | BT8: 0.015500469 | BV8: Ventas | BW8: =(GETPIVOTDATA("sep-26 ",TABLA!$B$3,"Nivel 4","1.- Importe neto de la cifra de negocios"))/1000 -> 624.72488 | BX8: =VLOOKUP(BV8,'P&L Mensualitzada 2025'!$A$5:$N$25,$BW$3+1,0) -> 842.11579 | BY8: =BW8-BX8 -> -217.39091 | BZ8: =+IF(IFERROR(BW8/BX8-1,"-")<300%,IFERROR(BW8/BX8-1,"-"),"n.a.") -> -0.25814848 | CA8: =VLOOKUP(BV8,'Budget26 sin EI'!$B:$O,$BW$3+1,0) -> 1026.5685 | CB8: =BW8-CA8 -> -401.84361 | CC8: =+IF(IFERROR(BW8/CA8-1,"-")<300%,IFERROR(BW8/CA8-1,"-"),"n.a.") -> -0.39144355 | CE8: Ventas | CF8: =(GETPIVOTDATA("oct-26 ",TABLA!$B$3,"Nivel 4","1.- Importe neto de la cifra de negocios"))/1000 -> 912.05501 | CG8: =VLOOKUP(CE8,'P&L Mensualitzada 2025'!$A$5:$N$25,$CF$3+1,0) -> 699.58345 | CH8: =CF8-CG8 -> 212.47156 | CI8: =+IF(IFERROR(CF8/CG8-1,"-")<300%,IFERROR(CF8/CG8-1,"-"),"n.a.") -> 0.30371153 | CJ8: =VLOOKUP(CE8,'Budget26 sin EI'!$B:$O,$CF$3+1,0) -> 798.56718 | CK8: =CF8-CJ8 -> 113.48783 | CL8: =+IF(IFERROR(CF8/CJ8-1,"-")<300%,IFERROR(CF8/CJ8-1,"-"),"n.a.") -> 0.14211431 | CN8: Ventas | CO8: =(GETPIVOTDATA("nov-26 ",TABLA!$B$3,"Nivel 4","1.- Importe neto de la cifra de negocios"))/1000 -> 1225.3218 | CP8: =VLOOKUP(CN8,'P&L Mensualitzada 2025'!$A$5:$N$25,$CO$3+1,0) -> 749.69916 | CQ8: =CO8-CP8 -> 475.62262 | CR8: =+IF(IFERROR(CO8/CP8-1,"-")<300%,IFERROR(CO8/CP8-1,"-"),"n.a.") -> 0.63441797 | CS8: =VLOOKUP(CN8,'Budget26 sin EI'!$B:$O,$CO$3+1,0) -> 1030.243 | CT8: =CO8-CS8 -> 195.07877 | CU8: =+IF(IFERROR(CO8/CS8-1,"-")<300%,IFERROR(CO8/CS8-1,"-"),"n.a.") -> 0.18935219 | CW8: Ventas | CX8: =(GETPIVOTDATA("dic-26 ",TABLA!$B$3,"Nivel 4","1.- Importe neto de la cifra de negocios"))/1000 -> 1142.4074 | CY8: =VLOOKUP(CW8,'P&L Mensualitzada 2025'!$A$5:$N$25,$CX$3+1,0) -> 248.50601 | CZ8: =CX8-CY8 -> 893.90137 | DA8: =+IF(IFERROR(CX8/CY8-1,"-")<300%,IFERROR(CX8/CY8-1,"-"),"n.a.") -> n.a. | DB8: =VLOOKUP(CW8,'Budget26 sin EI'!$B:$O,$CX$3+1,0) -> 659.94465 | DC8: =CX8-DB8 -> 482.46273 | DD8: =+IF(IFERROR(CX8/DB8-1,"-")<300%,IFERROR(CX8/DB8-1,"-"),"n.a.") -> 0.73106544 | DF8: Ventas | DG8: =(GETPIVOTDATA("Total 2026 ",TABLA!$B$3,"Nivel 4","1.- Importe neto de la cifra de negocios"))/1000 -> 15180 | DH8: =VLOOKUP(DF8,'P&L Mensualitzada 2025'!$A$5:$N$25,$CX$3+2,0) -> 12778.049 | DI8: =DG8-DH8 -> 2401.9508 | DJ8: =+IF(IFERROR(DG8/DH8-1,"-")<300%,IFERROR(DG8/DH8-1,"-"),"n.a.") -> 0.18797477 | DK8: =VLOOKUP(DF8,'Budget26 sin EI'!$B:$O,$CX$3+2,0) -> 15939 | DL8: =DG8-DK8 -> -759 | DM8: =+IF(IFERROR(DG8/DK8-1,"-")<300%,IFERROR(DG8/DK8-1,"-"),"n.a.") -> -0.047619048
B9: COGS | C9: -502.66555 | D9: -518.09465 | E9: 15.4291 | F9: -0.029780466 | G9: -276.70291 | H9: -225.96264 | I9: 0.81662548 | K9: COGS | L9: -356.23716 | M9: -451.51496 | N9: 95.2778 | O9: -0.21101804 | P9: -519.70141 | Q9: 163.46425 | R9: -0.31453494 | T9: COGS | U9: -385.69993 | V9: -510.02511 | W9: 124.32518 | X9: -0.24376286 | Y9: -790.66062 | Z9: 404.96069 | AA9: -0.51218017 | AC9: COGS | AD9: -506.20309 | AE9: -440.06148 | AF9: -66.14161 | AG9: 0.15030084 | AH9: -649.52213 | AI9: 143.31904 | AJ9: -0.22065305 | AL9: COGS | AM9: -624.27234 | AN9: -669.88812 | AO9: 45.61578 | AP9: -0.068094625 | AQ9: -562.17093 | AR9: -62.10141 | AS9: 0.11046713 | AU9: COGS | AV9: -743.55859 | AW9: -248.36745 | AX9: -495.19114 | AY9: 1.9937844 | AZ9: -738.47207 | BA9: -5.0865197 | BB9: 0.0068878972 | BD9: COGS | BE9: -525.31503 | BF9: -330.56434 | BG9: -194.75069 | BH9: 0.58914609 | BI9: -462.95679 | BJ9: -62.35824 | BK9: 0.13469559 | BM9: COGS | BN9: -272.12023 | BO9: -99.2048 | BP9: -172.91543 | BQ9: 1.7430148 | BR9: -266.53106 | BS9: -5.5891689 | BT9: 0.020970047 | BV9: COGS | BW9: =(GETPIVOTDATA("sep-26 ",TABLA!$B$3,"Nivel 4","2.- Variación de existencias")+GETPIVOTDATA("sep-26 ",TABLA!$B$3,"Nivel 4","4.- Aprovisionamientos"))/1000 -> -202.31205 | BX9: =VLOOKUP(BV9,'P&L Mensualitzada 2025'!$A$5:$N$25,$BW$3+1,0) -> -265.37091 | BY9: =BW9-BX9 -> 63.05886 | BZ9: =+IF(IFERROR(BW9/BX9-1,"-")<300%,IFERROR(BW9/BX9-1,"-"),"n.a.") -> -0.23762537 | CA9: =VLOOKUP(BV9,'Budget26 sin EI'!$B:$O,$BW$3+1,0) -> -352.55893 | CB9: =BW9-CA9 -> 150.24688 | CC9: =+IF(IFERROR(BW9/CA9-1,"-")<300%,IFERROR(BW9/CA9-1,"-"),"n.a.") -> -0.42616104 | CE9: COGS | CF9: =(GETPIVOTDATA("oct-26 ",TABLA!$B$3,"Nivel 4","2.- Variación de existencias")+GETPIVOTDATA("oct-26 ",TABLA!$B$3,"Nivel 4","4.- Aprovisionamientos"))/1000 -> -302.10136 | CG9: =VLOOKUP(CE9,'P&L Mensualitzada 2025'!$A$5:$N$25,$CF$3+1,0) -> -361.07371 | CH9: =CF9-CG9 -> 58.97235 | CI9: =+IF(IFERROR(CF9/CG9-1,"-")<300%,IFERROR(CF9/CG9-1,"-"),"n.a.") -> -0.16332496 | CJ9: =VLOOKUP(CE9,'Budget26 sin EI'!$B:$O,$CF$3+1,0) -> -274.25544 | CK9: =CF9-CJ9 -> -27.84592 | CL9: =+IF(IFERROR(CF9/CJ9-1,"-")<300%,IFERROR(CF9/CJ9-1,"-"),"n.a.") -> 0.10153279 | CN9: COGS | CO9: =(GETPIVOTDATA("nov-26 ",TABLA!$B$3,"Nivel 4","2.- Variación de existencias")+GETPIVOTDATA("nov-26 ",TABLA!$B$3,"Nivel 4","4.- Aprovisionamientos"))/1000 -> -404.42328 | CP9: =VLOOKUP(CN9,'P&L Mensualitzada 2025'!$A$5:$N$25,$CO$3+1,0) -> -275.74654 | CQ9: =CO9-CP9 -> -128.67674 | CR9: =+IF(IFERROR(CO9/CP9-1,"-")<300%,IFERROR(CO9/CP9-1,"-"),"n.a.") -> 0.46664861 | CS9: =VLOOKUP(CN9,'Budget26 sin EI'!$B:$O,$CO$3+1,0) -> -353.82089 | CT9: =CO9-CS9 -> -50.602393 | CU9: =+IF(IFERROR(CO9/CS9-1,"-")<300%,IFERROR(CO9/CS9-1,"-"),"n.a.") -> 0.14301697 | CW9: COGS | CX9: =(GETPIVOTDATA("dic-26 ",TABLA!$B$3,"Nivel 4","2.- Variación de existencias")+GETPIVOTDATA("dic-26 ",TABLA!$B$3,"Nivel 4","4.- Aprovisionamientos"))/1000 -> -449.14533 | CY9: =VLOOKUP(CW9,'P&L Mensualitzada 2025'!$A$5:$N$25,$CX$3+1,0) -> -116.4287 | CZ9: =CX9-CY9 -> -332.71663 | DA9: =+IF(IFERROR(CX9/CY9-1,"-")<300%,IFERROR(CX9/CY9-1,"-"),"n.a.") -> 2.8576857 | DB9: =VLOOKUP(CW9,'Budget26 sin EI'!$B:$O,$CX$3+1,0) -> -226.64682 | DC9: =CX9-DB9 -> -222.49851 | DD9: =+IF(IFERROR(CX9/DB9-1,"-")<300%,IFERROR(CX9/DB9-1,"-"),"n.a.") -> 0.981697 | DF9: COGS | DG9: =(GETPIVOTDATA("Total 2026 ",TABLA!$B$3,"Nivel 4","2.- Variación de existencias")+GETPIVOTDATA("Total 2026 ",TABLA!$B$3,"Nivel 4","4.- Aprovisionamientos"))/1000 -> -5233.5328 | DH9: =VLOOKUP(DF9,'P&L Mensualitzada 2025'!$A$5:$N$25,$CX$3+2,0) -> -4286.3408 | DI9: =DG9-DH9 -> -947.19208 | DJ9: =+IF(IFERROR(DG9/DH9-1,"-")<300%,IFERROR(DG9/DH9-1,"-"),"n.a.") -> 0.22097918 | DK9: =VLOOKUP(DF9,'Budget26 sin EI'!$B:$O,$CX$3+2,0) -> -5474 | DL9: =DG9-DK9 -> 240.46715 | DM9: =+IF(IFERROR(DG9/DK9-1,"-")<300%,IFERROR(DG9/DK9-1,"-"),"n.a.") -> -0.043928963
B10: Gross Profit | C10: 481.15158 | D10: 104.19249 | E10: 376.95909 | F10: 3.6179104 | G10: 528.99072 | H10: -47.839142 | I10: -0.090434747 | K10: Gross Profit | L10: 1114.191 | M10: 610.92613 | N10: 503.26486 | O10: 0.82377367 | P10: 993.54657 | Q10: 120.64442 | R10: 0.12142804 | T10: Gross Profit | U10: 1148.0895 | V10: 1285.1219 | W10: -137.03244 | X10: -0.10662991 | Y10: 1511.5567 | Z10: -363.46721 | AA10: -0.24045887 | AC10: Gross Profit | AD10: 955.94319 | AE10: 1094.2894 | AF10: -138.34622 | AG10: -0.12642562 | AH10: 1241.7332 | AI10: -285.79 | AJ10: -0.23015411 | AL10: Gross Profit | AM10: 1301.6576 | AN10: 814.02707 | AO10: 487.6305 | AP10: 0.59903475 | AQ10: 1074.7383 | AR10: 226.91929 | AS10: 0.21113911 | AU10: Gross Profit | AV10: 1218.7032 | AW10: 1512.5746 | AX10: -293.87131 | AY10: -0.1942855 | AZ10: 1411.7845 | BA10: -193.08126 | BB10: -0.13676397 | BD10: Gross Profit | BE10: 765.3392 | BF10: 984.00014 | BG10: -218.66094 | BH10: -0.22221637 | BI10: 885.06424 | BJ10: -119.72504 | BK10: -0.13527271 | BM10: Gross Profit | BN10: 515.98492 | BO10: 565.29214 | BP10: -49.30722 | BQ10: -0.087224316 | BR10: 509.54455 | BS10: 6.4403674 | BT10: 0.012639459 | BV10: Gross Profit | BW10: =BW8+BW9 -> 422.41283 | BX10: =SUM(BX8:BX9) -> 576.74488 | BY10: =BW10-BX10 -> -154.33205 | BZ10: =+IF(IFERROR(BW10/BX10-1,"-")<300%,IFERROR(BW10/BX10-1,"-"),"n.a.") -> -0.26759154 | CA10: =SUM(CA8:CA9) -> 674.00956 | CB10: =BW10-CA10 -> -251.59673 | CC10: =+IF(IFERROR(BW10/CA10-1,"-")<300%,IFERROR(BW10/CA10-1,"-"),"n.a.") -> -0.37328362 | CE10: Gross Profit | CF10: =CF8+CF9 -> 609.95365 | CG10: =SUM(CG8:CG9) -> 338.50974 | CH10: =CF10-CG10 -> 271.44391 | CI10: =+IF(IFERROR(CF10/CG10-1,"-")<300%,IFERROR(CF10/CG10-1,"-"),"n.a.") -> 0.80187917 | CJ10: =SUM(CJ8:CJ9) -> 524.31174 | CK10: =CF10-CJ10 -> 85.641906 | CL10: =+IF(IFERROR(CF10/CJ10-1,"-")<300%,IFERROR(CF10/CJ10-1,"-"),"n.a.") -> 0.16334157 | CN10: Gross Profit | CO10: =CO8+CO9 -> 820.8985 | CP10: =SUM(CP8:CP9) -> 473.95262 | CQ10: =CO10-CP10 -> 346.94588 | CR10: =+IF(IFERROR(CO10/CP10-1,"-")<300%,IFERROR(CO10/CP10-1,"-"),"n.a.") -> 0.73202651 | CS10: =SUM(CS8:CS9) -> 676.42212 | CT10: =CO10-CS10 -> 144.47638 | CU10: =+IF(IFERROR(CO10/CS10-1,"-")<300%,IFERROR(CO10/CS10-1,"-"),"n.a.") -> 0.21358908 | CW10: Gross Profit | CX10: =CX8+CX9 -> 693.26205 | CY10: =SUM(CY8:CY9) -> 132.07731 | CZ10: =CX10-CY10 -> 561.18474 | DA10: =+IF(IFERROR(CX10/CY10-1,"-")<300%,IFERROR(CX10/CY10-1,"-"),"n.a.") -> n.a. | DB10: =SUM(DB8:DB9) -> 433.29783 | DC10: =CX10-DB10 -> 259.96422 | DD10: =+IF(IFERROR(CX10/DB10-1,"-")<300%,IFERROR(CX10/DB10-1,"-"),"n.a.") -> 0.59996659 | DF10: Gross Profit | DG10: =DG8+DG9 -> 9946.4672 | DH10: =SUM(DH8:DH9) -> 8491.7084 | DI10: =DG10-DH10 -> 1454.7587 | DJ10: =+IF(IFERROR(DG10/DH10-1,"-")<300%,IFERROR(DG10/DH10-1,"-"),"n.a.") -> 0.1713152 | DK10: =SUM(DK8:DK9) -> 10465 | DL10: =DG10-DK10 -> -518.53285 | DM10: =+IF(IFERROR(DG10/DK10-1,"-")<300%,IFERROR(DG10/DK10-1,"-"),"n.a.") -> -0.049549245
B11: % Gross Margin | C11: 0.48906607 | D11: 0.16743475 | G11: 0.6565656 | K11: % Gross Margin | L11: 0.75773236 | M11: 0.57502118 | P11: 0.6565656 | T11: % Gross Margin | U11: 0.74853136 | V11: 0.71588672 | Y11: 0.6565656 | AC11: % Gross Margin | AD11: 0.6537945 | AE11: 0.71319371 | AH11: 0.6565656 | AL11: % Gross Margin | AM11: 0.67585926 | AN11: 0.54856711 | AQ11: 0.6565656 | AU11: % Gross Margin | AV11: 0.62107065 | AW11: 0.85895762 | AZ11: 0.6565656 | BD11: % Gross Margin | BE11: 0.59298547 | BF11: 0.74853699 | BI11: 0.6565656 | BM11: % Gross Margin | BN11: 0.65471583 | BO11: 0.85070691 | BR11: 0.6565656 | BV11: % Gross Margin | BW11: =BW10/BW8 -> 0.67615817 | BX11: =BX10/BX8 -> 0.68487598 | CA11: =CA10/CA8 -> 0.6565656 | CE11: % Gross Margin | CF11: =CF10/CF8 -> 0.66876849 | CG11: =CG10/CG8 -> 0.48387328 | CJ11: =CJ10/CJ8 -> 0.6565656 | CN11: % Gross Margin | CO11: =CO10/CO8 -> 0.66994524 | CP11: =CP10/CP8 -> 0.63219041 | CS11: =CS10/CS8 -> 0.6565656 | CW11: % Gross Margin | CX11: =CX10/CX8 -> 0.60684311 | CY11: =CY10/CY8 -> 0.53148538 | DB11: =DB10/DB8 -> 0.65656692 | DF11: % Gross Margin | DG11: =DG10/DG8 -> 0.65523499 | DH11: =DH10/DH8 -> 0.66455437 | DK11: =DK10/DK8 -> 0.65656566
B13: Gastos de Personal | C13: -111.53201 | D13: 17.397715 | E13: -128.92973 | F13: -7.4107275 | G13: -138.431 | H13: 26.898993 | I13: -0.19431336 | K13: Gastos de Personal | L13: -142.9272 | M13: -169.90228 | N13: 26.97508 | O13: -0.1587682 | P13: -152.80201 | Q13: 9.8748135 | R13: -0.064624891 | T13: Gastos de Personal | U13: -146.23331 | V13: -215.24045 | W13: 69.00714 | X13: -0.32060489 | Y13: -268.64421 | Z13: 122.4109 | AA13: -0.45566178 | AC13: Gastos de Personal | AD13: -130.04767 | AE13: -145.05985 | AF13: 15.01218 | AG13: -0.10348956 | AH13: -157.32982 | AI13: 27.282153 | AJ13: -0.17340739 | AL13: Gastos de Personal | AM13: -134.99252 | AN13: -141.27428 | AO13: 6.28176 | AP13: -0.044464994 | AQ13: -157.32982 | AR13: 22.337303 | AS13: -0.14197755 | AU13: Gastos de Personal | AV13: -145.07228 | AW13: -98.245985 | AX13: -46.826295 | AY13: 0.47662299 | AZ13: -290.07649 | BA13: 145.00421 | BB13: -0.49988267 | BD13: Gastos de Personal | BE13: -153.53365 | BF13: -218.74298 | BG13: 65.20933 | BH13: -0.29810936 | BI13: -157.32982 | BJ13: 3.7961735 | BK13: -0.02412876 | BM13: Gastos de Personal | BN13: -152.63279 | BO13: -131.97477 | BP13: -20.65802 | BQ13: 0.15653007 | BR13: -162.96321 | BS13: 10.330416 | BT13: -0.063391092 | BV13: Gastos de Personal | BW13: =GETPIVOTDATA("sep-26 ",TABLA!$B$3,"Nivel 4","6.- Gastos de personal")/1000 -> -165.80399 | BX13: =VLOOKUP(BV13,'P&L Mensualitzada 2025'!$A$5:$N$25,$BW$3+1,0) -> -133.7212 | BY13: =BW13-BX13 -> -32.08279 | BZ13: =+IF(IFERROR(BW13/BX13-1,"-")<300%,IFERROR(BW13/BX13-1,"-"),"n.a.") -> 0.23992299 | CA13: =VLOOKUP(BV13,'Budget26 sin EI'!$B:$O,$BW$3+1,0) -> -174.23 | CB13: =BW13-CA13 -> 8.42601 | CC13: =+IF(IFERROR(BW13/CA13-1,"-")<300%,IFERROR(BW13/CA13-1,"-"),"n.a.") -> -0.048361419 | CE13: Gastos de Personal | CF13: =GETPIVOTDATA("oct-26 ",TABLA!$B$3,"Nivel 4","6.- Gastos de personal")/1000 -> -152.63279 | CG13: =VLOOKUP(CE13,'P&L Mensualitzada 2025'!$A$5:$N$25,$CF$3+1,0) -> -300.72411 | CH13: =CF13-CG13 -> 148.09132 | CI13: =+IF(IFERROR(CF13/CG13-1,"-")<300%,IFERROR(CF13/CG13-1,"-"),"n.a.") -> -0.49244911 | CJ13: =VLOOKUP(CE13,'Budget26 sin EI'!$B:$O,$CF$3+1,0) -> -174.23 | CK13: =CF13-CJ13 -> 21.59721 | CL13: =+IF(IFERROR(CF13/CJ13-1,"-")<300%,IFERROR(CF13/CJ13-1,"-"),"n.a.") -> -0.12395804 | CN13: Gastos de Personal | CO13: =GETPIVOTDATA("nov-26 ",TABLA!$B$3,"Nivel 4","6.- Gastos de personal")/1000 -> -152.63279 | CP13: =VLOOKUP(CN13,'P&L Mensualitzada 2025'!$A$5:$N$25,$CO$3+1,0) -> -153.08435 | CQ13: =CO13-CP13 -> 0.45156 | CR13: =+IF(IFERROR(CO13/CP13-1,"-")<300%,IFERROR(CO13/CP13-1,"-"),"n.a.") -> -0.0029497463 | CS13: =VLOOKUP(CN13,'Budget26 sin EI'!$B:$O,$CO$3+1,0) -> -174.23 | CT13: =CO13-CS13 -> 21.59721 | CU13: =+IF(IFERROR(CO13/CS13-1,"-")<300%,IFERROR(CO13/CS13-1,"-"),"n.a.") -> -0.12395804 | CW13: Gastos de Personal | CX13: =GETPIVOTDATA("dic-26 ",TABLA!$B$3,"Nivel 4","6.- Gastos de personal")/1000 -> -431.63279 | CY13: =VLOOKUP(CW13,'P&L Mensualitzada 2025'!$A$5:$N$25,$CX$3+1,0) -> -172.01862 | CZ13: =CX13-CY13 -> -259.61417 | DA13: =+IF(IFERROR(CX13/CY13-1,"-")<300%,IFERROR(CX13/CY13-1,"-"),"n.a.") -> 1.5092213 | DB13: =VLOOKUP(CW13,'Budget26 sin EI'!$B:$O,$CX$3+1,0) -> -306.97667 | DC13: =CX13-DB13 -> -124.65612 | DD13: =+IF(IFERROR(CX13/DB13-1,"-")<300%,IFERROR(CX13/DB13-1,"-"),"n.a.") -> 0.40607687 | DF13: Gastos de Personal | DG13: =GETPIVOTDATA("Total 2026 ",TABLA!$B$3,"Nivel 4","6.- Gastos de personal")/1000 -> -2006.5026 | DH13: =VLOOKUP(DF13,'P&L Mensualitzada 2025'!$A$5:$N$25,$CX$3+2,0) -> -1862.5912 | DI13: =DG13-DH13 -> -143.91143 | DJ13: =+IF(IFERROR(DG13/DH13-1,"-")<300%,IFERROR(DG13/DH13-1,"-"),"n.a.") -> 0.0772641 | DK13: =VLOOKUP(DF13,'Budget26 sin EI'!$B:$O,$CX$3+2,0) -> -2314.5731 | DL13: =DG13-DK13 -> 308.07047 | DM13: =+IF(IFERROR(DG13/DK13-1,"-")<300%,IFERROR(DG13/DK13-1,"-"),"n.a.") -> -0.13310034
B14: % of Revenue | C14: -0.11336661 | D14: 0.027957697 | G14: -0.17181593 | K14: % of Revenue | L14: -0.097201077 | M14: -0.15991689 | P14: -0.10097619 | T14: % of Revenue | U14: -0.095341192 | V14: -0.11990129 | Y14: -0.11668934 | AC14: % of Revenue | AD14: -0.088942995 | AE14: -0.09454151 | AH14: -0.08318804 | AL14: % of Revenue | AM14: -0.070092125 | AN14: -0.095203743 | AQ14: -0.096113958 | AU14: % of Revenue | AV14: -0.073931153 | AW14: -0.055791721 | AZ14: -0.1349032 | BD14: % of Revenue | BE14: -0.118958 | BF14: -0.16639958 | BI14: -0.1167117 | BM14: % of Revenue | BN14: -0.19367059 | BO14: -0.19860854 | BR14: -0.20998367 | BV14: % of Revenue | BW14: =BW13/BW8 -> -0.26540321 | BX14: =BX13/BX8 -> -0.15879194 | CA14: =CA13/CA8 -> -0.16972078 | CE14: % of Revenue | CF14: =CF13/CF8 -> -0.16735042 | CG14: =CG13/CG8 -> -0.42986167 | CJ14: =CJ13/CJ8 -> -0.21817826 | CN14: % of Revenue | CO14: =CO13/CO8 -> -0.12456548 | CP14: =CP13/CP8 -> -0.20419437 | CS14: =CS13/CS8 -> -0.16911544 | CW14: % of Revenue | CX14: =CX13/CX8 -> -0.37782738 | CY14: =CY13/CY8 -> -0.69221111 | DB14: =DB13/DB8 -> -0.46515517 | DF14: % of Revenue | DG14: =DG13/DG8 -> -0.13218067 | DH14: =DH13/DH8 -> -0.14576491 | DK14: =DK13/DK8 -> -0.14521445
B16: Otros Ingresos Operativos | C16: 0 | D16: 0 | E16: 0 | F16: n.a. | G16: 0 | H16: 0 | I16: n.a. | K16: Otros Ingresos Operativos | L16: 0 | M16: 0.23944 | N16: -0.23944 | O16: -1 | P16: 0 | Q16: 0 | R16: n.a. | T16: Otros Ingresos Operativos | U16: 0 | V16: 0 | W16: 0 | X16: n.a. | Y16: 0 | Z16: 0 | AA16: n.a. | AC16: Otros Ingresos Operativos | AD16: 0.75075 | AE16: 0 | AF16: 0.75075 | AG16: n.a. | AH16: 0 | AI16: 0.75075 | AJ16: n.a. | AL16: Otros Ingresos Operativos | AM16: 25.14075 | AN16: 0.43575 | AO16: 24.705 | AP16: n.a. | AQ16: 0 | AR16: 25.14075 | AS16: n.a. | AU16: Otros Ingresos Operativos | AV16: 22.9776 | AW16: 0.11769 | AX16: 22.85991 | AY16: n.a. | AZ16: 0 | BA16: 22.9776 | BB16: n.a. | BD16: Otros Ingresos Operativos | BE16: 11.02724 | BF16: 0 | BG16: 11.02724 | BH16: n.a. | BI16: 0 | BJ16: 11.02724 | BK16: n.a. | BM16: Otros Ingresos Operativos | BN16: 11.429 | BO16: 0 | BP16: 11.429 | BQ16: n.a. | BR16: 0 | BS16: 11.429 | BT16: n.a. | BV16: Otros Ingresos Operativos | BW16: =GETPIVOTDATA("sep-26 ",TABLA!$B$3,"Nivel 4","5.- Otros ingresos de explotación")/1000 -> 9.613 | BX16: =VLOOKUP(BV16,'P&L Mensualitzada 2025'!$A$5:$N$25,$BW$3+1,0) -> 0 | BY16: =BW16-BX16 -> 9.613 | BZ16: =+IF(IFERROR(BW16/BX16-1,"-")<300%,IFERROR(BW16/BX16-1,"-"),"n.a.") -> n.a. | CA16: =VLOOKUP(BV16,'Budget26 sin EI'!$B:$O,$BW$3+1,0) -> 0 | CB16: =BW16-CA16 -> 9.613 | CC16: =+IF(IFERROR(BW16/CA16-1,"-")<300%,IFERROR(BW16/CA16-1,"-"),"n.a.") -> n.a. | CE16: Otros Ingresos Operativos | CF16: =GETPIVOTDATA("oct-26 ",TABLA!$B$3,"Nivel 4","5.- Otros ingresos de explotación")/1000 -> 21.379 | CG16: =VLOOKUP(CE16,'P&L Mensualitzada 2025'!$A$5:$N$25,$CF$3+1,0) -> 1.80096 | CH16: =CF16-CG16 -> 19.57804 | CI16: =+IF(IFERROR(CF16/CG16-1,"-")<300%,IFERROR(CF16/CG16-1,"-"),"n.a.") -> n.a. | CJ16: =VLOOKUP(CE16,'Budget26 sin EI'!$B:$O,$CF$3+1,0) -> 0 | CK16: =CF16-CJ16 -> 21.379 | CL16: =+IF(IFERROR(CF16/CJ16-1,"-")<300%,IFERROR(CF16/CJ16-1,"-"),"n.a.") -> n.a. | CN16: Otros Ingresos Operativos | CO16: =GETPIVOTDATA("nov-26 ",TABLA!$B$3,"Nivel 4","5.- Otros ingresos de explotación")/1000 -> 32.454 | CP16: =VLOOKUP(CN16,'P&L Mensualitzada 2025'!$A$5:$N$25,$CO$3+1,0) -> 0 | CQ16: =CO16-CP16 -> 32.454 | CR16: =+IF(IFERROR(CO16/CP16-1,"-")<300%,IFERROR(CO16/CP16-1,"-"),"n.a.") -> n.a. | CS16: =VLOOKUP(CN16,'Budget26 sin EI'!$B:$O,$CO$3+1,0) -> 0 | CT16: =CO16-CS16 -> 32.454 | CU16: =+IF(IFERROR(CO16/CS16-1,"-")<300%,IFERROR(CO16/CS16-1,"-"),"n.a.") -> n.a. | CW16: Otros Ingresos Operativos | CX16: =GETPIVOTDATA("dic-26 ",TABLA!$B$3,"Nivel 4","5.- Otros ingresos de explotación")/1000 -> 27.15 | CY16: =VLOOKUP(CW16,'P&L Mensualitzada 2025'!$A$5:$N$25,$CX$3+1,0) -> 47.20436 | CZ16: =CX16-CY16 -> -20.05436 | DA16: =+IF(IFERROR(CX16/CY16-1,"-")<300%,IFERROR(CX16/CY16-1,"-"),"n.a.") -> -0.42484126 | DB16: =VLOOKUP(CW16,'Budget26 sin EI'!$B:$O,$CX$3+1,0) -> 0 | DC16: =CX16-DB16 -> 27.15 | DD16: =+IF(IFERROR(CX16/DB16-1,"-")<300%,IFERROR(CX16/DB16-1,"-"),"n.a.") -> n.a. | DF16: Otros Ingresos Operativos | DG16: =GETPIVOTDATA("Total 2026 ",TABLA!$B$3,"Nivel 4","5.- Otros ingresos de explotación")/1000 -> 168.56134 | DH16: =VLOOKUP(DF16,'P&L Mensualitzada 2025'!$A$5:$N$25,$CX$3+2,0) -> 49.7982 | DI16: =DG16-DH16 -> 118.76314 | DJ16: =+IF(IFERROR(DG16/DH16-1,"-")<300%,IFERROR(DG16/DH16-1,"-"),"n.a.") -> 2.3848882 | DK16: =VLOOKUP(DF16,'Budget26 sin EI'!$B:$O,$CX$3+2,0) -> 0 | DL16: =DG16-DK16 -> 168.56134 | DM16: =+IF(IFERROR(DG16/DK16-1,"-")<300%,IFERROR(DG16/DK16-1,"-"),"n.a.") -> n.a.
B17: Otros Gastos Operativos | C17: -103.45176 | D17: -83.04566 | E17: -20.4061 | F17: 0.24572145 | G17: -183.33533 | H17: 79.883569 | I17: -0.43572382 | K17: Otros Gastos Operativos | L17: -62.49888 | M17: -74.84982 | N17: 12.35094 | O17: -0.16500962 | P17: -133.85532 | Q17: 71.356439 | R17: -0.53308632 | T17: Otros Gastos Operativos | U17: -110.60627 | V17: -105.74077 | W17: -4.8655 | X17: 0.046013472 | Y17: -128.94532 | Z17: 18.339049 | AA17: -0.14222346 | AC17: Otros Gastos Operativos | AD17: -107.70665 | AE17: -91.37805 | AF17: -16.3286 | AG17: 0.1786928 | AH17: -131.89532 | AI17: 24.188669 | AJ17: -0.18339293 | AL17: Otros Gastos Operativos | AM17: -123.39208 | AN17: -108.29459 | AO17: -15.09749 | AP17: 0.1394113 | AQ17: -126.94533 | AR17: 3.5532492 | AS17: -0.027990389 | AU17: Otros Gastos Operativos | AV17: -175.01376 | AW17: -116.04261 | AX17: -58.97115 | AY17: 0.50818531 | AZ17: -160.19533 | BA17: -14.818431 | BB17: 0.092502265 | BD17: Otros Gastos Operativos | BE17: -161.05174 | BF17: -102.38971 | BG17: -58.662034 | BH17: 0.572929 | BI17: -152.80333 | BJ17: -8.2484151 | BK17: 0.053980598 | BM17: Otros Gastos Operativos | BN17: -130.06066 | BO17: -68.70525 | BP17: -61.355411 | BQ17: 0.89302362 | BR17: -117.79333 | BS17: -12.267332 | BT17: 0.10414284 | BV17: Otros Gastos Operativos | BW17: =GETPIVOTDATA("sep-26 ",TABLA!$B$3,"Nivel 4","7.- Otros gastos de explotación")/1000 -> -108.09534 | BX17: =VLOOKUP(BV17,'P&L Mensualitzada 2025'!$A$5:$N$25,$BW$3+1,0) -> -73.91279 | BY17: =BW17-BX17 -> -34.18255 | BZ17: =+IF(IFERROR(BW17/BX17-1,"-")<300%,IFERROR(BW17/BX17-1,"-"),"n.a.") -> 0.46247138 | CA17: =VLOOKUP(BV17,'Budget26 sin EI'!$B:$O,$BW$3+1,0) -> -120.05333 | CB17: =BW17-CA17 -> 11.957989 | CC17: =+IF(IFERROR(BW17/CA17-1,"-")<300%,IFERROR(BW17/CA17-1,"-"),"n.a.") -> -0.099605644 | CE17: Otros Gastos Operativos | CF17: =GETPIVOTDATA("oct-26 ",TABLA!$B$3,"Nivel 4","7.- Otros gastos de explotación")/1000 -> -149.47019 | CG17: =VLOOKUP(CE17,'P&L Mensualitzada 2025'!$A$5:$N$25,$CF$3+1,0) -> -122.16905 | CH17: =CF17-CG17 -> -27.30114 | CI17: =+IF(IFERROR(CF17/CG17-1,"-")<300%,IFERROR(CF17/CG17-1,"-"),"n.a.") -> 0.22347018 | CJ17: =VLOOKUP(CE17,'Budget26 sin EI'!$B:$O,$CF$3+1,0) -> -144.84269 | CK17: =CF17-CJ17 -> -4.6275008 | CL17: =+IF(IFERROR(CF17/CJ17-1,"-")<300%,IFERROR(CF17/CJ17-1,"-"),"n.a.") -> 0.03194846 | CN17: Otros Gastos Operativos | CO17: =GETPIVOTDATA("nov-26 ",TABLA!$B$3,"Nivel 4","7.- Otros gastos de explotación")/1000 -> -162.36942 | CP17: =VLOOKUP(CN17,'P&L Mensualitzada 2025'!$A$5:$N$25,$CO$3+1,0) -> -68.32762 | CQ17: =CO17-CP17 -> -94.0418 | CR17: =+IF(IFERROR(CO17/CP17-1,"-")<300%,IFERROR(CO17/CP17-1,"-"),"n.a.") -> 1.3763365 | CS17: =VLOOKUP(CN17,'Budget26 sin EI'!$B:$O,$CO$3+1,0) -> -148.99269 | CT17: =CO17-CS17 -> -13.376731 | CU17: =+IF(IFERROR(CO17/CS17-1,"-")<300%,IFERROR(CO17/CS17-1,"-"),"n.a.") -> 0.089781122 | CW17: Otros Gastos Operativos | CX17: =GETPIVOTDATA("dic-26 ",TABLA!$B$3,"Nivel 4","7.- Otros gastos de explotación")/1000 -> -277.59629 | CY17: =VLOOKUP(CW17,'P&L Mensualitzada 2025'!$A$5:$N$25,$CX$3+1,0) -> -239.07332 | CZ17: =CX17-CY17 -> -38.52297 | DA17: =+IF(IFERROR(CX17/CY17-1,"-")<300%,IFERROR(CX17/CY17-1,"-"),"n.a.") -> 0.16113454 | DB17: =VLOOKUP(CW17,'Budget26 sin EI'!$B:$O,$CX$3+1,0) -> -180.34269 | DC17: =CX17-DB17 -> -97.253601 | DD17: =+IF(IFERROR(CX17/DB17-1,"-")<300%,IFERROR(CX17/DB17-1,"-"),"n.a.") -> 0.5392711 | DF17: Otros Gastos Operativos | DG17: =GETPIVOTDATA("Total 2026 ",TABLA!$B$3,"Nivel 4","7.- Otros gastos de explotación")/1000 -> -1684.026 | DH17: =VLOOKUP(DF17,'P&L Mensualitzada 2025'!$A$5:$N$25,$CX$3+2,0) -> -1253.9292 | DI17: =DG17-DH17 -> -430.09679 | DJ17: =+IF(IFERROR(DG17/DH17-1,"-")<300%,IFERROR(DG17/DH17-1,"-"),"n.a.") -> 0.34299925 | DK17: =VLOOKUP(DF17,'Budget26 sin EI'!$B:$O,$CX$3+2,0) -> -1730 | DL17: =DG17-DK17 -> 45.973975 | DM17: =+IF(IFERROR(DG17/DK17-1,"-")<300%,IFERROR(DG17/DK17-1,"-"),"n.a.") -> -0.026574552
B18: Operating Expenses | C18: -103.45176 | D18: -83.04566 | E18: -20.4061 | F18: 0.24572145 | G18: -183.33533 | H18: 79.883569 | I18: -0.43572382 | K18: Operating Expenses | L18: -62.49888 | M18: -74.61038 | N18: 12.1115 | O18: -0.16232996 | P18: -133.85532 | Q18: 71.356439 | R18: -0.53308632 | T18: Operating Expenses | U18: -110.60627 | V18: -105.74077 | W18: -4.8655 | X18: 0.046013472 | Y18: -128.94532 | Z18: 18.339049 | AA18: -0.14222346 | AC18: Operating Expenses | AD18: -106.9559 | AE18: -91.37805 | AF18: -15.57785 | AG18: 0.17047694 | AH18: -131.89532 | AI18: 24.939419 | AJ18: -0.18908494 | AL18: Operating Expenses | AM18: -98.25133 | AN18: -107.85884 | AO18: 9.60751 | AP18: -0.08907485 | AQ18: -126.94533 | AR18: 28.693999 | AS18: -0.2260343 | AU18: Operating Expenses | AV18: -152.03616 | AW18: -115.92492 | AX18: -36.11124 | AY18: 0.31150541 | AZ18: -160.19533 | BA18: 8.1591692 | BB18: -0.050932628 | BD18: Operating Expenses | BE18: -150.0245 | BF18: -102.38971 | BG18: -47.634794 | BH18: 0.46523029 | BI18: -152.80333 | BJ18: 2.7788249 | BK18: -0.018185631 | BM18: Operating Expenses | BN18: -118.63166 | BO18: -68.70525 | BP18: -49.926411 | BQ18: 0.72667534 | BR18: -117.79333 | BS18: -0.83833187 | BT18: 0.0071169724 | BV18: Operating Expenses | BW18: =SUM(BW16:BW17) -> -98.48234 | BX18: =SUM(BX16:BX17) -> -73.91279 | BY18: =BW18-BX18 -> -24.56955 | BZ18: =+IF(IFERROR(BW18/BX18-1,"-")<300%,IFERROR(BW18/BX18-1,"-"),"n.a.") -> 0.3324127 | CA18: =SUM(CA16:CA17) -> -120.05333 | CB18: =BW18-CA18 -> 21.570989 | CC18: =+IF(IFERROR(BW18/CA18-1,"-")<300%,IFERROR(BW18/CA18-1,"-"),"n.a.") -> -0.17967839 | CE18: Operating Expenses | CF18: =SUM(CF16:CF17) -> -128.09119 | CG18: =SUM(CG16:CG17) -> -120.36809 | CH18: =CF18-CG18 -> -7.7231 | CI18: =+IF(IFERROR(CF18/CG18-1,"-")<300%,IFERROR(CF18/CG18-1,"-"),"n.a.") -> 0.064162354 | CJ18: =SUM(CJ16:CJ17) -> -144.84269 | CK18: =CF18-CJ18 -> 16.751499 | CL18: =+IF(IFERROR(CF18/CJ18-1,"-")<300%,IFERROR(CF18/CJ18-1,"-"),"n.a.") -> -0.11565305 | CN18: Operating Expenses | CO18: =SUM(CO16:CO17) -> -129.91542 | CP18: =SUM(CP16:CP17) -> -68.32762 | CQ18: =CO18-CP18 -> -61.5878 | CR18: =+IF(IFERROR(CO18/CP18-1,"-")<300%,IFERROR(CO18/CP18-1,"-"),"n.a.") -> 0.90136024 | CS18: =SUM(CS16:CS17) -> -148.99269 | CT18: =CO18-CS18 -> 19.077269 | CU18: =+IF(IFERROR(CO18/CS18-1,"-")<300%,IFERROR(CO18/CS18-1,"-"),"n.a.") -> -0.12804165 | CW18: Operating Expenses | CX18: =SUM(CX16:CX17) -> -250.44629 | CY18: =SUM(CY16:CY17) -> -191.86896 | CZ18: =CX18-CY18 -> -58.57733 | DA18: =+IF(IFERROR(CX18/CY18-1,"-")<300%,IFERROR(CX18/CY18-1,"-"),"n.a.") -> 0.30529863 | DB18: =SUM(DB16:DB17) -> -180.34269 | DC18: =CX18-DB18 -> -70.103601 | DD18: =+IF(IFERROR(CX18/DB18-1,"-")<300%,IFERROR(CX18/DB18-1,"-"),"n.a.") -> 0.38872438 | DF18: Operating Expenses | DG18: =SUM(DG16:DG17) -> -1515.4647 | DH18: =SUM(DH16:DH17) -> -1204.131 | DI18: =DG18-DH18 -> -311.33365 | DJ18: =+IF(IFERROR(DG18/DH18-1,"-")<300%,IFERROR(DG18/DH18-1,"-"),"n.a.") -> 0.25855462 | DK18: =SUM(DK16:DK17) -> -1730 | DL18: =DG18-DK18 -> 214.53531 | DM18: =+IF(IFERROR(DG18/DK18-1,"-")<300%,IFERROR(DG18/DK18-1,"-"),"n.a.") -> -0.12400885
B19: % of Revenue | C19: -0.10515344 | D19: -0.13345232 | G19: -0.22754968 | K19: % of Revenue | L19: -0.042503865 | M19: -0.070225428 | P19: -0.08845564 | T19: % of Revenue | U19: -0.072113075 | V19: -0.058903682 | Y19: -0.056009187 | AC19: % of Revenue | AD19: -0.073149931 | AE19: -0.059554858 | AH19: -0.069739563 | AL19: % of Revenue | AM19: -0.051015008 | AN19: -0.072685313 | AQ19: -0.077551845 | AU19: % of Revenue | AV19: -0.077480058 | AW19: -0.065831197 | AZ19: -0.074500565 | BD19: % of Revenue | BE19: -0.11623911 | BF19: -0.077888694 | BI19: -0.11335382 | BM19: % of Revenue | BN19: -0.15052771 | BO19: -0.10339438 | BR19: -0.15178074 | BV19: % of Revenue | BW19: =BW18/BW8 -> -0.15764114 | BX19: =BX18/BX8 -> -0.087770341 | CA19: =CA18/CA8 -> -0.11694624 | CE19: % of Revenue | CF19: =CF18/CF8 -> -0.1404424 | CG19: =CG18/CG8 -> -0.1720568 | CJ19: =CJ18/CJ8 -> -0.18137821 | CN19: % of Revenue | CO19: =CO18/CO8 -> -0.10602555 | CP19: =CP18/CP8 -> -0.091140051 | CS19: =CS18/CS8 -> -0.14461898 | CW19: % of Revenue | CX19: =CX18/CX8 -> -0.21922678 | CY19: =CY18/CY8 -> -0.77208982 | DB19: =DB18/DB8 -> -0.27326941 | DF19: % of Revenue | DG19: =DG18/DG8 -> -0.099832983 | DH19: =DH18/DH8 -> -0.094234341 | DK19: =DK18/DK8 -> -0.1085388
B20: Gastos Fijos | C20: -214.98377 | D20: -65.647945 | E20: -149.33583 | F20: 2.2747982 | G20: -321.76633 | H20: 106.78256 | I20: -0.33186369 | K20: Gastos Fijos | L20: -205.42608 | M20: -244.51266 | N20: 39.08658 | O20: -0.15985504 | P20: -286.65733 | Q20: 81.231253 | R20: -0.28337406 | T20: Gastos Fijos | U20: -256.83958 | V20: -320.98122 | W20: 64.14164 | X20: -0.19982988 | Y20: -397.58953 | Z20: 140.74995 | AA20: -0.35400819 | AC20: Gastos Fijos | AD20: -237.00357 | AE20: -236.4379 | AF20: -0.56567 | AG20: 0.0023924675 | AH20: -289.22514 | AI20: 52.221573 | AJ20: -0.18055682 | AL20: Gastos Fijos | AM20: -233.24385 | AN20: -249.13312 | AO20: 15.88927 | AP20: -0.063778232 | AQ20: -284.27515 | AR20: 51.031303 | AS20: -0.17951376 | AU20: Gastos Fijos | AV20: -297.10844 | AW20: -214.1709 | AX20: -82.937535 | AY20: 0.38724931 | AZ20: -450.27182 | BA20: 153.16338 | BB20: -0.3401576 | BD20: Gastos Fijos | BE20: -303.55815 | BF20: -321.13269 | BG20: 17.574536 | BH20: -0.054726711 | BI20: -310.13315 | BJ20: 6.5749984 | BK20: -0.021200566 | BM20: Gastos Fijos | BN20: -271.26445 | BO20: -200.68002 | BP20: -70.584431 | BQ20: 0.35172625 | BR20: -280.75653 | BS20: 9.4920837 | BT20: -0.03380895 | BV20: Gastos Fijos | BW20: =BW18+BW13 -> -264.28633 | BX20: =BX18+BX13 -> -207.63399 | BY20: =BW20-BX20 -> -56.65234 | BZ20: =+IF(IFERROR(BW20/BX20-1,"-")<300%,IFERROR(BW20/BX20-1,"-"),"n.a.") -> 0.27284714 | CA20: =CA18+CA13 -> -294.28333 | CB20: =BW20-CA20 -> 29.996999 | CC20: =+IF(IFERROR(BW20/CA20-1,"-")<300%,IFERROR(BW20/CA20-1,"-"),"n.a.") -> -0.10193238 | CE20: Gastos Fijos | CF20: =CF18+CF13 -> -280.72398 | CG20: =CG18+CG13 -> -421.0922 | CH20: =CF20-CG20 -> 140.36822 | CI20: =+IF(IFERROR(CF20/CG20-1,"-")<300%,IFERROR(CF20/CG20-1,"-"),"n.a.") -> -0.3333432 | CJ20: =CJ18+CJ13 -> -319.07269 | CK20: =CF20-CJ20 -> 38.348709 | CL20: =+IF(IFERROR(CF20/CJ20-1,"-")<300%,IFERROR(CF20/CJ20-1,"-"),"n.a.") -> -0.120188 | CN20: Gastos Fijos | CO20: =CO18+CO13 -> -282.54821 | CP20: =CP18+CP13 -> -221.41197 | CQ20: =CO20-CP20 -> -61.13624 | CR20: =+IF(IFERROR(CO20/CP20-1,"-")<300%,IFERROR(CO20/CP20-1,"-"),"n.a.") -> 0.27611985 | CS20: =CS18+CS13 -> -323.22269 | CT20: =CO20-CS20 -> 40.674479 | CU20: =+IF(IFERROR(CO20/CS20-1,"-")<300%,IFERROR(CO20/CS20-1,"-"),"n.a.") -> -0.12584042 | CW20: Gastos Fijos | CX20: =CX18+CX13 -> -682.07908 | CY20: =CY18+CY13 -> -363.88758 | CZ20: =CX20-CY20 -> -318.1915 | DA20: =+IF(IFERROR(CX20/CY20-1,"-")<300%,IFERROR(CX20/CY20-1,"-"),"n.a.") -> 0.87442253 | DB20: =DB18+DB13 -> -487.31936 | DC20: =CX20-DB20 -> -194.75972 | DD20: =+IF(IFERROR(CX20/DB20-1,"-")<300%,IFERROR(CX20/DB20-1,"-"),"n.a.") -> 0.39965522 | DF20: Gastos Fijos | DG20: =DG18+DG13 -> -3521.9673 | DH20: =DH18+DH13 -> -3066.7222 | DI20: =DG20-DH20 -> -455.24508 | DJ20: =+IF(IFERROR(DG20/DH20-1,"-")<300%,IFERROR(DG20/DH20-1,"-"),"n.a.") -> 0.14844679 | DK20: =DK18+DK13 -> -4044.5731 | DL20: =DG20-DK20 -> 522.60578 | DM20: =+IF(IFERROR(DG20/DK20-1,"-")<300%,IFERROR(DG20/DK20-1,"-"),"n.a.") -> -0.12921161
B21: % of Revenue | C21: -0.21852005 | D21: -0.10549462 | G21: -0.39936562 | K21: % of Revenue | L21: -0.13970494 | M21: -0.23014232 | P21: -0.18943183 | T21: % of Revenue | U21: -0.16745427 | V21: -0.17880498 | Y21: -0.17269852 | AC21: % of Revenue | AD21: -0.16209293 | AE21: -0.15409637 | AH21: -0.1529276 | AL21: % of Revenue | AM21: -0.12110713 | AN21: -0.16788906 | AQ21: -0.1736658 | AU21: % of Revenue | AV21: -0.15141121 | AW21: -0.12162292 | AZ21: -0.20940376 | BD21: % of Revenue | BE21: -0.23519712 | BF21: -0.24428828 | BI21: -0.23006552 | BM21: % of Revenue | BN21: -0.3441983 | BO21: -0.30200293 | BR21: -0.36176441 | BV21: % of Revenue | BW21: =BW20/BW8 -> -0.42304435 | BX21: =BX20/BX8 -> -0.24656228 | CA21: =CA20/CA8 -> -0.28666702 | CE21: % of Revenue | CF21: =CF20/CF8 -> -0.30779282 | CG21: =CG20/CG8 -> -0.60191847 | CJ21: =CJ20/CJ8 -> -0.39955648 | CN21: % of Revenue | CO21: =CO20/CO8 -> -0.23059103 | CP21: =CP20/CP8 -> -0.29533442 | CS21: =CS20/CS8 -> -0.31373442 | CW21: % of Revenue | CX21: =CX20/CX8 -> -0.59705416 | CY21: =CY20/CY8 -> -1.4643009 | DB21: =DB20/DB8 -> -0.73842458 | DF21: % of Revenue | DG21: =DG20/DG8 -> -0.23201365 | DH21: =DH20/DH8 -> -0.23999925 | DK21: =DK20/DK8 -> -0.25375325
B22: Adjusted EBITDA | C22: 266.16781 | D22: 38.544545 | E22: 227.62326 | F22: 5.9054599 | G22: 207.22439 | H22: 58.943421 | I22: 0.28444249 | K22: Adjusted EBITDA | L22: 908.76491 | M22: 366.41347 | N22: 542.35144 | O22: 1.4801624 | P22: 706.88924 | Q22: 201.87567 | R22: 0.28558317 | T22: Adjusted EBITDA | U22: 891.2499 | V22: 964.1407 | W22: -72.8908 | X22: -0.075601829 | Y22: 1113.9672 | Z22: -222.71726 | AA22: -0.19993162 | AC22: Adjusted EBITDA | AD22: 718.93962 | AE22: 857.85151 | AF22: -138.91189 | AG22: -0.16192999 | AH22: 952.50805 | AI22: -233.56843 | AJ22: -0.24521412 | AL22: Adjusted EBITDA | AM22: 1068.4137 | AN22: 564.89395 | AO22: 503.51977 | AP22: 0.89135274 | AQ22: 790.46313 | AR22: 277.95059 | AS22: 0.35163005 | AU22: Adjusted EBITDA | AV22: 921.5948 | AW22: 1298.4036 | AX22: -376.80885 | AY22: -0.29020932 | AZ22: 961.51268 | BA22: -39.91788 | BB22: -0.041515709 | BD22: Adjusted EBITDA | BE22: 461.78105 | BF22: 662.86745 | BG22: -201.0864 | BH22: -0.30335839 | BI22: 574.93109 | BJ22: -113.15004 | BK22: -0.19680626 | BM22: Adjusted EBITDA | BN22: 244.72047 | BO22: 364.61212 | BP22: -119.89165 | BQ22: -0.32881971 | BR22: 228.78802 | BS22: 15.932451 | BT22: 0.069638486 | BV22: Adjusted EBITDA | BW22: =BW10+BW20 -> 158.1265 | BX22: =BX10+BX20 -> 369.11089 | BY22: =BW22-BX22 -> -210.98439 | BZ22: =+IF(IFERROR(BW22/BX22-1,"-")<300%,IFERROR(BW22/BX22-1,"-"),"n.a.") -> -0.57160164 | CA22: =CA10+CA20 -> 379.72623 | CB22: =BW22-CA22 -> -221.59973 | CC22: =+IF(IFERROR(BW22/CA22-1,"-")<300%,IFERROR(BW22/CA22-1,"-"),"n.a.") -> -0.58357762 | CE22: Adjusted EBITDA | CF22: =CF10+CF20 -> 329.22967 | CG22: =CG10+CG20 -> -82.58246 | CH22: =CF22-CG22 -> 411.81213 | CI22: =+IF(IFERROR(CF22/CG22-1,"-")<300%,IFERROR(CF22/CG22-1,"-"),"n.a.") -> -4.9866779 | CJ22: =CJ10+CJ20 -> 205.23905 | CK22: =CF22-CJ22 -> 123.99062 | CL22: =+IF(IFERROR(CF22/CJ22-1,"-")<300%,IFERROR(CF22/CJ22-1,"-"),"n.a.") -> 0.60412778 | CN22: Adjusted EBITDA | CO22: =CO10+CO20 -> 538.35029 | CP22: =CP10+CP20 -> 252.54065 | CQ22: =CO22-CP22 -> 285.80964 | CR22: =+IF(IFERROR(CO22/CP22-1,"-")<300%,IFERROR(CO22/CP22-1,"-"),"n.a.") -> 1.1317372 | CS22: =CS10+CS20 -> 353.19943 | CT22: =CO22-CS22 -> 185.15086 | CU22: =+IF(IFERROR(CO22/CS22-1,"-")<300%,IFERROR(CO22/CS22-1,"-"),"n.a.") -> 0.52421052 | CW22: Adjusted EBITDA | CX22: =CX10+CX20 -> 11.18297 | CY22: =CY10+CY20 -> -231.81027 | CZ22: =CX22-CY22 -> 242.99324 | DA22: =+IF(IFERROR(CX22/CY22-1,"-")<300%,IFERROR(CX22/CY22-1,"-"),"n.a.") -> -1.0482419 | DB22: =DB10+DB20 -> -54.021526 | DC22: =CX22-DB22 -> 65.204496 | DD22: =+IF(IFERROR(CX22/DB22-1,"-")<300%,IFERROR(CX22/DB22-1,"-"),"n.a.") -> -1.2070095 | DF22: Adjusted EBITDA | DG22: =DG10+DG20 -> 6424.4999 | DH22: =DH10+DH20 -> 5424.9862 | DI22: =DG22-DH22 -> 999.51367 | DJ22: =+IF(IFERROR(DG22/DH22-1,"-")<300%,IFERROR(DG22/DH22-1,"-"),"n.a.") -> 0.18424262 | DK22: =DK10+DK20 -> 6420.4269 | DL22: =DG22-DK22 -> 4.0729318 | DM22: =+IF(IFERROR(DG22/DK22-1,"-")<300%,IFERROR(DG22/DK22-1,"-"),"n.a.") -> 0.00063437087
B23: % Adj. EBITDA Margin | C23: 0.27054602 | D23: 0.061940128 | G23: 0.25719999 | K23: % Adj. EBITDA Margin | L23: 0.61802742 | M23: 0.34487886 | P23: 0.46713377 | T23: % Adj. EBITDA Margin | U23: 0.5810771 | V23: 0.53708175 | X23: 0.081915562 | Y23: 0.48386708 | AC23: % Adj. EBITDA Margin | AD23: 0.49170157 | AE23: 0.55909735 | AG23: -0.1205439 | AH23: 0.503638 | AL23: % Adj. EBITDA Margin | AM23: 0.55475213 | AN23: 0.38067806 | AP23: 0.45727373 | AQ23: 0.4828998 | AU23: % Adj. EBITDA Margin | AV23: 0.46965944 | AW23: 0.7373347 | AY23: -0.36303087 | AZ23: 0.44716184 | BD23: % Adj. EBITDA Margin | BE23: 0.35778835 | BF23: 0.50424872 | BH23: -0.29045263 | BI23: 0.42650009 | BM23: % Adj. EBITDA Margin | BN23: 0.31051754 | BO23: 0.54870399 | BQ23: -0.43408916 | BR23: 0.29480119 | BV23: % Adj. EBITDA Margin | BW23: =BW22/BW8 -> 0.25311382 | BX23: =BX22/BX8 -> 0.4383137 | BZ23: =+IF(IFERROR(BW23/BX23-1,"-")<300%,IFERROR(BW23/BX23-1,"-"),"n.a.") -> -0.42252816 | CA23: =CA22/CA8 -> 0.36989858 | CE23: % Adj. EBITDA Margin | CF23: =CF22/CF8 -> 0.36097567 | CG23: =CG22/CG8 -> -0.11804519 | CI23: =+IF(IFERROR(CF23/CG23-1,"-")<300%,IFERROR(CF23/CG23-1,"-"),"n.a.") -> -4.0579448 | CJ23: =CJ22/CJ8 -> 0.25700913 | CN23: % Adj. EBITDA Margin | CO23: =CO22/CO8 -> 0.43935422 | CP23: =CP22/CP8 -> 0.33685599 | CR23: =+IF(IFERROR(CO23/CP23-1,"-")<300%,IFERROR(CO23/CP23-1,"-"),"n.a.") -> 0.30427908 | CS23: =CS22/CS8 -> 0.34283119 | CW23: % Adj. EBITDA Margin | CX23: =CX22/CX8 -> 0.0097889511 | CY23: =CY22/CY8 -> -0.93281555 | DA23: =+IF(IFERROR(CX23/CY23-1,"-")<300%,IFERROR(CX23/CY23-1,"-"),"n.a.") -> -1.010494 | DB23: =DB22/DB8 -> -0.081857662 | DF23: % Adj. EBITDA Margin | DG23: =DG22/DG8 -> 0.42322134 | DH23: =DH22/DH8 -> 0.42455512 | DJ23: =+IF(IFERROR(DG23/DH23-1,"-")<300%,IFERROR(DG23/DH23-1,"-"),"n.a.") -> -0.003141605 | DK23: =DK22/DK8 -> 0.40281241
B25: D&A | C25: -19.13287 | D25: 0 | E25: -19.13287 | F25: n.a. | G25: -20.833333 | H25: 1.700463 | I25: -0.081622225 | K25: D&A | L25: -19.13287 | M25: 0 | N25: -19.13287 | O25: n.a. | P25: -20.833333 | Q25: 1.700463 | R25: -0.081622225 | T25: D&A | U25: -18.90355 | V25: 0 | W25: -18.90355 | X25: n.a. | Y25: -20.833333 | Z25: 1.929783 | AA25: -0.092629585 | AC25: D&A | AD25: -18.90355 | AE25: 0 | AF25: -18.90355 | AG25: n.a. | AH25: -20.833333 | AI25: 1.929783 | AJ25: -0.092629585 | AL25: D&A | AM25: -19.18968 | AN25: 0 | AO25: -19.18968 | AP25: n.a. | AQ25: -20.833333 | AR25: 1.643653 | AS25: -0.078895345 | AU25: D&A | AV25: -19.06025 | AW25: 0 | AX25: -19.06025 | AY25: n.a. | AZ25: -20.833333 | BA25: 1.773083 | BB25: -0.085107985 | BD25: D&A | BE25: -19.22529 | BF25: 0 | BG25: -19.22529 | BH25: n.a. | BI25: -20.833333 | BJ25: 1.608043 | BK25: -0.077186065 | BM25: D&A | BN25: -19.22529 | BO25: 0 | BP25: -19.22529 | BQ25: n.a. | BR25: -20.833333 | BS25: 1.608043 | BT25: -0.077186065 | BV25: D&A | BW25: =GETPIVOTDATA("sep-26 ",TABLA!$B$3,"Nivel 4","8.- Amortización del inmovilizado")/1000 -> -19.34267 | BX25: =VLOOKUP(BV25,'P&L Mensualitzada 2025'!$A$5:$N$25,$BW$3+1,0) -> 0 | BY25: =BW25-BX25 -> -19.34267 | BZ25: =+IF(IFERROR(BW25/BX25-1,"-")<300%,IFERROR(BW25/BX25-1,"-"),"n.a.") -> n.a. | CA25: =VLOOKUP(BV25,'Budget26 sin EI'!$B:$O,$BW$3+1,0) -> -20.833333 | CB25: =BW25-CA25 -> 1.490663 | CC25: =+IF(IFERROR(BW25/CA25-1,"-")<300%,IFERROR(BW25/CA25-1,"-"),"n.a.") -> -0.071551825 | CE25: D&A | CF25: =GETPIVOTDATA("oct-26 ",TABLA!$B$3,"Nivel 4","8.- Amortización del inmovilizado")/1000 -> -19.22535 | CG25: =VLOOKUP(CE25,'P&L Mensualitzada 2025'!$A$5:$N$25,$CF$3+1,0) -> -194.71201 | CH25: =CF25-CG25 -> 175.48666 | CI25: =+IF(IFERROR(CF25/CG25-1,"-")<300%,IFERROR(CF25/CG25-1,"-"),"n.a.") -> -0.90126264 | CJ25: =VLOOKUP(CE25,'Budget26 sin EI'!$B:$O,$CF$3+1,0) -> -20.833333 | CK25: =CF25-CJ25 -> 1.607983 | CL25: =+IF(IFERROR(CF25/CJ25-1,"-")<300%,IFERROR(CF25/CJ25-1,"-"),"n.a.") -> -0.077183185 | CN25: D&A | CO25: =GETPIVOTDATA("nov-26 ",TABLA!$B$3,"Nivel 4","8.- Amortización del inmovilizado")/1000 -> -19.22535 | CP25: =VLOOKUP(CN25,'P&L Mensualitzada 2025'!$A$5:$N$25,$CO$3+1,0) -> -19.4712 | CQ25: =CO25-CP25 -> 0.24585 | CR25: =+IF(IFERROR(CO25/CP25-1,"-")<300%,IFERROR(CO25/CP25-1,"-"),"n.a.") -> -0.01262634 | CS25: =VLOOKUP(CN25,'Budget26 sin EI'!$B:$O,$CO$3+1,0) -> -20.833333 | CT25: =CO25-CS25 -> 1.607983 | CU25: =+IF(IFERROR(CO25/CS25-1,"-")<300%,IFERROR(CO25/CS25-1,"-"),"n.a.") -> -0.077183185 | CW25: D&A | CX25: =GETPIVOTDATA("dic-26 ",TABLA!$B$3,"Nivel 4","8.- Amortización del inmovilizado")/1000 -> -19.22535 | CY25: =VLOOKUP(CW25,'P&L Mensualitzada 2025'!$A$5:$N$25,$CX$3+1,0) -> -34.07237 | CZ25: =CX25-CY25 -> 14.84702 | DA25: =+IF(IFERROR(CX25/CY25-1,"-")<300%,IFERROR(CX25/CY25-1,"-"),"n.a.") -> -0.43574955 | DB25: =VLOOKUP(CW25,'Budget26 sin EI'!$B:$O,$CX$3+1,0) -> -20.833333 | DC25: =CX25-DB25 -> 1.607983 | DD25: =+IF(IFERROR(CX25/DB25-1,"-")<300%,IFERROR(CX25/DB25-1,"-"),"n.a.") -> -0.077183185 | DF25: D&A | DG25: =GETPIVOTDATA("Total 2026 ",TABLA!$B$3,"Nivel 4","8.- Amortización del inmovilizado")/1000 -> -229.67475 | DH25: =VLOOKUP(DF25,'P&L Mensualitzada 2025'!$A$5:$N$25,$CX$3+2,0) -> -248.25558 | DI25: =DG25-DH25 -> 18.58083 | DJ25: =+IF(IFERROR(DG25/DH25-1,"-")<300%,IFERROR(DG25/DH25-1,"-"),"n.a.") -> -0.074845568 | DK25: =VLOOKUP(DF25,'Budget26 sin EI'!$B:$O,$CX$3+2,0) -> -250 | DL25: =DG25-DK25 -> 20.325246 | DM25: =+IF(IFERROR(DG25/DK25-1,"-")<300%,IFERROR(DG25/DK25-1,"-"),"n.a.") -> -0.081300985
B26: Other Gains/Losses | C26: 3.06527 | D26: 0.92147 | E26: 2.1438 | F26: 2.3265 | G26: 0 | H26: 3.06527 | I26: n.a. | K26: Other Gains/Losses | L26: 2e-05 | M26: 0.03183 | N26: -0.03181 | O26: -0.99937166 | P26: 0 | Q26: 2e-05 | R26: n.a. | T26: Other Gains/Losses | U26: 1.99986 | V26: -1e-05 | W26: 1.99987 | X26: n.a. | Y26: 0 | Z26: 1.99986 | AA26: n.a. | AC26: Other Gains/Losses | AD26: 1.02426 | AE26: 2e-05 | AF26: 1.02424 | AG26: n.a. | AH26: 0 | AI26: 1.02426 | AJ26: n.a. | AL26: Other Gains/Losses | AM26: 0 | AN26: 0.00031 | AO26: -0.00031 | AP26: n.a. | AQ26: 0 | AR26: 0 | AS26: n.a. | AU26: Other Gains/Losses | AV26: 0 | AW26: 0.00228 | AX26: -0.00228 | AY26: n.a. | AZ26: 0 | BA26: 0 | BB26: n.a. | BD26: Other Gains/Losses | BE26: -0.08803 | BF26: 0.00357 | BG26: -0.0916 | BH26: n.a. | BI26: 0 | BJ26: -0.08803 | BK26: n.a. | BM26: Other Gains/Losses | BN26: -0.01 | BO26: 0.47301 | BP26: -0.48301 | BQ26: n.a. | BR26: 0 | BS26: -0.01 | BT26: n.a. | BV26: Other Gains/Losses | BW26: =GETPIVOTDATA("sep-26 ",TABLA!$B$3,"Nivel 4","13.- Otros resultados")+GETPIVOTDATA("ago-26 ",TABLA!$B$3,"Nivel 4","11.- Deterioro y resultado por enajenaciones del inmovilizado")/1000 -> 0.2 | BX26: =VLOOKUP(BV26,'P&L Mensualitzada 2025'!$A$5:$N$25,$BW$3+1,0) -> -0.04064 | BY26: =BW26-BX26 -> 0.24064 | BZ26: n.a. | CA26: =VLOOKUP(BV26,'Budget26 sin EI'!$B:$O,$BW$3+1,0) -> 0 | CB26: =BW26-CA26 -> 0.2 | CC26: =+IF(IFERROR(BW26/CA26-1,"-")<300%,IFERROR(BW26/CA26-1,"-"),"n.a.") -> n.a. | CE26: Other Gains/Losses | CF26: =GETPIVOTDATA("oct-26 ",TABLA!$B$3,"Nivel 4","13.- Otros resultados")+GETPIVOTDATA("ago-26 ",TABLA!$B$3,"Nivel 4","11.- Deterioro y resultado por enajenaciones del inmovilizado")/1000 -> 0 | CG26: =VLOOKUP(CE26,'P&L Mensualitzada 2025'!$A$5:$N$25,$CF$3+1,0) -> 0.81001 | CH26: =CF26-CG26 -> -0.81001 | CI26: n.a. | CJ26: =VLOOKUP(CE26,'Budget26 sin EI'!$B:$O,$CF$3+1,0) -> 0 | CK26: =CF26-CJ26 -> 0 | CL26: =+IF(IFERROR(CF26/CJ26-1,"-")<300%,IFERROR(CF26/CJ26-1,"-"),"n.a.") -> n.a. | CN26: Other Gains/Losses | CO26: =GETPIVOTDATA("nov-26 ",TABLA!$B$3,"Nivel 4","13.- Otros resultados")+GETPIVOTDATA("ago-26 ",TABLA!$B$3,"Nivel 4","11.- Deterioro y resultado por enajenaciones del inmovilizado")/1000 -> 0 | CP26: =VLOOKUP(CN26,'P&L Mensualitzada 2025'!$A$5:$N$25,$CO$3+1,0) -> 0.00443 | CQ26: =CO26-CP26 -> -0.00443 | CR26: n.a. | CS26: =VLOOKUP(CN26,'Budget26 sin EI'!$B:$O,$CO$3+1,0) -> 0 | CT26: =CO26-CS26 -> 0 | CU26: =+IF(IFERROR(CO26/CS26-1,"-")<300%,IFERROR(CO26/CS26-1,"-"),"n.a.") -> n.a. | CW26: Other Gains/Losses | CX26: =GETPIVOTDATA("dic-26 ",TABLA!$B$3,"Nivel 4","13.- Otros resultados")+GETPIVOTDATA("ago-26 ",TABLA!$B$3,"Nivel 4","11.- Deterioro y resultado por enajenaciones del inmovilizado")/1000 -> 0 | CY26: =VLOOKUP(CW26,'P&L Mensualitzada 2025'!$A$5:$N$25,$CX$3+1,0) -> 0.15045 | CZ26: =CX26-CY26 -> -0.15045 | DA26: n.a. | DB26: =VLOOKUP(CW26,'Budget26 sin EI'!$B:$O,$CX$3+1,0) -> 0 | DC26: =CX26-DB26 -> 0 | DD26: =+IF(IFERROR(CX26/DB26-1,"-")<300%,IFERROR(CX26/DB26-1,"-"),"n.a.") -> n.a. | DF26: Other Gains/Losses | DG26: =(GETPIVOTDATA("Total 2026 ",TABLA!$B$3,"Nivel 4","13.- Otros resultados")+GETPIVOTDATA("Total 2026 ",TABLA!$B$3,"Nivel 4","11.- Deterioro y resultado por enajenaciones del inmovilizado"))/1000 -> 5.99994 | DH26: =VLOOKUP(DF26,'P&L Mensualitzada 2025'!$A$5:$N$25,$CX$3+2,0) -> 2.35673 | DI26: =DG26-DH26 -> 3.64321 | DJ26: n.a. | DK26: =VLOOKUP(DF26,'Budget26 sin EI'!$B:$O,$CX$3+2,0) -> 0 | DL26: =DG26-DK26 -> 5.99994 | DM26: =+IF(IFERROR(DG26/DK26-1,"-")<300%,IFERROR(DG26/DK26-1,"-"),"n.a.") -> n.a.
B27: Adjusted EBIT | C27: 250.10021 | D27: 39.466015 | E27: 210.63419 | F27: 5.3371032 | G27: 186.39106 | H27: 63.709154 | I27: 0.3418037 | K27: Adjusted EBIT | L27: 889.63206 | M27: 366.4453 | N27: 523.18676 | O27: 1.4277349 | P27: 686.05591 | Q27: 203.57615 | R27: 0.29673406 | T27: Adjusted EBIT | U27: 874.34621 | V27: 964.14069 | W27: -89.79448 | X27: -0.093134208 | Y27: 1093.1338 | Z27: -218.78762 | AA27: -0.20014715 | AC27: Adjusted EBIT | AD27: 701.06033 | AE27: 857.85153 | AF27: -156.7912 | AG27: -0.18277195 | AH27: 931.67471 | AI27: -230.61438 | AJ27: -0.24752672 | AL27: Adjusted EBIT | AM27: 1049.224 | AN27: 564.89426 | AO27: 484.32978 | AP27: 0.85738131 | AQ27: 769.6298 | AR27: 279.59424 | AS27: 0.36328407 | AU27: Adjusted EBIT | AV27: 902.53455 | AW27: 1298.4059 | AX27: -395.87138 | AY27: -0.3048903 | AZ27: 940.67935 | BA27: -38.144797 | BB27: -0.040550265 | BD27: Adjusted EBIT | BE27: 442.46773 | BF27: 662.87102 | BG27: -220.40329 | BH27: -0.33249801 | BI27: 554.09775 | BJ27: -111.63003 | BK27: -0.2014627 | BM27: Adjusted EBIT | BN27: 225.48518 | BO27: 365.08513 | BP27: -139.59995 | BQ27: -0.38237644 | BR27: 207.95468 | BS27: 17.530494 | BT27: 0.084299587 | BV27: Adjusted EBIT | BW27: =BW22+BW25+BW26 -> 138.98383 | BX27: =BX22+BX25+BX26 -> 369.07025 | BY27: =BW27-BX27 -> -230.08642 | BZ27: =+IF(IFERROR(BW27/BX27-1,"-")<300%,IFERROR(BW27/BX27-1,"-"),"n.a.") -> -0.62342175 | CA27: =CA22+CA25+CA26 -> 358.8929 | CB27: =BW27-CA27 -> -219.90907 | CC27: =+IF(IFERROR(BW27/CA27-1,"-")<300%,IFERROR(BW27/CA27-1,"-"),"n.a.") -> -0.61274288 | CE27: Adjusted EBIT | CF27: =CF22+CF25+CF26 -> 310.00432 | CG27: =CG22+CG25+CG26 -> -276.48446 | CH27: =CF27-CG27 -> 586.48878 | CI27: =+IF(IFERROR(CF27/CG27-1,"-")<300%,IFERROR(CF27/CG27-1,"-"),"n.a.") -> -2.121236 | CJ27: =CJ22+CJ25+CJ26 -> 184.40572 | CK27: =CF27-CJ27 -> 125.5986 | CL27: =+IF(IFERROR(CF27/CJ27-1,"-")<300%,IFERROR(CF27/CJ27-1,"-"),"n.a.") -> 0.68109925 | CN27: Adjusted EBIT | CO27: =CO22+CO25+CO26 -> 519.12494 | CP27: =CP22+CP25+CP26 -> 233.07388 | CQ27: =CO27-CP27 -> 286.05106 | CR27: =+IF(IFERROR(CO27/CP27-1,"-")<300%,IFERROR(CO27/CP27-1,"-"),"n.a.") -> 1.2272978 | CS27: =CS22+CS25+CS26 -> 332.3661 | CT27: =CO27-CS27 -> 186.75884 | CU27: =+IF(IFERROR(CO27/CS27-1,"-")<300%,IFERROR(CO27/CS27-1,"-"),"n.a.") -> 0.56190701 | CW27: Adjusted EBIT | CX27: =CX22+CX25+CX26 -> -8.04238 | CY27: =CY22+CY25+CY26 -> -265.73219 | CZ27: =CX27-CY27 -> 257.68981 | DA27: =+IF(IFERROR(CX27/CY27-1,"-")<300%,IFERROR(CX27/CY27-1,"-"),"n.a.") -> -0.96973502 | DB27: =DB22+DB25+DB26 -> -74.854859 | DC27: =CX27-DB27 -> 66.812479 | DD27: =+IF(IFERROR(CX27/DB27-1,"-")<300%,IFERROR(CX27/DB27-1,"-"),"n.a.") -> -0.89256035 | DF27: Adjusted EBIT | DG27: =DG22+DG25+DG26 -> 6200.8251 | DH27: =DH22+DH25+DH26 -> 5179.0874 | DI27: =DG27-DH27 -> 1021.7377 | DJ27: =+IF(IFERROR(DG27/DH27-1,"-")<300%,IFERROR(DG27/DH27-1,"-"),"n.a.") -> 0.19728142 | DK27: =DK22+DK25+DK26 -> 6170.4269 | DL27: =DG27-DK27 -> 30.398118 | DM27: =+IF(IFERROR(DG27/DK27-1,"-")<300%,IFERROR(DG27/DK27-1,"-"),"n.a.") -> 0.0049264205
B28: % EBIT Margin | C28: 0.25421412 | D28: 0.063420907 | G28: 0.23134235 | K28: % EBIT Margin | L28: 0.60501566 | M28: 0.34490882 | P28: 0.45336648 | T28: % EBIT Margin | U28: 0.57005623 | V28: 0.53708174 | Y28: 0.47481783 | AC28: % EBIT Margin | AD28: 0.47947346 | AE28: 0.55909736 | AH28: 0.49262239 | AL28: % EBIT Margin | AM28: 0.54478828 | AN28: 0.38067827 | AQ28: 0.47017256 | AU28: % EBIT Margin | AV28: 0.45994604 | AW28: 0.737336 | AZ28: 0.43747307 | BD28: % EBIT Margin | BE28: 0.34282437 | BF28: 0.50425143 | BI28: 0.41104533 | BM28: % EBIT Margin | BN28: 0.28611053 | BO28: 0.54941582 | BR28: 0.26795673 | BV28: % EBIT Margin | BW28: =BW27/BW8 -> 0.22247206 | BX28: =BX27/BX8 -> 0.43826544 | CA28: =CA27/CA8 -> 0.34960443 | CE28: % EBIT Margin | CF28: =CF27/CF8 -> 0.33989652 | CG28: =CG27/CG8 -> -0.39521298 | CJ28: =CJ27/CJ8 -> 0.23092074 | CN28: % EBIT Margin | CO28: =CO27/CO8 -> 0.42366417 | CP28: =CP27/CP8 -> 0.31088988 | CS28: =CS27/CS8 -> 0.32260942 | CW28: % EBIT Margin | CX28: =CX27/CX8 -> -0.007039853 | CY28: =CY27/CY8 -> -1.069319 | DB28: =DB27/DB8 -> -0.11342597 | DF28: % EBIT Margin | DG28: =DG27/DG8 -> 0.4084865 | DH28: =DH27/DH8 -> 0.40531127 | DK28: =DK27/DK8 -> 0.38712761
BM31: P&L YTD Actual
BP32: Variación | BS32: Variación
BM33: € '000 | BN33: 2026A | BO33: 2025A | BP33: EUR | BQ33: % | BR33: 2026B | BS33: EUR | BT33: %
BM34: Ventas | BN34: 11417.132 | BO34: 10238.145 | BP34: 1178.9873 | BQ34: 0.11515634 | BR34: 12423.677 | BS34: -1006.5446 | BT34: -0.081018253 | BW34: -0.036197428
BM35: COGS | BN35: -3916.0719 | BO35: -3267.7209 | BP35: -648.35101 | BQ35: 0.19841077 | BR35: -4266.7179 | BS35: 350.64599 | BT35: -0.082181668
BM36: Gross Profit | BN36: 7501.0602 | BO36: 6970.4239 | BP36: 530.63632 | BQ36: 0.076126837 | BR36: 8156.9587 | BS36: -655.89858 | BT36: -0.080409697 | CW36: =CX8*BW34 -> -41.352208
BM37: % Gross Margin | BN37: 0.65700038 | BO37: 0.6808288 | BR37: 0.6565656 | CN37: =BW34*CO8 -> -44.353496
BW38: =BW34*625 -> -22.623392 | CE38: =BW34*CF8 -> -33.014045
BM39: Gastos de Personal | BN39: -1116.9714 | BO39: -1103.0429 | BP39: -13.92855 | BQ39: 0.012627388 | BR39: -1484.9064 | BS39: 367.93496 | BT39: -0.24778327
BM40: % of Revenue | BN40: -0.097832925 | BO40: -0.10773855 | BR40: -0.1195223
BM42: Otros Ingresos Operativos | BN42: 71.32534 | BO42: 0.79288 | BP42: 70.53246 | BQ42: n.a. | BR42: 0 | BS42: 71.32534 | BT42: n.a.
BM43: Otros Gastos Operativos | BN43: -973.78181 | BO43: -750.44646 | BP43: -223.33535 | BQ43: 0.2976033 | BR43: -1135.7686 | BS43: 161.9868 | BT43: -0.14262306
BM44: Operating Expenses | BN44: -902.45647 | BO44: -749.65358 | BP44: -152.80289 | BQ44: 0.20383133 | BR44: -1135.7686 | BS44: 233.31214 | BT44: -0.20542225
BM45: % of Revenue | BN45: -0.079044059 | BO45: -0.073221623 | BR45: -0.091419685
BM46: Gastos Fijos | BN46: -2019.4279 | BO46: -1852.6965 | BP46: -166.73144 | BQ46: 0.08999393 | BR46: -2620.675 | BS46: 601.2471 | BT46: -0.22942452
BM47: % of Revenue | BN47: -0.17687698 | BO47: -0.18096017 | BR47: -0.21094198
BM48: Adjusted EBITDA | BN48: 5481.6323 | BO48: 5117.7274 | BP48: 363.90488 | BQ48: 0.071106735 | BR48: 5536.2838 | BS48: -54.651478 | BT48: -0.0098715096
...

Sheet TABLA
B1: Periodo | C1: 2026
B3: Detalle sin Ajustar | C3: ene-26 | D3: feb-26 | E3: mar-26 | F3: abr-26 | G3: may-26 | H3: jun-26 | I3: jul-26 | J3: ago-26 | K3: sep-26 | L3: oct-26 | M3: nov-26 | N3: dic-26 | O3: Total 2026
B4: 1.- Importe neto de la cifra de negocios | C4: 983817.13 | D4: 1470428.1 | E4: 1533789.4 | F4: 1462146.3 | G4: 1925929.9 | H4: 1962261.8 | I4: 1290654.2 | J4: 788105.15 | K4: 624724.88 | L4: 912055.01 | M4: 1225321.8 | N4: 1142407.4 | O4: 15180000
B5: 2.- Variación de existencias | C5: -84878.08 | D5: 50005.57 | E5: 83552.77 | F5: 8645.2 | G5: -30291.1 | H5: -90104.87 | I5: -6292.63 | J5: 6734.64 | K5: -109366.49 | L5: 0 | M5: 0 | N5: 0 | O5: -62628.5
B6: 4.- Aprovisionamientos | C6: -417787.47 | D6: -406242.73 | E6: -469252.7 | F6: -514848.29 | G6: -593981.24 | H6: -653453.72 | I6: -519022.4 | J6: -278854.87 | K6: -92945.56 | L6: -302101.36 | M6: -404423.28 | N6: -449145.33 | O6: -5170904.3
B7: 6.- Gastos de personal | C7: -111532.01 | D7: -142927.2 | E7: -146233.31 | F7: -130047.67 | G7: -134992.52 | H7: -145072.28 | I7: -153533.65 | J7: -152632.79 | K7: -165803.99 | L7: -152632.79 | M7: -152632.79 | N7: -431632.79 | O7: -2006502.6
B8: 5.- Otros ingresos de explotación | C8: 0 | D8: 0 | E8: 0 | F8: 750.75 | G8: 25140.75 | H8: 22977.6 | I8: 11027.24 | J8: 11429 | K8: 9613 | L8: 21379 | M8: 32454 | N8: 27150 | O8: 168561.34
B9: 7.- Otros gastos de explotación | C9: -103451.76 | D9: -62498.88 | E9: -110606.27 | F9: -107706.65 | G9: -123392.08 | H9: -175013.76 | I9: -161051.74 | J9: -130060.66 | K9: -108095.34 | L9: -149470.19 | M9: -162369.42 | N9: -277596.29 | O9: -1684026
B10: 11.- Deterioro y resultado por enajenaciones del inmovilizado | C10: 0 | D10: 0 | E10: 2000 | F10: 0 | G10: 0 | H10: 0 | I10: 0 | J10: 0 | K10: 0 | L10: 0 | M10: 0 | N10: 0 | O10: 2000
B11: 8.- Amortización del inmovilizado | C11: -19132.87 | D11: -19132.87 | E11: -18903.55 | F11: -18903.55 | G11: -19189.68 | H11: -19060.25 | I11: -19225.29 | J11: -19225.29 | K11: -19342.67 | L11: -19225.35 | M11: -19225.35 | N11: -19225.35 | O11: -229674.75
B12: 13.- Otros resultados | C12: 3065.27 | D12: 0.02 | E12: -0.14 | F12: 1024.26 | G12: -1.43 | H12: 0 | I12: -88.03 | J12: -0.01 | K12: 0.2 | L12: 0 | M12: 0 | N12: 0 | O12: 3999.94
B13: 15.- Gastos financieros | C13: -52.82 | D13: 0 | E13: -79.37 | F13: -24483.47 | G13: -38651.64 | H13: -78497.33 | I13: -32604.18 | J13: -19768.43 | K13: -8347.1 | L13: -24579.01 | M13: -33042.67 | N13: -35674.22 | O13: -300408.35
B14: 17.- Diferencias de cambio | C14: 0 | D14: 78.79 | E14: 15.51 | F14: 0 | G14: 2879.75 | H14: 1665.7 | I14: 604.76 | J14: 0 | K14: 0 | L14: 0 | M14: 0 | N14: 0 | O14: 5244.51
B15: 14.- Ingresos financieros | C15: 0 | D15: 0 | E15: 0 | F15: 0 | G15: 0 | H15: 4495.93 | I15: 0 | J15: 0 | K15: 0 | L15: 0 | M15: 0 | N15: 0 | O15: 4495.93
B16: Total general | C16: 250047.39 | D16: 889710.85 | E16: 874282.35 | F16: 676576.86 | G16: 1013450.7 | H16: 830198.85 | I16: 410468.31 | J16: 205726.74 | K16: 130436.93 | L16: 285425.31 | M16: 486082.27 | N16: -43716.6 | O16: 5910157.2
B17: EBITDA | C17: =+SUM(C4:C9) -> 266167.81 | D17: =+SUM(D4:D9) -> 908764.91 | E17: =+SUM(E4:E9) -> 891249.9 | F17: =+SUM(F4:F9) -> 718939.62 | G17: =+SUM(G4:G9) -> 1068413.7 | H17: =+SUM(H4:H9) -> 921594.8 | I17: =+SUM(I4:I9) -> 461781.05 | J17: =+SUM(J4:J9) -> 244720.47 | ... O17: =+SUM(O4:O9) -> 6424499.9
B18: EBITDA % | C18: =C17/C4 -> 0.27054602 | D18: =D17/D4 -> 0.61802742 | E18: =E17/E4 -> 0.5810771 | F18: =F17/F4 -> 0.49170157 | G18: =G17/G4 -> 0.55475213 | H18: =H17/H4 -> 0.46965944 | I18: =I17/I4 -> 0.35778835 | J18: =J17/J4 -> 0.31051754 | ... O18: =O17/O4 -> 0.42322134
N19: Check | O19: =SUM(C16:N16)-O16 -> 98532.82

Sheet PL Mensual 2026
K2: =SUBTOTAL(9,K4:K216) -> 250047.39 | L2: =SUBTOTAL(9,L4:L216) -> 889710.85 | M2: =SUBTOTAL(9,M4:M216) -> 874282.35 | N2: =SUBTOTAL(9,N4:N216) -> 676576.86 | O2: =SUBTOTAL(9,O4:O2028) -> 1013450.7 | P2: =SUBTOTAL(9,P4:P2028) -> 830198.85 | Q2: =SUBTOTAL(9,Q4:Q2097) -> 410468.31 | R2: =SUBTOTAL(9,R4:R2016) -> 205726.74 | S2: =SUBTOTAL(9,S4:S216) -> 130436.93 | T2: =SUBTOTAL(9,T4:T216) -> 285425.31 | U2: =SUBTOTAL(9,U4:U216) -> 486082.27 | V2: =SUBTOTAL(9,V4:V216) -> -43716.6 | W2: =SUBTOTAL(9,W4:W2037) -> 6008690
B3: Periodo | C3: Empresa | D3: Nivel 1 | E3: Nivel 2 | F3: Nivel 3 | G3: Nivel 4 | H3: Nivel 5 | I3: Cuenta | J3: Grupo Ext Item | K3: 46023 | L3: 46054 | M3: 46082 | N3: 46113 | O3: 46143 | P3: 46174 | Q3: 46204 | R3: 46235 | S3: 46266 | T3: 46296 | U3: 46327 | V3: 46357 | W3: Total 2026
B4: 2026 | C4: Codiagro | D4: RESULTADO DEL EJERCICIO | E4: RESULTADO ANTES DE IMPUESTOS | F4: RESULTADO DE LA EXPLOTACION | G4: 1.- Importe neto de la cifra de negocios | H4: (700) Ventas | I4: 700000000 - Ventas de mercaderías | J4: - | K4: 993280.49 | L4: 1607538 | M4: 1536177.9 | N4: 1217250.4 | O4: 2029267 | P4: 2009948.7 | Q4: 1288443.6 | R4: 802410.56 | S4: =IFERROR(VLOOKUP(I4,'[1]PL Mensual 2026'!$I:$S,11,0),0) -> 632880.07 | T4: 910333.55 | U4: 1223802.8 | V4: 1321267.5 | W4: =SUM(K4:V4) -> 15572601 | X4: Presupuesto de Ventas 2026 ajustado para cuadrar la Cifra Neta de Negocios en 15.180.000,00 € exactos tras considerar la provisión anual de rappels (333k€) y gestión de envases. | AA4: =VLOOKUP(I4,'[2]BBDD P&L'!$J:$AK,28,0) -> 15572601 | AB4: =W4-AA4 -> 0
B5: 2026 | C5: Codiagro | D5: RESULTADO DEL EJERCICIO | E5: RESULTADO ANTES DE IMPUESTOS | F5: RESULTADO DE LA EXPLOTACION | G5: 1.- Importe neto de la cifra de negocios | H5: (700) Ventas | I5: 700000001 - VENTA MERCADERIAS POR ANTICIPO | J5: - | K5: 0 | L5: 0 | M5: 0 | N5: 106250.17 | O5: -106250.17 | P5: 0 | Q5: 0 | R5: 0 | S5: =IFERROR(VLOOKUP(I5,'[1]PL Mensual 2026'!$I:$S,11,0),0) -> 0 | T5: 0 | U5: 0 | V5: 0 | W5: =SUM(K5:V5) -> 0 | X5: Cuenta sin saldo en el ejercicio. Sin previsión de movimientos. | AA5: =VLOOKUP(I5,'[2]BBDD P&L'!$J:$AK,28,0) -> 0 | AB5: =W5-AA5 -> 0
