Workbook
Name Datos: #REF!

Sheet 2027
BV2: Seleccionar las formulas de P&L YTD Mes anterior y de P&L YTD Actual y cambiar la referencia al mes anterior
C4: RELLENAR | L4: RELLENAR | U4: RELLENAR | AD4: RELLENAR | AM4: RELLENAR | AV4: RELLENAR | BE4: RELLENAR | BN4: RELLENAR | BW4: RELLENAR | CF4: RELLENAR | CO4: RELLENAR | CX4: RELLENAR | DG4: RELLENAR
B5: MES | C5: 1 | K5: MES | L5: 2 | T5: MES | U5: 3 | AC5: MES | AD5: 4 | AL5: MES | AM5: 5 | AU5: MES | AV5: 6 | BD5: MES | BE5: 7 | BM5: MES | BN5: 8 | BV5: MES | BW5: 9 | CE5: MES | CF5: 10 | CN5: MES | CO5: 11 | CW5: MES | CX5: 12 | DF5: MES | DG5: 12 | DH5: YTD
B7: P&L Mensual | K7: P&L Mensual | T7: P&L Mensual | AC7: P&L Mensual | AL7: P&L Mensual | AU7: P&L Mensual | BD7: P&L Mensual | BM7: P&L Mensual | BV7: P&L Mensual | CE7: P&L Mensual | CN7: P&L Mensual | CW7: P&L Mensual | DF7: P&L YTD
E8: Variación | H8: Variación | N8: Variación | Q8: Variación | W8: Variación | Z8: Variación | AF8: Variación | AI8: Variación | AO8: Variación | AR8: Variación | AX8: Variación | BA8: Variación | BG8: Variación | BJ8: Variación | BP8: Variación | BS8: Variación | BY8: Variación | CB8: Variación | CH8: Variación | CK8: Variación | CQ8: Variación | CT8: Variación | CZ8: Variación | DC8: Variación | DI8: Variación | DL8: Variación
B9: € '000 | C9: 2027A | D9: 2026A | E9: EUR | F9: % | G9: 2027B | H9: EUR | I9: % | K9: € '000 | L9: 2027A | M9: 2026A | N9: EUR | O9: % | P9: 2027B | Q9: EUR | R9: % | T9: € '000 | U9: 2027A | V9: 2026A | W9: EUR | X9: % | Y9: 2027B | Z9: EUR | AA9: % | AC9: € '000 | AD9: 2027A | AE9: 2026A | AF9: EUR | AG9: % | AH9: 2027B | AI9: EUR | AJ9: % | AL9: € '000 | AM9: 2027A | AN9: 2026A | AO9: EUR | AP9: % | AQ9: 2027B | AR9: EUR | AS9: % | AU9: € '000 | AV9: 2027A | AW9: 2026A | AX9: EUR | AY9: % | AZ9: 2027B | BA9: EUR | BB9: % | BD9: € '000 | BE9: 2027A | BF9: 2026A | BG9: EUR | BH9: % | BI9: 2027B | BJ9: EUR | BK9: % | BM9: € '000 | BN9: 2027A | BO9: 2026A | BP9: EUR | BQ9: % | BR9: 2027B | BS9: EUR | BT9: % | BV9: € '000 | BW9: 2027A | BX9: 2026A | BY9: EUR | BZ9: % | CA9: 2027B | CB9: EUR | CC9: % | CE9: € '000 | CF9: 2027A | CG9: 2026A | CH9: EUR | CI9: % | CJ9: 2027B | CK9: EUR | CL9: % | CN9: € '000 | CO9: 2027A | CP9: 2026A | CQ9: EUR | CR9: % | CS9: 2027B | CT9: EUR | CU9: % | CW9: € '000 | CX9: 2027A | CY9: 2026A | CZ9: EUR | DA9: % | DB9: 2027B | DC9: EUR | DD9: % | DF9: € '000 | DG9: 2027A | DH9: 2026A | DI9: EUR | DJ9: % | DK9: 2027B | DL9: EUR | DM9: %
B10: Ventas | C10: =(GETPIVOTDATA("ene-27 ",TABLA!$B$3,"Nivel 4","1.- Importe neto de la cifra de negocios"))/1000 -> 1143.7325 | D10: 983.81713 | E10: =C10-D10 -> 159.91537 | F10: =+IF(IFERROR(C10/D10-1,"-")<300%,IFERROR(C10/D10-1,"-"),"n.a.") -> 0.16254583 | G10: =C10 -> 1143.7325 | H10: =C10-G10 -> 0 | I10: =+IF(IFERROR(C10/G10-1,"-")<300%,IFERROR(C10/G10-1,"-"),"n.a.") -> 0 | K10: Ventas | L10: =(GETPIVOTDATA("feb-27 ",TABLA!$B$3,"Nivel 4","1.- Importe neto de la cifra de negocios"))/1000 -> 1852.6413 | M10: 1470.4281 | N10: =L10-M10 -> 382.21312 | O10: =+IF(IFERROR(L10/M10-1,"-")<300%,IFERROR(L10/M10-1,"-"),"n.a.") -> 0.25993322 | P10: =L10 -> 1852.6413 | Q10: =L10-P10 -> 0 | R10: =+IF(IFERROR(L10/P10-1,"-")<300%,IFERROR(L10/P10-1,"-"),"n.a.") -> 0 | T10: Ventas | U10: =(GETPIVOTDATA("mar-27 ",TABLA!$B$3,"Nivel 4","1.- Importe neto de la cifra de negocios"))/1000 -> 1777.1341 | V10: 1533.7894 | W10: =U10-V10 -> 243.34469 | X10: =+IF(IFERROR(U10/V10-1,"-")<300%,IFERROR(U10/V10-1,"-"),"n.a.") -> 0.15865587 | Y10: =U10 -> 1777.1341 | Z10: =U10-Y10 -> 0 | AA10: =+IF(IFERROR(U10/Y10-1,"-")<300%,IFERROR(U10/Y10-1,"-"),"n.a.") -> 0 | AC10: Ventas | AD10: =(GETPIVOTDATA("abr-27 ",TABLA!$B$3,"Nivel 4","1.- Importe neto de la cifra de negocios"))/1000 -> 1430.7518 | AE10: 1462.1463 | AF10: =AD10-AE10 -> -31.39444 | AG10: =+IF(IFERROR(AD10/AE10-1,"-")<300%,IFERROR(AD10/AE10-1,"-"),"n.a.") -> -0.021471477 | AH10: =AD10 -> 1430.7518 | AI10: =AD10-AH10 -> 0 | AJ10: =+IF(IFERROR(AD10/AH10-1,"-")<300%,IFERROR(AD10/AH10-1,"-"),"n.a.") -> 0 | AL10: Ventas | AM10: =(GETPIVOTDATA("may-27 ",TABLA!$B$3,"Nivel 4","1.- Importe neto de la cifra de negocios"))/1000 -> 2349.0314 | AN10: 1925.9299 | AO10: =AM10-AN10 -> 423.10151 | AP10: =+IF(IFERROR(AM10/AN10-1,"-")<300%,IFERROR(AM10/AN10-1,"-"),"n.a.") -> 0.21968687 | AQ10: =AM10 -> 2349.0314 | AR10: =AM10-AQ10 -> 0 | AS10: =+IF(IFERROR(AM10/AQ10-1,"-")<300%,IFERROR(AM10/AQ10-1,"-"),"n.a.") -> 0 | AU10: Ventas | AV10: =GETPIVOTDATA("jun-27 ",TABLA!$B$3,"Nivel 4","1.- Importe neto de la cifra de negocios")/1000 -> 2329.4837 | AW10: 1962.2618 | AX10: =AV10-AW10 -> 367.22192 | AY10: =+IF(IFERROR(AV10/AW10-1,"-")<300%,IFERROR(AV10/AW10-1,"-"),"n.a.") -> 0.18714216 | AZ10: =AV10 -> 2329.4837 | BA10: =AV10-AZ10 -> 0 | BB10: =+IF(IFERROR(AV10/AZ10-1,"-")<300%,IFERROR(AV10/AZ10-1,"-"),"n.a.") -> 0 | BD10: Ventas | BE10: =(GETPIVOTDATA("jul-27 ",TABLA!$B$3,"Nivel 4","1.- Importe neto de la cifra de negocios"))/1000 -> 1477.9823 | BF10: 1290.6542 | BG10: =BE10-BF10 -> 187.32808 | BH10: =+IF(IFERROR(BE10/BF10-1,"-")<300%,IFERROR(BE10/BF10-1,"-"),"n.a.") -> 0.14514196 | BI10: =BE10 -> 1477.9823 | BJ10: =BE10-BI10 -> 0 | BK10: =+IF(IFERROR(BE10/BI10-1,"-")<300%,IFERROR(BE10/BI10-1,"-"),"n.a.") -> 0 | BM10: Ventas | BN10: =(GETPIVOTDATA("ago-27 ",TABLA!$B$3,"Nivel 4","1.- Importe neto de la cifra de negocios"))/1000 -> 943.22127 | BO10: 788.10515 | BP10: =BN10-BO10 -> 155.11612 | BQ10: =+IF(IFERROR(BN10/BO10-1,"-")<300%,IFERROR(BN10/BO10-1,"-"),"n.a.") -> 0.1968216 | BR10: =BN10 -> 943.22127 | BS10: =BN10-BR10 -> 0 | BT10: =+IF(IFERROR(BN10/BR10-1,"-")<300%,IFERROR(BN10/BR10-1,"-"),"n.a.") -> 0 | BV10: Ventas | BW10: =(GETPIVOTDATA("sep-27 ",TABLA!$B$3,"Nivel 4","1.- Importe neto de la cifra de negocios"))/1000 -> 547.89618 | BX10: 483.08374 | BY10: =BW10-BX10 -> 64.81244 | BZ10: =+IF(IFERROR(BW10/BX10-1,"-")<300%,IFERROR(BW10/BX10-1,"-"),"n.a.") -> 0.13416399 | CA10: =BW10 -> 547.89618 | CB10: =BW10-CA10 -> 0 | CC10: =+IF(IFERROR(BW10/CA10-1,"-")<300%,IFERROR(BW10/CA10-1,"-"),"n.a.") -> 0 | CE10: Ventas | CF10: =(GETPIVOTDATA("oct-27 ",TABLA!$B$3,"Nivel 4","1.- Importe neto de la cifra de negocios"))/1000 -> 916.29691 | CG10: 912.05501 | CH10: =CF10-CG10 -> 4.2419 | CI10: =+IF(IFERROR(CF10/CG10-1,"-")<300%,IFERROR(CF10/CG10-1,"-"),"n.a.") -> 0.0046509256 | CJ10: =CF10 -> 916.29691 | CK10: =CF10-CJ10 -> 0 | CL10: =+IF(IFERROR(CF10/CJ10-1,"-")<300%,IFERROR(CF10/CJ10-1,"-"),"n.a.") -> 0 | CN10: Ventas | CO10: =(GETPIVOTDATA("nov-27 ",TABLA!$B$3,"Nivel 4","1.- Importe neto de la cifra de negocios"))/1000 -> 1416.3668 | CP10: 1225.3218 | CQ10: =CO10-CP10 -> 191.04503 | CR10: =+IF(IFERROR(CO10/CP10-1,"-")<300%,IFERROR(CO10/CP10-1,"-"),"n.a.") -> 0.15591417 | CS10: =CO10 -> 1416.3668 | CT10: =CO10-CS10 -> 0 | CU10: =+IF(IFERROR(CO10/CS10-1,"-")<300%,IFERROR(CO10/CS10-1,"-"),"n.a.") -> 0 | CW10: Ventas | CX10: =(GETPIVOTDATA("dic-27 ",TABLA!$B$3,"Nivel 4","1.- Importe neto de la cifra de negocios"))/1000 -> 1553.6219 | CY10: 1142.4074 | CZ10: =CX10-CY10 -> 411.21455 | DA10: =+IF(IFERROR(CX10/CY10-1,"-")<300%,IFERROR(CX10/CY10-1,"-"),"n.a.") -> 0.35995439 | DB10: =CX10 -> 1553.6219 | DC10: =CX10-DB10 -> 0 | DD10: =+IF(IFERROR(CX10/DB10-1,"-")<300%,IFERROR(CX10/DB10-1,"-"),"n.a.") -> 0 | DF10: Ventas | DG10: =(GETPIVOTDATA("Total 2027 ",TABLA!$B$3,"Nivel 4","1.- Importe neto de la cifra de negocios"))/1000 -> 17738.16 | DH10: =CY10+CP10+CG10+BX10+BO10+BF10+AW10+AN10+AE10+V10+M10+D10 -> 15180 | DI10: =DG10-DH10 -> 2558.1603 | DJ10: =+IF(IFERROR(DG10/DH10-1,"-")<300%,IFERROR(DG10/DH10-1,"-"),"n.a.") -> 0.16852176 | DK10: =DG10 -> 17738.16 | DL10: =DG10-DK10 -> 0 | DM10: =+IF(IFERROR(DG10/DK10-1,"-")<300%,IFERROR(DG10/DK10-1,"-"),"n.a.") -> 0
B11: COGS | C11: =(GETPIVOTDATA("ene-27 ",TABLA!$B$3,"Nivel 4","2.- Variación de existencias")+GETPIVOTDATA("ene-27 ",TABLA!$B$3,"Nivel 4","4.- Aprovisionamientos"))/1000 -> -329.98443 | D11: -502.66555 | E11: =C11-D11 -> 172.68112 | F11: =+IF(IFERROR(C11/D11-1,"-")<300%,IFERROR(C11/D11-1,"-"),"n.a.") -> -0.34353084 | G11: =C11 -> -329.98443 | H11: =C11-G11 -> 0 | I11: =+IF(IFERROR(C11/G11-1,"-")<300%,IFERROR(C11/G11-1,"-"),"n.a.") -> 0 | K11: COGS | L11: =(GETPIVOTDATA("feb-27 ",TABLA!$B$3,"Nivel 4","2.- Variación de existencias")+GETPIVOTDATA("feb-27 ",TABLA!$B$3,"Nivel 4","4.- Aprovisionamientos"))/1000 -> -632.15977 | M11: -356.23716 | N11: =L11-M11 -> -275.92261 | O11: =+IF(IFERROR(L11/M11-1,"-")<300%,IFERROR(L11/M11-1,"-"),"n.a.") -> 0.77454752 | P11: =L11 -> -632.15977 | Q11: =L11-P11 -> 0 | R11: =+IF(IFERROR(L11/P11-1,"-")<300%,IFERROR(L11/P11-1,"-"),"n.a.") -> 0 | T11: COGS | U11: =(GETPIVOTDATA("mar-27 ",TABLA!$B$3,"Nivel 4","2.- Variación de existencias")+GETPIVOTDATA("mar-27 ",TABLA!$B$3,"Nivel 4","4.- Aprovisionamientos"))/1000 -> -664.98037 | V11: -385.69993 | W11: =U11-V11 -> -279.28044 | X11: =+IF(IFERROR(U11/V11-1,"-")<300%,IFERROR(U11/V11-1,"-"),"n.a.") -> 0.72408735 | Y11: =U11 -> -664.98037 | Z11: =U11-Y11 -> 0 | AA11: =+IF(IFERROR(U11/Y11-1,"-")<300%,IFERROR(U11/Y11-1,"-"),"n.a.") -> 0 | AC11: COGS | AD11: =(GETPIVOTDATA("abr-27 ",TABLA!$B$3,"Nivel 4","2.- Variación de existencias")+GETPIVOTDATA("abr-27 ",TABLA!$B$3,"Nivel 4","4.- Aprovisionamientos"))/1000 -> -517.76813 | AE11: -506.20309 | AF11: =AD11-AE11 -> -11.56504 | AG11: =+IF(IFERROR(AD11/AE11-1,"-")<300%,IFERROR(AD11/AE11-1,"-"),"n.a.") -> 0.02284664 | AH11: =AD11 -> -517.76813 | AI11: =AD11-AH11 -> 0 | AJ11: =+IF(IFERROR(AD11/AH11-1,"-")<300%,IFERROR(AD11/AH11-1,"-"),"n.a.") -> 0 | AL11: COGS | AM11: =(GETPIVOTDATA("may-27 ",TABLA!$B$3,"Nivel 4","2.- Variación de existencias")+GETPIVOTDATA("may-27 ",TABLA!$B$3,"Nivel 4","4.- Aprovisionamientos"))/1000 -> -838.0582 | AN11: -624.27234 | AO11: =AM11-AN11 -> -213.78586 | AP11: =+IF(IFERROR(AM11/AN11-1,"-")<300%,IFERROR(AM11/AN11-1,"-"),"n.a.") -> 0.34245608 | AQ11: =AM11 -> -838.0582 | AR11: =AM11-AQ11 -> 0 | AS11: =+IF(IFERROR(AM11/AQ11-1,"-")<300%,IFERROR(AM11/AQ11-1,"-"),"n.a.") -> 0 | AU11: COGS | AV11: =(GETPIVOTDATA("jun-27 ",TABLA!$B$3,"Nivel 4","2.- Variación de existencias")+GETPIVOTDATA("jun-27 ",TABLA!$B$3,"Nivel 4","4.- Aprovisionamientos"))/1000 -> -864.73897 | AW11: -743.55859 | AX11: =AV11-AW11 -> -121.18038 | AY11: =+IF(IFERROR(AV11/AW11-1,"-")<300%,IFERROR(AV11/AW11-1,"-"),"n.a.") -> 0.16297355 | AZ11: =AV11 -> -864.73897 | BA11: =AV11-AZ11 -> 0 | BB11: =+IF(IFERROR(AV11/AZ11-1,"-")<300%,IFERROR(AV11/AZ11-1,"-"),"n.a.") -> 0 | BD11: COGS | BE11: =(GETPIVOTDATA("jul-27 ",TABLA!$B$3,"Nivel 4","2.- Variación de existencias")+GETPIVOTDATA("jul-27 ",TABLA!$B$3,"Nivel 4","4.- Aprovisionamientos"))/1000 -> -562.0112 | BF11: -525.31503 | BG11: =BE11-BF11 -> -36.69617 | BH11: =+IF(IFERROR(BE11/BF11-1,"-")<300%,IFERROR(BE11/BF11-1,"-"),"n.a.") -> 0.069855549 | BI11: =BE11 -> -562.0112 | BJ11: =BE11-BI11 -> 0 | BK11: =+IF(IFERROR(BE11/BI11-1,"-")<300%,IFERROR(BE11/BI11-1,"-"),"n.a.") -> 0 | BM11: COGS | BN11: =(GETPIVOTDATA("ago-27 ",TABLA!$B$3,"Nivel 4","2.- Variación de existencias")+GETPIVOTDATA("ago-27 ",TABLA!$B$3,"Nivel 4","4.- Aprovisionamientos"))/1000 -> -339.95813 | BO11: -272.12023 | BP11: =BN11-BO11 -> -67.8379 | BQ11: =+IF(IFERROR(BN11/BO11-1,"-")<300%,IFERROR(BN11/BO11-1,"-"),"n.a.") -> 0.24929385 | BR11: =BN11 -> -339.95813 | BS11: =BN11-BR11 -> 0 | BT11: =+IF(IFERROR(BN11/BR11-1,"-")<300%,IFERROR(BN11/BR11-1,"-"),"n.a.") -> 0 | BV11: COGS | BW11: =(GETPIVOTDATA("sep-27 ",TABLA!$B$3,"Nivel 4","2.- Variación de existencias")+GETPIVOTDATA("sep-27 ",TABLA!$B$3,"Nivel 4","4.- Aprovisionamientos"))/1000 -> -210.01274 | BX11: -161.79096 | BY11: =BW11-BX11 -> -48.22178 | BZ11: =+IF(IFERROR(BW11/BX11-1,"-")<300%,IFERROR(BW11/BX11-1,"-"),"n.a.") -> 0.2980499 | CA11: =BW11 -> -210.01274 | CB11: =BW11-CA11 -> 0 | CC11: =+IF(IFERROR(BW11/CA11-1,"-")<300%,IFERROR(BW11/CA11-1,"-"),"n.a.") -> 0 | CE11: COGS | CF11: =(GETPIVOTDATA("oct-27 ",TABLA!$B$3,"Nivel 4","2.- Variación de existencias")+GETPIVOTDATA("oct-27 ",TABLA!$B$3,"Nivel 4","4.- Aprovisionamientos"))/1000 -> -342.59167 | CG11: -302.10136 | CH11: =CF11-CG11 -> -40.49031 | CI11: =+IF(IFERROR(CF11/CG11-1,"-")<300%,IFERROR(CF11/CG11-1,"-"),"n.a.") -> 0.13402889 | CJ11: =CF11 -> -342.59167 | CK11: =CF11-CJ11 -> 0 | CL11: =+IF(IFERROR(CF11/CJ11-1,"-")<300%,IFERROR(CF11/CJ11-1,"-"),"n.a.") -> 0 | CN11: COGS | CO11: =(GETPIVOTDATA("nov-27 ",TABLA!$B$3,"Nivel 4","2.- Variación de existencias")+GETPIVOTDATA("nov-27 ",TABLA!$B$3,"Nivel 4","4.- Aprovisionamientos"))/1000 -> -542.66987 | CP11: -404.42328 | CQ11: =CO11-CP11 -> -138.24659 | CR11: =+IF(IFERROR(CO11/CP11-1,"-")<300%,IFERROR(CO11/CP11-1,"-"),"n.a.") -> 0.34183638 | CS11: =CO11 -> -542.66987 | CT11: =CO11-CS11 -> 0 | CU11: =+IF(IFERROR(CO11/CS11-1,"-")<300%,IFERROR(CO11/CS11-1,"-"),"n.a.") -> 0 | CW11: COGS | CX11: =(GETPIVOTDATA("dic-27 ",TABLA!$B$3,"Nivel 4","2.- Variación de existencias")+GETPIVOTDATA("dic-27 ",TABLA!$B$3,"Nivel 4","4.- Aprovisionamientos"))/1000 -> -562.31302 | CY11: -449.14533 | CZ11: =CX11-CY11 -> -113.16769 | DA11: =+IF(IFERROR(CX11/CY11-1,"-")<300%,IFERROR(CX11/CY11-1,"-"),"n.a.") -> 0.2519623 | DB11: =CX11 -> -562.31302 | DC11: =CX11-DB11 -> 0 | DD11: =+IF(IFERROR(CX11/DB11-1,"-")<300%,IFERROR(CX11/DB11-1,"-"),"n.a.") -> 0 | DF11: COGS | DG11: =(GETPIVOTDATA("Total 2027 ",TABLA!$B$3,"Nivel 4","2.- Variación de existencias")+GETPIVOTDATA("Total 2027 ",TABLA!$B$3,"Nivel 4","4.- Aprovisionamientos"))/1000 -> -6407.2465 | DH11: =CY11+CP11+CG11+BX11+BO11+BF11+AW11+AN11+AE11+V11+M11+D11 -> -5233.5328 | DI11: =DG11-DH11 -> -1173.7136 | DJ11: =+IF(IFERROR(DG11/DH11-1,"-")<300%,IFERROR(DG11/DH11-1,"-"),"n.a.") -> 0.22426794 | DK11: =DG11 -> -6407.2465 | DL11: =DG11-DK11 -> 0 | DM11: =+IF(IFERROR(DG11/DK11-1,"-")<300%,IFERROR(DG11/DK11-1,"-"),"n.a.") -> 0
B12: Gross Profit | C12: =C10+C11 -> 813.74807 | D12: 481.15158 | E12: =C12-D12 -> 332.59649 | F12: =+IF(IFERROR(C12/D12-1,"-")<300%,IFERROR(C12/D12-1,"-"),"n.a.") -> 0.69125096 | G12: =SUM(G10:G11) -> 813.74807 | H12: =C12-G12 -> 0 | I12: =+IF(IFERROR(C12/G12-1,"-")<300%,IFERROR(C12/G12-1,"-"),"n.a.") -> 0 | K12: Gross Profit | L12: =L10+L11 -> 1220.4815 | M12: 1114.191 | N12: =L12-M12 -> 106.29051 | O12: =+IF(IFERROR(L12/M12-1,"-")<300%,IFERROR(L12/M12-1,"-"),"n.a.") -> 0.095397029 | P12: =SUM(P10:P11) -> 1220.4815 | Q12: =L12-P12 -> 0 | R12: =+IF(IFERROR(L12/P12-1,"-")<300%,IFERROR(L12/P12-1,"-"),"n.a.") -> 0 | T12: Gross Profit | U12: =U10+U11 -> 1112.1537 | V12: 1148.0895 | W12: =U12-V12 -> -35.93575 | X12: =+IF(IFERROR(U12/V12-1,"-")<300%,IFERROR(U12/V12-1,"-"),"n.a.") -> -0.031300478 | Y12: =SUM(Y10:Y11) -> 1112.1537 | Z12: =U12-Y12 -> 0 | AA12: =+IF(IFERROR(U12/Y12-1,"-")<300%,IFERROR(U12/Y12-1,"-"),"n.a.") -> 0 | AC12: Gross Profit | AD12: =AD10+AD11 -> 912.98371 | AE12: 955.94319 | AF12: =AD12-AE12 -> -42.95948 | AG12: =+IF(IFERROR(AD12/AE12-1,"-")<300%,IFERROR(AD12/AE12-1,"-"),"n.a.") -> -0.044939365 | AH12: =SUM(AH10:AH11) -> 912.98371 | AI12: =AD12-AH12 -> 0 | AJ12: =+IF(IFERROR(AD12/AH12-1,"-")<300%,IFERROR(AD12/AH12-1,"-"),"n.a.") -> 0 | AL12: Gross Profit | AM12: =AM10+AM11 -> 1510.9732 | AN12: 1301.6576 | AO12: =AM12-AN12 -> 209.31565 | AP12: =+IF(IFERROR(AM12/AN12-1,"-")<300%,IFERROR(AM12/AN12-1,"-"),"n.a.") -> 0.160807 | AQ12: =SUM(AQ10:AQ11) -> 1510.9732 | AR12: =AM12-AQ12 -> 0 | AS12: =+IF(IFERROR(AM12/AQ12-1,"-")<300%,IFERROR(AM12/AQ12-1,"-"),"n.a.") -> 0 | AU12: Gross Profit | AV12: =AV10+AV11 -> 1464.7448 | AW12: 1218.7032 | AX12: =AV12-AW12 -> 246.04154 | AY12: =+IF(IFERROR(AV12/AW12-1,"-")<300%,IFERROR(AV12/AW12-1,"-"),"n.a.") -> 0.20188798 | AZ12: =SUM(AZ10:AZ11) -> 1464.7448 | BA12: =AV12-AZ12 -> 0 | BB12: =+IF(IFERROR(AV12/AZ12-1,"-")<300%,IFERROR(AV12/AZ12-1,"-"),"n.a.") -> 0 | BD12: Gross Profit | BE12: =BE10+BE11 -> 915.97111 | BF12: 765.3392 | BG12: =BE12-BF12 -> 150.63191 | BH12: =+IF(IFERROR(BE12/BF12-1,"-")<300%,IFERROR(BE12/BF12-1,"-"),"n.a.") -> 0.19681719 | BI12: =SUM(BI10:BI11) -> 915.97111 | BJ12: =BE12-BI12 -> 0 | BK12: =+IF(IFERROR(BE12/BI12-1,"-")<300%,IFERROR(BE12/BI12-1,"-"),"n.a.") -> 0 | BM12: Gross Profit | BN12: =BN10+BN11 -> 603.26314 | BO12: 515.98492 | BP12: =BN12-BO12 -> 87.27822 | BQ12: =+IF(IFERROR(BN12/BO12-1,"-")<300%,IFERROR(BN12/BO12-1,"-"),"n.a.") -> 0.16914878 | BR12: =SUM(BR10:BR11) -> 603.26314 | BS12: =BN12-BR12 -> 0 | BT12: =+IF(IFERROR(BN12/BR12-1,"-")<300%,IFERROR(BN12/BR12-1,"-"),"n.a.") -> 0 | BV12: Gross Profit | BW12: =BW10+BW11 -> 337.88344 | BX12: 321.29278 | BY12: =BW12-BX12 -> 16.59066 | BZ12: =+IF(IFERROR(BW12/BX12-1,"-")<300%,IFERROR(BW12/BX12-1,"-"),"n.a.") -> 0.051637201 | CA12: =SUM(CA10:CA11) -> 337.88344 | CB12: =BW12-CA12 -> 0 | CC12: =+IF(IFERROR(BW12/CA12-1,"-")<300%,IFERROR(BW12/CA12-1,"-"),"n.a.") -> 0 | CE12: Gross Profit | CF12: =CF10+CF11 -> 573.70524 | CG12: 609.95365 | CH12: =CF12-CG12 -> -36.24841 | CI12: =+IF(IFERROR(CF12/CG12-1,"-")<300%,IFERROR(CF12/CG12-1,"-"),"n.a.") -> -0.059428139 | CJ12: =SUM(CJ10:CJ11) -> 573.70524 | CK12: =CF12-CJ12 -> 0 | CL12: =+IF(IFERROR(CF12/CJ12-1,"-")<300%,IFERROR(CF12/CJ12-1,"-"),"n.a.") -> 0 | CN12: Gross Profit | CO12: =CO10+CO11 -> 873.69694 | CP12: 820.8985 | CQ12: =CO12-CP12 -> 52.79844 | CR12: =+IF(IFERROR(CO12/CP12-1,"-")<300%,IFERROR(CO12/CP12-1,"-"),"n.a.") -> 0.064317866 | CS12: =SUM(CS10:CS11) -> 873.69694 | CT12: =CO12-CS12 -> 0 | CU12: =+IF(IFERROR(CO12/CS12-1,"-")<300%,IFERROR(CO12/CS12-1,"-"),"n.a.") -> 0 | CW12: Gross Profit | CX12: =CX10+CX11 -> 991.30891 | CY12: 693.26205 | CZ12: =CX12-CY12 -> 298.04686 | DA12: =+IF(IFERROR(CX12/CY12-1,"-")<300%,IFERROR(CX12/CY12-1,"-"),"n.a.") -> 0.42991948 | DB12: =SUM(DB10:DB11) -> 991.30891 | DC12: =CX12-DB12 -> 0 | DD12: =+IF(IFERROR(CX12/DB12-1,"-")<300%,IFERROR(CX12/DB12-1,"-"),"n.a.") -> 0 | DF12: Gross Profit | DG12: =DG10+DG11 -> 11330.914 | DH12: =DH10+DH11 -> 9946.4671 | DI12: =DG12-DH12 -> 1384.4466 | DJ12: =+IF(IFERROR(DG12/DH12-1,"-")<300%,IFERROR(DG12/DH12-1,"-"),"n.a.") -> 0.13918979 | DK12: =SUM(DK10:DK11) -> 11330.914 | DL12: =DG12-DK12 -> 0 | DM12: =+IF(IFERROR(DG12/DK12-1,"-")<300%,IFERROR(DG12/DK12-1,"-"),"n.a.") -> 0
B13: % Gross Margin | C13: =C12/C10 -> 0.71148461 | D13: 0.48906607 | G13: =G12/G10 -> 0.71148461 | K13: % Gross Margin | L13: =L12/L10 -> 0.65877918 | M13: 0.75773236 | P13: =P12/P10 -> 0.65877918 | T13: % Gross Margin | U13: =U12/U10 -> 0.62581306 | V13: 0.74853136 | Y13: =Y12/Y10 -> 0.62581306 | AC13: % Gross Margin | AD13: =AD12/AD10 -> 0.63811465 | AE13: 0.6537945 | AH13: =AH12/AH10 -> 0.63811465 | AL13: % Gross Margin | AM13: =AM12/AM10 -> 0.64323244 | AN13: 0.67585926 | AQ13: =AQ12/AQ10 -> 0.64323244 | AU13: % Gross Margin | AV13: =AV12/AV10 -> 0.62878515 | AW13: 0.62107065 | AZ13: =AZ12/AZ10 -> 0.62878515 | BD13: % Gross Margin | BE13: =BE12/BE10 -> 0.6197443 | BF13: 0.59298547 | BI13: =BI12/BI10 -> 0.6197443 | BM13: % Gross Margin | BN13: =BN12/BN10 -> 0.63957754 | BO13: 0.65471583 | BR13: =BR12/BR10 -> 0.63957754 | BV13: % Gross Margin | BW13: =BW12/BW10 -> 0.61669245 | BX13: 0.66508713 | CA13: =CA12/CA10 -> 0.61669245 | CE13: % Gross Margin | CF13: =CF12/CF10 -> 0.62611282 | CG13: 0.66876849 | CJ13: =CJ12/CJ10 -> 0.62611282 | CN13: % Gross Margin | CO13: =CO12/CO10 -> 0.61685782 | CP13: 0.66994524 | CS13: =CS12/CS10 -> 0.61685782 | CW13: % Gross Margin | CX13: =CX12/CX10 -> 0.63806315 | CY13: 0.60684311 | DB13: =DB12/DB10 -> 0.63806315 | DF13: % Gross Margin | DG13: =DG12/DG10 -> 0.63878743 | DH13: =DH12/DH10 -> 0.65523499 | DK13: =DK12/DK10 -> 0.63878743
B15: Gastos de Personal | C15: =GETPIVOTDATA("ene-27 ",TABLA!$B$3,"Nivel 4","6.- Gastos de personal")/1000 -> -162.38274 | D15: -111.53201 | E15: =C15-D15 -> -50.85073 | F15: =+IF(IFERROR(C15/D15-1,"-")<300%,IFERROR(C15/D15-1,"-"),"n.a.") -> 0.45592947 | G15: =C15 -> -162.38274 | H15: =C15-G15 -> 0 | I15: =+IF(IFERROR(C15/G15-1,"-")<300%,IFERROR(C15/G15-1,"-"),"n.a.") -> 0 | K15: Gastos de Personal | L15: =GETPIVOTDATA("feb-27 ",TABLA!$B$3,"Nivel 4","6.- Gastos de personal")/1000 -> -162.38274 | M15: -142.9272 | N15: =L15-M15 -> -19.45554 | O15: =+IF(IFERROR(L15/M15-1,"-")<300%,IFERROR(L15/M15-1,"-"),"n.a.") -> 0.13612203 | P15: =L15 -> -162.38274 | Q15: =L15-P15 -> 0 | R15: =+IF(IFERROR(L15/P15-1,"-")<300%,IFERROR(L15/P15-1,"-"),"n.a.") -> 0 | T15: Gastos de Personal | U15: =GETPIVOTDATA("mar-27 ",TABLA!$B$3,"Nivel 4","6.- Gastos de personal")/1000 -> -162.38274 | V15: -146.23331 | W15: =U15-V15 -> -16.14943 | X15: =+IF(IFERROR(U15/V15-1,"-")<300%,IFERROR(U15/V15-1,"-"),"n.a.") -> 0.11043606 | Y15: =U15 -> -162.38274 | Z15: =U15-Y15 -> 0 | AA15: =+IF(IFERROR(U15/Y15-1,"-")<300%,IFERROR(U15/Y15-1,"-"),"n.a.") -> 0 | AC15: Gastos de Personal | AD15: =GETPIVOTDATA("abr-27 ",TABLA!$B$3,"Nivel 4","6.- Gastos de personal")/1000 -> -162.38274 | AE15: -130.04767 | AF15: =AD15-AE15 -> -32.33507 | AG15: =+IF(IFERROR(AD15/AE15-1,"-")<300%,IFERROR(AD15/AE15-1,"-"),"n.a.") -> 0.24864013 | AH15: =AD15 -> -162.38274 | AI15: =AD15-AH15 -> 0 | AJ15: =+IF(IFERROR(AD15/AH15-1,"-")<300%,IFERROR(AD15/AH15-1,"-"),"n.a.") -> 0 | AL15: Gastos de Personal | AM15: =GETPIVOTDATA("may-27 ",TABLA!$B$3,"Nivel 4","6.- Gastos de personal")/1000 -> -162.38274 | AN15: -134.99252 | AO15: =AM15-AN15 -> -27.39022 | AP15: =+IF(IFERROR(AM15/AN15-1,"-")<300%,IFERROR(AM15/AN15-1,"-"),"n.a.") -> 0.20290176 | AQ15: =AM15 -> -162.38274 | AR15: =AM15-AQ15 -> 0 | AS15: =+IF(IFERROR(AM15/AQ15-1,"-")<300%,IFERROR(AM15/AQ15-1,"-"),"n.a.") -> 0 | AU15: Gastos de Personal | AV15: =GETPIVOTDATA("jun-27 ",TABLA!$B$3,"Nivel 4","6.- Gastos de personal")/1000 -> -162.38274 | AW15: -145.07228 | AX15: =AV15-AW15 -> -17.31046 | AY15: =+IF(IFERROR(AV15/AW15-1,"-")<300%,IFERROR(AV15/AW15-1,"-"),"n.a.") -> 0.119323 | AZ15: =AV15 -> -162.38274 | BA15: =AV15-AZ15 -> 0 | BB15: =+IF(IFERROR(AV15/AZ15-1,"-")<300%,IFERROR(AV15/AZ15-1,"-"),"n.a.") -> 0 | BD15: Gastos de Personal | BE15: =GETPIVOTDATA("jul-27 ",TABLA!$B$3,"Nivel 4","6.- Gastos de personal")/1000 -> -162.38274 | BF15: -153.53365 | BG15: =BE15-BF15 -> -8.84909 | BH15: =+IF(IFERROR(BE15/BF15-1,"-")<300%,IFERROR(BE15/BF15-1,"-"),"n.a.") -> 0.05763616 | BI15: =BE15 -> -162.38274 | BJ15: =BE15-BI15 -> 0 | BK15: =+IF(IFERROR(BE15/BI15-1,"-")<300%,IFERROR(BE15/BI15-1,"-"),"n.a.") -> 0 | BM15: Gastos de Personal | BN15: =GETPIVOTDATA("ago-27 ",TABLA!$B$3,"Nivel 4","6.- Gastos de personal")/1000 -> -162.38274 | BO15: -152.63279 | BP15: =BN15-BO15 -> -9.74995 | BQ15: =+IF(IFERROR(BN15/BO15-1,"-")<300%,IFERROR(BN15/BO15-1,"-"),"n.a.") -> 0.063878476 | BR15: =BN15 -> -162.38274 | BS15: =BN15-BR15 -> 0 | BT15: =+IF(IFERROR(BN15/BR15-1,"-")<300%,IFERROR(BN15/BR15-1,"-"),"n.a.") -> 0 | BV15: Gastos de Personal | BW15: =GETPIVOTDATA("sep-27 ",TABLA!$B$3,"Nivel 4","6.- Gastos de personal")/1000 -> -162.38274 | BX15: -152.63279 | BY15: =BW15-BX15 -> -9.74995 | BZ15: =+IF(IFERROR(BW15/BX15-1,"-")<300%,IFERROR(BW15/BX15-1,"-"),"n.a.") -> 0.063878476 | CA15: =BW15 -> -162.38274 | CB15: =BW15-CA15 -> 0 | CC15: =+IF(IFERROR(BW15/CA15-1,"-")<300%,IFERROR(BW15/CA15-1,"-"),"n.a.") -> 0 | CE15: Gastos de Personal | CF15: =GETPIVOTDATA("oct-27 ",TABLA!$B$3,"Nivel 4","6.- Gastos de personal")/1000 -> -162.38274 | CG15: -152.63279 | CH15: =CF15-CG15 -> -9.74995 | CI15: =+IF(IFERROR(CF15/CG15-1,"-")<300%,IFERROR(CF15/CG15-1,"-"),"n.a.") -> 0.063878476 | CJ15: =CF15 -> -162.38274 | CK15: =CF15-CJ15 -> 0 | CL15: =+IF(IFERROR(CF15/CJ15-1,"-")<300%,IFERROR(CF15/CJ15-1,"-"),"n.a.") -> 0 | CN15: Gastos de Personal | CO15: =GETPIVOTDATA("nov-27 ",TABLA!$B$3,"Nivel 4","6.- Gastos de personal")/1000 -> -163.38274 | CP15: -152.63279 | CQ15: =CO15-CP15 -> -10.74995 | CR15: =+IF(IFERROR(CO15/CP15-1,"-")<300%,IFERROR(CO15/CP15-1,"-"),"n.a.") -> 0.070430148 | CS15: =CO15 -> -163.38274 | CT15: =CO15-CS15 -> 0 | CU15: =+IF(IFERROR(CO15/CS15-1,"-")<300%,IFERROR(CO15/CS15-1,"-"),"n.a.") -> 0 | CW15: Gastos de Personal | CX15: =GETPIVOTDATA("dic-27 ",TABLA!$B$3,"Nivel 4","6.- Gastos de personal")/1000 -> -441.39946 | CY15: -431.63279 | CZ15: =CX15-CY15 -> -9.76667 | DA15: =+IF(IFERROR(CX15/CY15-1,"-")<300%,IFERROR(CX15/CY15-1,"-"),"n.a.") -> 0.022627266 | DB15: =CX15 -> -441.39946 | DC15: =CX15-DB15 -> 0 | DD15: =+IF(IFERROR(CX15/DB15-1,"-")<300%,IFERROR(CX15/DB15-1,"-"),"n.a.") -> 0 | DF15: Gastos de Personal | DG15: =GETPIVOTDATA("Total 2027 ",TABLA!$B$3,"Nivel 4","6.- Gastos de personal")/1000 -> -2228.6096 | DH15: =CY15+CP15+CG15+BX15+BO15+BF15+AW15+AN15+AE15+V15+M15+D15 -> -2006.5026 | DI15: =DG15-DH15 -> -222.10701 | DJ15: =+IF(IFERROR(DG15/DH15-1,"-")<300%,IFERROR(DG15/DH15-1,"-"),"n.a.") -> 0.11069361 | DK15: =DG15 -> -2228.6096 | DL15: =DG15-DK15 -> 0 | DM15: =+IF(IFERROR(DG15/DK15-1,"-")<300%,IFERROR(DG15/DK15-1,"-"),"n.a.") -> 0
B16: % of Revenue | C16: =C15/C10 -> -0.14197615 | D16: -0.11336661 | G16: =G15/G10 -> -0.14197615 | K16: % of Revenue | L16: =L15/L10 -> -0.087649316 | M16: -0.097201077 | P16: =P15/P10 -> -0.087649316 | T16: % of Revenue | U16: =U15/U10 -> -0.091373375 | V16: -0.095341192 | Y16: =Y15/Y10 -> -0.091373375 | AC16: % of Revenue | AD16: =AD15/AD10 -> -0.11349469 | AE16: -0.088942995 | AH16: =AH15/AH10 -> -0.11349469 | AL16: % of Revenue | AM16: =AM15/AM10 -> -0.06912753 | AN16: -0.070092125 | AQ16: =AQ15/AQ10 -> -0.06912753 | AU16: % of Revenue | AV16: =AV15/AV10 -> -0.069707608 | AW16: -0.073931153 | AZ16: =AZ15/AZ10 -> -0.069707608 | BD16: % of Revenue | BE16: =BE15/BE10 -> -0.10986785 | BF16: -0.118958 | BI16: =BI15/BI10 -> -0.10986785 | BM16: % of Revenue | BN16: =BN15/BN10 -> -0.17215763 | BO16: -0.19367059 | BR16: =BR15/BR10 -> -0.17215763 | BV16: % of Revenue | BW16: =BW15/BW10 -> -0.29637502 | BX16: -0.31595514 | CA16: =CA15/CA10 -> -0.29637502 | CE16: % of Revenue | CF16: =CF15/CF10 -> -0.17721629 | CG16: -0.16735042 | CJ16: =CJ15/CJ10 -> -0.17721629 | CN16: % of Revenue | CO16: =CO15/CO10 -> -0.11535341 | CP16: -0.12456548 | CS16: =CS15/CS10 -> -0.11535341 | CW16: % of Revenue | CX16: =CX15/CX10 -> -0.28410996 | CY16: -0.37782738 | DB16: =DB15/DB10 -> -0.28410996 | DF16: % of Revenue | DG16: =DG15/DG10 -> -0.12563928 | DH16: =DH15/DH10 -> -0.13218067 | DK16: =DK15/DK10 -> -0.12563928
B18: Otros Ingresos Operativos | C18: =GETPIVOTDATA("ene-27 ",TABLA!$B$3,"Nivel 4","5.- Otros ingresos de explotación")/1000 -> 29.8092 | D18: 0 | E18: =C18-D18 -> 29.8092 | F18: =+IF(IFERROR(C18/D18-1,"-")<300%,IFERROR(C18/D18-1,"-"),"n.a.") -> n.a. | G18: =C18 -> 29.8092 | H18: =C18-G18 -> 0 | I18: =+IF(IFERROR(C18/G18-1,"-")<300%,IFERROR(C18/G18-1,"-"),"n.a.") -> 0 | K18: Otros Ingresos Operativos | L18: =GETPIVOTDATA("feb-27 ",TABLA!$B$3,"Nivel 4","5.- Otros ingresos de explotación")/1000 -> 21.2467 | M18: 0 | N18: =L18-M18 -> 21.2467 | O18: =+IF(IFERROR(L18/M18-1,"-")<300%,IFERROR(L18/M18-1,"-"),"n.a.") -> n.a. | P18: =L18 -> 21.2467 | Q18: =L18-P18 -> 0 | R18: =+IF(IFERROR(L18/P18-1,"-")<300%,IFERROR(L18/P18-1,"-"),"n.a.") -> 0 | T18: Otros Ingresos Operativos | U18: =GETPIVOTDATA("mar-27 ",TABLA!$B$3,"Nivel 4","5.- Otros ingresos de explotación")/1000 -> 19.6383 | V18: 0 | W18: =U18-V18 -> 19.6383 | X18: =+IF(IFERROR(U18/V18-1,"-")<300%,IFERROR(U18/V18-1,"-"),"n.a.") -> n.a. | Y18: =U18 -> 19.6383 | Z18: =U18-Y18 -> 0 | AA18: =+IF(IFERROR(U18/Y18-1,"-")<300%,IFERROR(U18/Y18-1,"-"),"n.a.") -> 0 | AC18: Otros Ingresos Operativos | AD18: =GETPIVOTDATA("abr-27 ",TABLA!$B$3,"Nivel 4","5.- Otros ingresos de explotación")/1000 -> 8.0042 | AE18: 0.75075 | AF18: =AD18-AE18 -> 7.25345 | AG18: =+IF(IFERROR(AD18/AE18-1,"-")<300%,IFERROR(AD18/AE18-1,"-"),"n.a.") -> n.a. | AH18: =AD18 -> 8.0042 | AI18: =AD18-AH18 -> 0 | AJ18: =+IF(IFERROR(AD18/AH18-1,"-")<300%,IFERROR(AD18/AH18-1,"-"),"n.a.") -> 0 | AL18: Otros Ingresos Operativos | AM18: =GETPIVOTDATA("may-27 ",TABLA!$B$3,"Nivel 4","5.- Otros ingresos de explotación")/1000 -> 38.7188 | AN18: 25.14075 | AO18: =AM18-AN18 -> 13.57805 | AP18: =+IF(IFERROR(AM18/AN18-1,"-")<300%,IFERROR(AM18/AN18-1,"-"),"n.a.") -> 0.54008134 | AQ18: =AM18 -> 38.7188 | AR18: =AM18-AQ18 -> 0 | AS18: =+IF(IFERROR(AM18/AQ18-1,"-")<300%,IFERROR(AM18/AQ18-1,"-"),"n.a.") -> 0 | AU18: Otros Ingresos Operativos | AV18: =GETPIVOTDATA("jun-27 ",TABLA!$B$3,"Nivel 4","5.- Otros ingresos de explotación")/1000 -> 33.492 | AW18: 22.9776 | AX18: =AV18-AW18 -> 10.5144 | AY18: =+IF(IFERROR(AV18/AW18-1,"-")<300%,IFERROR(AV18/AW18-1,"-"),"n.a.") -> 0.45759348 | AZ18: =AV18 -> 33.492 | BA18: =AV18-AZ18 -> 0 | BB18: =+IF(IFERROR(AV18/AZ18-1,"-")<300%,IFERROR(AV18/AZ18-1,"-"),"n.a.") -> 0 | BD18: Otros Ingresos Operativos | BE18: =GETPIVOTDATA("jul-27 ",TABLA!$B$3,"Nivel 4","5.- Otros ingresos de explotación")/1000 -> 13.2128 | BF18: 11.02724 | BG18: =BE18-BF18 -> 2.18556 | BH18: =+IF(IFERROR(BE18/BF18-1,"-")<300%,IFERROR(BE18/BF18-1,"-"),"n.a.") -> 0.19819647 | BI18: =BE18 -> 13.2128 | BJ18: =BE18-BI18 -> 0 | BK18: =+IF(IFERROR(BE18/BI18-1,"-")<300%,IFERROR(BE18/BI18-1,"-"),"n.a.") -> 0 | BM18: Otros Ingresos Operativos | BN18: =GETPIVOTDATA("ago-27 ",TABLA!$B$3,"Nivel 4","5.- Otros ingresos de explotación")/1000 -> 18.5096 | BO18: 11.429 | BP18: =BN18-BO18 -> 7.0806 | BQ18: =+IF(IFERROR(BN18/BO18-1,"-")<300%,IFERROR(BN18/BO18-1,"-"),"n.a.") -> 0.61952927 | BR18: =BN18 -> 18.5096 | BS18: =BN18-BR18 -> 0 | BT18: =+IF(IFERROR(BN18/BR18-1,"-")<300%,IFERROR(BN18/BR18-1,"-"),"n.a.") -> 0 | BV18: Otros Ingresos Operativos | BW18: =GETPIVOTDATA("sep-27 ",TABLA!$B$3,"Nivel 4","5.- Otros ingresos de explotación")/1000 -> 24.1489 | BX18: 16.253 | BY18: =BW18-BX18 -> 7.8959 | BZ18: =+IF(IFERROR(BW18/BX18-1,"-")<300%,IFERROR(BW18/BX18-1,"-"),"n.a.") -> 0.48581185 | CA18: =BW18 -> 24.1489 | CB18: =BW18-CA18 -> 0 | CC18: =+IF(IFERROR(BW18/CA18-1,"-")<300%,IFERROR(BW18/CA18-1,"-"),"n.a.") -> 0 | CE18: Otros Ingresos Operativos | CF18: =GETPIVOTDATA("oct-27 ",TABLA!$B$3,"Nivel 4","5.- Otros ingresos de explotación")/1000 -> 23.4113 | CG18: 21.379 | CH18: =CF18-CG18 -> 2.0323 | CI18: =+IF(IFERROR(CF18/CG18-1,"-")<300%,IFERROR(CF18/CG18-1,"-"),"n.a.") -> 0.095060573 | CJ18: =CF18 -> 23.4113 | CK18: =CF18-CJ18 -> 0 | CL18: =+IF(IFERROR(CF18/CJ18-1,"-")<300%,IFERROR(CF18/CJ18-1,"-"),"n.a.") -> 0 | CN18: Otros Ingresos Operativos | CO18: =GETPIVOTDATA("nov-27 ",TABLA!$B$3,"Nivel 4","5.- Otros ingresos de explotación")/1000 -> 40.6507 | CP18: 32.454 | CQ18: =CO18-CP18 -> 8.1967 | CR18: =+IF(IFERROR(CO18/CP18-1,"-")<300%,IFERROR(CO18/CP18-1,"-"),"n.a.") -> 0.25256363 | CS18: =CO18 -> 40.6507 | CT18: =CO18-CS18 -> 0 | CU18: =+IF(IFERROR(CO18/CS18-1,"-")<300%,IFERROR(CO18/CS18-1,"-"),"n.a.") -> 0 | CW18: Otros Ingresos Operativos | CX18: =GETPIVOTDATA("dic-27 ",TABLA!$B$3,"Nivel 4","5.- Otros ingresos de explotación")/1000 -> 34.3808 | CY18: 27.15 | CZ18: =CX18-CY18 -> 7.2308 | DA18: =+IF(IFERROR(CX18/CY18-1,"-")<300%,IFERROR(CX18/CY18-1,"-"),"n.a.") -> 0.26632781 | DB18: =CX18 -> 34.3808 | DC18: =CX18-DB18 -> 0 | DD18: =+IF(IFERROR(CX18/DB18-1,"-")<300%,IFERROR(CX18/DB18-1,"-"),"n.a.") -> 0 | DF18: Otros Ingresos Operativos | DG18: =GETPIVOTDATA("Total 2027 ",TABLA!$B$3,"Nivel 4","5.- Otros ingresos de explotación")/1000 -> 305.2233 | DH18: =CY18+CP18+CG18+BX18+BO18+BF18+AW18+AN18+AE18+V18+M18+D18 -> 168.56134 | DI18: =DG18-DH18 -> 136.66196 | DJ18: =+IF(IFERROR(DG18/DH18-1,"-")<300%,IFERROR(DG18/DH18-1,"-"),"n.a.") -> 0.81075506 | DK18: =DG18 -> 305.2233 | DL18: =DG18-DK18 -> 0 | DM18: =+IF(IFERROR(DG18/DK18-1,"-")<300%,IFERROR(DG18/DK18-1,"-"),"n.a.") -> 0
B19: Otros Gastos Operativos | C19: =GETPIVOTDATA("ene-27 ",TABLA!$B$3,"Nivel 4","7.- Otros gastos de explotación")/1000 -> -162.8549 | D19: -103.45176 | E19: =C19-D19 -> -59.40314 | F19: =+IF(IFERROR(C19/D19-1,"-")<300%,IFERROR(C19/D19-1,"-"),"n.a.") -> 0.57421101 | G19: =C19 -> -162.8549 | H19: =C19-G19 -> 0 | I19: =+IF(IFERROR(C19/G19-1,"-")<300%,IFERROR(C19/G19-1,"-"),"n.a.") -> 0 | K19: Otros Gastos Operativos | L19: =GETPIVOTDATA("feb-27 ",TABLA!$B$3,"Nivel 4","7.- Otros gastos de explotación")/1000 -> -156.65463 | M19: -62.49888 | N19: =L19-M19 -> -94.15575 | O19: =+IF(IFERROR(L19/M19-1,"-")<300%,IFERROR(L19/M19-1,"-"),"n.a.") -> 1.506519 | P19: =L19 -> -156.65463 | Q19: =L19-P19 -> 0 | R19: =+IF(IFERROR(L19/P19-1,"-")<300%,IFERROR(L19/P19-1,"-"),"n.a.") -> 0 | T19: Otros Gastos Operativos | U19: =GETPIVOTDATA("mar-27 ",TABLA!$B$3,"Nivel 4","7.- Otros gastos de explotación")/1000 -> -161.54122 | V19: -110.60627 | W19: =U19-V19 -> -50.93495 | X19: =+IF(IFERROR(U19/V19-1,"-")<300%,IFERROR(U19/V19-1,"-"),"n.a.") -> 0.4605069 | Y19: =U19 -> -161.54122 | Z19: =U19-Y19 -> 0 | AA19: =+IF(IFERROR(U19/Y19-1,"-")<300%,IFERROR(U19/Y19-1,"-"),"n.a.") -> 0 | AC19: Otros Gastos Operativos | AD19: =GETPIVOTDATA("abr-27 ",TABLA!$B$3,"Nivel 4","7.- Otros gastos de explotación")/1000 -> -151.8867 | AE19: -107.70665 | AF19: =AD19-AE19 -> -44.18005 | AG19: =+IF(IFERROR(AD19/AE19-1,"-")<300%,IFERROR(AD19/AE19-1,"-"),"n.a.") -> 0.41018869 | AH19: =AD19 -> -151.8867 | AI19: =AD19-AH19 -> 0 | AJ19: =+IF(IFERROR(AD19/AH19-1,"-")<300%,IFERROR(AD19/AH19-1,"-"),"n.a.") -> 0 | AL19: Otros Gastos Operativos | AM19: =GETPIVOTDATA("may-27 ",TABLA!$B$3,"Nivel 4","7.- Otros gastos de explotación")/1000 -> -184.77671 | AN19: -123.39208 | AO19: =AM19-AN19 -> -61.38463 | AP19: =+IF(IFERROR(AM19/AN19-1,"-")<300%,IFERROR(AM19/AN19-1,"-"),"n.a.") -> 0.49747626 | AQ19: =AM19 -> -184.77671 | AR19: =AM19-AQ19 -> 0 | AS19: =+IF(IFERROR(AM19/AQ19-1,"-")<300%,IFERROR(AM19/AQ19-1,"-"),"n.a.") -> 0 | AU19: Otros Gastos Operativos | AV19: =GETPIVOTDATA("jun-27 ",TABLA!$B$3,"Nivel 4","7.- Otros gastos de explotación")/1000 -> -161.34468 | AW19: -175.01376 | AX19: =AV19-AW19 -> 13.66908 | AY19: =+IF(IFERROR(AV19/AW19-1,"-")<300%,IFERROR(AV19/AW19-1,"-"),"n.a.") -> -0.078102887 | AZ19: =AV19 -> -161.34468 | BA19: =AV19-AZ19 -> 0 | BB19: =+IF(IFERROR(AV19/AZ19-1,"-")<300%,IFERROR(AV19/AZ19-1,"-"),"n.a.") -> 0 | BD19: Otros Gastos Operativos | BE19: =GETPIVOTDATA("jul-27 ",TABLA!$B$3,"Nivel 4","7.- Otros gastos de explotación")/1000 -> -132.69654 | BF19: -161.05174 | BG19: =BE19-BF19 -> 28.355204 | BH19: =+IF(IFERROR(BE19/BF19-1,"-")<300%,IFERROR(BE19/BF19-1,"-"),"n.a.") -> -0.1760627 | BI19: =BE19 -> -132.69654 | BJ19: =BE19-BI19 -> 0 | BK19: =+IF(IFERROR(BE19/BI19-1,"-")<300%,IFERROR(BE19/BI19-1,"-"),"n.a.") -> 0 | BM19: Otros Gastos Operativos | BN19: =GETPIVOTDATA("ago-27 ",TABLA!$B$3,"Nivel 4","7.- Otros gastos de explotación")/1000 -> -131.76464 | BO19: -130.06066 | BP19: =BN19-BO19 -> -1.703979 | BQ19: =+IF(IFERROR(BN19/BO19-1,"-")<300%,IFERROR(BN19/BO19-1,"-"),"n.a.") -> 0.013101417 | BR19: =BN19 -> -131.76464 | BS19: =BN19-BR19 -> 0 | BT19: =+IF(IFERROR(BN19/BR19-1,"-")<300%,IFERROR(BN19/BR19-1,"-"),"n.a.") -> 0 | BV19: Otros Gastos Operativos | BW19: =GETPIVOTDATA("sep-27 ",TABLA!$B$3,"Nivel 4","7.- Otros gastos de explotación")/1000 -> -150.22285 | BX19: -120.80832 | BY19: =BW19-BX19 -> -29.41453 | BZ19: =+IF(IFERROR(BW19/BX19-1,"-")<300%,IFERROR(BW19/BX19-1,"-"),"n.a.") -> 0.243481 | CA19: =BW19 -> -150.22285 | CB19: =BW19-CA19 -> 0 | CC19: =+IF(IFERROR(BW19/CA19-1,"-")<300%,IFERROR(BW19/CA19-1,"-"),"n.a.") -> 0 | CE19: Otros Gastos Operativos | CF19: =GETPIVOTDATA("oct-27 ",TABLA!$B$3,"Nivel 4","7.- Otros gastos de explotación")/1000 -> -146.34194 | CG19: -149.47019 | CH19: =CF19-CG19 -> 3.12825 | CI19: =+IF(IFERROR(CF19/CG19-1,"-")<300%,IFERROR(CF19/CG19-1,"-"),"n.a.") -> -0.020928922 | CJ19: =CF19 -> -146.34194 | CK19: =CF19-CJ19 -> 0 | CL19: =+IF(IFERROR(CF19/CJ19-1,"-")<300%,IFERROR(CF19/CJ19-1,"-"),"n.a.") -> 0 | CN19: Otros Gastos Operativos | CO19: =GETPIVOTDATA("nov-27 ",TABLA!$B$3,"Nivel 4","7.- Otros gastos de explotación")/1000 -> -183.50703 | CP19: -162.36942 | CQ19: =CO19-CP19 -> -21.13761 | CR19: =+IF(IFERROR(CO19/CP19-1,"-")<300%,IFERROR(CO19/CP19-1,"-"),"n.a.") -> 0.13018221 | CS19: =CO19 -> -183.50703 | CT19: =CO19-CS19 -> 0 | CU19: =+IF(IFERROR(CO19/CS19-1,"-")<300%,IFERROR(CO19/CS19-1,"-"),"n.a.") -> 0 | CW19: Otros Gastos Operativos | CX19: =GETPIVOTDATA("dic-27 ",TABLA!$B$3,"Nivel 4","7.- Otros gastos de explotación")/1000 -> -286.91589 | CY19: -277.59629 | CZ19: =CX19-CY19 -> -9.3196 | DA19: =+IF(IFERROR(CX19/CY19-1,"-")<300%,IFERROR(CX19/CY19-1,"-"),"n.a.") -> 0.033572495 | DB19: =CX19 -> -286.91589 | DC19: =CX19-DB19 -> 0 | DD19: =+IF(IFERROR(CX19/DB19-1,"-")<300%,IFERROR(CX19/DB19-1,"-"),"n.a.") -> 0 | DF19: Otros Gastos Operativos | DG19: =GETPIVOTDATA("Total 2027 ",TABLA!$B$3,"Nivel 4","7.- Otros gastos de explotación")/1000 -> -2010.5077 | DH19: =CY19+CP19+CG19+BX19+BO19+BF19+AW19+AN19+AE19+V19+M19+D19 -> -1684.026 | DI19: =DG19-DH19 -> -326.4817 | DJ19: =+IF(IFERROR(DG19/DH19-1,"-")<300%,IFERROR(DG19/DH19-1,"-"),"n.a.") -> 0.19386975 | DK19: =DG19 -> -2010.5077 | DL19: =DG19-DK19 -> 0 | DM19: =+IF(IFERROR(DG19/DK19-1,"-")<300%,IFERROR(DG19/DK19-1,"-"),"n.a.") -> 0
B20: Operating Expenses | C20: =SUM(C18:C19) -> -133.0457 | D20: -103.45176 | E20: =C20-D20 -> -29.59394 | F20: =+IF(IFERROR(C20/D20-1,"-")<300%,IFERROR(C20/D20-1,"-"),"n.a.") -> 0.28606512 | G20: =SUM(G18:G19) -> -133.0457 | H20: =C20-G20 -> 0 | I20: =+IF(IFERROR(C20/G20-1,"-")<300%,IFERROR(C20/G20-1,"-"),"n.a.") -> 0 | K20: Operating Expenses | L20: =SUM(L18:L19) -> -135.40793 | M20: -62.49888 | N20: =L20-M20 -> -72.90905 | O20: =+IF(IFERROR(L20/M20-1,"-")<300%,IFERROR(L20/M20-1,"-"),"n.a.") -> 1.1665657 | P20: =SUM(P18:P19) -> -135.40793 | Q20: =L20-P20 -> 0 | R20: =+IF(IFERROR(L20/P20-1,"-")<300%,IFERROR(L20/P20-1,"-"),"n.a.") -> 0 | T20: Operating Expenses | U20: =SUM(U18:U19) -> -141.90292 | V20: -110.60627 | W20: =U20-V20 -> -31.29665 | X20: =+IF(IFERROR(U20/V20-1,"-")<300%,IFERROR(U20/V20-1,"-"),"n.a.") -> 0.28295548 | Y20: =SUM(Y18:Y19) -> -141.90292 | Z20: =U20-Y20 -> 0 | AA20: =+IF(IFERROR(U20/Y20-1,"-")<300%,IFERROR(U20/Y20-1,"-"),"n.a.") -> 0 | AC20: Operating Expenses | AD20: =SUM(AD18:AD19) -> -143.8825 | AE20: -106.9559 | AF20: =AD20-AE20 -> -36.9266 | AG20: =+IF(IFERROR(AD20/AE20-1,"-")<300%,IFERROR(AD20/AE20-1,"-"),"n.a.") -> 0.34525071 | AH20: =SUM(AH18:AH19) -> -143.8825 | AI20: =AD20-AH20 -> 0 | AJ20: =+IF(IFERROR(AD20/AH20-1,"-")<300%,IFERROR(AD20/AH20-1,"-"),"n.a.") -> 0 | AL20: Operating Expenses | AM20: =SUM(AM18:AM19) -> -146.05791 | AN20: -98.25133 | AO20: =AM20-AN20 -> -47.80658 | AP20: =+IF(IFERROR(AM20/AN20-1,"-")<300%,IFERROR(AM20/AN20-1,"-"),"n.a.") -> 0.48657438 | AQ20: =SUM(AQ18:AQ19) -> -146.05791 | AR20: =AM20-AQ20 -> 0 | AS20: =+IF(IFERROR(AM20/AQ20-1,"-")<300%,IFERROR(AM20/AQ20-1,"-"),"n.a.") -> 0 | AU20: Operating Expenses | AV20: =SUM(AV18:AV19) -> -127.85268 | AW20: -152.03616 | AX20: =AV20-AW20 -> 24.18348 | AY20: =+IF(IFERROR(AV20/AW20-1,"-")<300%,IFERROR(AV20/AW20-1,"-"),"n.a.") -> -0.159064 | AZ20: =SUM(AZ18:AZ19) -> -127.85268 | BA20: =AV20-AZ20 -> 0 | BB20: =+IF(IFERROR(AV20/AZ20-1,"-")<300%,IFERROR(AV20/AZ20-1,"-"),"n.a.") -> 0 | BD20: Operating Expenses | BE20: =SUM(BE18:BE19) -> -119.48374 | BF20: -150.0245 | BG20: =BE20-BF20 -> 30.540764 | BH20: =+IF(IFERROR(BE20/BF20-1,"-")<300%,IFERROR(BE20/BF20-1,"-"),"n.a.") -> -0.20357184 | BI20: =SUM(BI18:BI19) -> -119.48374 | BJ20: =BE20-BI20 -> 0 | BK20: =+IF(IFERROR(BE20/BI20-1,"-")<300%,IFERROR(BE20/BI20-1,"-"),"n.a.") -> 0 | BM20: Operating Expenses | BN20: =SUM(BN18:BN19) -> -113.25504 | BO20: -118.63166 | BP20: =BN20-BO20 -> 5.376621 | BQ20: =+IF(IFERROR(BN20/BO20-1,"-")<300%,IFERROR(BN20/BO20-1,"-"),"n.a.") -> -0.045321974 | BR20: =SUM(BR18:BR19) -> -113.25504 | BS20: =BN20-BR20 -> 0 | BT20: =+IF(IFERROR(BN20/BR20-1,"-")<300%,IFERROR(BN20/BR20-1,"-"),"n.a.") -> 0 | BV20: Operating Expenses | BW20: =SUM(BW18:BW19) -> -126.07395 | BX20: -104.55532 | BY20: =BW20-BX20 -> -21.51863 | BZ20: =+IF(IFERROR(BW20/BX20-1,"-")<300%,IFERROR(BW20/BX20-1,"-"),"n.a.") -> 0.20581095 | CA20: =SUM(CA18:CA19) -> -126.07395 | CB20: =BW20-CA20 -> 0 | CC20: =+IF(IFERROR(BW20/CA20-1,"-")<300%,IFERROR(BW20/CA20-1,"-"),"n.a.") -> 0 | CE20: Operating Expenses | CF20: =SUM(CF18:CF19) -> -122.93064 | CG20: -128.09119 | CH20: =CF20-CG20 -> 5.16055 | CI20: =+IF(IFERROR(CF20/CG20-1,"-")<300%,IFERROR(CF20/CG20-1,"-"),"n.a.") -> -0.040288095 | CJ20: =SUM(CJ18:CJ19) -> -122.93064 | CK20: =CF20-CJ20 -> 0 | CL20: =+IF(IFERROR(CF20/CJ20-1,"-")<300%,IFERROR(CF20/CJ20-1,"-"),"n.a.") -> 0 | CN20: Operating Expenses | CO20: =SUM(CO18:CO19) -> -142.85633 | CP20: -129.91542 | CQ20: =CO20-CP20 -> -12.94091 | CR20: =+IF(IFERROR(CO20/CP20-1,"-")<300%,IFERROR(CO20/CP20-1,"-"),"n.a.") -> 0.09961027 | CS20: =SUM(CS18:CS19) -> -142.85633 | CT20: =CO20-CS20 -> 0 | CU20: =+IF(IFERROR(CO20/CS20-1,"-")<300%,IFERROR(CO20/CS20-1,"-"),"n.a.") -> 0 | CW20: Operating Expenses | CX20: =SUM(CX18:CX19) -> -252.53509 | CY20: -250.44629 | CZ20: =CX20-CY20 -> -2.0888 | DA20: =+IF(IFERROR(CX20/CY20-1,"-")<300%,IFERROR(CX20/CY20-1,"-"),"n.a.") -> 0.0083403112 | DB20: =SUM(DB18:DB19) -> -252.53509 | DC20: =CX20-DB20 -> 0 | DD20: =+IF(IFERROR(CX20/DB20-1,"-")<300%,IFERROR(CX20/DB20-1,"-"),"n.a.") -> 0 | DF20: Operating Expenses | DG20: =SUM(DG18:DG19) -> -1705.2844 | DH20: =SUM(DH18:DH19) -> -1515.4647 | DI20: =DG20-DH20 -> -189.81974 | DJ20: =+IF(IFERROR(DG20/DH20-1,"-")<300%,IFERROR(DG20/DH20-1,"-"),"n.a.") -> 0.12525514 | DK20: =SUM(DK18:DK19) -> -1705.2844 | DL20: =DG20-DK20 -> 0 | DM20: =+IF(IFERROR(DG20/DK20-1,"-")<300%,IFERROR(DG20/DK20-1,"-"),"n.a.") -> 0
B21: % of Revenue | C21: =C20/C10 -> -0.11632589 | D21: -0.10515344 | G21: =G20/G10 -> -0.11632589 | K21: % of Revenue | L21: =L20/L10 -> -0.073089125 | M21: -0.042503865 | P21: =P20/P10 -> -0.073089125 | T21: % of Revenue | U21: =U20/U10 -> -0.079849303 | V21: -0.072113075 | Y21: =Y20/Y10 -> -0.079849303 | AC21: % of Revenue | AD21: =AD20/AD10 -> -0.10056426 | AE21: -0.073149931 | AH21: =AH20/AH10 -> -0.10056426 | AL21: % of Revenue | AM21: =AM20/AM10 -> -0.062177929 | AN21: -0.051015008 | AQ21: =AQ20/AQ10 -> -0.062177929 | AU21: % of Revenue | AV21: =AV20/AV10 -> -0.054884555 | AW21: -0.077480058 | AZ21: =AZ20/AZ10 -> -0.054884555 | BD21: % of Revenue | BE21: =BE20/BE10 -> -0.08084247 | BF21: -0.11623911 | BI21: =BI20/BI10 -> -0.08084247 | BM21: % of Revenue | BN21: =BN20/BN10 -> -0.12007261 | BO21: -0.15052771 | BR21: =BR20/BR10 -> -0.12007261 | BV21: % of Revenue | BW21: =BW20/BW10 -> -0.23010555 | BX21: -0.21643312 | CA21: =CA20/CA10 -> -0.23010555 | CE21: % of Revenue | CF21: =CF20/CF10 -> -0.13416027 | CG21: -0.1404424 | CJ21: =CJ20/CJ10 -> -0.13416027 | CN21: % of Revenue | CO21: =CO20/CO10 -> -0.10086111 | CP21: -0.10602555 | CS21: =CS20/CS10 -> -0.10086111 | CW21: % of Revenue | CX21: =CX20/CX10 -> -0.16254604 | CY21: -0.21922678 | DB21: =DB20/DB10 -> -0.16254604 | DF21: % of Revenue | DG21: =DG20/DG10 -> -0.096136488 | DH21: =DH20/DH10 -> -0.099832983 | DK21: =DK20/DK10 -> -0.096136488
B22: Gastos Fijos | C22: =C20+C15 -> -295.42844 | D22: -214.98377 | E22: =C22-D22 -> -80.44467 | F22: =+IF(IFERROR(C22/D22-1,"-")<300%,IFERROR(C22/D22-1,"-"),"n.a.") -> 0.3741895 | G22: =G20+G15 -> -295.42844 | H22: =C22-G22 -> 0 | I22: =+IF(IFERROR(C22/G22-1,"-")<300%,IFERROR(C22/G22-1,"-"),"n.a.") -> 0 | K22: Gastos Fijos | L22: =L20+L15 -> -297.79067 | M22: -205.42608 | N22: =L22-M22 -> -92.36459 | O22: =+IF(IFERROR(L22/M22-1,"-")<300%,IFERROR(L22/M22-1,"-"),"n.a.") -> 0.44962446 | P22: =P20+P15 -> -297.79067 | Q22: =L22-P22 -> 0 | R22: =+IF(IFERROR(L22/P22-1,"-")<300%,IFERROR(L22/P22-1,"-"),"n.a.") -> 0 | T22: Gastos Fijos | U22: =U20+U15 -> -304.28566 | V22: -256.83958 | W22: =U22-V22 -> -47.44608 | X22: =+IF(IFERROR(U22/V22-1,"-")<300%,IFERROR(U22/V22-1,"-"),"n.a.") -> 0.18473041 | Y22: =Y20+Y15 -> -304.28566 | Z22: =U22-Y22 -> 0 | AA22: =+IF(IFERROR(U22/Y22-1,"-")<300%,IFERROR(U22/Y22-1,"-"),"n.a.") -> 0 | AC22: Gastos Fijos | AD22: =AD20+AD15 -> -306.26524 | AE22: -237.00357 | AF22: =AD22-AE22 -> -69.26167 | AG22: =+IF(IFERROR(AD22/AE22-1,"-")<300%,IFERROR(AD22/AE22-1,"-"),"n.a.") -> 0.29223893 | AH22: =AH20+AH15 -> -306.26524 | AI22: =AD22-AH22 -> 0 | AJ22: =+IF(IFERROR(AD22/AH22-1,"-")<300%,IFERROR(AD22/AH22-1,"-"),"n.a.") -> 0 | AL22: Gastos Fijos | AM22: =AM20+AM15 -> -308.44065 | AN22: -233.24385 | AO22: =AM22-AN22 -> -75.1968 | AP22: =+IF(IFERROR(AM22/AN22-1,"-")<300%,IFERROR(AM22/AN22-1,"-"),"n.a.") -> 0.32239564 | AQ22: =AQ20+AQ15 -> -308.44065 | AR22: =AM22-AQ22 -> 0 | AS22: =+IF(IFERROR(AM22/AQ22-1,"-")<300%,IFERROR(AM22/AQ22-1,"-"),"n.a.") -> 0 | AU22: Gastos Fijos | AV22: =AV20+AV15 -> -290.23542 | AW22: -297.10844 | AX22: =AV22-AW22 -> 6.87302 | AY22: =+IF(IFERROR(AV22/AW22-1,"-")<300%,IFERROR(AV22/AW22-1,"-"),"n.a.") -> -0.023133035 | AZ22: =AZ20+AZ15 -> -290.23542 | BA22: =AV22-AZ22 -> 0 | BB22: =+IF(IFERROR(AV22/AZ22-1,"-")<300%,IFERROR(AV22/AZ22-1,"-"),"n.a.") -> 0 | BD22: Gastos Fijos | BE22: =BE20+BE15 -> -281.86648 | BF22: -303.55815 | BG22: =BE22-BF22 -> 21.691674 | BH22: =+IF(IFERROR(BE22/BF22-1,"-")<300%,IFERROR(BE22/BF22-1,"-"),"n.a.") -> -0.071458052 | BI22: =BI20+BI15 -> -281.86648 | BJ22: =BE22-BI22 -> 0 | BK22: =+IF(IFERROR(BE22/BI22-1,"-")<300%,IFERROR(BE22/BI22-1,"-"),"n.a.") -> 0 | BM22: Gastos Fijos | BN22: =BN20+BN15 -> -275.63778 | BO22: -271.26445 | BP22: =BN22-BO22 -> -4.373329 | BQ22: =+IF(IFERROR(BN22/BO22-1,"-")<300%,IFERROR(BN22/BO22-1,"-"),"n.a.") -> 0.016122013 | BR22: =BR20+BR15 -> -275.63778 | BS22: =BN22-BR22 -> 0 | BT22: =+IF(IFERROR(BN22/BR22-1,"-")<300%,IFERROR(BN22/BR22-1,"-"),"n.a.") -> 0 | BV22: Gastos Fijos | BW22: =BW20+BW15 -> -288.45669 | BX22: -257.18811 | BY22: =BW22-BX22 -> -31.26858 | BZ22: =+IF(IFERROR(BW22/BX22-1,"-")<300%,IFERROR(BW22/BX22-1,"-"),"n.a.") -> 0.12157864 | CA22: =CA20+CA15 -> -288.45669 | CB22: =BW22-CA22 -> 0 | CC22: =+IF(IFERROR(BW22/CA22-1,"-")<300%,IFERROR(BW22/CA22-1,"-"),"n.a.") -> 0 | CE22: Gastos Fijos | CF22: =CF20+CF15 -> -285.31338 | CG22: -280.72398 | CH22: =CF22-CG22 -> -4.5894 | CI22: =+IF(IFERROR(CF22/CG22-1,"-")<300%,IFERROR(CF22/CG22-1,"-"),"n.a.") -> 0.016348443 | CJ22: =CJ20+CJ15 -> -285.31338 | CK22: =CF22-CJ22 -> 0 | CL22: =+IF(IFERROR(CF22/CJ22-1,"-")<300%,IFERROR(CF22/CJ22-1,"-"),"n.a.") -> 0 | CN22: Gastos Fijos | CO22: =CO20+CO15 -> -306.23907 | CP22: -282.54821 | CQ22: =CO22-CP22 -> -23.69086 | CR22: =+IF(IFERROR(CO22/CP22-1,"-")<300%,IFERROR(CO22/CP22-1,"-"),"n.a.") -> 0.083847142 | CS22: =CS20+CS15 -> -306.23907 | CT22: =CO22-CS22 -> 0 | CU22: =+IF(IFERROR(CO22/CS22-1,"-")<300%,IFERROR(CO22/CS22-1,"-"),"n.a.") -> 0 | CW22: Gastos Fijos | CX22: =CX20+CX15 -> -693.93455 | CY22: -682.07908 | CZ22: =CX22-CY22 -> -11.85547 | DA22: =+IF(IFERROR(CX22/CY22-1,"-")<300%,IFERROR(CX22/CY22-1,"-"),"n.a.") -> 0.017381372 | DB22: =DB20+DB15 -> -693.93455 | DC22: =CX22-DB22 -> 0 | DD22: =+IF(IFERROR(CX22/DB22-1,"-")<300%,IFERROR(CX22/DB22-1,"-"),"n.a.") -> 0 | DF22: Gastos Fijos | DG22: =DG20+DG15 -> -3933.894 | DH22: =DH20+DH15 -> -3521.9673 | DI22: =DG22-DH22 -> -411.92675 | DJ22: =+IF(IFERROR(DG22/DH22-1,"-")<300%,IFERROR(DG22/DH22-1,"-"),"n.a.") -> 0.11695928 | DK22: =DK20+DK15 -> -3933.894 | DL22: =DG22-DK22 -> 0 | DM22: =+IF(IFERROR(DG22/DK22-1,"-")<300%,IFERROR(DG22/DK22-1,"-"),"n.a.") -> 0
B23: % of Revenue | C23: =C22/C10 -> -0.25830204 | D23: -0.21852005 | G23: =G22/G10 -> -0.25830204 | K23: % of Revenue | L23: =L22/L10 -> -0.16073844 | M23: -0.13970494 | P23: =P22/P10 -> -0.16073844 | T23: % of Revenue | U23: =U22/U10 -> -0.17122268 | V23: -0.16745427 | Y23: =Y22/Y10 -> -0.17122268 | AC23: % of Revenue | AD23: =AD22/AD10 -> -0.21405895 | AE23: -0.16209293 | AH23: =AH22/AH10 -> -0.21405895 | AL23: % of Revenue | AM23: =AM22/AM10 -> -0.13130546 | AN23: -0.12110713 | AQ23: =AQ22/AQ10 -> -0.13130546 | AU23: % of Revenue | AV23: =AV22/AV10 -> -0.12459216 | AW23: -0.15141121 | AZ23: =AZ22/AZ10 -> -0.12459216 | BD23: % of Revenue | BE23: =BE22/BE10 -> -0.19071032 | BF23: -0.23519712 | BI23: =BI22/BI10 -> -0.19071032 | BM23: % of Revenue | BN23: =BN22/BN10 -> -0.29223024 | BO23: -0.3441983 | BR23: =BR22/BR10 -> -0.29223024 | BV23: % of Revenue | BW23: =BW22/BW10 -> -0.52648056 | BX23: -0.53238826 | CA23: =CA22/CA10 -> -0.52648056 | CE23: % of Revenue | CF23: =CF22/CF10 -> -0.31137656 | CG23: -0.30779282 | CJ23: =CJ22/CJ10 -> -0.31137656 | CN23: % of Revenue | CO23: =CO22/CO10 -> -0.21621452 | CP23: -0.23059103 | CS23: =CS22/CS10 -> -0.21621452 | CW23: % of Revenue | CX23: =CX22/CX10 -> -0.446656 | CY23: -0.59705416 | DB23: =DB22/DB10 -> -0.446656 | DF23: % of Revenue | DG23: =DG22/DG10 -> -0.22177576 | DH23: =DH22/DH10 -> -0.23201365 | DK23: =DK22/DK10 -> -0.22177576
B24: Adjusted EBITDA | C24: =C12+C22 -> 518.31963 | D24: 266.16781 | E24: =C24-D24 -> 252.15182 | F24: =+IF(IFERROR(C24/D24-1,"-")<300%,IFERROR(C24/D24-1,"-"),"n.a.") -> 0.94734153 | G24: =G12+G22 -> 518.31963 | H24: =C24-G24 -> 0 | I24: =+IF(IFERROR(C24/G24-1,"-")<300%,IFERROR(C24/G24-1,"-"),"n.a.") -> 0 | K24: Adjusted EBITDA | L24: =L12+L22 -> 922.69083 | M24: 908.76491 | N24: =L24-M24 -> 13.92592 | O24: =+IF(IFERROR(L24/M24-1,"-")<300%,IFERROR(L24/M24-1,"-"),"n.a.") -> 0.015324007 | P24: =P12+P22 -> 922.69083 | Q24: =L24-P24 -> 0 | R24: =+IF(IFERROR(L24/P24-1,"-")<300%,IFERROR(L24/P24-1,"-"),"n.a.") -> 0 | T24: Adjusted EBITDA | U24: =U12+U22 -> 807.86807 | V24: 891.2499 | W24: =U24-V24 -> -83.38183 | X24: =+IF(IFERROR(U24/V24-1,"-")<300%,IFERROR(U24/V24-1,"-"),"n.a.") -> -0.093556061 | Y24: =Y12+Y22 -> 807.86807 | Z24: =U24-Y24 -> 0 | AA24: =+IF(IFERROR(U24/Y24-1,"-")<300%,IFERROR(U24/Y24-1,"-"),"n.a.") -> 0 | AC24: Adjusted EBITDA | AD24: =AD12+AD22 -> 606.71847 | AE24: 718.93962 | AF24: =AD24-AE24 -> -112.22115 | AG24: =+IF(IFERROR(AD24/AE24-1,"-")<300%,IFERROR(AD24/AE24-1,"-"),"n.a.") -> -0.15609259 | AH24: =AH12+AH22 -> 606.71847 | AI24: =AD24-AH24 -> 0 | AJ24: =+IF(IFERROR(AD24/AH24-1,"-")<300%,IFERROR(AD24/AH24-1,"-"),"n.a.") -> 0 | AL24: Adjusted EBITDA | AM24: =AM12+AM22 -> 1202.5326 | AN24: 1068.4137 | AO24: =AM24-AN24 -> 134.11885 | AP24: =+IF(IFERROR(AM24/AN24-1,"-")<300%,IFERROR(AM24/AN24-1,"-"),"n.a.") -> 0.12553082 | AQ24: =AQ12+AQ22 -> 1202.5326 | AR24: =AM24-AQ24 -> 0 | AS24: =+IF(IFERROR(AM24/AQ24-1,"-")<300%,IFERROR(AM24/AQ24-1,"-"),"n.a.") -> 0 | AU24: Adjusted EBITDA | AV24: =AV12+AV22 -> 1174.5094 | AW24: 921.5948 | AX24: =AV24-AW24 -> 252.91456 | AY24: =+IF(IFERROR(AV24/AW24-1,"-")<300%,IFERROR(AV24/AW24-1,"-"),"n.a.") -> 0.27443141 | AZ24: =AZ12+AZ22 -> 1174.5094 | BA24: =AV24-AZ24 -> 0 | BB24: =+IF(IFERROR(AV24/AZ24-1,"-")<300%,IFERROR(AV24/AZ24-1,"-"),"n.a.") -> 0 | BD24: Adjusted EBITDA | BE24: =BE12+BE22 -> 634.10463 | BF24: 461.78105 | BG24: =BE24-BF24 -> 172.32358 | BH24: =+IF(IFERROR(BE24/BF24-1,"-")<300%,IFERROR(BE24/BF24-1,"-"),"n.a.") -> 0.37317163 | BI24: =BI12+BI22 -> 634.10463 | BJ24: =BE24-BI24 -> 0 | BK24: =+IF(IFERROR(BE24/BI24-1,"-")<300%,IFERROR(BE24/BI24-1,"-"),"n.a.") -> 0 | BM24: Adjusted EBITDA | BN24: =BN12+BN22 -> 327.62536 | BO24: 244.72047 | BP24: =BN24-BO24 -> 82.904891 | BQ24: =+IF(IFERROR(BN24/BO24-1,"-")<300%,IFERROR(BN24/BO24-1,"-"),"n.a.") -> 0.33877383 | BR24: =BR12+BR22 -> 327.62536 | BS24: =BN24-BR24 -> 0 | BT24: =+IF(IFERROR(BN24/BR24-1,"-")<300%,IFERROR(BN24/BR24-1,"-"),"n.a.") -> 0 | BV24: Adjusted EBITDA | BW24: =BW12+BW22 -> 49.42675 | BX24: 64.10467 | BY24: =BW24-BX24 -> -14.67792 | BZ24: =+IF(IFERROR(BW24/BX24-1,"-")<300%,IFERROR(BW24/BX24-1,"-"),"n.a.") -> -0.22896803 | CA24: =CA12+CA22 -> 49.42675 | CB24: =BW24-CA24 -> 0 | CC24: =+IF(IFERROR(BW24/CA24-1,"-")<300%,IFERROR(BW24/CA24-1,"-"),"n.a.") -> 0 | CE24: Adjusted EBITDA | CF24: =CF12+CF22 -> 288.39186 | CG24: 329.22967 | CH24: =CF24-CG24 -> -40.83781 | CI24: =+IF(IFERROR(CF24/CG24-1,"-")<300%,IFERROR(CF24/CG24-1,"-"),"n.a.") -> -0.12404049 | CJ24: =CJ12+CJ22 -> 288.39186 | CK24: =CF24-CJ24 -> 0 | CL24: =+IF(IFERROR(CF24/CJ24-1,"-")<300%,IFERROR(CF24/CJ24-1,"-"),"n.a.") -> 0 | CN24: Adjusted EBITDA | CO24: =CO12+CO22 -> 567.45787 | CP24: 538.35029 | CQ24: =CO24-CP24 -> 29.10758 | CR24: =+IF(IFERROR(CO24/CP24-1,"-")<300%,IFERROR(CO24/CP24-1,"-"),"n.a.") -> 0.054068105 | CS24: =CS12+CS22 -> 567.45787 | CT24: =CO24-CS24 -> 0 | CU24: =+IF(IFERROR(CO24/CS24-1,"-")<300%,IFERROR(CO24/CS24-1,"-"),"n.a.") -> 0 | CW24: Adjusted EBITDA | CX24: =CX12+CX22 -> 297.37436 | CY24: 11.18297 | CZ24: =CX24-CY24 -> 286.19139 | DA24: =+IF(IFERROR(CX24/CY24-1,"-")<300%,IFERROR(CX24/CY24-1,"-"),"n.a.") -> n.a. | DB24: =DB12+DB22 -> 297.37436 | DC24: =CX24-DB24 -> 0 | DD24: =+IF(IFERROR(CX24/DB24-1,"-")<300%,IFERROR(CX24/DB24-1,"-"),"n.a.") -> 0 | DF24: Adjusted EBITDA | DG24: =DG12+DG22 -> 7397.0198 | DH24: =DH12+DH22 -> 6424.4999 | DI24: =DG24-DH24 -> 972.51989 | DJ24: =+IF(IFERROR(DG24/DH24-1,"-")<300%,IFERROR(DG24/DH24-1,"-"),"n.a.") -> 0.15137675 | DK24: =DK12+DK22 -> 7397.0198 | DL24: =DG24-DK24 -> 0 | DM24: =+IF(IFERROR(DG24/DK24-1,"-")<300%,IFERROR(DG24/DK24-1,"-"),"n.a.") -> 0
B25: % Adj. EBITDA Margin | C25: =C24/C10 -> 0.45318257 | D25: 0.27054602 | F25: =+IF(IFERROR(C25/D25-1,"-")<300%,IFERROR(C25/D25-1,"-"),"n.a.") -> 0.67506646 | G25: =G24/G10 -> 0.45318257 | K25: % Adj. EBITDA Margin | L25: =L24/L10 -> 0.49804074 | M25: 0.61802742 | O25: =+IF(IFERROR(L25/M25-1,"-")<300%,IFERROR(L25/M25-1,"-"),"n.a.") -> -0.19414458 | P25: =P24/P10 -> 0.49804074 | T25: % Adj. EBITDA Margin | U25: =U24/U10 -> 0.45459038 | V25: 0.5810771 | X25: =+IF(IFERROR(U25/V25-1,"-")<300%,IFERROR(U25/V25-1,"-"),"n.a.") -> -0.21767631 | Y25: =Y24/Y10 -> 0.45459038 | AC25: % Adj. EBITDA Margin | AD25: =AD24/AD10 -> 0.4240557 | AE25: 0.49170157 | AG25: =+IF(IFERROR(AD25/AE25-1,"-")<300%,IFERROR(AD25/AE25-1,"-"),"n.a.") -> -0.13757506 | AH25: =AH24/AH10 -> 0.4240557 | AL25: % Adj. EBITDA Margin | AM25: =AM24/AM10 -> 0.51192698 | AN25: 0.55475213 | AP25: =+IF(IFERROR(AM25/AN25-1,"-")<300%,IFERROR(AM25/AN25-1,"-"),"n.a.") -> -0.077196903 | AQ25: =AQ24/AQ10 -> 0.51192698 | AU25: % Adj. EBITDA Margin | AV25: =AV24/AV10 -> 0.50419298 | AW25: 0.46965944 | AY25: =+IF(IFERROR(AV25/AW25-1,"-")<300%,IFERROR(AV25/AW25-1,"-"),"n.a.") -> 0.073528892 | AZ25: =AZ24/AZ10 -> 0.50419298 | BD25: % Adj. EBITDA Margin | BE25: =BE24/BE10 -> 0.42903398 | BF25: 0.35778835 | BH25: =+IF(IFERROR(BE25/BF25-1,"-")<300%,IFERROR(BE25/BF25-1,"-"),"n.a.") -> 0.19912786 | BI25: =BI24/BI10 -> 0.42903398 | BM25: % Adj. EBITDA Margin | BN25: =BN24/BN10 -> 0.3473473 | BO25: 0.31051754 | BQ25: =+IF(IFERROR(BN25/BO25-1,"-")<300%,IFERROR(BN25/BO25-1,"-"),"n.a.") -> 0.11860767 | BR25: =BR24/BR10 -> 0.3473473 | BV25: % Adj. EBITDA Margin | BW25: =BW24/BW10 -> 0.09021189 | BX25: 0.13269888 | BZ25: =+IF(IFERROR(BW25/BX25-1,"-")<300%,IFERROR(BW25/BX25-1,"-"),"n.a.") -> -0.32017594 | CA25: =CA24/CA10 -> 0.09021189 | CE25: % Adj. EBITDA Margin | CF25: =CF24/CF10 -> 0.31473626 | CG25: 0.36097567 | CI25: =+IF(IFERROR(CF25/CG25-1,"-")<300%,IFERROR(CF25/CG25-1,"-"),"n.a.") -> -0.12809565 | CJ25: =CJ24/CJ10 -> 0.31473626 | CN25: % Adj. EBITDA Margin | CO25: =CO24/CO10 -> 0.4006433 | CP25: 0.43935422 | CR25: =+IF(IFERROR(CO25/CP25-1,"-")<300%,IFERROR(CO25/CP25-1,"-"),"n.a.") -> -0.088108675 | CS25: =CS24/CS10 -> 0.4006433 | CW25: % Adj. EBITDA Margin | CX25: =CX24/CX10 -> 0.19140716 | CY25: 0.0097889511 | DA25: =+IF(IFERROR(CX25/CY25-1,"-")<300%,IFERROR(CX25/CY25-1,"-"),"n.a.") -> n.a. | DB25: =DB24/DB10 -> 0.19140716 | DF25: % Adj. EBITDA Margin | DG25: =DG24/DG10 -> 0.41701167 | DH25: =DH24/DH10 -> 0.42322134 | DJ25: =+IF(IFERROR(DG25/DH25-1,"-")<300%,IFERROR(DG25/DH25-1,"-"),"n.a.") -> -0.014672395 | DK25: =DK24/DK10 -> 0.41701167
