Workbook

Sheet Resumen
A2: CODIAGRO – PRESUPUESTO DE MARKETING 2027
A4: Programas integrados por cliente construidos desde las familias A/B, su ciclo de vida y su rol estratégico
A6: Ventas presupuestadas 2027 | B6: =Supuestos!B3 -> 17738160 | D6: Plan asignado | E6: =SUM('Plan acciones'!Q5:Q500) -> 266072.4 | G6: Reserva táctica | H6: =SUMIF('Plan acciones'!B5:B500,"Reserva táctica",'Plan acciones'!Q5:Q500) -> 10372.4
A7: Presupuesto MKT | B7: =Supuestos!B4 -> 266072.4 | D7: Inversión / ventas | E7: =E6/B6 -> 0.015 | G7: Diferencia vs límite | H7: =B7-E6 -> 0
A10: Bloque presupuestario | B10: Presupuesto (€) | C10: % total | E10: Mes | F10: Presupuesto (€) | G10: % anual | H10: Acciones / líneas | J10: Datos gráfico | K10: Presupuesto
A11: Ferias y encuentros | B11: =SUMIF('Plan acciones'!B5:B500,A11,'Plan acciones'!Q5:Q500) -> 33770 | C11: =B11/$B$7 -> 0.12692034 | E11: Enero | F11: =SUMIFS('Plan acciones'!Q5:Q500,'Plan acciones'!D5:D500,1,'Plan acciones'!B5:B500,"<>Cliente-producto")+SUMIF('Diseño A-B'!Q5:Q600,1,'Diseño A-B'!S5:S600) -> 25641 | G11: =F11/$B$7 -> 0.096368507 | H11: =COUNTIFS('Plan acciones'!D5:D500,1,'Plan acciones'!B5:B500,"<>Cliente-producto")+COUNTIFS('Diseño A-B'!Q5:Q600,1,'Diseño A-B'!S5:S600,">0") -> 37 | J11: Ferias y encuentros | K11: =B11 -> 33770
A12: Corporativo y transversal | B12: =SUMIF('Plan acciones'!B5:B500,A12,'Plan acciones'!Q5:Q500) -> 25630 | C12: =B12/$B$7 -> 0.096327165 | E12: Febrero | F12: =SUMIFS('Plan acciones'!Q5:Q500,'Plan acciones'!D5:D500,2,'Plan acciones'!B5:B500,"<>Cliente-producto")+SUMIF('Diseño A-B'!Q5:Q600,2,'Diseño A-B'!S5:S600) -> 31207 | G12: =F12/$B$7 -> 0.11728763 | H12: =COUNTIFS('Plan acciones'!D5:D500,2,'Plan acciones'!B5:B500,"<>Cliente-producto")+COUNTIFS('Diseño A-B'!Q5:Q600,2,'Diseño A-B'!S5:S600,">0") -> 25 | J12: Corporativo y transversal | K12: =B12 -> 25630
A13: Cliente-producto | B13: =SUMIF('Plan acciones'!B5:B500,A13,'Plan acciones'!Q5:Q500) -> 196300 | C13: =B13/$B$7 -> 0.73776912 | E13: Marzo | F13: =SUMIFS('Plan acciones'!Q5:Q500,'Plan acciones'!D5:D500,3,'Plan acciones'!B5:B500,"<>Cliente-producto")+SUMIF('Diseño A-B'!Q5:Q600,3,'Diseño A-B'!S5:S600) -> 29843 | G13: =F13/$B$7 -> 0.1121612 | H13: =COUNTIFS('Plan acciones'!D5:D500,3,'Plan acciones'!B5:B500,"<>Cliente-producto")+COUNTIFS('Diseño A-B'!Q5:Q600,3,'Diseño A-B'!S5:S600,">0") -> 42 | J13: Cliente-producto | K13: =B13 -> 196300
A14: Reserva táctica | B14: =SUMIF('Plan acciones'!B5:B500,A14,'Plan acciones'!Q5:Q500) -> 10372.4 | C14: =B14/$B$7 -> 0.038983374 | E14: Abril | F14: =SUMIFS('Plan acciones'!Q5:Q500,'Plan acciones'!D5:D500,4,'Plan acciones'!B5:B500,"<>Cliente-producto")+SUMIF('Diseño A-B'!Q5:Q600,4,'Diseño A-B'!S5:S600) -> 33565 | G14: =F14/$B$7 -> 0.12614987 | H14: =COUNTIFS('Plan acciones'!D5:D500,4,'Plan acciones'!B5:B500,"<>Cliente-producto")+COUNTIFS('Diseño A-B'!Q5:Q600,4,'Diseño A-B'!S5:S600,">0") -> 40 | J14: Reserva táctica | K14: =B14 -> 10372.4
A15: TOTAL | B15: =SUM(B11:B14) -> 266072.4 | C15: =SUM(C11:C14) -> 1 | E15: Mayo | F15: =SUMIFS('Plan acciones'!Q5:Q500,'Plan acciones'!D5:D500,5,'Plan acciones'!B5:B500,"<>Cliente-producto")+SUMIF('Diseño A-B'!Q5:Q600,5,'Diseño A-B'!S5:S600) -> 26406 | G15: =F15/$B$7 -> 0.099243665
E16: Junio | F16: =SUMIFS('Plan acciones'!Q5:Q500,'Plan acciones'!D5:D500,6,'Plan acciones'!B5:B500,"<>Cliente-producto")+SUMIF('Diseño A-B'!Q5:Q600,6,'Diseño A-B'!S5:S600) -> 18861 | G16: =F16/$B$7 -> 0.070886721 | H16: =COUNTIFS('Plan acciones'!D5:D500,6,'Plan acciones'!B5:B500,"<>Cliente-producto")+COUNTIFS('Diseño A-B'!Q5:Q600,6,'Diseño A-B'!S5:S600,">0") -> 30
E17: Julio | F17: =SUMIFS('Plan acciones'!Q5:Q500,'Plan acciones'!D5:D500,7,'Plan acciones'!B5:B500,"<>Cliente-producto")+SUMIF('Diseño A-B'!Q5:Q600,7,'Diseño A-B'!S5:S600) -> 16163 | G17: =F17/$B$7 -> 0.060746624 | H17: =COUNTIFS('Plan acciones'!D5:D500,7,'Plan acciones'!B5:B500,"<>Cliente-producto")+COUNTIFS('Diseño A-B'!Q5:Q600,7,'Diseño A-B'!S5:S600,">0") -> 23
A18: Prioridad cliente–familia | B18: Combinaciones | C18: Ventas 2027 (€) | E18: Agosto | F18: =SUMIFS('Plan acciones'!Q5:Q500,'Plan acciones'!D5:D500,8,'Plan acciones'!B5:B500,"<>Cliente-producto")+SUMIF('Diseño A-B'!Q5:Q600,8,'Diseño A-B'!S5:S600) -> 6831 | G18: =F18/$B$7 -> 0.025673463 | H18: =COUNTIFS('Plan acciones'!D5:D500,8,'Plan acciones'!B5:B500,"<>Cliente-producto")+COUNTIFS('Diseño A-B'!Q5:Q600,8,'Diseño A-B'!S5:S600,">0") -> 5
A19: A | B19: 176 | C19: 12564756 | E19: Septiembre | F19: =SUMIFS('Plan acciones'!Q5:Q500,'Plan acciones'!D5:D500,9,'Plan acciones'!B5:B500,"<>Cliente-producto")+SUMIF('Diseño A-B'!Q5:Q600,9,'Diseño A-B'!S5:S600) -> 19390 | G19: =F19/$B$7 -> 0.072874902 | H19: =COUNTIFS('Plan acciones'!D5:D500,9,'Plan acciones'!B5:B500,"<>Cliente-producto")+COUNTIFS('Diseño A-B'!Q5:Q600,9,'Diseño A-B'!S5:S600,">0") -> 11
A20: B | B20: 311 | C20: 3774932.6 | E20: Octubre | F20: =SUMIFS('Plan acciones'!Q5:Q500,'Plan acciones'!D5:D500,10,'Plan acciones'!B5:B500,"<>Cliente-producto")+SUMIF('Diseño A-B'!Q5:Q600,10,'Diseño A-B'!S5:S600) -> 13399 | G20: =F20/$B$7 -> 0.050358474 | H20: =COUNTIFS('Plan acciones'!D5:D500,10,'Plan acciones'!B5:B500,"<>Cliente-producto")+COUNTIFS('Diseño A-B'!Q5:Q600,10,'Diseño A-B'!S5:S600,">0") -> 15
A21: C | B21: 161 | C21: 1044695.7 | E21: Noviembre | F21: =SUMIFS('Plan acciones'!Q5:Q500,'Plan acciones'!D5:D500,11,'Plan acciones'!B5:B500,"<>Cliente-producto")+SUMIF('Diseño A-B'!Q5:Q600,11,'Diseño A-B'!S5:S600) -> 28994 | G21: =F21/$B$7 -> 0.10897034 | H21: =COUNTIFS('Plan acciones'!D5:D500,11,'Plan acciones'!B5:B500,"<>Cliente-producto")+COUNTIFS('Diseño A-B'!Q5:Q600,11,'Diseño A-B'!S5:S600,">0") -> 17
A22: D | B22: 81 | C22: 353775.74 | E22: Diciembre | F22: =SUMIFS('Plan acciones'!Q5:Q500,'Plan acciones'!D5:D500,12,'Plan acciones'!B5:B500,"<>Cliente-producto")+SUMIF('Diseño A-B'!Q5:Q600,12,'Diseño A-B'!S5:S600) -> 15772.4 | G22: =F22/$B$7 -> 0.059278602 | H22: =COUNTIFS('Plan acciones'!D5:D500,12,'Plan acciones'!B5:B500,"<>Cliente-producto")+COUNTIFS('Diseño A-B'!Q5:Q600,12,'Diseño A-B'!S5:S600,">0") -> 3
A25: Criterio temporal: el plan del cliente comienza dos meses antes de su pico conjunto; la ejecución y el presupuesto de cada familia se sitúan un mes antes de su propio pico de ventas.

Sheet Plan acciones
A2: Plan integrado de acciones y presupuesto
A4: ID | B4: Bloque | C4: Categoría | D4: Mes inicio plan acciones | E4: Comercial | F4: País | G4: Cliente | H4: Clasificación cliente | I4: Nº familias A/B | J4: Mix prioridad | K4: Familias foco | L4: Programa integrado | M4: Componentes 2027 | N4: Público objetivo | O4: Intensidad | P4: Score máximo | Q4: Presupuesto total programa (€) | R4: Estado / nota
A5: 1 | B5: Ferias y encuentros | C5: Ferias | D5: 10 | F5: ESPAÑA | L5: Fruit Attraction | Q5: 3420 | R5: Estimación inicial
A6: 2 | B6: Ferias y encuentros | C6: Ferias | D6: 2 | F6: ALEMANIA | L6: Fruit Logistica | Q6: 3710 | R6: Estimación inicial
A7: 3 | B7: Ferias y encuentros | C7: Ferias | D7: 9 | F7: EGIPTO | L7: Sahara Expo | Q7: 3990 | R7: Estimación inicial
A8: 4 | B8: Ferias y encuentros | C8: Ferias | D8: 11 | F8: TURQUÍA | L8: Growtech | Q8: 3430 | R8: Estimación inicial
A9: 5 | B9: Ferias y encuentros | C9: Ferias | D9: 10 | F9: RUMANÍA | L9: INDAGRA | Q9: 2540 | R9: Estimación inicial
A10: 6 | B10: Ferias y encuentros | C10: Ferias | D10: 5 | F10: AZERBAIYÁN | L10: Caspian Agro | Q10: 4240 | R10: Estimación inicial
A11: 7 | B11: Ferias y encuentros | C11: Ferias | D11: 4 | F11: MARRUECOS | L11: SIAM | Q11: 3330 | R11: Estimación inicial
A12: 8 | B12: Ferias y encuentros | C12: Ferias | D12: 11 | F12: MÉXICO | L12: Expo AgroAlimentaria Guanajuato | Q12: 6040 | R12: Estimación inicial
A13: 9 | B13: Ferias y encuentros | C13: Contingencia ferias | D13: 12 | F13: MULTIPAÍS | L13: Contingencia 10% ferias | Q13: 3070 | R13: Estimación inicial
A14: 10 | B14: Corporativo y transversal | C14: Corporativo | D14: 2 | F14: GLOBAL | L14: Actualización catálogo y adaptación digital | Q14: 4300 | R14: Estimación inicial
A15: 11 | B15: Corporativo y transversal | C15: Corporativo | D15: 3 | F15: GLOBAL | L15: Versión inglesa del catálogo | Q15: 1500 | R15: Estimación inicial
A16: 12 | B16: Corporativo y transversal | C16: Corporativo | D16: 4 | F16: GLOBAL | L16: Materiales técnicos bilingües | Q16: 4000 | R16: Estimación inicial
... A28: 24 | B28: Reserva táctica | C28: Reserva | D28: 12 | F28: GLOBAL | L28: Reserva táctica y ajustes | Q28: 10372.4 | R28: Estimación inicial
A29: 25 | B29: Cliente-producto | C29: Programa integrado cliente-producto | D29: 1 | E29: Alfonso | F29: ESPAÑA | G29: ACTIV. PRODUC. Y COMERC. LA VEGUILLA, SL | H29: Consolidado/estratégico | I29: 4 | J29: 3 A / 1 B | K29: BIORAD-20, CODIORGAN A-50, AGROPOTASION | L29: Generación de demanda y adopción | M29: Campo demostrativo: BIORAD-20 | Formación técnica al distribuidor: BIORAD-20, CODIORGAN A-50, AGROPOTASION | Bolsa de muestras: BIORAD-20, CODIORGAN A-50 | N29: Agricultores y técnicos; Equipo comercial y técnico del distribuidor; Distribuidor y agricultores seleccionados | O29: Media | P29: 95 | Q29: 3300 | R29: Programa integrado; validar con Comercial/Técnico
A30: 26 | B30: Cliente-producto | C30: Programa integrado cliente-producto | D30: 1 | E30: García | F30: ESPAÑA | G30: AGROREBOLLO, S.L. | H30: En desarrollo/nuevo | I30: 2 | J30: 1 A / 1 B | K30: AQUOM | L30: Desarrollo de producto | M30: Campo demostrativo: AQUOM | N30: Agricultores y técnicos | O30: Media | P30: 81.02997 | Q30: 2200 | R30: Programa integrado; validar con Comercial/Técnico
A31: 27 | B31: Cliente-producto | C31: Programa integrado cliente-producto | D31: 1 | E31: Ricardo | F31: CHILE | G31: BAYER, S.A. | H31: Consolidado/estratégico | I31: 4 | J31: 2 A / 2 B | K31: BAYFOLAN CALCIO, ALCAPLANT | L31: Desarrollo de producto | M31: Campo demostrativo: BAYFOLAN CALCIO | Jornada técnica con agricultores: ALCAPLANT | N31: Agricultores y técnicos | O31: Alta | P31: 91.25 | Q31: 5600 | R31: Programa integrado; validar con Comercial/Técnico
A32: 28 | B32: Cliente-producto | C32: Programa integrado cliente-producto | D32: 1 | E32: García | F32: ESPAÑA | G32: BOSCO ABASCAL, S.L. | H32: Con potencial | I32: 6 | J32: 2 A / 4 B | K32: AGROXIGREEN-MG, AGROXILATO ZN PLUS | L32: Desarrollo de producto | M32: Campo demostrativo: AGROXIGREEN-MG | Bolsa de muestras: AGROXIGREEN-MG | Campaña de sell-out / consumo: AGROXILATO ZN PLUS | N32: Agricultores y técnicos; Distribuidor y agricultores seleccionados; Distribuidor y compradores | O32: Media | P32: 88.682829 | Q32: 4500 | R32: Programa integrado; validar con Comercial/Técnico
A33: 29 | B33: Cliente-producto | C33: Programa integrado cliente-producto | D33: 1 | E33: Alfonso | F33: ESPAÑA | G33: COMERCIAL NANCLARES, S.L. | H33: Con potencial | I33: 3 | J33: 1 A / 2 B | K33: CODICOBRE, CODIBOR-L | L33: Fidelización y desarrollo de cartera | M33: Campaña de sell-out / consumo: CODICOBRE, CODIBOR-L | N33: Distribuidor y compradores | O33: Media | P33: 86.51901 | Q33: 2000 | R33: Programa integrado; validar con Comercial/Técnico
A34: 30 | B34: Cliente-producto | C34: Programa integrado cliente-producto | D34: 1 | E34: García | F34: EGIPTO | G34: DIPLOMATS ORCHARDS FOR TRADE AGENCIES | H34: Consolidado/estratégico | I34: 6 | J34: 4 A / 2 B | K34: FLORAMEC AVANCE, CODIORGAN A-50, SAL-WAX Ca, AGROXILATO-K, SPRINTENE | L34: Lanzamiento técnico | M34: Formación técnica al distribuidor: FLORAMEC AVANCE, CODIORGAN A-50, SAL-WAX Ca, AGROXILATO-K, SPRINTENE | Jornada técnica con agricultores: SAL-WAX Ca, AGROXILATO-K, SPRINTENE, FLORAMEC AVANCE | Campo demostrativo: FLORAMEC AVANCE | Bolsa de muestras: FLORAMEC AVANCE, CODIORGAN A-50 | N34: Equipo comercial y técnico del distribuidor; Agricultores y técnicos; Distribuidor y agricultores seleccionados | O34: Alta | P34: 91.200967 | Q34: 7200 | R34: Programa integrado; validar con Comercial/Técnico
A35: 31 | B35: Cliente-producto | C35: Programa integrado cliente-producto | D35: 1 | E35: García | F35: EGIPTO | G35: DOTRA CHEMICALS | H35: Consolidado/estratégico | I35: 7 | J35: 4 A / 3 B | K35: FLORAMEC AVANCE, CODIORGAN A-50, SAL-WAX Ca, ALCAPLANT, SPRINTENE, AGROXILATO-K | L35: Lanzamiento técnico | M35: Formación técnica al distribuidor: FLORAMEC AVANCE, CODIORGAN A-50, SAL-WAX Ca, ALCAPLANT, SPRINTENE +1 | Jornada técnica con agricultores: SAL-WAX Ca, ALCAPLANT, SPRINTENE, FLORAMEC AVANCE | Campo demostrativo: FLORAMEC AVANCE | Bolsa de muestras: FLORAMEC AVANCE, CODIORGAN A-50 | N35: Equipo comercial y técnico del distribuidor; Agricultores y técnicos; Distribuidor y agricultores seleccionados | O35: Alta | P35: 91.200967 | Q35: 7200 | R35: Programa integrado; validar con Comercial/Técnico
A36: 32 | B36: Cliente-producto | C36: Programa integrado cliente-producto | D36: 1 | E36: García | F36: ESPAÑA | G36: ECO-PONIENTE, S.L.U. | H36: Baja aportación | I36: 1 | J36: 0 A / 1 B | K36: AGROXILATO-K | L36: Refuerzo técnico y cross-selling | M36: Seguimiento comercial sin inversión específica: AGROXILATO-K | N36: Distribuidor | O36: Seguimiento | P36: 73.716129 | Q36: 0 | R36: Programa integrado; validar con Comercial/Técnico
A37: 33 | B37: Cliente-producto | C37: Programa integrado cliente-producto | D37: 1 | E37: Ricardo | F37: ECUADOR (incluidas las Islas Galápagos) | G37: ECUAQUIMICA | H37: Con potencial | I37: 2 | J37: 1 A / 1 B | K37: ALCAPLANT, CODICOBRE | L37: Refuerzo técnico y cross-selling | M37: Formación técnica al distribuidor: ALCAPLANT | Campaña de sell-out / consumo: CODICOBRE | N37: Equipo comercial y técnico del distribuidor; Distribuidor y compradores | O37: Media | P37: 87.5 | Q37: 4300 | R37: Programa integrado; validar con Comercial/Técnico
A38: 34 | B38: Cliente-producto | C38: Programa integrado cliente-producto | D38: 1 | E38: García | F38: GRECIA | G38: EMPHYTON POULTSIDIS GEORGIOS | H38: Con potencial | I38: 2 | J38: 1 A / 1 B | K38: VITA-S, TONAZ | L38: Refuerzo técnico y cross-selling | M38: Formación técnica al distribuidor: VITA-S | Campaña de sell-out / consumo: TONAZ | N38: Equipo comercial y técnico del distribuidor; Distribuidor y compradores | O38: Media | P38: 83.5 | Q38: 4300 | R38: Programa integrado; validar con Comercial/Técnico
A39: 35 | B39: Cliente-producto | C39: Programa integrado cliente-producto | D39: 1 | E39: Pedro | F39: ESPAÑA | G39: FITOMURCIA S.L. | H39: Consolidado/estratégico | I39: 21 | J39: 7 A / 14 B | K39: HIDROSTRESS, ALCAPLANT, AGROPOTASION, AGROXILATO-COMPLET, BIORAD-20, CODIORGAN A-50, RUN STRESS, FITOKONTROL CA FLOW +2 | L39: Generación de demanda y adopción | M39: Campo demostrativo: HIDROSTRESS | Jornada técnica con agricultores: HIDROSTRESS, ALCAPLANT, AGROPOTASION, AGROXILATO-COMPLET, BIORAD-20 +1 | Bolsa de muestras: HIDROSTRESS, AGROXILATO-COMPLET, BIORAD-20, CODIORGAN A-50, RUN STRESS +3 | N39: Agricultores y técnicos; Distribuidor y agricultores seleccionados | O39: Media | P39: 87.75 | Q39: 4100 | R39: Programa integrado; validar con Comercial/Técnico
A40: 36 | B40: Cliente-producto | C40: Programa integrado cliente-producto | D40: 1 | E40: Ricardo | F40: PERÚ | G40: HORTIFRUT PERU, S.A.C. | H40: Consolidado/estratégico | I40: 1 | J40: 0 A / 1 B | K40: FITOKONTROL-K | L40: Campaña de consumo y volumen | M40: Campaña de sell-out / consumo: FITOKONTROL-K | N40: Distribuidor y compradores | O40: Media | P40: 72.5 | Q40: 3000 | R40: Programa integrado; validar con Comercial/Técnico
... A110: 106 | B110: Cliente-producto | C110: Programa integrado cliente-producto | D110: 10 | E110: García | F110: MARRUECOS | G110: STE BBMAGRI, SARL | H110: Consolidado/estratégico | I110: 14 | J110: 5 A / 9 B | K110: BIORAD-20, AGROXILATO-K, FLORAMEC AVANCE, ALCAPLANT, CODIORGAN A-50, FITOKONTROL CA FLOW, RUN STRESS, AGROXIGREEN-MG | L110: Generación de demanda y adopción | M110: Campo demostrativo: BIORAD-20 | Jornada técnica con agricultores: BIORAD-20, AGROXILATO-K, FLORAMEC AVANCE, ALCAPLANT | Bolsa de muestras: BIORAD-20, CODIORGAN A-50, FITOKONTROL CA FLOW, RUN STRESS, AGROXIGREEN-MG | N110: Agricultores y técnicos; Distribuidor y agricultores seleccionados | O110: Alta | P110: 95 | Q110: 5900 | R110: Programa integrado; validar con Comercial/Técnico

Sheet Diseño A-B
A2: Diseño de Marketing para familias A y B
A4: Comercial | B4: País | C4: Cliente | D4: Clasificación cliente | E4: Familia | F4: Ventas 2027 (€) | G4: Score | H4: Prioridad | I4: Ciclo dominante | J4: Rol dominante | K4: Objetivo de Marketing | L4: Programa recomendado | M4: Acciones recomendadas | N4: Público objetivo | O4: Intensidad recomendada | P4: Mes pico ventas | Q4: Mes ejecución (-1) | R4: Componentes presupuestados | S4: Presupuesto asignado (€)
A5: Alfonso | B5: ESPAÑA | C5: ACTIV. PRODUC. Y COMERC. LA VEGUILLA, SL | D5: Consolidado/estratégico | E5: BIORAD-20 | F5: 10761.87 | G5: 95 | H5: A | I5: Ramp-Up/Crecimiento | J5: Innovador/Notorio | K5: Generar demanda, referencias y prescripción técnica | L5: Generación de demanda y adopción | M5: Campo demostrativo; formación técnica; jornada con agricultores y desarrollo de casos | N5: Distribuidor, técnicos y agricultores | O5: Alta | P5: 9 | Q5: 8 | R5: Campo demostrativo; Bolsa de muestras; Formación técnica al distribuidor | S5: 2635
A6: Alfonso | B6: ESPAÑA | C6: ACTIV. PRODUC. Y COMERC. LA VEGUILLA, SL | D6: Consolidado/estratégico | E6: CODIORGAN A-50 | F6: 8004.21 | G6: 91.335273 | H6: A | I6: Ramp-Up/Crecimiento | J6: Esencial/Core | K6: Ampliar adopción y repetición de compra | L6: Desarrollo de producto | M6: Demostración; formación de prescripción; muestras y venta cruzada | N6: Equipo del distribuidor y agricultores | O6: Alta | P6: 3 | Q6: 2 | R6: Bolsa de muestras; Formación técnica al distribuidor | S6: 322
A7: Alfonso | B7: ESPAÑA | C7: ACTIV. PRODUC. Y COMERC. LA VEGUILLA, SL | D7: Consolidado/estratégico | E7: AGROPOTASION | F7: 14909.75 | G7: 91.212102 | H7: A | I7: Maduro | J7: Innovador/Notorio | K7: Defender la prescripción y ampliar venta cruzada | L7: Refuerzo técnico y cross-selling | M7: Actualización técnica; casos de referencia y jornada selectiva con agricultores | N7: Técnicos del distribuidor y agricultores clave | O7: Alta | P7: 4 | Q7: 3 | R7: Formación técnica al distribuidor | S7: 343
A8: Alfonso | B8: ESPAÑA | C8: ACTIV. PRODUC. Y COMERC. LA VEGUILLA, SL | D8: Consolidado/estratégico | E8: BROTAMEC | F8: 11596.75 | G8: 78.75 | H8: B | I8: Maduro | J8: Esencial/Core | K8: Retener volumen y aumentar profundidad de catálogo | L8: Fidelización y desarrollo de cartera | M8: Formación de refresco; venta cruzada dirigida y seguimiento de consumo | N8: Equipo comercial del distribuidor | O8: Selectiva | P8: 9 | Q8: 8 | R8: Sin componente presupuestado | S8: 0
A9: Alfonso | B9: ESPAÑA | C9: AGRICOLA DEL JUCAR DE CUENCA, S.L. | D9: Consolidado/estratégico | E9: AGROXILATO-K | F9: 2254.66 | G9: 91.216129 | H9: A | I9: Maduro | J9: Innovador/Notorio | K9: Defender la prescripción y ampliar venta cruzada | L9: Refuerzo técnico y cross-selling | M9: Actualización técnica; casos de referencia y jornada selectiva con agricultores | N9: Técnicos del distribuidor y agricultores clave | O9: Alta | P9: 4 | Q9: 3 | R9: Formación técnica al distribuidor | S9: 381
A10: Alfonso | B10: ESPAÑA | C10: AGRICOLA DEL JUCAR DE CUENCA, S.L. | D10: Consolidado/estratégico | E10: SAL-WAX STAR | F10: 3350.62 | G10: 87.75 | H10: A | I10: Maduro | J10: Esencial/Core | K10: Retener volumen y aumentar profundidad de catálogo | L10: Fidelización y desarrollo de cartera | M10: Formación de refresco; venta cruzada dirigida y seguimiento de consumo | N10: Equipo comercial del distribuidor | O10: Alta | P10: 3 | Q10: 2 | R10: Sin componente presupuestado | S10: 0
A11: Alfonso | B11: ESPAÑA | C11: AGRICOLA DEL JUCAR DE CUENCA, S.L. | D11: Consolidado/estratégico | E11: ALCAPLANT | F11: 2101.43 | G11: 86.25 | H11: A | I11: Maduro | J11: Innovador/Notorio | K11: Defender la prescripción y ampliar venta cruzada | L11: Refuerzo técnico y cross-selling | M11: Actualización técnica; casos de referencia y jornada selectiva con agricultores | N11: Técnicos del distribuidor y agricultores clave | O11: Alta | P11: 5 | Q11: 4 | R11: Formación técnica al distribuidor | S11: 338
A12: Alfonso | B12: ESPAÑA | C12: AGRICOLA DEL JUCAR DE CUENCA, S.L. | D12: Consolidado/estratégico | E12: BR-59 | F12: 542.51 | G12: 73.5 | H12: B | I12: Maduro | J12: Innovador/Notorio | K12: Defender la prescripción y ampliar venta cruzada | L12: Refuerzo técnico y cross-selling | M12: Actualización técnica; casos de referencia y jornada selectiva con agricultores | N12: Técnicos del distribuidor y agricultores clave | O12: Selectiva | P12: 7 | Q12: 6 | R12: Formación técnica al distribuidor | S12: 81
A13: Alfonso | B13: ESPAÑA | C13: AGRITEC MEDINA, S.L.U. | D13: Con potencial | E13: HIDROSTRESS | F13: 8732.83 | G13: 94.25 | H13: A | I13: Ramp-Up/Crecimiento | J13: Innovador/Notorio | K13: Generar demanda, referencias y prescripción técnica | L13: Generación de demanda y adopción | M13: Campo demostrativo; formación técnica; jornada con agricultores y desarrollo de casos | N13: Distribuidor, técnicos y agricultores | O13: Alta | P13: 4 | Q13: 3 | R13: Campo demostrativo; Bolsa de muestras | S13: 2398
A14: Alfonso | B14: ESPAÑA | C14: AGRITEC MEDINA, S.L.U. | D14: Con potencial | E14: ALCAPLANT | F14: 1874.54 | G14: 82.5 | H14: A | I14: Maduro | J14: Innovador/Notorio | K14: Defender la prescripción y ampliar venta cruzada | L14: Refuerzo técnico y cross-selling | M14: Actualización técnica; casos de referencia y jornada selectiva con agricultores | N14: Técnicos del distribuidor y agricultores clave | O14: Alta | P14: 4 | Q14: 3 | R14: Sin componente presupuestado | S14: 0
A15: Alfonso | B15: ESPAÑA | C15: AGRITEC MEDINA, S.L.U. | D15: Con potencial | E15: AGROXILATO-K | F15: 1952.95 | G15: 82.466129 | H15: A | I15: Maduro | J15: Innovador/Notorio | K15: Defender la prescripción y ampliar venta cruzada | L15: Refuerzo técnico y cross-selling | M15: Actualización técnica; casos de referencia y jornada selectiva con agricultores | N15: Técnicos del distribuidor y agricultores clave | O15: Alta | P15: 5 | Q15: 4 | R15: Sin componente presupuestado | S15: 0
A16: Alfonso | B16: ESPAÑA | C16: AGRITEC MEDINA, S.L.U. | D16: Con potencial | E16: BIORAD-20 | F16: 674.84 | G16: 77.5 | H16: B | I16: Ramp-Up/Crecimiento | J16: Innovador/Notorio | K16: Generar demanda, referencias y prescripción técnica | L16: Generación de demanda y adopción | M16: Campo demostrativo; formación técnica; jornada con agricultores y desarrollo de casos | N16: Distribuidor, técnicos y agricultores | O16: Selectiva | P16: 2 | Q16: 1 | R16: Bolsa de muestras | S16: 30
... A491: Mehmet | B491: TURQUÍA | C491: ÇITAR ÇIÇEK TARIM TIC. LTD. STI | D491: Consolidado/estratégico | E491: CODIORGAN A-50 | F491: 26559.78 | G491: 80.585273 | H491: A | I491: Ramp-Up/Crecimiento | J491: Innovador/Notorio | K491: Generar demanda, referencias y prescripción técnica | L491: Generación de demanda y adopción | M491: Campo demostrativo; formación técnica; jornada con agricultores y desarrollo de casos | N491: Distribuidor, técnicos y agricultores | O491: Alta | P491: 4 | Q491: 3 | R491: Jornada técnica con agricultores; Bolsa de muestras | S491: 201

Sheet Priorización
A2: Priorización cliente–familia de producto
A4: Comercial | B4: País | C4: Cliente | D4: Clasificación cliente | E4: Familia | F4: Ventas 2027 (€) | G4: Ventas cliente (€) | H4: % cliente | I4: Ranking familia | J4: Score cliente | K4: Score producto | L4: Score dentro cliente | M4: Score global | N4: Score total | O4: Prioridad | P4: Ciclo dominante | Q4: Rol dominante
A5: Ricardo | B5: DOMINICANA, REPÚBLICA | C5: JUAN JIMENEZ, SRL | D5: Consolidado/estratégico | E5: BIORAD-20 | F5: 54520.41 | G5: 360957.46 | H5: 0.15104387 | I5: 1 | J5: 100 | K5: 100 | L5: 100 | M5: 100 | N5: =J5*Supuestos!$B$7+K5*Supuestos!$B$8+L5*Supuestos!$B$9+M5*Supuestos!$B$10 -> 100 | O5: =IF(N5>=80,"A",IF(N5>=65,"B",IF(N5>=50,"C","D"))) -> A | P5: Ramp-Up/Crecimiento | Q5: Innovador/Notorio
A6: García | B6: ESPAÑA | C6: AGROSER BERNARDINO, S.L. | D6: Consolidado/estratégico | E6: BIORAD-20 | F6: 17487.76 | G6: 67968.18 | H6: 0.25729335 | I6: 1 | J6: 100 | K6: 100 | L6: 100 | M6: 100 | N6: =J6*Supuestos!$B$7+K6*Supuestos!$B$8+L6*Supuestos!$B$9+M6*Supuestos!$B$10 -> 100 | O6: =IF(N6>=80,"A",IF(N6>=65,"B",IF(N6>=50,"C","D"))) -> A | P6: Ramp-Up/Crecimiento | Q6: Innovador/Notorio
A7: Mehmet | B7: GEORGIA | C7: BORN AGROCHEMISTRY, LLC | D7: Con potencial | E7: BIORAD-20 | F7: 154003.92 | G7: 324829.33 | H7: 0.47410719 | I7: 1 | J7: 85 | K7: 100 | L7: 100 | M7: 100 | N7: =J7*Supuestos!$B$7+K7*Supuestos!$B$8+L7*Supuestos!$B$9+M7*Supuestos!$B$10 -> 96.25 | O7: =IF(N7>=80,"A",IF(N7>=65,"B",IF(N7>=50,"C","D"))) -> A | P7: Ramp-Up/Crecimiento | Q7: Innovador/Notorio
A8: Mehmet | B8: TURQUÍA | C8: DOGA TARIM TIC.SAN.VE TUR. LTD. STI | D8: Con potencial | E8: BIORAD-20 | F8: 54573.47 | G8: 117128.89 | H8: 0.46592662 | I8: 1 | J8: 85 | K8: 100 | L8: 100 | M8: 100 | N8: =J8*Supuestos!$B$7+K8*Supuestos!$B$8+L8*Supuestos!$B$9+M8*Supuestos!$B$10 -> 96.25 | O8: =IF(N8>=80,"A",IF(N8>=65,"B",IF(N8>=50,"C","D"))) -> A | P8: Ramp-Up/Crecimiento | Q8: Innovador/Notorio
A9: Mehmet | B9: SERBIA | C9: PLANTA SANA, D.O.O. | D9: Con potencial | E9: CODIORGAN A-50 | F9: 29697.91 | G9: 77674.73 | H9: 0.38233684 | I9: 1 | J9: 85 | K9: 100 | L9: 100 | M9: 96.676367 | N9: =J9*Supuestos!$B$7+K9*Supuestos!$B$8+L9*Supuestos!$B$9+M9*Supuestos!$B$10 -> 95.585273 | O9: =IF(N9>=80,"A",IF(N9>=65,"B",IF(N9>=50,"C","D"))) -> A | P9: Ramp-Up/Crecimiento | Q9: Innovador/Notorio
A10: Alfonso | B10: ESPAÑA | C10: AGROTÉCNICA DEL NORTE, S.L | D10: Con potencial | E10: CODIORGAN A-50 | F10: 10309.22 | G10: 45460.47 | H10: 0.22677325 | I10: 1 | J10: 85 | K10: 100 | L10: 100 | M10: 96.676367 | N10: =J10*Supuestos!$B$7+K10*Supuestos!$B$8+L10*Supuestos!$B$9+M10*Supuestos!$B$10 -> 95.585273 | O10: =IF(N10>=80,"A",IF(N10>=65,"B",IF(N10>=50,"C","D"))) -> A | P10: Ramp-Up/Crecimiento | Q10: Innovador/Notorio
A11: Alfonso | B11: ESPAÑA | C11: CARDONA Y CELMA, S.L. | D11: Con potencial | E11: CODIORGAN A-50 | F11: 6937.54 | G11: 13875.87 | H11: 0.49997183 | I11: 2 | J11: 85 | K11: 100 | L11: 100 | M11: 96.676367 | N11: =J11*Supuestos!$B$7+K11*Supuestos!$B$8+L11*Supuestos!$B$9+M11*Supuestos!$B$10 -> 95.585273 | O11: =IF(N11>=80,"A",IF(N11>=65,"B",IF(N11>=50,"C","D"))) -> A | P11: Ramp-Up/Crecimiento | Q11: Innovador/Notorio
A12: Mehmet | B12: AZERBAIYÁN | C12: ZTB AQRO MMC | D12: Consolidado/estratégico | E12: BIORAD-20 | F12: 123718.96 | G12: 1083764 | H12: 0.11415673 | I12: 2 | J12: 100 | K12: 100 | L12: 80 | M12: 100 | N12: =J12*Supuestos!$B$7+K12*Supuestos!$B$8+L12*Supuestos!$B$9+M12*Supuestos!$B$10 -> 95 | O12: =IF(N12>=80,"A",IF(N12>=65,"B",IF(N12>=50,"C","D"))) -> A | P12: Ramp-Up/Crecimiento | Q12: Innovador/Notorio
A13: García | B13: MARRUECOS | C13: STE BBMAGRI, SARL | D13: Consolidado/estratégico | E13: BIORAD-20 | F13: 82142.48 | G13: 642203.68 | H13: 0.1279072 | I13: 2 | J13: 100 | K13: 100 | L13: 80 | M13: 100 | N13: =J13*Supuestos!$B$7+K13*Supuestos!$B$8+L13*Supuestos!$B$9+M13*Supuestos!$B$10 -> 95 | O13: =IF(N13>=80,"A",IF(N13>=65,"B",IF(N13>=50,"C","D"))) -> A | P13: Ramp-Up/Crecimiento | Q13: Innovador/Notorio
A14: Ricardo | B14: PANAMÁ | C14: SERVICIOS AGROPECUARIOS EL LLANO, S. A. | D14: Consolidado/estratégico | E14: BIORAD-20 | F14: 19914 | G14: 159511.36 | H14: 0.12484376 | I14: 3 | J14: 100 | K14: 100 | L14: 80 | M14: 100 | N14: =J14*Supuestos!$B$7+K14*Supuestos!$B$8+L14*Supuestos!$B$9+M14*Supuestos!$B$10 -> 95 | O14: =IF(N14>=80,"A",IF(N14>=65,"B",IF(N14>=50,"C","D"))) -> A | P14: Ramp-Up/Crecimiento | Q14: Innovador/Notorio
A15: Javier | B15: ESPAÑA | C15: FITOXENT S.C.L.V. | D15: Consolidado/estratégico | E15: BIORAD-20 | F15: 13427.38 | G15: 132474.8 | H15: 0.10135802 | I15: 3 | J15: 100 | K15: 100 | L15: 80 | M15: 100 | N15: =J15*Supuestos!$B$7+K15*Supuestos!$B$8+L15*Supuestos!$B$9+M15*Supuestos!$B$10 -> 95 | O15: =IF(N15>=80,"A",IF(N15>=65,"B",IF(N15>=50,"C","D"))) -> A | P15: Ramp-Up/Crecimiento | Q15: Innovador/Notorio
A16: García | B16: ESPAÑA | C16: SERVIAGRI´ 97, S.L. | D16: Consolidado/estratégico | E16: BIORAD-20 | F16: 12642.2 | G16: 114879.92 | H16: 0.11004712 | I16: 4 | J16: 100 | K16: 100 | L16: 80 | M16: 100 | N16: =J16*Supuestos!$B$7+K16*Supuestos!$B$8+L16*Supuestos!$B$9+M16*Supuestos!$B$10 -> 95 | O16: =IF(N16>=80,"A",IF(N16>=65,"B",IF(N16>=50,"C","D"))) -> A | P16: Ramp-Up/Crecimiento | Q16: Innovador/Notorio
... A733: Alfonso | B733: ESPAÑA | C733: HORTICOLAS Y PATATAS HNOS. MORAN, S.A.T. | D733: Baja aportación | E733: AMINOSOIL MG | F733: 326.47 | G733: 5062.1 | H733: 0.064493544 | I733: 8 | J733: 30 | K733: 0 | L733: 55 | M733: 32.5 | N733: =J733*Supuestos!$B$7+K733*Supuestos!$B$8+L733*Supuestos!$B$9+M733*Supuestos!$B$10 -> 27.75 | O733: =IF(N733>=80,"A",IF(N733>=65,"B",IF(N733>=50,"C","D"))) -> D | P733: Declive | Q733: Banalizado/Commodity

Sheet Supuestos
A2: Supuestos y metodología
A3: Ventas presupuestadas 2027 | B3: 17738160
A4: Presupuesto MKT 2027 | B4: =ROUND(B3*B6,2) -> 266072.4
A5: Supuesto general | B5: Valor | D5: Componente | E5: España (€) | F5: Exportación (€) | G5: Unidad | H5: Criterio
A6: Tasa de inversión MKT | B6: 0.015 | D6: Campo demostrativo | E6: 2200 | F6: 3200 | G6: Por producto | H6: Familias A en introducción o Ramp-Up
A7: Peso clasificación cliente | B7: 0.25 | D7: Formación técnica al distribuidor | E7: 800 | F7: 1300 | G7: Por cliente | H7: Sesión conjunta para productos en lanzamiento, crecimiento o notorios
A8: Peso clasificación producto | B8: 0.3 | D8: Jornada técnica con agricultores | E8: 1600 | F8: 2400 | G8: Por cliente | H8: Mercados y clientes clave con productos innovadores/notorios A
A9: Peso importancia en cliente | B9: 0.25 | D9: Bolsa de muestras | E9: Variable | F9: Variable | G9: Por cliente | H9: 0,15% de la venta de familias en introducción/Ramp-Up; límites aplicados
A10: Peso relevancia global | B10: 0.2 | D10: Campaña de sell-out / consumo | E10: 2000 | F10: 3000 | G10: Por cliente | H10: Productos maduros core o commodity con peso relevante
D11: Kit activación / seguimiento digital | E11: 300 | F11: 500 | G11: Por cliente | H11: Clientes de baja aportación con una oportunidad A concreta
A13: Metodología | B13: Detalle | D13: Escalas utilizadas
A14: Familia de producto | B14: Agrupa formatos, etiquetas de país y marcas privadas equivalentes. | D14: Clasificación cliente | E14: Score cliente | G14: Prioridad | H14: Umbral Score total
A15: Importancia en cliente | B15: 100: primera familia o ≥25%; 80: top 3 o 10%-25%; 55: 5%-10%; 25: <5%. | D15: Consolidado/estratégico | E15: 100 | G15: A | H15: ≥ 80
A16: Relevancia global | B16: 50% ranking de ventas, 25% presencia en clientes y 25% valor estratégico del producto. | D16: Con potencial | E16: 85 | G16: B | H16: 65 a 79,9
A17: Universo de diseño | B17: Se diseña una respuesta para todas las combinaciones cliente–familia con prioridad A o B. | D17: En desarrollo/nuevo | E17: 75 | G17: C | H17: 50 a 64,9
A18: Inicio del plan cliente | B18: El kick-off se sitúa dos meses antes del mes de mayor venta conjunta de las familias A/B del cliente. | D18: Baja aportación | E18: 30 | G18: D | H18: < 50
A19: Ejecución por familia | B19: Cada línea cliente–familia se programa un mes antes de su propio pico de ventas para acercar la acción al momento de consumo.
A20: Mensualización | B20: El resumen mensual toma ferias y acciones corporativas del Plan de acciones y el presupuesto cliente–producto del detalle Diseño A-B, sin duplicar importes. | D20: Ciclo / rol | E20: Innovador/Notorio | F20: Esencial/Core | G20: Banalizado/Commodity
A21: Reparto de costes | B21: Los componentes directos se imputan a su familia. Los compartidos se distribuyen entre las familias vinculadas según ventas, Score y prioridad, con un mínimo operativo cuando es posible. | D21: Nuevo/Introducción | E21: 100 | F21: 90 | G21: 50
A22: Matriz estratégica | B22: El ciclo determina el objetivo de Marketing y el rol define si debe primar explicación técnica, demostración, adopción, fidelización o consumo. | D22: Ramp-Up/Crecimiento | E22: 100 | F22: 90 | G22: 60
A23: Introducción y Ramp-Up | B23: Se priorizan demostraciones, formación, jornadas y muestras para generar conocimiento, prueba y demanda. | D23: Maduro | E23: 75 | F23: 65 | G23: 30
A24: Innovador/Notorio | B24: Requiere explicación técnica, evidencias, casos y contacto con agricultores o prescriptores. | D24: Declive | E24: 25 | F24: 20 | G24: 0
A25: Maduro Commodity | B25: Se orienta a volumen, rotación y sell-out mediante campañas de consumo, packs o incentivos.
A26: Consolidación por cliente | B26: Las acciones compatibles se integran en un solo programa; no se repiten formaciones, muestras o jornadas como líneas independientes.
A27: Ajuste presupuestario | B27: Primero se preserva una acción central por cliente, los lanzamientos y las campañas de consumo materiales. Los componentes secundarios se priorizan después.
A28: Muestras | B28: Valoradas a precio de venta presupuestado, según criterio definido por Dirección.
A29: Fuente | B29: Presupuesto_Prevision_2026_2027_V6_DEFINITIVO.xlsx. LekkerBio se reclasifica comercialmente de Países Bajos a México.
A32: Guía breve para interpretar los parámetros
A33: Familia de producto | B33: Agrupa variantes, formatos, etiquetas y marcas privadas equivalentes para decidir Marketing a nivel de producto real. Ejemplo: los distintos formatos de BIORAD-20 se analizan como una sola familia.
A34: Clasificación cliente | B34: Indica la importancia comercial y el potencial del cliente. Se transforma en Score cliente: estratégico 100, potencial 85, desarrollo 75 y baja aportación 30. Ejemplo: Marcoser, como cliente estratégico, obtiene 100.
A35: Ventas 2027 (€) | B35: Venta presupuestada de esa familia en ese cliente. No decide por sí sola la prioridad, pero determina su peso económico. Ejemplo: 31.056 € de BIORAD-20 en Marcoser.
A36: Ventas cliente (€) | B36: Venta presupuestada total del cliente, sumando todas sus familias. Sirve como base para calcular el peso de cada producto dentro de su cartera.
A37: % cliente | B37: Porcentaje de las ventas del cliente que corresponde a la familia. Ejemplo: 25.000 € sobre un cliente de 100.000 € representan el 25 %.
A38: Ranking familia | B38: Posición de la familia por ventas dentro del cliente: 1 es la familia de mayor venta. Ayuda a identificar qué productos sostienen la relación comercial.
A39: Score cliente | B39: Puntuación de 0 a 100 derivada de la clasificación del cliente. Cuanto mayor es, más justificada está una inversión de Marketing en ese cliente.
A40: Score producto | B40: Mide la necesidad y el potencial de apoyo de Marketing según ciclo y rol. Un Ramp-Up innovador obtiene 100; un producto maduro commodity, 30. No mide ventas: mide el tipo de esfuerzo requerido.
A41: Score dentro cliente | B41: Mide la importancia de la familia en el cliente: 100 si es la primera o pesa ≥25 %; 80 si está en el top 3 o pesa 10-25 %; 55 si pesa 5-10 %; 25 si pesa <5 %.
A42: Score global | B42: Mide la relevancia de la familia para CODIAGRO: 50 % posición por ventas globales, 25 % presencia en clientes y 25 % valor estratégico del producto. Una familia importante en varios mercados obtiene un valor alto.
A43: Score total | B43: Resultado ponderado: 25 % cliente + 30 % producto + 25 % importancia dentro del cliente + 20 % relevancia global. Ejemplo AQUOM–Agrorebollo: 75×25 % + 90×30 % + 80×25 % + 76,4×20 % = 81,0.
A44: Prioridad | B44: Traduce el Score total en una categoría operativa: A ≥80; B 65-79,9; C 50-64,9; D <50. El plan de acciones se construye con las familias A y B.
...

Sheet Mapa familias
A2: Mapa de SKU y etiquetas a familias
A4: Código artículo | B4: Descripción | C4: Familia asignada | D4: Ventas 2027 (€) | E4: Ciclo | F4: Rol
A5: SSEG0005EG | B5: SAL-WAX Ca | C5: SAL-WAX Ca | D5: 1090857.7 | E5: Maduro | F5: Innovador/Notorio
A6: AN0020CL | B6: MAGNIFIC Ca FLOW, 20 KG | C6: ALCAPLANT | D6: 803631.39 | E6: Maduro | F6: Innovador/Notorio
A7: AGXK0020 | B7: AGROXILATO-K, 20 L | C7: AGROXILATO-K | D7: 636040.84 | E7: Maduro | F7: Innovador/Notorio
A8: SPCE2B0001EG | B8: NEW SPRINTENE | C8: SPRINTENE | D8: 508491.05 | E8: Maduro | F8: Innovador/Notorio
A9: AGXK0005EG | B9: AGROXILATO+K | C9: AGROXILATO-K | D9: 439874.83 | E9: Maduro | F9: Innovador/Notorio
A10: SSEG0005EG | B10: SALWAX CALCIO EGIPTO, 5 KG | C10: SAL-WAX Ca | D10: 435173.64 | E10: Maduro | F10: Innovador/Notorio
A11: SSEG0005EG | B11: SAL-WAX Ca, 5 KG | C11: SAL-WAX Ca | D11: 370005.26 | E11: Maduro | F11: Innovador/Notorio
A12: AGXK0020AZ | B12: AGROXILATO-K | C12: AGROXILATO-K | D12: 354240.96 | E12: Maduro | F12: Innovador/Notorio
A13: W330020CL | B13: BAYFOLAN SUN, 20 KG | C13: BAYFOLAN SUN | D13: 343555.13 | E13: Ramp-Up/Crecimiento | F13: Banalizado/Commodity
A14: PT0020 | B14: AGROPOTASION, 20 L | C14: AGROPOTASION | D14: 331276.62 | E14: Maduro | F14: Innovador/Notorio
A15: AN0020 | B15: ALCAPLANT NEW, 20 KG | C15: ALCAPLANT | D15: 328906.36 | E15: Maduro | F15: Innovador/Notorio
A16: AN0020CL | B16: MAGNIFIC Ca FLOW | C16: ALCAPLANT | D16: 315131.58 | E16: Maduro | F16: Innovador/Notorio
... A624: S0005 | B624: SAL-WAX STAR, 5 L | C624: SAL-WAX STAR | D624: 48.99 | E624: Maduro | F624: Esencial/Core
