Workbook

Sheet Resumen mensual
A2: Presupuesto de compras · resumen mensual 2027
A4: Compras netas tras aplicar el stock; FILM incorpora las necesidades mensuales de FILMPR.
A6: Mes | B6: Formulados | C6: Envasados | D6: Compras calculadas | E6: Líneas sin precio | F6: Total sin reserva | G6: Reserva 3 % | H6: Presupuesto con reserva
A7: Ene | B7: =SUMIF(Importes!$C$8:$C$149,"Formulados",Importes!E8:E149) -> 265351.09 | C7: =SUMIF(Importes!$C$8:$C$149,"Envasados",Importes!E8:E149) -> 44591.897 | D7: =SUM(B7:C7) -> 309942.98 | E7: =COUNTIFS(Unidades!S8:S149,">0",Precios!$I$8:$I$149,"FALTA PRECIO") -> 0 | F7: =IF(E7=0,D7,"") -> 309942.98 | G7: =IF(E7=0,F7*Supuestos!$B$6,"") -> 9298.2895 | H7: =IF(E7=0,F7+G7,"") -> 319241.27
A8: Feb | B8: =SUMIF(Importes!$C$8:$C$149,"Formulados",Importes!F8:F149) -> 486359.41 | C8: =SUMIF(Importes!$C$8:$C$149,"Envasados",Importes!F8:F149) -> 114627.59 | D8: =SUM(B8:C8) -> 600987 | E8: =COUNTIFS(Unidades!T8:T149,">0",Precios!$I$8:$I$149,"FALTA PRECIO") -> 0 | F8: =IF(E8=0,D8,"") -> 600987 | G8: =IF(E8=0,F8*Supuestos!$B$6,"") -> 18029.61 | H8: =IF(E8=0,F8+G8,"") -> 619016.61
A9: Mar | B9: =SUMIF(Importes!$C$8:$C$149,"Formulados",Importes!G8:G149) -> 505792 | C9: =SUMIF(Importes!$C$8:$C$149,"Envasados",Importes!G8:G149) -> 127059.65 | D9: =SUM(B9:C9) -> 632851.65 | E9: =COUNTIFS(Unidades!U8:U149,">0",Precios!$I$8:$I$149,"FALTA PRECIO") -> 0 | F9: =IF(E9=0,D9,"") -> 632851.65 | G9: =IF(E9=0,F9*Supuestos!$B$6,"") -> 18985.549 | H9: =IF(E9=0,F9+G9,"") -> 651837.2
A10: Abr | B10: =SUMIF(Importes!$C$8:$C$149,"Formulados",Importes!H8:H149) -> 394529.55 | C10: =SUMIF(Importes!$C$8:$C$149,"Envasados",Importes!H8:H149) -> 95397.618 | D10: =SUM(B10:C10) -> 489927.17 | E10: =COUNTIFS(Unidades!V8:V149,">0",Precios!$I$8:$I$149,"FALTA PRECIO") -> 0 | F10: =IF(E10=0,D10,"") -> 489927.17 | G10: =IF(E10=0,F10*Supuestos!$B$6,"") -> 14697.815 | H10: =IF(E10=0,F10+G10,"") -> 504624.98
A11: May | B11: =SUMIF(Importes!$C$8:$C$149,"Formulados",Importes!I8:I149) -> 630729.55 | C11: =SUMIF(Importes!$C$8:$C$149,"Envasados",Importes!I8:I149) -> 170158.83 | D11: =SUM(B11:C11) -> 800888.39 | E11: =COUNTIFS(Unidades!W8:W149,">0",Precios!$I$8:$I$149,"FALTA PRECIO") -> 0 | F11: =IF(E11=0,D11,"") -> 800888.39 | G11: =IF(E11=0,F11*Supuestos!$B$6,"") -> 24026.652 | H11: =IF(E11=0,F11+G11,"") -> 824915.04
A12: Jun | B12: =SUMIF(Importes!$C$8:$C$149,"Formulados",Importes!J8:J149) -> 655001.92 | C12: =SUMIF(Importes!$C$8:$C$149,"Envasados",Importes!J8:J149) -> 171790.12 | D12: =SUM(B12:C12) -> 826792.04 | E12: =COUNTIFS(Unidades!X8:X149,">0",Precios!$I$8:$I$149,"FALTA PRECIO") -> 0 | F12: =IF(E12=0,D12,"") -> 826792.04 | G12: =IF(E12=0,F12*Supuestos!$B$6,"") -> 24803.761 | H12: =IF(E12=0,F12+G12,"") -> 851595.8
A13: Jul | B13: =SUMIF(Importes!$C$8:$C$149,"Formulados",Importes!K8:K149) -> 422019.33 | C13: =SUMIF(Importes!$C$8:$C$149,"Envasados",Importes!K8:K149) -> 110862.26 | D13: =SUM(B13:C13) -> 532881.59 | E13: =COUNTIFS(Unidades!Y8:Y149,">0",Precios!$I$8:$I$149,"FALTA PRECIO") -> 0 | F13: =IF(E13=0,D13,"") -> 532881.59 | G13: =IF(E13=0,F13*Supuestos!$B$6,"") -> 15986.448 | H13: =IF(E13=0,F13+G13,"") -> 548868.04
A14: Ago | B14: =SUMIF(Importes!$C$8:$C$149,"Formulados",Importes!L8:L149) -> 254773.2 | C14: =SUMIF(Importes!$C$8:$C$149,"Envasados",Importes!L8:L149) -> 64852.99 | D14: =SUM(B14:C14) -> 319626.19 | E14: =COUNTIFS(Unidades!Z8:Z149,">0",Precios!$I$8:$I$149,"FALTA PRECIO") -> 0 | F14: =IF(E14=0,D14,"") -> 319626.19 | G14: =IF(E14=0,F14*Supuestos!$B$6,"") -> 9588.7857 | H14: =IF(E14=0,F14+G14,"") -> 329214.98
A15: Sep | B15: =SUMIF(Importes!$C$8:$C$149,"Formulados",Importes!M8:M149) -> 157733.49 | C15: =SUMIF(Importes!$C$8:$C$149,"Envasados",Importes!M8:M149) -> 35732.125 | D15: =SUM(B15:C15) -> 193465.61 | E15: =COUNTIFS(Unidades!AA8:AA149,">0",Precios!$I$8:$I$149,"FALTA PRECIO") -> 0 | F15: =IF(E15=0,D15,"") -> 193465.61 | G15: =IF(E15=0,F15*Supuestos!$B$6,"") -> 5803.9684 | H15: =IF(E15=0,F15+G15,"") -> 199269.58
A16: Oct | B16: =SUMIF(Importes!$C$8:$C$149,"Formulados",Importes!N8:N149) -> 259565.29 | C16: =SUMIF(Importes!$C$8:$C$149,"Envasados",Importes!N8:N149) -> 62617.725 | D16: =SUM(B16:C16) -> 322183.02 | E16: =COUNTIFS(Unidades!AB8:AB149,">0",Precios!$I$8:$I$149,"FALTA PRECIO") -> 0 | F16: =IF(E16=0,D16,"") -> 322183.02 | G16: =IF(E16=0,F16*Supuestos!$B$6,"") -> 9665.4906 | H16: =IF(E16=0,F16+G16,"") -> 331848.51
A17: Nov | B17: =SUMIF(Importes!$C$8:$C$149,"Formulados",Importes!O8:O149) -> 406765.12 | C17: =SUMIF(Importes!$C$8:$C$149,"Envasados",Importes!O8:O149) -> 107338.49 | D17: =SUM(B17:C17) -> 514103.6 | E17: =COUNTIFS(Unidades!AC8:AC149,">0",Precios!$I$8:$I$149,"FALTA PRECIO") -> 0 | F17: =IF(E17=0,D17,"") -> 514103.6 | G17: =IF(E17=0,F17*Supuestos!$B$6,"") -> 15423.108 | H17: =IF(E17=0,F17+G17,"") -> 529526.71
A18: Dic | B18: =SUMIF(Importes!$C$8:$C$149,"Formulados",Importes!P8:P149) -> 411940.97 | C18: =SUMIF(Importes!$C$8:$C$149,"Envasados",Importes!P8:P149) -> 116379.27 | D18: =SUM(B18:C18) -> 528320.24 | E18: =COUNTIFS(Unidades!AD8:AD149,">0",Precios!$I$8:$I$149,"FALTA PRECIO") -> 0 | F18: =IF(E18=0,D18,"") -> 528320.24 | G18: =IF(E18=0,F18*Supuestos!$B$6,"") -> 15849.607 | H18: =IF(E18=0,F18+G18,"") -> 544169.85
A19: TOTAL 2027 | B19: =SUM(B7:B18) -> 4850560.9 | C19: =SUM(C7:C18) -> 1221408.6 | D19: =SUM(D7:D18) -> 6071969.5 | E19: =COUNTIF(Precios!I8:I149,"FALTA PRECIO") -> 0 | F19: =IF(E19=0,D19,"") -> 6071969.5 | G19: =SUM(G7:G18) -> 182159.08 | H19: =SUM(H7:H18) -> 6254128.6
A22: Stock al 31/12 del archivo aportado. LAM1 se toma exclusivamente de envasados.
A23: ROJ, VER, CONVER y JAU omitidos. FILMPR se suma a FILM, sin línea ni precio propios.
A24: La reserva es una previsión monetaria por pedidos mínimos desconocidos; no equivale a unidades compradas.

Sheet Resumen anual
A2: Presupuesto de compras · resumen anual 2027
A4: Resultado | B4: Importe / líneas
A5: Compras calculadas | B5: ='Resumen mensual'!D19 -> 6071969.5
A6: Líneas sin precio | B6: ='Resumen mensual'!E19 -> 0
A7: Total sin reserva | B7: =IF(B6=0,B5,"") -> 6071969.5
A8: Reserva pedidos mínimos | B8: ='Resumen mensual'!G19 -> 182159.08
A9: Presupuesto con reserva | B9: =IF(B6=0,B7+B8,"") -> 6254128.6
A12: Grupo | B12: Compras calculadas | C12: Líneas sin precio
A13: Formulados | B13: =SUMIF(Importes!$C$8:$C$149,A13,Importes!Q8:Q149) -> 4850560.9 | C13: =COUNTIFS(Unidades!$C$8:$C$149,A13,Precios!$I$8:$I$149,"FALTA PRECIO") -> 0
A14: Envasados | B14: =SUMIF(Importes!$C$8:$C$149,A14,Importes!Q8:Q149) -> 1221408.6 | C14: =COUNTIFS(Unidades!$C$8:$C$149,A14,Precios!$I$8:$I$149,"FALTA PRECIO") -> 0
A15: TOTAL | B15: =SUM(B13:B14) -> 6071969.5 | C15: =SUM(C13:C14) -> 0
A18: Las unidades de kg, g y ud no se suman entre artículos; consulta Unidades para cantidades por referencia.
A19: La reserva del 3 % es presupuestaria y no representa gasto consumido ni compra asignada a artículos.

Sheet Supuestos
A2: Supuestos del presupuesto de compras 2027
A4: Parámetro | B4: Valor
A5: Incremento precios 2027 | B5: 0.1
A6: Reserva por mínimos de pedido | B6: 0.03
A8: Fuente | B8: 3º MP PARA FORMULADOS y 4º MP PARA ENVASADOS del archivo NECESIDADES ENE_DIC_2027(3).xlsx.
A9: Stock inicial 2027 | B9: Se toma la columna STOCK AL 31/12 de cada hoja; el usuario indica que recoge la previsión y compras realizadas.
A10: Compras mensuales | B10: Necesidad acumulada menos stock al 31/12 y compras anteriores; se asignan al primer mes con déficit.
A11: LAM1 | B11: Solo se usa envasados: stock al 31/12 724,81 kg y sus necesidades mensuales. La fila de formulados queda excluida.
A12: FILMPR | B12: Las necesidades de FILMPR (kg) se suman mes a mes a FILM (kg), con precio de FILM. Ambos stocks al 31/12 son cero; FILMPR no se valora por separado.
A13: Lotes mínimos | B13: CMG 500 kg, HGA-FE 1.200 kg, HGA-MGL 1.250 kg, sólo cuando hay déficit.
A14: Exclusiones confirmadas | B14: ROJ, VER, CONVER y JAU omitidos por indicación del usuario.
A15: Exclusiones anteriores | B15: BAG, CMC500, CTRE0020 y LFIX excluidos según comentarios anteriores. LOT es actividad de loteado.
A16: Precios | B16: Precio neto del último mes disponible por código, más 4,5 % de inflación y 5,5 % de variación del combustible (10 % en conjunto). Se mantienen los precios manuales indicados.
A17: Códigos corregidos | B17: EPA220 usa KIA220; EPP220 usa KIA220P; KIA250 es correcto. Se respetan las equivalencias ya aplicadas.
A18: Reserva de compra | B18: 3 % provisional sobre las compras calculadas de cada mes y el total anual, por posibles formatos y pedidos mínimos desconocidos. No se imputa a unidades ni a artículos.
A19: Interpretación | B19: El presupuesto con reserva es una previsión de fondos para compras. Los materiales adquiridos y no consumidos quedarán en stock; la reserva no es gasto contable automático.
... A21: Alcance | B21: Totales mensuales y anuales ligados a las hojas Unidades, Precios e Importes; todos los artículos con compra deben tener precio.
A23: Las partidas anuales genéricas del presupuesto previo (FILM, CUP, CANT) no se duplican: aquí se valoran los códigos concretos de necesidades.

Sheet Importes
A2: Coste de compras netas por artículo · 2027
A4: Celdas vacías: compras sin precio confirmado. El subtotal valorado no incluye esas partidas.
A7: Artículo | B7: Descripción | C7: Grupo | D7: Precio 2027 | E7: Ene | F7: Feb | G7: Mar | H7: Abr | I7: May | J7: Jun | K7: Jul | L7: Ago | M7: Sep | N7: Oct | O7: Nov | P7: Dic | Q7: Total año
A8: ACE | B8: ACETAMIDA | C8: Formulados | D8: =IF(ISNUMBER(Precios!H8),Precios!H8,"") -> 40.92 | E8: =IF(Unidades!S8=0,0,IF(ISNUMBER($D8),Unidades!S8*$D8,"")) -> 0 | F8: =IF(Unidades!T8=0,0,IF(ISNUMBER($D8),Unidades!T8*$D8,"")) -> 0 | G8: =IF(Unidades!U8=0,0,IF(ISNUMBER($D8),Unidades!U8*$D8,"")) -> 0 | H8: =IF(Unidades!V8=0,0,IF(ISNUMBER($D8),Unidades!V8*$D8,"")) -> 0 | I8: =IF(Unidades!W8=0,0,IF(ISNUMBER($D8),Unidades!W8*$D8,"")) -> 0 | J8: =IF(Unidades!X8=0,0,IF(ISNUMBER($D8),Unidades!X8*$D8,"")) -> 0 | K8: =IF(Unidades!Y8=0,0,IF(ISNUMBER($D8),Unidades!Y8*$D8,"")) -> 1071.8314 | L8: =IF(Unidades!Z8=0,0,IF(ISNUMBER($D8),Unidades!Z8*$D8,"")) -> 573.87026 | ... P8: =IF(Unidades!AD8=0,0,IF(ISNUMBER($D8),Unidades!AD8*$D8,"")) -> 4244.4679 | Q8: =IF(AND(Unidades!AE8>0,NOT(ISNUMBER(D8))),"",SUM(E8:P8)) -> 8539.1298
A9: ACIT | B9: ACIDO CÍTRICO MONOHIDRATADO | C9: Formulados | D9: =IF(ISNUMBER(Precios!H9),Precios!H9,"") -> 1.43 | E9: =IF(Unidades!S9=0,0,IF(ISNUMBER($D9),Unidades!S9*$D9,"")) -> 1891.2465 | F9: =IF(Unidades!T9=0,0,IF(ISNUMBER($D9),Unidades!T9*$D9,"")) -> 4199.6061 | G9: =IF(Unidades!U9=0,0,IF(ISNUMBER($D9),Unidades!U9*$D9,"")) -> 1278.3664 | H9: =IF(Unidades!V9=0,0,IF(ISNUMBER($D9),Unidades!V9*$D9,"")) -> 2032.1194 | I9: =IF(Unidades!W9=0,0,IF(ISNUMBER($D9),Unidades!W9*$D9,"")) -> 1082.5457 | J9: =IF(Unidades!X9=0,0,IF(ISNUMBER($D9),Unidades!X9*$D9,"")) -> 4079.1429 | K9: =IF(Unidades!Y9=0,0,IF(ISNUMBER($D9),Unidades!Y9*$D9,"")) -> 703.274 | L9: =IF(Unidades!Z9=0,0,IF(ISNUMBER($D9),Unidades!Z9*$D9,"")) -> 2552.9969 | ... P9: =IF(Unidades!AD9=0,0,IF(ISNUMBER($D9),Unidades!AD9*$D9,"")) -> 5873.01 | Q9: =IF(AND(Unidades!AE9>0,NOT(ISNUMBER(D9))),"",SUM(E9:P9)) -> 32041.924
A10: ADI | B10: ACIDO ADIPICO | C10: Formulados | D10: =IF(ISNUMBER(Precios!H10),Precios!H10,"") -> 2.706 | E10: =IF(Unidades!S10=0,0,IF(ISNUMBER($D10),Unidades!S10*$D10,"")) -> 0 | F10: =IF(Unidades!T10=0,0,IF(ISNUMBER($D10),Unidades!T10*$D10,"")) -> 0 | G10: =IF(Unidades!U10=0,0,IF(ISNUMBER($D10),Unidades!U10*$D10,"")) -> 0 | H10: =IF(Unidades!V10=0,0,IF(ISNUMBER($D10),Unidades!V10*$D10,"")) -> 0 | I10: =IF(Unidades!W10=0,0,IF(ISNUMBER($D10),Unidades!W10*$D10,"")) -> 0 | J10: =IF(Unidades!X10=0,0,IF(ISNUMBER($D10),Unidades!X10*$D10,"")) -> 0 | K10: =IF(Unidades!Y10=0,0,IF(ISNUMBER($D10),Unidades!Y10*$D10,"")) -> 975.40063 | L10: =IF(Unidades!Z10=0,0,IF(ISNUMBER($D10),Unidades!Z10*$D10,"")) -> 1396.296 | ... P10: =IF(Unidades!AD10=0,0,IF(ISNUMBER($D10),Unidades!AD10*$D10,"")) -> 4188.888 | Q10: =IF(AND(Unidades!AE10>0,NOT(ISNUMBER(D10))),"",SUM(E10:P10)) -> 10480.469
A11: AMARILLO | B11: COLOR AMARILLO | C11: Formulados | D11: =IF(ISNUMBER(Precios!H11),Precios!H11,"") | E11: =IF(Unidades!S11=0,0,IF(ISNUMBER($D11),Unidades!S11*$D11,"")) -> 0 | F11: =IF(Unidades!T11=0,0,IF(ISNUMBER($D11),Unidades!T11*$D11,"")) -> 0 | G11: =IF(Unidades!U11=0,0,IF(ISNUMBER($D11),Unidades!U11*$D11,"")) -> 0 | H11: =IF(Unidades!V11=0,0,IF(ISNUMBER($D11),Unidades!V11*$D11,"")) -> 0 | I11: =IF(Unidades!W11=0,0,IF(ISNUMBER($D11),Unidades!W11*$D11,"")) -> 0 | J11: =IF(Unidades!X11=0,0,IF(ISNUMBER($D11),Unidades!X11*$D11,"")) -> 0 | K11: =IF(Unidades!Y11=0,0,IF(ISNUMBER($D11),Unidades!Y11*$D11,"")) -> 0 | L11: =IF(Unidades!Z11=0,0,IF(ISNUMBER($D11),Unidades!Z11*$D11,"")) -> 0 | ... P11: =IF(Unidades!AD11=0,0,IF(ISNUMBER($D11),Unidades!AD11*$D11,"")) -> 0 | Q11: =IF(AND(Unidades!AE11>0,NOT(ISNUMBER(D11))),"",SUM(E11:P11)) -> 0
A12: AMO | B12: AMONÍACO | C12: Formulados | D12: =IF(ISNUMBER(Precios!H12),Precios!H12,"") -> 0.418 | E12: =IF(Unidades!S12=0,0,IF(ISNUMBER($D12),Unidades!S12*$D12,"")) -> 91.834603 | F12: =IF(Unidades!T12=0,0,IF(ISNUMBER($D12),Unidades!T12*$D12,"")) -> 688.13607 | G12: =IF(Unidades!U12=0,0,IF(ISNUMBER($D12),Unidades!U12*$D12,"")) -> 1439.8257 | H12: =IF(Unidades!V12=0,0,IF(ISNUMBER($D12),Unidades!V12*$D12,"")) -> 723.77369 | I12: =IF(Unidades!W12=0,0,IF(ISNUMBER($D12),Unidades!W12*$D12,"")) -> 1342.6703 | J12: =IF(Unidades!X12=0,0,IF(ISNUMBER($D12),Unidades!X12*$D12,"")) -> 1020.2178 | K12: =IF(Unidades!Y12=0,0,IF(ISNUMBER($D12),Unidades!Y12*$D12,"")) -> 413.32613 | L12: =IF(Unidades!Z12=0,0,IF(ISNUMBER($D12),Unidades!Z12*$D12,"")) -> 550.21967 | ... P12: =IF(Unidades!AD12=0,0,IF(ISNUMBER($D12),Unidades!AD12*$D12,"")) -> 364.55159 | Q12: =IF(AND(Unidades!AE12>0,NOT(ISNUMBER(D12))),"",SUM(E12:P12)) -> 7967.7599
A13: ANTI | B13: ANTIESPUMANTE ANTISCHIUMA GEN | C13: Formulados | D13: =IF(ISNUMBER(Precios!H13),Precios!H13,"") -> 8.525 | E13: =IF(Unidades!S13=0,0,IF(ISNUMBER($D13),Unidades!S13*$D13,"")) -> 0 | F13: =IF(Unidades!T13=0,0,IF(ISNUMBER($D13),Unidades!T13*$D13,"")) -> 0 | G13: =IF(Unidades!U13=0,0,IF(ISNUMBER($D13),Unidades!U13*$D13,"")) -> 0 | H13: =IF(Unidades!V13=0,0,IF(ISNUMBER($D13),Unidades!V13*$D13,"")) -> 0 | I13: =IF(Unidades!W13=0,0,IF(ISNUMBER($D13),Unidades!W13*$D13,"")) -> 0 | J13: =IF(Unidades!X13=0,0,IF(ISNUMBER($D13),Unidades!X13*$D13,"")) -> 0 | K13: =IF(Unidades!Y13=0,0,IF(ISNUMBER($D13),Unidades!Y13*$D13,"")) -> 0 | L13: =IF(Unidades!Z13=0,0,IF(ISNUMBER($D13),Unidades!Z13*$D13,"")) -> 0 | ... P13: =IF(Unidades!AD13=0,0,IF(ISNUMBER($D13),Unidades!AD13*$D13,"")) -> 0 | Q13: =IF(AND(Unidades!AE13>0,NOT(ISNUMBER(D13))),"",SUM(E13:P13)) -> 0
A14: AR | B14: FINDET AR-52 | C14: Formulados | D14: =IF(ISNUMBER(Precios!H14),Precios!H14,"") -> 3.19 | E14: =IF(Unidades!S14=0,0,IF(ISNUMBER($D14),Unidades!S14*$D14,"")) -> 1518.8376 | F14: =IF(Unidades!T14=0,0,IF(ISNUMBER($D14),Unidades!T14*$D14,"")) -> 2072.3146 | G14: =IF(Unidades!U14=0,0,IF(ISNUMBER($D14),Unidades!U14*$D14,"")) -> 5943.0669 | H14: =IF(Unidades!V14=0,0,IF(ISNUMBER($D14),Unidades!V14*$D14,"")) -> 2962.3015 | I14: =IF(Unidades!W14=0,0,IF(ISNUMBER($D14),Unidades!W14*$D14,"")) -> 9088.3896 | J14: =IF(Unidades!X14=0,0,IF(ISNUMBER($D14),Unidades!X14*$D14,"")) -> 6570.4403 | K14: =IF(Unidades!Y14=0,0,IF(ISNUMBER($D14),Unidades!Y14*$D14,"")) -> 4652.5875 | L14: =IF(Unidades!Z14=0,0,IF(ISNUMBER($D14),Unidades!Z14*$D14,"")) -> 1649.338 | ... P14: =IF(Unidades!AD14=0,0,IF(ISNUMBER($D14),Unidades!AD14*$D14,"")) -> 5215.0595 | Q14: =IF(AND(Unidades!AE14>0,NOT(ISNUMBER(D14))),"",SUM(E14:P14)) -> 44664.776
A15: ATC | B15: AATC | C15: Formulados | D15: =IF(ISNUMBER(Precios!H15),Precios!H15,"") -> 35.09 | E15: =IF(Unidades!S15=0,0,IF(ISNUMBER($D15),Unidades!S15*$D15,"")) -> 275.24596 | F15: =IF(Unidades!T15=0,0,IF(ISNUMBER($D15),Unidades!T15*$D15,"")) -> 533.43818 | G15: =IF(Unidades!U15=0,0,IF(ISNUMBER($D15),Unidades!U15*$D15,"")) -> 89.30405 | H15: =IF(Unidades!V15=0,0,IF(ISNUMBER($D15),Unidades!V15*$D15,"")) -> 504.45384 | I15: =IF(Unidades!W15=0,0,IF(ISNUMBER($D15),Unidades!W15*$D15,"")) -> 153.86965 | J15: =IF(Unidades!X15=0,0,IF(ISNUMBER($D15),Unidades!X15*$D15,"")) -> 294.93145 | K15: =IF(Unidades!Y15=0,0,IF(ISNUMBER($D15),Unidades!Y15*$D15,"")) -> 111.69147 | L15: =IF(Unidades!Z15=0,0,IF(ISNUMBER($D15),Unidades!Z15*$D15,"")) -> 330.61798 | ... P15: =IF(Unidades!AD15=0,0,IF(ISNUMBER($D15),Unidades!AD15*$D15,"")) -> 397.42934 | Q15: =IF(AND(Unidades!AE15>0,NOT(ISNUMBER(D15))),"",SUM(E15:P15)) -> 3105.1492
A16: AV24 | B16: AV24 | C16: Formulados | D16: =IF(ISNUMBER(Precios!H16),Precios!H16,"") -> 1.705 | E16: =IF(Unidades!S16=0,0,IF(ISNUMBER($D16),Unidades!S16*$D16,"")) -> 0 | F16: =IF(Unidades!T16=0,0,IF(ISNUMBER($D16),Unidades!T16*$D16,"")) -> 8696.5452 | G16: =IF(Unidades!U16=0,0,IF(ISNUMBER($D16),Unidades!U16*$D16,"")) -> 0 | H16: =IF(Unidades!V16=0,0,IF(ISNUMBER($D16),Unidades!V16*$D16,"")) -> 19.69275 | I16: =IF(Unidades!W16=0,0,IF(ISNUMBER($D16),Unidades!W16*$D16,"")) -> 0 | J16: =IF(Unidades!X16=0,0,IF(ISNUMBER($D16),Unidades!X16*$D16,"")) -> 366.31925 | K16: =IF(Unidades!Y16=0,0,IF(ISNUMBER($D16),Unidades!Y16*$D16,"")) -> 0 | L16: =IF(Unidades!Z16=0,0,IF(ISNUMBER($D16),Unidades!Z16*$D16,"")) -> 262.27162 | ... P16: =IF(Unidades!AD16=0,0,IF(ISNUMBER($D16),Unidades!AD16*$D16,"")) -> 5263.9249 | Q16: =IF(AND(Unidades!AE16>0,NOT(ISNUMBER(D16))),"",SUM(E16:P16)) -> 14979.335
A17: BET | B17: BETAÍNA DE REMOLACHA | C17: Formulados | D17: =IF(ISNUMBER(Precios!H17),Precios!H17,"") -> 5.665 | E17: =IF(Unidades!S17=0,0,IF(ISNUMBER($D17),Unidades!S17*$D17,"")) -> 3376.2494 | F17: =IF(Unidades!T17=0,0,IF(ISNUMBER($D17),Unidades!T17*$D17,"")) -> 5225.9953 | G17: =IF(Unidades!U17=0,0,IF(ISNUMBER($D17),Unidades!U17*$D17,"")) -> 5762.0415 | H17: =IF(Unidades!V17=0,0,IF(ISNUMBER($D17),Unidades!V17*$D17,"")) -> 9392.5105 | I17: =IF(Unidades!W17=0,0,IF(ISNUMBER($D17),Unidades!W17*$D17,"")) -> 9817.1334 | J17: =IF(Unidades!X17=0,0,IF(ISNUMBER($D17),Unidades!X17*$D17,"")) -> 20005.429 | K17: =IF(Unidades!Y17=0,0,IF(ISNUMBER($D17),Unidades!Y17*$D17,"")) -> 7763.7239 | L17: =IF(Unidades!Z17=0,0,IF(ISNUMBER($D17),Unidades!Z17*$D17,"")) -> 2620.4364 | ... P17: =IF(Unidades!AD17=0,0,IF(ISNUMBER($D17),Unidades!AD17*$D17,"")) -> 2341.9082 | Q17: =IF(AND(Unidades!AE17>0,NOT(ISNUMBER(D17))),"",SUM(E17:P17)) -> 78471.65
A18: BICAR | B18: BICARBONATO SÓDICO ALIM. | C18: Formulados | D18: =IF(ISNUMBER(Precios!H18),Precios!H18,"") -> 0.517 | E18: =IF(Unidades!S18=0,0,IF(ISNUMBER($D18),Unidades!S18*$D18,"")) -> 0 | F18: =IF(Unidades!T18=0,0,IF(ISNUMBER($D18),Unidades!T18*$D18,"")) -> 0 | G18: =IF(Unidades!U18=0,0,IF(ISNUMBER($D18),Unidades!U18*$D18,"")) -> 0 | H18: =IF(Unidades!V18=0,0,IF(ISNUMBER($D18),Unidades!V18*$D18,"")) -> 0 | I18: =IF(Unidades!W18=0,0,IF(ISNUMBER($D18),Unidades!W18*$D18,"")) -> 0 | J18: =IF(Unidades!X18=0,0,IF(ISNUMBER($D18),Unidades!X18*$D18,"")) -> 0 | K18: =IF(Unidades!Y18=0,0,IF(ISNUMBER($D18),Unidades!Y18*$D18,"")) -> 0 | L18: =IF(Unidades!Z18=0,0,IF(ISNUMBER($D18),Unidades!Z18*$D18,"")) -> 0 | ... P18: =IF(Unidades!AD18=0,0,IF(ISNUMBER($D18),Unidades!AD18*$D18,"")) -> 0 | Q18: =IF(AND(Unidades!AE18>0,NOT(ISNUMBER(D18))),"",SUM(E18:P18)) -> 0
A19: BOCAL | B19: BRETAX-CL | C19: Formulados | D19: =IF(ISNUMBER(Precios!H19),Precios!H19,"") -> 0.44 | E19: =IF(Unidades!S19=0,0,IF(ISNUMBER($D19),Unidades!S19*$D19,"")) -> 0 | F19: =IF(Unidades!T19=0,0,IF(ISNUMBER($D19),Unidades!T19*$D19,"")) -> 0 | G19: =IF(Unidades!U19=0,0,IF(ISNUMBER($D19),Unidades!U19*$D19,"")) -> 0 | H19: =IF(Unidades!V19=0,0,IF(ISNUMBER($D19),Unidades!V19*$D19,"")) -> 0 | I19: =IF(Unidades!W19=0,0,IF(ISNUMBER($D19),Unidades!W19*$D19,"")) -> 0 | J19: =IF(Unidades!X19=0,0,IF(ISNUMBER($D19),Unidades!X19*$D19,"")) -> 0 | K19: =IF(Unidades!Y19=0,0,IF(ISNUMBER($D19),Unidades!Y19*$D19,"")) -> 0 | L19: =IF(Unidades!Z19=0,0,IF(ISNUMBER($D19),Unidades!Z19*$D19,"")) -> 0 | ... P19: =IF(Unidades!AD19=0,0,IF(ISNUMBER($D19),Unidades!AD19*$D19,"")) -> 0 | Q19: =IF(AND(Unidades!AE19>0,NOT(ISNUMBER(D19))),"",SUM(E19:P19)) -> 0
... A149: TPD63VS | B149: TAPÓN D63 VALVULA SETA, BLANCO | C149: Envasados | D149: =IF(ISNUMBER(Precios!H149),Precios!H149,"") -> 0.3179 | E149: =IF(Unidades!S149=0,0,IF(ISNUMBER($D149),Unidades!S149*$D149,"")) -> 609.47788 | F149: =IF(Unidades!T149=0,0,IF(ISNUMBER($D149),Unidades!T149*$D149,"")) -> 545.1985 | G149: =IF(Unidades!U149=0,0,IF(ISNUMBER($D149),Unidades!U149*$D149,"")) -> 126.19356 | H149: =IF(Unidades!V149=0,0,IF(ISNUMBER($D149),Unidades!V149*$D149,"")) -> 247.3262 | I149: =IF(Unidades!W149=0,0,IF(ISNUMBER($D149),Unidades!W149*$D149,"")) -> 342.3783 | J149: =IF(Unidades!X149=0,0,IF(ISNUMBER($D149),Unidades!X149*$D149,"")) -> 273.0761 | K149: =IF(Unidades!Y149=0,0,IF(ISNUMBER($D149),Unidades!Y149*$D149,"")) -> 258.4527 | L149: =IF(Unidades!Z149=0,0,IF(ISNUMBER($D149),Unidades!Z149*$D149,"")) -> 325.2117 | ... P149: =IF(Unidades!AD149=0,0,IF(ISNUMBER($D149),Unidades!AD149*$D149,"")) -> 498.7851 | Q149: =IF(AND(Unidades!AE149>0,NOT(ISNUMBER(D149))),"",SUM(E149:P149)) -> 3540.5031
A150: SUBTOTAL VALORADO | E150: =SUM(E8:E149) -> 309942.98 | F150: =SUM(F8:F149) -> 600987 | G150: =SUM(G8:G149) -> 632851.65 | H150: =SUM(H8:H149) -> 489927.17 | I150: =SUM(I8:I149) -> 800888.39 | J150: =SUM(J8:J149) -> 826792.04 | K150: =SUM(K8:K149) -> 532881.59 | L150: =SUM(L8:L149) -> 319626.19 | ... Q150: =SUM(Q8:Q149) -> 6071969.5

Sheet Unidades
A2: Compras netas después del stock · 2027
A4: El stock al 31/12 se consume cronológicamente. Las compras surgen cuando la necesidad acumulada lo supera.
A6: Para CMG y HGA se aplican los lotes mínimos confirmados cuando aparece la primera necesidad de compra.
A7: Artículo | B7: Descripción | C7: Grupo | D7: Unidad | E7: Stock 31/12 | F7: Nec. Ene | G7: Nec. Feb | H7: Nec. Mar | I7: Nec. Abr | J7: Nec. May | K7: Nec. Jun | L7: Nec. Jul | M7: Nec. Ago | N7: Nec. Sep | O7: Nec. Oct | P7: Nec. Nov | Q7: Nec. Dic | R7: Necesidad año | S7: Compra Ene | T7: Compra Feb | U7: Compra Mar | V7: Compra Abr | W7: Compra May | X7: Compra Jun | Y7: Compra Jul | Z7: Compra Ago | AA7: Compra Sep | AB7: Compra Oct | AC7: Compra Nov | AD7: Compra Dic | AE7: Compra año | AF7: Lote mín. | AG7: Criterio
A8: ACE | B8: ACETAMIDA | C8: Formulados | D8: kg | E8: 238.55654 | F8: 22.182981 | G8: 45.6496 | H8: 30.034 | I8: 19.638 | J8: 49.811 | K8: 63.861 | L8: 33.5733 | M8: 14.0242 | N8: 10.125 | O8: 33.7158 | P8: 20.8943 | Q8: 103.726 | R8: =SUM(F8:Q8) -> 447.23518 | S8: =IF(SUM($F8:F8)-$E8-0>0,MAX($AF8,SUM($F8:F8)-$E8-0),0) -> 0 | T8: =IF(SUM($F8:G8)-$E8-SUM($S8:S8)>0,MAX($AF8,SUM($F8:G8)-$E8-SUM($S8:S8)),0) -> 0 | U8: =IF(SUM($F8:H8)-$E8-SUM($S8:T8)>0,MAX($AF8,SUM($F8:H8)-$E8-SUM($S8:T8)),0) -> 0 | V8: =IF(SUM($F8:I8)-$E8-SUM($S8:U8)>0,MAX($AF8,SUM($F8:I8)-$E8-SUM($S8:U8)),0) -> 0 | W8: =IF(SUM($F8:J8)-$E8-SUM($S8:V8)>0,MAX($AF8,SUM($F8:J8)-$E8-SUM($S8:V8)),0) -> 0 | X8: =IF(SUM($F8:K8)-$E8-SUM($S8:W8)>0,MAX($AF8,SUM($F8:K8)-$E8-SUM($S8:W8)),0) -> 0 | Y8: =IF(SUM($F8:L8)-$E8-SUM($S8:X8)>0,MAX($AF8,SUM($F8:L8)-$E8-SUM($S8:X8)),0) -> 26.193338 | Z8: =IF(SUM($F8:M8)-$E8-SUM($S8:Y8)>0,MAX($AF8,SUM($F8:M8)-$E8-SUM($S8:Y8)),0) -> 14.0242 | AA8: =IF(SUM($F8:N8)-$E8-SUM($S8:Z8)>0,MAX($AF8,SUM($F8:N8)-$E8-SUM($S8:Z8)),0) -> 10.125 | ... AD8: =IF(SUM($F8:Q8)-$E8-SUM($S8:AC8)>0,MAX($AF8,SUM($F8:Q8)-$E8-SUM($S8:AC8)),0) -> 103.726 | AE8: =SUM(S8:AD8) -> 208.67864 | AF8: 0
A9: ACIT | B9: ACIDO CÍTRICO MONOHIDRATADO | C9: Formulados | D9: kg | E9: 0 | F9: 1322.55 | G9: 2936.7875 | H9: 893.9625 | I9: 1421.0625 | J9: 757.025 | K9: 2852.5475 | L9: 491.8 | M9: 1785.3125 | N9: 2331.45 | O9: 1477.9875 | P9: 2029.455 | Q9: 4107 | R9: =SUM(F9:Q9) -> 22406.94 | S9: =IF(SUM($F9:F9)-$E9-0>0,MAX($AF9,SUM($F9:F9)-$E9-0),0) -> 1322.55 | T9: =IF(SUM($F9:G9)-$E9-SUM($S9:S9)>0,MAX($AF9,SUM($F9:G9)-$E9-SUM($S9:S9)),0) -> 2936.7875 | U9: =IF(SUM($F9:H9)-$E9-SUM($S9:T9)>0,MAX($AF9,SUM($F9:H9)-$E9-SUM($S9:T9)),0) -> 893.9625 | V9: =IF(SUM($F9:I9)-$E9-SUM($S9:U9)>0,MAX($AF9,SUM($F9:I9)-$E9-SUM($S9:U9)),0) -> 1421.0625 | W9: =IF(SUM($F9:J9)-$E9-SUM($S9:V9)>0,MAX($AF9,SUM($F9:J9)-$E9-SUM($S9:V9)),0) -> 757.025 | X9: =IF(SUM($F9:K9)-$E9-SUM($S9:W9)>0,MAX($AF9,SUM($F9:K9)-$E9-SUM($S9:W9)),0) -> 2852.5475 | Y9: =IF(SUM($F9:L9)-$E9-SUM($S9:X9)>0,MAX($AF9,SUM($F9:L9)-$E9-SUM($S9:X9)),0) -> 491.8 | Z9: =IF(SUM($F9:M9)-$E9-SUM($S9:Y9)>0,MAX($AF9,SUM($F9:M9)-$E9-SUM($S9:Y9)),0) -> 1785.3125 | AA9: =IF(SUM($F9:N9)-$E9-SUM($S9:Z9)>0,MAX($AF9,SUM($F9:N9)-$E9-SUM($S9:Z9)),0) -> 2331.45 | ... AD9: =IF(SUM($F9:Q9)-$E9-SUM($S9:AC9)>0,MAX($AF9,SUM($F9:Q9)-$E9-SUM($S9:AC9)),0) -> 4107 | AE9: =SUM(S9:AD9) -> 22406.94 | AF9: 0
A10: ADI | B10: ACIDO ADIPICO | C10: Formulados | D10: kg | E10: 4952.0039 | F10: 0 | G10: 1700.8 | H10: 61.471543 | I10: 0 | J10: 1465.8308 | K10: 878.36 | L10: 1206 | M10: 516 | N10: 330 | O10: 462.59 | P10: 656 | Q10: 1548 | R10: =SUM(F10:Q10) -> 8825.0523 | S10: =IF(SUM($F10:F10)-$E10-0>0,MAX($AF10,SUM($F10:F10)-$E10-0),0) -> 0 | T10: =IF(SUM($F10:G10)-$E10-SUM($S10:S10)>0,MAX($AF10,SUM($F10:G10)-$E10-SUM($S10:S10)),0) -> 0 | U10: =IF(SUM($F10:H10)-$E10-SUM($S10:T10)>0,MAX($AF10,SUM($F10:H10)-$E10-SUM($S10:T10)),0) -> 0 | V10: =IF(SUM($F10:I10)-$E10-SUM($S10:U10)>0,MAX($AF10,SUM($F10:I10)-$E10-SUM($S10:U10)),0) -> 0 | W10: =IF(SUM($F10:J10)-$E10-SUM($S10:V10)>0,MAX($AF10,SUM($F10:J10)-$E10-SUM($S10:V10)),0) -> 0 | X10: =IF(SUM($F10:K10)-$E10-SUM($S10:W10)>0,MAX($AF10,SUM($F10:K10)-$E10-SUM($S10:W10)),0) -> 0 | Y10: =IF(SUM($F10:L10)-$E10-SUM($S10:X10)>0,MAX($AF10,SUM($F10:L10)-$E10-SUM($S10:X10)),0) -> 360.45847 | Z10: =IF(SUM($F10:M10)-$E10-SUM($S10:Y10)>0,MAX($AF10,SUM($F10:M10)-$E10-SUM($S10:Y10)),0) -> 516 | AA10: =IF(SUM($F10:N10)-$E10-SUM($S10:Z10)>0,MAX($AF10,SUM($F10:N10)-$E10-SUM($S10:Z10)),0) -> 330 | ... AD10: =IF(SUM($F10:Q10)-$E10-SUM($S10:AC10)>0,MAX($AF10,SUM($F10:Q10)-$E10-SUM($S10:AC10)),0) -> 1548 | AE10: =SUM(S10:AD10) -> 3873.0485 | AF10: 0
A11: AMARILLO | B11: COLOR AMARILLO | C11: Formulados | D11: kg | E11: 2.9307963 | F11: 0.06624 | G11: 0.04714 | H11: 0.0438 | I11: 0.0079 | J11: 0.0938 | K11: 0.18998 | L11: 0.01071 | M11: 0.01467 | N11: 0.0008 | O11: 0.032 | P11: 0.01133 | Q11: 0.03 | R11: =SUM(F11:Q11) -> 0.54837 | S11: =IF(SUM($F11:F11)-$E11-0>0,MAX($AF11,SUM($F11:F11)-$E11-0),0) -> 0 | T11: =IF(SUM($F11:G11)-$E11-SUM($S11:S11)>0,MAX($AF11,SUM($F11:G11)-$E11-SUM($S11:S11)),0) -> 0 | U11: =IF(SUM($F11:H11)-$E11-SUM($S11:T11)>0,MAX($AF11,SUM($F11:H11)-$E11-SUM($S11:T11)),0) -> 0 | V11: =IF(SUM($F11:I11)-$E11-SUM($S11:U11)>0,MAX($AF11,SUM($F11:I11)-$E11-SUM($S11:U11)),0) -> 0 | W11: =IF(SUM($F11:J11)-$E11-SUM($S11:V11)>0,MAX($AF11,SUM($F11:J11)-$E11-SUM($S11:V11)),0) -> 0 | X11: =IF(SUM($F11:K11)-$E11-SUM($S11:W11)>0,MAX($AF11,SUM($F11:K11)-$E11-SUM($S11:W11)),0) -> 0 | Y11: =IF(SUM($F11:L11)-$E11-SUM($S11:X11)>0,MAX($AF11,SUM($F11:L11)-$E11-SUM($S11:X11)),0) -> 0 | Z11: =IF(SUM($F11:M11)-$E11-SUM($S11:Y11)>0,MAX($AF11,SUM($F11:M11)-$E11-SUM($S11:Y11)),0) -> 0 | AA11: =IF(SUM($F11:N11)-$E11-SUM($S11:Z11)>0,MAX($AF11,SUM($F11:N11)-$E11-SUM($S11:Z11)),0) -> 0 | ... AD11: =IF(SUM($F11:Q11)-$E11-SUM($S11:AC11)>0,MAX($AF11,SUM($F11:Q11)-$E11-SUM($S11:AC11)),0) -> 0 | AE11: =SUM(S11:AD11) -> 0 | AF11: 0
A12: AMO | B12: AMONÍACO | C12: Formulados | D12: kg | E12: 1052.311 | F12: 1272.011 | G12: 1646.2585 | H12: 3444.559 | I12: 1731.516 | J12: 3212.13 | K12: 2440.7125 | L12: 988.8185 | M12: 1316.315 | N12: 753.876 | O12: 1089.428 | P12: 1346.18 | Q12: 872.133 | R12: =SUM(F12:Q12) -> 20113.937 | S12: =IF(SUM($F12:F12)-$E12-0>0,MAX($AF12,SUM($F12:F12)-$E12-0),0) -> 219.70001 | T12: =IF(SUM($F12:G12)-$E12-SUM($S12:S12)>0,MAX($AF12,SUM($F12:G12)-$E12-SUM($S12:S12)),0) -> 1646.2585 | U12: =IF(SUM($F12:H12)-$E12-SUM($S12:T12)>0,MAX($AF12,SUM($F12:H12)-$E12-SUM($S12:T12)),0) -> 3444.559 | V12: =IF(SUM($F12:I12)-$E12-SUM($S12:U12)>0,MAX($AF12,SUM($F12:I12)-$E12-SUM($S12:U12)),0) -> 1731.516 | W12: =IF(SUM($F12:J12)-$E12-SUM($S12:V12)>0,MAX($AF12,SUM($F12:J12)-$E12-SUM($S12:V12)),0) -> 3212.13 | X12: =IF(SUM($F12:K12)-$E12-SUM($S12:W12)>0,MAX($AF12,SUM($F12:K12)-$E12-SUM($S12:W12)),0) -> 2440.7125 | Y12: =IF(SUM($F12:L12)-$E12-SUM($S12:X12)>0,MAX($AF12,SUM($F12:L12)-$E12-SUM($S12:X12)),0) -> 988.8185 | Z12: =IF(SUM($F12:M12)-$E12-SUM($S12:Y12)>0,MAX($AF12,SUM($F12:M12)-$E12-SUM($S12:Y12)),0) -> 1316.315 | AA12: =IF(SUM($F12:N12)-$E12-SUM($S12:Z12)>0,MAX($AF12,SUM($F12:N12)-$E12-SUM($S12:Z12)),0) -> 753.876 | ... AD12: =IF(SUM($F12:Q12)-$E12-SUM($S12:AC12)>0,MAX($AF12,SUM($F12:Q12)-$E12-SUM($S12:AC12)),0) -> 872.133 | AE12: =SUM(S12:AD12) -> 19061.627 | AF12: 0
A13: ANTI | B13: ANTIESPUMANTE ANTISCHIUMA GEN | C13: Formulados | D13: kg | E13: 78.63163 | F13: 0.785 | G13: 1.0692588 | H13: 1.6735559 | I13: 1.8875 | J13: 0.7898 | K13: 1.0176 | L13: 1.8383 | M13: 2.8921 | N13: 0.3582 | O13: 1.2905 | P13: 6.3137 | Q13: 5.0494 | R13: =SUM(F13:Q13) -> 24.964915 | S13: =IF(SUM($F13:F13)-$E13-0>0,MAX($AF13,SUM($F13:F13)-$E13-0),0) -> 0 | T13: =IF(SUM($F13:G13)-$E13-SUM($S13:S13)>0,MAX($AF13,SUM($F13:G13)-$E13-SUM($S13:S13)),0) -> 0 | U13: =IF(SUM($F13:H13)-$E13-SUM($S13:T13)>0,MAX($AF13,SUM($F13:H13)-$E13-SUM($S13:T13)),0) -> 0 | V13: =IF(SUM($F13:I13)-$E13-SUM($S13:U13)>0,MAX($AF13,SUM($F13:I13)-$E13-SUM($S13:U13)),0) -> 0 | W13: =IF(SUM($F13:J13)-$E13-SUM($S13:V13)>0,MAX($AF13,SUM($F13:J13)-$E13-SUM($S13:V13)),0) -> 0 | X13: =IF(SUM($F13:K13)-$E13-SUM($S13:W13)>0,MAX($AF13,SUM($F13:K13)-$E13-SUM($S13:W13)),0) -> 0 | Y13: =IF(SUM($F13:L13)-$E13-SUM($S13:X13)>0,MAX($AF13,SUM($F13:L13)-$E13-SUM($S13:X13)),0) -> 0 | Z13: =IF(SUM($F13:M13)-$E13-SUM($S13:Y13)>0,MAX($AF13,SUM($F13:M13)-$E13-SUM($S13:Y13)),0) -> 0 | AA13: =IF(SUM($F13:N13)-$E13-SUM($S13:Z13)>0,MAX($AF13,SUM($F13:N13)-$E13-SUM($S13:Z13)),0) -> 0 | ... AD13: =IF(SUM($F13:Q13)-$E13-SUM($S13:AC13)>0,MAX($AF13,SUM($F13:Q13)-$E13-SUM($S13:AC13)),0) -> 0 | AE13: =SUM(S13:AD13) -> 0 | AF13: 0
A14: AR | B14: FINDET AR-52 | C14: Formulados | D14: kg | E14: 0 | F14: 476.12463 | G14: 649.62839 | H14: 1863.0304 | I14: 928.62117 | J14: 2849.025 | K14: 2059.6992 | L14: 1458.4914 | M14: 517.03386 | N14: 395.11568 | O14: 434.77509 | P14: 735.13768 | Q14: 1634.8149 | R14: =SUM(F14:Q14) -> 14001.497 | S14: =IF(SUM($F14:F14)-$E14-0>0,MAX($AF14,SUM($F14:F14)-$E14-0),0) -> 476.12463 | T14: =IF(SUM($F14:G14)-$E14-SUM($S14:S14)>0,MAX($AF14,SUM($F14:G14)-$E14-SUM($S14:S14)),0) -> 649.62839 | U14: =IF(SUM($F14:H14)-$E14-SUM($S14:T14)>0,MAX($AF14,SUM($F14:H14)-$E14-SUM($S14:T14)),0) -> 1863.0304 | V14: =IF(SUM($F14:I14)-$E14-SUM($S14:U14)>0,MAX($AF14,SUM($F14:I14)-$E14-SUM($S14:U14)),0) -> 928.62117 | W14: =IF(SUM($F14:J14)-$E14-SUM($S14:V14)>0,MAX($AF14,SUM($F14:J14)-$E14-SUM($S14:V14)),0) -> 2849.025 | X14: =IF(SUM($F14:K14)-$E14-SUM($S14:W14)>0,MAX($AF14,SUM($F14:K14)-$E14-SUM($S14:W14)),0) -> 2059.6992 | Y14: =IF(SUM($F14:L14)-$E14-SUM($S14:X14)>0,MAX($AF14,SUM($F14:L14)-$E14-SUM($S14:X14)),0) -> 1458.4914 | Z14: =IF(SUM($F14:M14)-$E14-SUM($S14:Y14)>0,MAX($AF14,SUM($F14:M14)-$E14-SUM($S14:Y14)),0) -> 517.03386 | AA14: =IF(SUM($F14:N14)-$E14-SUM($S14:Z14)>0,MAX($AF14,SUM($F14:N14)-$E14-SUM($S14:Z14)),0) -> 395.11568 | ... AD14: =IF(SUM($F14:Q14)-$E14-SUM($S14:AC14)>0,MAX($AF14,SUM($F14:Q14)-$E14-SUM($S14:AC14)),0) -> 1634.8149 | AE14: =SUM(S14:AD14) -> 14001.497 | AF14: 0
A15: ATC | B15: AATC | C15: Formulados | D15: kg | E15: 0 | F15: 7.844 | G15: 15.202 | H15: 2.545 | I15: 14.376 | J15: 4.385 | K15: 8.405 | L15: 3.183 | M15: 9.422 | N15: 7.023 | O15: 1.57 | P15: 3.21 | Q15: 11.326 | R15: =SUM(F15:Q15) -> 88.491 | S15: =IF(SUM($F15:F15)-$E15-0>0,MAX($AF15,SUM($F15:F15)-$E15-0),0) -> 7.844 | T15: =IF(SUM($F15:G15)-$E15-SUM($S15:S15)>0,MAX($AF15,SUM($F15:G15)-$E15-SUM($S15:S15)),0) -> 15.202 | U15: =IF(SUM($F15:H15)-$E15-SUM($S15:T15)>0,MAX($AF15,SUM($F15:H15)-$E15-SUM($S15:T15)),0) -> 2.545 | V15: =IF(SUM($F15:I15)-$E15-SUM($S15:U15)>0,MAX($AF15,SUM($F15:I15)-$E15-SUM($S15:U15)),0) -> 14.376 | W15: =IF(SUM($F15:J15)-$E15-SUM($S15:V15)>0,MAX($AF15,SUM($F15:J15)-$E15-SUM($S15:V15)),0) -> 4.385 | X15: =IF(SUM($F15:K15)-$E15-SUM($S15:W15)>0,MAX($AF15,SUM($F15:K15)-$E15-SUM($S15:W15)),0) -> 8.405 | Y15: =IF(SUM($F15:L15)-$E15-SUM($S15:X15)>0,MAX($AF15,SUM($F15:L15)-$E15-SUM($S15:X15)),0) -> 3.183 | Z15: =IF(SUM($F15:M15)-$E15-SUM($S15:Y15)>0,MAX($AF15,SUM($F15:M15)-$E15-SUM($S15:Y15)),0) -> 9.422 | AA15: =IF(SUM($F15:N15)-$E15-SUM($S15:Z15)>0,MAX($AF15,SUM($F15:N15)-$E15-SUM($S15:Z15)),0) -> 7.023 | ... AD15: =IF(SUM($F15:Q15)-$E15-SUM($S15:AC15)>0,MAX($AF15,SUM($F15:Q15)-$E15-SUM($S15:AC15)),0) -> 11.326 | AE15: =SUM(S15:AD15) -> 88.491 | AF15: 0
A16: AV24 | B16: AV24 | C16: Formulados | D16: kg | E16: 0 | F16: 0 | G16: 5100.613 | H16: 0 | I16: 11.55 | J16: 0 | K16: 214.85 | L16: 0 | M16: 153.825 | N16: 0 | O16: 0 | P16: 217.35 | Q16: 3087.346 | R16: =SUM(F16:Q16) -> 8785.534 | S16: =IF(SUM($F16:F16)-$E16-0>0,MAX($AF16,SUM($F16:F16)-$E16-0),0) -> 0 | T16: =IF(SUM($F16:G16)-$E16-SUM($S16:S16)>0,MAX($AF16,SUM($F16:G16)-$E16-SUM($S16:S16)),0) -> 5100.613 | U16: =IF(SUM($F16:H16)-$E16-SUM($S16:T16)>0,MAX($AF16,SUM($F16:H16)-$E16-SUM($S16:T16)),0) -> 0 | V16: =IF(SUM($F16:I16)-$E16-SUM($S16:U16)>0,MAX($AF16,SUM($F16:I16)-$E16-SUM($S16:U16)),0) -> 11.55 | W16: =IF(SUM($F16:J16)-$E16-SUM($S16:V16)>0,MAX($AF16,SUM($F16:J16)-$E16-SUM($S16:V16)),0) -> 0 | X16: =IF(SUM($F16:K16)-$E16-SUM($S16:W16)>0,MAX($AF16,SUM($F16:K16)-$E16-SUM($S16:W16)),0) -> 214.85 | Y16: =IF(SUM($F16:L16)-$E16-SUM($S16:X16)>0,MAX($AF16,SUM($F16:L16)-$E16-SUM($S16:X16)),0) -> 0 | Z16: =IF(SUM($F16:M16)-$E16-SUM($S16:Y16)>0,MAX($AF16,SUM($F16:M16)-$E16-SUM($S16:Y16)),0) -> 153.825 | AA16: =IF(SUM($F16:N16)-$E16-SUM($S16:Z16)>0,MAX($AF16,SUM($F16:N16)-$E16-SUM($S16:Z16)),0) -> 0 | ... AD16: =IF(SUM($F16:Q16)-$E16-SUM($S16:AC16)>0,MAX($AF16,SUM($F16:Q16)-$E16-SUM($S16:AC16)),0) -> 3087.346 | AE16: =SUM(S16:AD16) -> 8785.534 | AF16: 0
A17: BET | B17: BETAÍNA DE REMOLACHA | C17: Formulados | D17: kg | E17: 0 | F17: 595.984 | G17: 922.50579 | H17: 1017.13 | I17: 1657.9895 | J17: 1732.945 | K17: 3531.4085 | L17: 1370.472 | M17: 462.566 | N17: 174.171 | O17: 874.575 | P17: 1098.866 | Q17: 413.3995 | R17: =SUM(F17:Q17) -> 13852.012 | S17: =IF(SUM($F17:F17)-$E17-0>0,MAX($AF17,SUM($F17:F17)-$E17-0),0) -> 595.984 | T17: =IF(SUM($F17:G17)-$E17-SUM($S17:S17)>0,MAX($AF17,SUM($F17:G17)-$E17-SUM($S17:S17)),0) -> 922.50579 | U17: =IF(SUM($F17:H17)-$E17-SUM($S17:T17)>0,MAX($AF17,SUM($F17:H17)-$E17-SUM($S17:T17)),0) -> 1017.13 | V17: =IF(SUM($F17:I17)-$E17-SUM($S17:U17)>0,MAX($AF17,SUM($F17:I17)-$E17-SUM($S17:U17)),0) -> 1657.9895 | W17: =IF(SUM($F17:J17)-$E17-SUM($S17:V17)>0,MAX($AF17,SUM($F17:J17)-$E17-SUM($S17:V17)),0) -> 1732.945 | X17: =IF(SUM($F17:K17)-$E17-SUM($S17:W17)>0,MAX($AF17,SUM($F17:K17)-$E17-SUM($S17:W17)),0) -> 3531.4085 | Y17: =IF(SUM($F17:L17)-$E17-SUM($S17:X17)>0,MAX($AF17,SUM($F17:L17)-$E17-SUM($S17:X17)),0) -> 1370.472 | Z17: =IF(SUM($F17:M17)-$E17-SUM($S17:Y17)>0,MAX($AF17,SUM($F17:M17)-$E17-SUM($S17:Y17)),0) -> 462.566 | AA17: =IF(SUM($F17:N17)-$E17-SUM($S17:Z17)>0,MAX($AF17,SUM($F17:N17)-$E17-SUM($S17:Z17)),0) -> 174.171 | ... AD17: =IF(SUM($F17:Q17)-$E17-SUM($S17:AC17)>0,MAX($AF17,SUM($F17:Q17)-$E17-SUM($S17:AC17)),0) -> 413.3995 | AE17: =SUM(S17:AD17) -> 13852.012 | AF17: 0
A18: BICAR | B18: BICARBONATO SÓDICO ALIM. | C18: Formulados | D18: kg | E18: 3485 | F18: 0 | G18: 0 | H18: 0 | I18: 238.99807 | J18: 0 | K18: 105 | L18: 210 | M18: 425 | N18: 0 | O18: 510 | P18: 0 | Q18: 0 | R18: =SUM(F18:Q18) -> 1488.9981 | S18: =IF(SUM($F18:F18)-$E18-0>0,MAX($AF18,SUM($F18:F18)-$E18-0),0) -> 0 | T18: =IF(SUM($F18:G18)-$E18-SUM($S18:S18)>0,MAX($AF18,SUM($F18:G18)-$E18-SUM($S18:S18)),0) -> 0 | U18: =IF(SUM($F18:H18)-$E18-SUM($S18:T18)>0,MAX($AF18,SUM($F18:H18)-$E18-SUM($S18:T18)),0) -> 0 | V18: =IF(SUM($F18:I18)-$E18-SUM($S18:U18)>0,MAX($AF18,SUM($F18:I18)-$E18-SUM($S18:U18)),0) -> 0 | W18: =IF(SUM($F18:J18)-$E18-SUM($S18:V18)>0,MAX($AF18,SUM($F18:J18)-$E18-SUM($S18:V18)),0) -> 0 | X18: =IF(SUM($F18:K18)-$E18-SUM($S18:W18)>0,MAX($AF18,SUM($F18:K18)-$E18-SUM($S18:W18)),0) -> 0 | Y18: =IF(SUM($F18:L18)-$E18-SUM($S18:X18)>0,MAX($AF18,SUM($F18:L18)-$E18-SUM($S18:X18)),0) -> 0 | Z18: =IF(SUM($F18:M18)-$E18-SUM($S18:Y18)>0,MAX($AF18,SUM($F18:M18)-$E18-SUM($S18:Y18)),0) -> 0 | AA18: =IF(SUM($F18:N18)-$E18-SUM($S18:Z18)>0,MAX($AF18,SUM($F18:N18)-$E18-SUM($S18:Z18)),0) -> 0 | ... AD18: =IF(SUM($F18:Q18)-$E18-SUM($S18:AC18)>0,MAX($AF18,SUM($F18:Q18)-$E18-SUM($S18:AC18)),0) -> 0 | AE18: =SUM(S18:AD18) -> 0 | AF18: 0
A19: BOCAL | B19: BRETAX-CL | C19: Formulados | D19: kg | E19: 19980.673 | F19: 663.228 | G19: 2205.42 | H19: 1435.392 | I19: 1661.808 | J19: 1523.6468 | K19: 2057.235 | L19: 1749.733 | M19: 2600.58 | N19: 625.848 | O19: 1482.384 | P19: 1393.74 | Q19: 35.244 | R19: =SUM(F19:Q19) -> 17434.259 | S19: =IF(SUM($F19:F19)-$E19-0>0,MAX($AF19,SUM($F19:F19)-$E19-0),0) -> 0 | T19: =IF(SUM($F19:G19)-$E19-SUM($S19:S19)>0,MAX($AF19,SUM($F19:G19)-$E19-SUM($S19:S19)),0) -> 0 | U19: =IF(SUM($F19:H19)-$E19-SUM($S19:T19)>0,MAX($AF19,SUM($F19:H19)-$E19-SUM($S19:T19)),0) -> 0 | V19: =IF(SUM($F19:I19)-$E19-SUM($S19:U19)>0,MAX($AF19,SUM($F19:I19)-$E19-SUM($S19:U19)),0) -> 0 | W19: =IF(SUM($F19:J19)-$E19-SUM($S19:V19)>0,MAX($AF19,SUM($F19:J19)-$E19-SUM($S19:V19)),0) -> 0 | X19: =IF(SUM($F19:K19)-$E19-SUM($S19:W19)>0,MAX($AF19,SUM($F19:K19)-$E19-SUM($S19:W19)),0) -> 0 | Y19: =IF(SUM($F19:L19)-$E19-SUM($S19:X19)>0,MAX($AF19,SUM($F19:L19)-$E19-SUM($S19:X19)),0) -> 0 | Z19: =IF(SUM($F19:M19)-$E19-SUM($S19:Y19)>0,MAX($AF19,SUM($F19:M19)-$E19-SUM($S19:Y19)),0) -> 0 | AA19: =IF(SUM($F19:N19)-$E19-SUM($S19:Z19)>0,MAX($AF19,SUM($F19:N19)-$E19-SUM($S19:Z19)),0) -> 0 | ... AD19: =IF(SUM($F19:Q19)-$E19-SUM($S19:AC19)>0,MAX($AF19,SUM($F19:Q19)-$E19-SUM($S19:AC19)),0) -> 0 | AE19: =SUM(S19:AD19) -> 0 | AF19: 0
... A28: CLORPO | B28: CLORURO POTASICO | C28: Formulados | D28: kg | E28: 0 | F28: 753.08977 | G28: 247.11707 | H28: 1207.05 | I28: 34.32 | J28: 356.07 | K28: 1212.822 | L28: 169.26 | M28: 449.28 | N28: 0 | O28: 740.532 | P28: 934.128 | Q28: 128.544 | R28: =SUM(F28:Q28) -> 6232.2128 | S28: =IF(SUM($F28:F28)-$E28-0>0,MAX($AF28,SUM($F28:F28)-$E28-0),0) -> 753.08977 | T28: =IF(SUM($F28:G28)-$E28-SUM($S28:S28)>0,MAX($AF28,SUM($F28:G28)-$E28-SUM($S28:S28)),0) -> 247.11707 | U28: =IF(SUM($F28:H28)-$E28-SUM($S28:T28)>0,MAX($AF28,SUM($F28:H28)-$E28-SUM($S28:T28)),0) -> 1207.05 | V28: =IF(SUM($F28:I28)-$E28-SUM($S28:U28)>0,MAX($AF28,SUM($F28:I28)-$E28-SUM($S28:U28)),0) -> 34.32 | W28: =IF(SUM($F28:J28)-$E28-SUM($S28:V28)>0,MAX($AF28,SUM($F28:J28)-$E28-SUM($S28:V28)),0) -> 356.07 | X28: =IF(SUM($F28:K28)-$E28-SUM($S28:W28)>0,MAX($AF28,SUM($F28:K28)-$E28-SUM($S28:W28)),0) -> 1212.822 | Y28: =IF(SUM($F28:L28)-$E28-SUM($S28:X28)>0,MAX($AF28,SUM($F28:L28)-$E28-SUM($S28:X28)),0) -> 169.26 | Z28: =IF(SUM($F28:M28)-$E28-SUM($S28:Y28)>0,MAX($AF28,SUM($F28:M28)-$E28-SUM($S28:Y28)),0) -> 449.28 | AA28: =IF(SUM($F28:N28)-$E28-SUM($S28:Z28)>0,MAX($AF28,SUM($F28:N28)-$E28-SUM($S28:Z28)),0) -> 0 | ... AD28: =IF(SUM($F28:Q28)-$E28-SUM($S28:AC28)>0,MAX($AF28,SUM($F28:Q28)-$E28-SUM($S28:AC28)),0) -> 128.544 | AE28: =SUM(S28:AD28) -> 6232.2128 | AF28: 0
A29: CMG | B29: CARBONATO DE MAGNESIO - MAGNESITA | C29: Formulados | D29: kg | E29: 0 | F29: 0 | G29: 0 | H29: 3.1381869 | I29: 0 | J29: 11.135 | K29: 2.04 | L29: 0 | M29: 0 | N29: 0 | O29: 3.91 | P29: 0 | Q29: 0 | R29: =SUM(F29:Q29) -> 20.223187 | S29: =IF(SUM($F29:F29)-$E29-0>0,MAX($AF29,SUM($F29:F29)-$E29-0),0) -> 0 | T29: =IF(SUM($F29:G29)-$E29-SUM($S29:S29)>0,MAX($AF29,SUM($F29:G29)-$E29-SUM($S29:S29)),0) -> 0 | U29: =IF(SUM($F29:H29)-$E29-SUM($S29:T29)>0,MAX($AF29,SUM($F29:H29)-$E29-SUM($S29:T29)),0) -> 500 | V29: =IF(SUM($F29:I29)-$E29-SUM($S29:U29)>0,MAX($AF29,SUM($F29:I29)-$E29-SUM($S29:U29)),0) -> 0 | W29: =IF(SUM($F29:J29)-$E29-SUM($S29:V29)>0,MAX($AF29,SUM($F29:J29)-$E29-SUM($S29:V29)),0) -> 0 | X29: =IF(SUM($F29:K29)-$E29-SUM($S29:W29)>0,MAX($AF29,SUM($F29:K29)-$E29-SUM($S29:W29)),0) -> 0 | Y29: =IF(SUM($F29:L29)-$E29-SUM($S29:X29)>0,MAX($AF29,SUM($F29:L29)-$E29-SUM($S29:X29)),0) -> 0 | Z29: =IF(SUM($F29:M29)-$E29-SUM($S29:Y29)>0,MAX($AF29,SUM($F29:M29)-$E29-SUM($S29:Y29)),0) -> 0 | AA29: =IF(SUM($F29:N29)-$E29-SUM($S29:Z29)>0,MAX($AF29,SUM($F29:N29)-$E29-SUM($S29:Z29)),0) -> 0 | ... AD29: =IF(SUM($F29:Q29)-$E29-SUM($S29:AC29)>0,MAX($AF29,SUM($F29:Q29)-$E29-SUM($S29:AC29)),0) -> 0 | AE29: =SUM(S29:AD29) -> 500 | AF29: 500 | AG29: Lote mínimo indicado por el usuario.
A30: CMN | B30: CLORURO DE MANGANESO | C30: Formulados | D30: kg | E30: 166.51672 | F30: 38.016 | G30: 125.796 | H30: 33.88 | I30: 0 | J30: 107.712 | K30: 125.84 | L30: 44 | M30: 0 | N30: 0 | O30: 18.04 | P30: 133.1 | Q30: 0 | R30: =SUM(F30:Q30) -> 626.384 | S30: =IF(SUM($F30:F30)-$E30-0>0,MAX($AF30,SUM($F30:F30)-$E30-0),0) -> 0 | T30: =IF(SUM($F30:G30)-$E30-SUM($S30:S30)>0,MAX($AF30,SUM($F30:G30)-$E30-SUM($S30:S30)),0) -> 0 | U30: =IF(SUM($F30:H30)-$E30-SUM($S30:T30)>0,MAX($AF30,SUM($F30:H30)-$E30-SUM($S30:T30)),0) -> 31.175276 | V30: =IF(SUM($F30:I30)-$E30-SUM($S30:U30)>0,MAX($AF30,SUM($F30:I30)-$E30-SUM($S30:U30)),0) -> 0 | W30: =IF(SUM($F30:J30)-$E30-SUM($S30:V30)>0,MAX($AF30,SUM($F30:J30)-$E30-SUM($S30:V30)),0) -> 107.712 | X30: =IF(SUM($F30:K30)-$E30-SUM($S30:W30)>0,MAX($AF30,SUM($F30:K30)-$E30-SUM($S30:W30)),0) -> 125.84 | Y30: =IF(SUM($F30:L30)-$E30-SUM($S30:X30)>0,MAX($AF30,SUM($F30:L30)-$E30-SUM($S30:X30)),0) -> 44 | Z30: =IF(SUM($F30:M30)-$E30-SUM($S30:Y30)>0,MAX($AF30,SUM($F30:M30)-$E30-SUM($S30:Y30)),0) -> 0 | AA30: =IF(SUM($F30:N30)-$E30-SUM($S30:Z30)>0,MAX($AF30,SUM($F30:N30)-$E30-SUM($S30:Z30)),0) -> 0 | ... AD30: =IF(SUM($F30:Q30)-$E30-SUM($S30:AC30)>0,MAX($AF30,SUM($F30:Q30)-$E30-SUM($S30:AC30)),0) -> 0 | AE30: =SUM(S30:AD30) -> 459.86728 | AF30: 0
A31: CZN | B31: CLORURO DE ZINC | C31: Formulados | D31: kg | E31: 157.16897 | F31: 22.464 | G31: 74.334 | H31: 20.02 | I31: 0 | J31: 63.648 | K31: 74.36 | L31: 26 | M31: 0 | N31: 0 | O31: 10.66 | P31: 78.65 | Q31: 0 | R31: =SUM(F31:Q31) -> 370.136 | S31: =IF(SUM($F31:F31)-$E31-0>0,MAX($AF31,SUM($F31:F31)-$E31-0),0) -> 0 | T31: =IF(SUM($F31:G31)-$E31-SUM($S31:S31)>0,MAX($AF31,SUM($F31:G31)-$E31-SUM($S31:S31)),0) -> 0 | U31: =IF(SUM($F31:H31)-$E31-SUM($S31:T31)>0,MAX($AF31,SUM($F31:H31)-$E31-SUM($S31:T31)),0) -> 0 | V31: =IF(SUM($F31:I31)-$E31-SUM($S31:U31)>0,MAX($AF31,SUM($F31:I31)-$E31-SUM($S31:U31)),0) -> 0 | W31: =IF(SUM($F31:J31)-$E31-SUM($S31:V31)>0,MAX($AF31,SUM($F31:J31)-$E31-SUM($S31:V31)),0) -> 23.297027 | X31: =IF(SUM($F31:K31)-$E31-SUM($S31:W31)>0,MAX($AF31,SUM($F31:K31)-$E31-SUM($S31:W31)),0) -> 74.36 | Y31: =IF(SUM($F31:L31)-$E31-SUM($S31:X31)>0,MAX($AF31,SUM($F31:L31)-$E31-SUM($S31:X31)),0) -> 26 | Z31: =IF(SUM($F31:M31)-$E31-SUM($S31:Y31)>0,MAX($AF31,SUM($F31:M31)-$E31-SUM($S31:Y31)),0) -> 0 | AA31: =IF(SUM($F31:N31)-$E31-SUM($S31:Z31)>0,MAX($AF31,SUM($F31:N31)-$E31-SUM($S31:Z31)),0) -> 0 | ... AD31: =IF(SUM($F31:Q31)-$E31-SUM($S31:AC31)>0,MAX($AF31,SUM($F31:Q31)-$E31-SUM($S31:AC31)),0) -> 0 | AE31: =SUM(S31:AD31) -> 212.96703 | AF31: 0
A32: D55 | B32: DADMEL 55 | C32: Formulados | D32: kg | E32: 0 | F32: 1126 | G32: 1413.2375 | H32: 1578.5094 | I32: 1889.16 | J32: 1712.16 | K32: 2117 | L32: 1614.93 | M32: 1019 | N32: 623.28 | O32: 2503.96 | P32: 2793.08 | Q32: 925.68 | R32: =SUM(F32:Q32) -> 19315.997 | S32: =IF(SUM($F32:F32)-$E32-0>0,MAX($AF32,SUM($F32:F32)-$E32-0),0) -> 1126 | T32: =IF(SUM($F32:G32)-$E32-SUM($S32:S32)>0,MAX($AF32,SUM($F32:G32)-$E32-SUM($S32:S32)),0) -> 1413.2375 | U32: =IF(SUM($F32:H32)-$E32-SUM($S32:T32)>0,MAX($AF32,SUM($F32:H32)-$E32-SUM($S32:T32)),0) -> 1578.5094 | V32: =IF(SUM($F32:I32)-$E32-SUM($S32:U32)>0,MAX($AF32,SUM($F32:I32)-$E32-SUM($S32:U32)),0) -> 1889.16 | W32: =IF(SUM($F32:J32)-$E32-SUM($S32:V32)>0,MAX($AF32,SUM($F32:J32)-$E32-SUM($S32:V32)),0) -> 1712.16 | X32: =IF(SUM($F32:K32)-$E32-SUM($S32:W32)>0,MAX($AF32,SUM($F32:K32)-$E32-SUM($S32:W32)),0) -> 2117 | Y32: =IF(SUM($F32:L32)-$E32-SUM($S32:X32)>0,MAX($AF32,SUM($F32:L32)-$E32-SUM($S32:X32)),0) -> 1614.93 | Z32: =IF(SUM($F32:M32)-$E32-SUM($S32:Y32)>0,MAX($AF32,SUM($F32:M32)-$E32-SUM($S32:Y32)),0) -> 1019 | AA32: =IF(SUM($F32:N32)-$E32-SUM($S32:Z32)>0,MAX($AF32,SUM($F32:N32)-$E32-SUM($S32:Z32)),0) -> 623.28 | ... AD32: =IF(SUM($F32:Q32)-$E32-SUM($S32:AC32)>0,MAX($AF32,SUM($F32:Q32)-$E32-SUM($S32:AC32)),0) -> 925.68 | AE32: =SUM(S32:AD32) -> 19315.997 | AF32: 0
A33: DECL | B33: DESHCOFIX -108-(LÍQUIDO) | C33: Formulados | D33: kg | E33: 0 | F33: 16267.592 | G33: 22195.637 | H33: 63653.537 | I33: 31727.89 | J33: 97341.686 | K33: 70373.055 | L33: 49831.789 | M33: 17665.323 | N33: 13499.786 | O33: 14854.816 | P33: 25117.204 | Q33: 55856.175 | R33: =SUM(F33:Q33) -> 478384.49 | S33: =IF(SUM($F33:F33)-$E33-0>0,MAX($AF33,SUM($F33:F33)-$E33-0),0) -> 16267.592 | T33: =IF(SUM($F33:G33)-$E33-SUM($S33:S33)>0,MAX($AF33,SUM($F33:G33)-$E33-SUM($S33:S33)),0) -> 22195.637 | U33: =IF(SUM($F33:H33)-$E33-SUM($S33:T33)>0,MAX($AF33,SUM($F33:H33)-$E33-SUM($S33:T33)),0) -> 63653.537 | V33: =IF(SUM($F33:I33)-$E33-SUM($S33:U33)>0,MAX($AF33,SUM($F33:I33)-$E33-SUM($S33:U33)),0) -> 31727.89 | W33: =IF(SUM($F33:J33)-$E33-SUM($S33:V33)>0,MAX($AF33,SUM($F33:J33)-$E33-SUM($S33:V33)),0) -> 97341.686 | X33: =IF(SUM($F33:K33)-$E33-SUM($S33:W33)>0,MAX($AF33,SUM($F33:K33)-$E33-SUM($S33:W33)),0) -> 70373.055 | Y33: =IF(SUM($F33:L33)-$E33-SUM($S33:X33)>0,MAX($AF33,SUM($F33:L33)-$E33-SUM($S33:X33)),0) -> 49831.789 | Z33: =IF(SUM($F33:M33)-$E33-SUM($S33:Y33)>0,MAX($AF33,SUM($F33:M33)-$E33-SUM($S33:Y33)),0) -> 17665.323 | AA33: =IF(SUM($F33:N33)-$E33-SUM($S33:Z33)>0,MAX($AF33,SUM($F33:N33)-$E33-SUM($S33:Z33)),0) -> 13499.786 | ... AD33: =IF(SUM($F33:Q33)-$E33-SUM($S33:AC33)>0,MAX($AF33,SUM($F33:Q33)-$E33-SUM($S33:AC33)),0) -> 55856.175 | AE33: =SUM(S33:AD33) -> 478384.49 | AF33: 0
A34: EBRO | B34: EBROSIL | C34: Formulados | D34: kg | E34: 0 | F34: 68.55 | G34: 62.3 | H34: 42.903796 | I34: 111.99 | J34: 255.99 | K34: 50.5 | L34: 45.61 | M34: 37.75 | N34: 186.53 | O34: 8.82 | P34: 55.01 | Q34: 358.76 | R34: =SUM(F34:Q34) -> 1284.7138 | S34: =IF(SUM($F34:F34)-$E34-0>0,MAX($AF34,SUM($F34:F34)-$E34-0),0) -> 68.55 | T34: =IF(SUM($F34:G34)-$E34-SUM($S34:S34)>0,MAX($AF34,SUM($F34:G34)-$E34-SUM($S34:S34)),0) -> 62.3 | U34: =IF(SUM($F34:H34)-$E34-SUM($S34:T34)>0,MAX($AF34,SUM($F34:H34)-$E34-SUM($S34:T34)),0) -> 42.903796 | V34: =IF(SUM($F34:I34)-$E34-SUM($S34:U34)>0,MAX($AF34,SUM($F34:I34)-$E34-SUM($S34:U34)),0) -> 111.99 | W34: =IF(SUM($F34:J34)-$E34-SUM($S34:V34)>0,MAX($AF34,SUM($F34:J34)-$E34-SUM($S34:V34)),0) -> 255.99 | X34: =IF(SUM($F34:K34)-$E34-SUM($S34:W34)>0,MAX($AF34,SUM($F34:K34)-$E34-SUM($S34:W34)),0) -> 50.5 | Y34: =IF(SUM($F34:L34)-$E34-SUM($S34:X34)>0,MAX($AF34,SUM($F34:L34)-$E34-SUM($S34:X34)),0) -> 45.61 | Z34: =IF(SUM($F34:M34)-$E34-SUM($S34:Y34)>0,MAX($AF34,SUM($F34:M34)-$E34-SUM($S34:Y34)),0) -> 37.75 | AA34: =IF(SUM($F34:N34)-$E34-SUM($S34:Z34)>0,MAX($AF34,SUM($F34:N34)-$E34-SUM($S34:Z34)),0) -> 186.53 | ... AD34: =IF(SUM($F34:Q34)-$E34-SUM($S34:AC34)>0,MAX($AF34,SUM($F34:Q34)-$E34-SUM($S34:AC34)),0) -> 358.76 | AE34: =SUM(S34:AD34) -> 1284.7138 | AF34: 0
A35: EDT | B35: EDTA | C35: Formulados | D35: kg | E35: 0 | F35: 350.02856 | G35: 727.94118 | H35: 468.84456 | I35: 614.4725 | J35: 566.04278 | K35: 1059.7312 | L35: 608.5239 | M35: 400.68 | N35: 327.8881 | O35: 474.5331 | P35: 468.8626 | Q35: 1359.8344 | R35: =SUM(F35:Q35) -> 7427.3829 | S35: =IF(SUM($F35:F35)-$E35-0>0,MAX($AF35,SUM($F35:F35)-$E35-0),0) -> 350.02856 | T35: =IF(SUM($F35:G35)-$E35-SUM($S35:S35)>0,MAX($AF35,SUM($F35:G35)-$E35-SUM($S35:S35)),0) -> 727.94118 | U35: =IF(SUM($F35:H35)-$E35-SUM($S35:T35)>0,MAX($AF35,SUM($F35:H35)-$E35-SUM($S35:T35)),0) -> 468.84456 | V35: =IF(SUM($F35:I35)-$E35-SUM($S35:U35)>0,MAX($AF35,SUM($F35:I35)-$E35-SUM($S35:U35)),0) -> 614.4725 | W35: =IF(SUM($F35:J35)-$E35-SUM($S35:V35)>0,MAX($AF35,SUM($F35:J35)-$E35-SUM($S35:V35)),0) -> 566.04278 | X35: =IF(SUM($F35:K35)-$E35-SUM($S35:W35)>0,MAX($AF35,SUM($F35:K35)-$E35-SUM($S35:W35)),0) -> 1059.7312 | Y35: =IF(SUM($F35:L35)-$E35-SUM($S35:X35)>0,MAX($AF35,SUM($F35:L35)-$E35-SUM($S35:X35)),0) -> 608.5239 | Z35: =IF(SUM($F35:M35)-$E35-SUM($S35:Y35)>0,MAX($AF35,SUM($F35:M35)-$E35-SUM($S35:Y35)),0) -> 400.68 | AA35: =IF(SUM($F35:N35)-$E35-SUM($S35:Z35)>0,MAX($AF35,SUM($F35:N35)-$E35-SUM($S35:Z35)),0) -> 327.8881 | ... AD35: =IF(SUM($F35:Q35)-$E35-SUM($S35:AC35)>0,MAX($AF35,SUM($F35:Q35)-$E35-SUM($S35:AC35)),0) -> 1359.8344 | AE35: =SUM(S35:AD35) -> 7427.3829 | AF35: 0
A36: EDTACU | B36: DISSOLVINE - EDTA- CU-15 | C36: Formulados | D36: kg | E36: 64.498712 | F36: 0 | G36: 0 | H36: 0 | I36: 0 | J36: 80 | K36: 0 | L36: 2.438 | M36: 2.438 | N36: 0 | O36: 80 | P36: 300.586 | Q36: 80 | R36: =SUM(F36:Q36) -> 545.462 | S36: =IF(SUM($F36:F36)-$E36-0>0,MAX($AF36,SUM($F36:F36)-$E36-0),0) -> 0 | T36: =IF(SUM($F36:G36)-$E36-SUM($S36:S36)>0,MAX($AF36,SUM($F36:G36)-$E36-SUM($S36:S36)),0) -> 0 | U36: =IF(SUM($F36:H36)-$E36-SUM($S36:T36)>0,MAX($AF36,SUM($F36:H36)-$E36-SUM($S36:T36)),0) -> 0 | V36: =IF(SUM($F36:I36)-$E36-SUM($S36:U36)>0,MAX($AF36,SUM($F36:I36)-$E36-SUM($S36:U36)),0) -> 0 | W36: =IF(SUM($F36:J36)-$E36-SUM($S36:V36)>0,MAX($AF36,SUM($F36:J36)-$E36-SUM($S36:V36)),0) -> 15.501288 | X36: =IF(SUM($F36:K36)-$E36-SUM($S36:W36)>0,MAX($AF36,SUM($F36:K36)-$E36-SUM($S36:W36)),0) -> 0 | Y36: =IF(SUM($F36:L36)-$E36-SUM($S36:X36)>0,MAX($AF36,SUM($F36:L36)-$E36-SUM($S36:X36)),0) -> 2.438 | Z36: =IF(SUM($F36:M36)-$E36-SUM($S36:Y36)>0,MAX($AF36,SUM($F36:M36)-$E36-SUM($S36:Y36)),0) -> 2.438 | AA36: =IF(SUM($F36:N36)-$E36-SUM($S36:Z36)>0,MAX($AF36,SUM($F36:N36)-$E36-SUM($S36:Z36)),0) -> 0 | ... AD36: =IF(SUM($F36:Q36)-$E36-SUM($S36:AC36)>0,MAX($AF36,SUM($F36:Q36)-$E36-SUM($S36:AC36)),0) -> 80 | AE36: =SUM(S36:AD36) -> 480.96329 | AF36: 0
A37: EDTAFE | B37: DISSOLVINE - EDTA-FE 13 | C37: Formulados | D37: kg | E37: 37.819609 | F37: 0 | G37: 0 | H37: 0 | I37: 0 | J37: 0 | K37: 0 | L37: 2.438 | M37: 2.438 | N37: 0 | O37: 0 | P37: 2.346 | Q37: 0 | R37: =SUM(F37:Q37) -> 7.222 | S37: =IF(SUM($F37:F37)-$E37-0>0,MAX($AF37,SUM($F37:F37)-$E37-0),0) -> 0 | T37: =IF(SUM($F37:G37)-$E37-SUM($S37:S37)>0,MAX($AF37,SUM($F37:G37)-$E37-SUM($S37:S37)),0) -> 0 | U37: =IF(SUM($F37:H37)-$E37-SUM($S37:T37)>0,MAX($AF37,SUM($F37:H37)-$E37-SUM($S37:T37)),0) -> 0 | V37: =IF(SUM($F37:I37)-$E37-SUM($S37:U37)>0,MAX($AF37,SUM($F37:I37)-$E37-SUM($S37:U37)),0) -> 0 | W37: =IF(SUM($F37:J37)-$E37-SUM($S37:V37)>0,MAX($AF37,SUM($F37:J37)-$E37-SUM($S37:V37)),0) -> 0 | X37: =IF(SUM($F37:K37)-$E37-SUM($S37:W37)>0,MAX($AF37,SUM($F37:K37)-$E37-SUM($S37:W37)),0) -> 0 | Y37: =IF(SUM($F37:L37)-$E37-SUM($S37:X37)>0,MAX($AF37,SUM($F37:L37)-$E37-SUM($S37:X37)),0) -> 0 | Z37: =IF(SUM($F37:M37)-$E37-SUM($S37:Y37)>0,MAX($AF37,SUM($F37:M37)-$E37-SUM($S37:Y37)),0) -> 0 | AA37: =IF(SUM($F37:N37)-$E37-SUM($S37:Z37)>0,MAX($AF37,SUM($F37:N37)-$E37-SUM($S37:Z37)),0) -> 0 | ... AD37: =IF(SUM($F37:Q37)-$E37-SUM($S37:AC37)>0,MAX($AF37,SUM($F37:Q37)-$E37-SUM($S37:AC37)),0) -> 0 | AE37: =SUM(S37:AD37) -> 0 | AF37: 0
A38: EDTAMN | B38: DISSOLVINE - EDTA MN 13 | C38: Formulados | D38: kg | E38: 511.76761 | F38: 0 | G38: 0 | H38: 0 | I38: 0 | J38: 0 | K38: 0 | L38: 1.378 | M38: 1.378 | N38: 0 | O38: 0 | P38: 1.326 | Q38: 0 | R38: =SUM(F38:Q38) -> 4.082 | S38: =IF(SUM($F38:F38)-$E38-0>0,MAX($AF38,SUM($F38:F38)-$E38-0),0) -> 0 | T38: =IF(SUM($F38:G38)-$E38-SUM($S38:S38)>0,MAX($AF38,SUM($F38:G38)-$E38-SUM($S38:S38)),0) -> 0 | U38: =IF(SUM($F38:H38)-$E38-SUM($S38:T38)>0,MAX($AF38,SUM($F38:H38)-$E38-SUM($S38:T38)),0) -> 0 | V38: =IF(SUM($F38:I38)-$E38-SUM($S38:U38)>0,MAX($AF38,SUM($F38:I38)-$E38-SUM($S38:U38)),0) -> 0 | W38: =IF(SUM($F38:J38)-$E38-SUM($S38:V38)>0,MAX($AF38,SUM($F38:J38)-$E38-SUM($S38:V38)),0) -> 0 | X38: =IF(SUM($F38:K38)-$E38-SUM($S38:W38)>0,MAX($AF38,SUM($F38:K38)-$E38-SUM($S38:W38)),0) -> 0 | Y38: =IF(SUM($F38:L38)-$E38-SUM($S38:X38)>0,MAX($AF38,SUM($F38:L38)-$E38-SUM($S38:X38)),0) -> 0 | Z38: =IF(SUM($F38:M38)-$E38-SUM($S38:Y38)>0,MAX($AF38,SUM($F38:M38)-$E38-SUM($S38:Y38)),0) -> 0 | AA38: =IF(SUM($F38:N38)-$E38-SUM($S38:Z38)>0,MAX($AF38,SUM($F38:N38)-$E38-SUM($S38:Z38)),0) -> 0 | ... AD38: =IF(SUM($F38:Q38)-$E38-SUM($S38:AC38)>0,MAX($AF38,SUM($F38:Q38)-$E38-SUM($S38:AC38)),0) -> 0 | AE38: =SUM(S38:AD38) -> 0 | AF38: 0
A39: EDTAZN | B39: DISSOLVINE - EDTA ZN 15 | C39: Formulados | D39: kg | E39: 0 | F39: 0 | G39: 0 | H39: 0 | I39: 0 | J39: 80 | K39: 0 | L39: 1.378 | M39: 1.378 | N39: 0 | O39: 80 | P39: 299.566 | Q39: 80 | R39: =SUM(F39:Q39) -> 542.322 | S39: =IF(SUM($F39:F39)-$E39-0>0,MAX($AF39,SUM($F39:F39)-$E39-0),0) -> 0 | T39: =IF(SUM($F39:G39)-$E39-SUM($S39:S39)>0,MAX($AF39,SUM($F39:G39)-$E39-SUM($S39:S39)),0) -> 0 | U39: =IF(SUM($F39:H39)-$E39-SUM($S39:T39)>0,MAX($AF39,SUM($F39:H39)-$E39-SUM($S39:T39)),0) -> 0 | V39: =IF(SUM($F39:I39)-$E39-SUM($S39:U39)>0,MAX($AF39,SUM($F39:I39)-$E39-SUM($S39:U39)),0) -> 0 | W39: =IF(SUM($F39:J39)-$E39-SUM($S39:V39)>0,MAX($AF39,SUM($F39:J39)-$E39-SUM($S39:V39)),0) -> 80 | X39: =IF(SUM($F39:K39)-$E39-SUM($S39:W39)>0,MAX($AF39,SUM($F39:K39)-$E39-SUM($S39:W39)),0) -> 0 | Y39: =IF(SUM($F39:L39)-$E39-SUM($S39:X39)>0,MAX($AF39,SUM($F39:L39)-$E39-SUM($S39:X39)),0) -> 1.378 | Z39: =IF(SUM($F39:M39)-$E39-SUM($S39:Y39)>0,MAX($AF39,SUM($F39:M39)-$E39-SUM($S39:Y39)),0) -> 1.378 | AA39: =IF(SUM($F39:N39)-$E39-SUM($S39:Z39)>0,MAX($AF39,SUM($F39:N39)-$E39-SUM($S39:Z39)),0) -> 0 | ... AD39: =IF(SUM($F39:Q39)-$E39-SUM($S39:AC39)>0,MAX($AF39,SUM($F39:Q39)-$E39-SUM($S39:AC39)),0) -> 80 | AE39: =SUM(S39:AD39) -> 542.322 | AF39: 0
A40: FMA | B40: FOSFATO MONOAMONICO | C40: Formulados | D40: kg | E40: 725.84426 | F40: 657.6723 | G40: 1145.3147 | H40: 221.94394 | I40: 923.455 | J40: 1327.581 | K40: 1110.575 | L40: 648.475 | M40: 1169.571 | N40: 345.575 | O40: 446.375 | P40: 1233.802 | Q40: 882.9 | R40: =SUM(F40:Q40) -> 10113.24 | S40: =IF(SUM($F40:F40)-$E40-0>0,MAX($AF40,SUM($F40:F40)-$E40-0),0) -> 0 | T40: =IF(SUM($F40:G40)-$E40-SUM($S40:S40)>0,MAX($AF40,SUM($F40:G40)-$E40-SUM($S40:S40)),0) -> 1077.1427 | U40: =IF(SUM($F40:H40)-$E40-SUM($S40:T40)>0,MAX($AF40,SUM($F40:H40)-$E40-SUM($S40:T40)),0) -> 221.94394 | V40: =IF(SUM($F40:I40)-$E40-SUM($S40:U40)>0,MAX($AF40,SUM($F40:I40)-$E40-SUM($S40:U40)),0) -> 923.455 | W40: =IF(SUM($F40:J40)-$E40-SUM($S40:V40)>0,MAX($AF40,SUM($F40:J40)-$E40-SUM($S40:V40)),0) -> 1327.581 | X40: =IF(SUM($F40:K40)-$E40-SUM($S40:W40)>0,MAX($AF40,SUM($F40:K40)-$E40-SUM($S40:W40)),0) -> 1110.575 | Y40: =IF(SUM($F40:L40)-$E40-SUM($S40:X40)>0,MAX($AF40,SUM($F40:L40)-$E40-SUM($S40:X40)),0) -> 648.475 | Z40: =IF(SUM($F40:M40)-$E40-SUM($S40:Y40)>0,MAX($AF40,SUM($F40:M40)-$E40-SUM($S40:Y40)),0) -> 1169.571 | AA40: =IF(SUM($F40:N40)-$E40-SUM($S40:Z40)>0,MAX($AF40,SUM($F40:N40)-$E40-SUM($S40:Z40)),0) -> 345.575 | ... AD40: =IF(SUM($F40:Q40)-$E40-SUM($S40:AC40)>0,MAX($AF40,SUM($F40:Q40)-$E40-SUM($S40:AC40)),0) -> 882.9 | AE40: =SUM(S40:AD40) -> 9387.3956 | AF40: 0
A41: FMP | B41: FOSFATO MONOPOTASICO | C41: Formulados | D41: kg | E41: 0 | F41: 2701.733 | G41: 8618.3836 | H41: 3492.14 | I41: 3999.19 | J41: 10408.615 | K41: 9099.39 | L41: 3973.235 | M41: 5932.962 | N41: 1134.925 | O41: 3132.555 | P41: 3159.943 | Q41: 14337.35 | R41: =SUM(F41:Q41) -> 69990.422 | S41: =IF(SUM($F41:F41)-$E41-0>0,MAX($AF41,SUM($F41:F41)-$E41-0),0) -> 2701.733 | T41: =IF(SUM($F41:G41)-$E41-SUM($S41:S41)>0,MAX($AF41,SUM($F41:G41)-$E41-SUM($S41:S41)),0) -> 8618.3836 | U41: =IF(SUM($F41:H41)-$E41-SUM($S41:T41)>0,MAX($AF41,SUM($F41:H41)-$E41-SUM($S41:T41)),0) -> 3492.14 | V41: =IF(SUM($F41:I41)-$E41-SUM($S41:U41)>0,MAX($AF41,SUM($F41:I41)-$E41-SUM($S41:U41)),0) -> 3999.19 | W41: =IF(SUM($F41:J41)-$E41-SUM($S41:V41)>0,MAX($AF41,SUM($F41:J41)-$E41-SUM($S41:V41)),0) -> 10408.615 | X41: =IF(SUM($F41:K41)-$E41-SUM($S41:W41)>0,MAX($AF41,SUM($F41:K41)-$E41-SUM($S41:W41)),0) -> 9099.39 | Y41: =IF(SUM($F41:L41)-$E41-SUM($S41:X41)>0,MAX($AF41,SUM($F41:L41)-$E41-SUM($S41:X41)),0) -> 3973.235 | Z41: =IF(SUM($F41:M41)-$E41-SUM($S41:Y41)>0,MAX($AF41,SUM($F41:M41)-$E41-SUM($S41:Y41)),0) -> 5932.962 | AA41: =IF(SUM($F41:N41)-$E41-SUM($S41:Z41)>0,MAX($AF41,SUM($F41:N41)-$E41-SUM($S41:Z41)),0) -> 1134.925 | ... AD41: =IF(SUM($F41:Q41)-$E41-SUM($S41:AC41)>0,MAX($AF41,SUM($F41:Q41)-$E41-SUM($S41:AC41)),0) -> 14337.35 | AE41: =SUM(S41:AD41) -> 69990.422 | AF41: 0
... A53: HCA | B53: HIDROXIDO DE CAL | C53: Formulados | D53: kg | E53: 0 | F53: 44276.052 | G53: 63813.897 | H53: 189992.62 | I53: 91522.918 | J53: 276095.67 | K53: 206333.45 | L53: 146863.16 | M53: 50358.702 | N53: 32088.806 | O53: 43217.429 | P53: 72859.483 | Q53: 144059.71 | R53: =SUM(F53:Q53) -> 1361481.9 | S53: =IF(SUM($F53:F53)-$E53-0>0,MAX($AF53,SUM($F53:F53)-$E53-0),0) -> 44276.052 | T53: =IF(SUM($F53:G53)-$E53-SUM($S53:S53)>0,MAX($AF53,SUM($F53:G53)-$E53-SUM($S53:S53)),0) -> 63813.897 | U53: =IF(SUM($F53:H53)-$E53-SUM($S53:T53)>0,MAX($AF53,SUM($F53:H53)-$E53-SUM($S53:T53)),0) -> 189992.62 | V53: =IF(SUM($F53:I53)-$E53-SUM($S53:U53)>0,MAX($AF53,SUM($F53:I53)-$E53-SUM($S53:U53)),0) -> 91522.918 | W53: =IF(SUM($F53:J53)-$E53-SUM($S53:V53)>0,MAX($AF53,SUM($F53:J53)-$E53-SUM($S53:V53)),0) -> 276095.67 | X53: =IF(SUM($F53:K53)-$E53-SUM($S53:W53)>0,MAX($AF53,SUM($F53:K53)-$E53-SUM($S53:W53)),0) -> 206333.45 | Y53: =IF(SUM($F53:L53)-$E53-SUM($S53:X53)>0,MAX($AF53,SUM($F53:L53)-$E53-SUM($S53:X53)),0) -> 146863.16 | Z53: =IF(SUM($F53:M53)-$E53-SUM($S53:Y53)>0,MAX($AF53,SUM($F53:M53)-$E53-SUM($S53:Y53)),0) -> 50358.702 | AA53: =IF(SUM($F53:N53)-$E53-SUM($S53:Z53)>0,MAX($AF53,SUM($F53:N53)-$E53-SUM($S53:Z53)),0) -> 32088.806 | ... AD53: =IF(SUM($F53:Q53)-$E53-SUM($S53:AC53)>0,MAX($AF53,SUM($F53:Q53)-$E53-SUM($S53:AC53)),0) -> 144059.71 | AE53: =SUM(S53:AD53) -> 1361481.9 | AF53: 0
A54: HGA-FE | B54: HEPTAGLUCONATO DE HIERRO | C54: Formulados | D54: kg | E54: 315 | F54: 0 | G54: 0 | H54: 543 | I54: 103 | J54: 35 | K54: 0 | L54: 0 | M54: 0 | N54: 0 | O54: 0 | P54: 0 | Q54: 0 | R54: =SUM(F54:Q54) -> 681 | S54: =IF(SUM($F54:F54)-$E54-0>0,MAX($AF54,SUM($F54:F54)-$E54-0),0) -> 0 | T54: =IF(SUM($F54:G54)-$E54-SUM($S54:S54)>0,MAX($AF54,SUM($F54:G54)-$E54-SUM($S54:S54)),0) -> 0 | U54: =IF(SUM($F54:H54)-$E54-SUM($S54:T54)>0,MAX($AF54,SUM($F54:H54)-$E54-SUM($S54:T54)),0) -> 1200 | V54: =IF(SUM($F54:I54)-$E54-SUM($S54:U54)>0,MAX($AF54,SUM($F54:I54)-$E54-SUM($S54:U54)),0) -> 0 | W54: =IF(SUM($F54:J54)-$E54-SUM($S54:V54)>0,MAX($AF54,SUM($F54:J54)-$E54-SUM($S54:V54)),0) -> 0 | X54: =IF(SUM($F54:K54)-$E54-SUM($S54:W54)>0,MAX($AF54,SUM($F54:K54)-$E54-SUM($S54:W54)),0) -> 0 | Y54: =IF(SUM($F54:L54)-$E54-SUM($S54:X54)>0,MAX($AF54,SUM($F54:L54)-$E54-SUM($S54:X54)),0) -> 0 | Z54: =IF(SUM($F54:M54)-$E54-SUM($S54:Y54)>0,MAX($AF54,SUM($F54:M54)-$E54-SUM($S54:Y54)),0) -> 0 | AA54: =IF(SUM($F54:N54)-$E54-SUM($S54:Z54)>0,MAX($AF54,SUM($F54:N54)-$E54-SUM($S54:Z54)),0) -> 0 | ... AD54: =IF(SUM($F54:Q54)-$E54-SUM($S54:AC54)>0,MAX($AF54,SUM($F54:Q54)-$E54-SUM($S54:AC54)),0) -> 0 | AE54: =SUM(S54:AD54) -> 1200 | AF54: 1200 | AG54: Lote mínimo indicado por el usuario.
