Workbook

Sheet Resumen general
A2: Presupuesto de transporte · Codiagro
A3: Cuatrimestre septiembre–diciembre 2026 y ejercicio completo 2027 · nacional, Canarias y exportación.
A5: Período | B5: Resto nacional (€) | C5: Canarias (€) | D5: Exportación (€) | E5: Total (€)
A6: 2026 · sep-dic | B6: ='Nacional 2026'!D11 -> 31199.837 | C6: ='Nacional 2026'!G11 -> 22275.215 | D6: ='Export · costes'!C11 -> 97236 | E6: =SUM(B6:D6) -> 150711.05
A7: 2027 · ene-dic | B7: ='Nacional 2027'!D19 -> 166472.15 | C7: ='Nacional 2027'!G19 -> 79198.291 | D7: ='Export · costes'!C27 -> 305223.3 | E7: =SUM(B7:D7) -> 550893.74
A10: 2026 · septiembre a diciembre
A11: Mes | B11: Resto nacional (€) | C11: Canarias (€) | D11: Exportación (€) | E11: Total (€)
A12: Sep | B12: ='Nacional 2026'!D7 -> 6434.5324 | C12: ='Nacional 2026'!G7 -> 2450.109 | D12: ='Export · costes'!C7 -> 16253 | E12: =SUM(B12:D12) -> 25137.641
A13: Oct | B13: ='Nacional 2026'!D8 -> 10499.025 | C13: ='Nacional 2026'!G8 -> 7990.591 | D13: ='Export · costes'!C8 -> 21379 | E13: =SUM(B13:D13) -> 39868.616
A14: Nov | B14: ='Nacional 2026'!D9 -> 10212.345 | C14: ='Nacional 2026'!G9 -> 11300.379 | D14: ='Export · costes'!C9 -> 32454 | E14: =SUM(B14:D14) -> 53966.724
A15: Dic | B15: ='Nacional 2026'!D10 -> 4053.9348 | C15: ='Nacional 2026'!G10 -> 534.13573 | D15: ='Export · costes'!C10 -> 27150 | E15: =SUM(B15:D15) -> 31738.071
A16: TOTAL 2026 | B16: =SUM(B12:B15) -> 31199.837 | C16: =SUM(C12:C15) -> 22275.215 | D16: =SUM(D12:D15) -> 97236 | E16: =SUM(E12:E15) -> 150711.05
A19: 2027 · enero a diciembre
A20: Mes | B20: Resto nacional (€) | C20: Canarias (€) | D20: Exportación (€) | E20: Total (€)
A21: Ene | B21: ='Nacional 2027'!D7 -> 7016.8542 | C21: ='Nacional 2027'!G7 -> 6088.1813 | D21: ='Export · costes'!C15 -> 29809.2 | E21: =SUM(B21:D21) -> 42914.235
A22: Feb | B22: ='Nacional 2027'!D8 -> 13619.902 | C22: ='Nacional 2027'!G8 -> 5367.2581 | D22: ='Export · costes'!C16 -> 21246.7 | E22: =SUM(B22:D22) -> 40233.86
A23: Mar | B23: ='Nacional 2027'!D9 -> 18607.541 | C23: ='Nacional 2027'!G9 -> 7224.7247 | D23: ='Export · costes'!C17 -> 19638.3 | E23: =SUM(B23:D23) -> 45470.566
A24: Abr | B24: ='Nacional 2027'!D10 -> 22055.439 | C24: ='Nacional 2027'!G10 -> 3712.0421 | D24: ='Export · costes'!C18 -> 8004.2 | E24: =SUM(B24:D24) -> 33771.681
A25: May | B25: ='Nacional 2027'!D11 -> 18645.631 | C25: ='Nacional 2027'!G11 -> 14028.954 | D25: ='Export · costes'!C19 -> 38718.8 | E25: =SUM(B25:D25) -> 71393.385
A26: Jun | B26: ='Nacional 2027'!D12 -> 20396.407 | C26: ='Nacional 2027'!G12 -> 2584.44 | D26: ='Export · costes'!C20 -> 33492 | E26: =SUM(B26:D26) -> 56472.847
A27: Jul | B27: ='Nacional 2027'!D13 -> 14747.912 | C27: ='Nacional 2027'!G13 -> 4588.2983 | D27: ='Export · costes'!C21 -> 13212.8 | E27: =SUM(B27:D27) -> 32549.01
A28: Ago | B28: ='Nacional 2027'!D14 -> 13338.449 | C28: ='Nacional 2027'!G14 -> 8667.6855 | D28: ='Export · costes'!C22 -> 18509.6 | E28: =SUM(B28:D28) -> 40515.734
A29: Sep | B29: ='Nacional 2027'!D15 -> 7825.8588 | C29: ='Nacional 2027'!G15 -> 2950.8535 | D29: ='Export · costes'!C23 -> 24148.9 | E29: =SUM(B29:D29) -> 34925.612
A30: Oct | B30: ='Nacional 2027'!D16 -> 12700.116 | C30: ='Nacional 2027'!G16 -> 9635.0411 | D30: ='Export · costes'!C24 -> 23411.3 | E30: =SUM(B30:D30) -> 45746.457
A31: Nov | B31: ='Nacional 2027'!D17 -> 12528.192 | C31: ='Nacional 2027'!G17 -> 13725.162 | D31: ='Export · costes'!C25 -> 40650.7 | E31: =SUM(B31:D31) -> 66904.053
A32: Dic | B32: ='Nacional 2027'!D18 -> 4989.8491 | C32: ='Nacional 2027'!G18 -> 625.65144 | D32: ='Export · costes'!C26 -> 34380.8 | E32: =SUM(B32:D32) -> 39996.301
A33: TOTAL 2027 | B33: =SUM(B21:B32) -> 166472.15 | C33: =SUM(C21:C32) -> 79198.291 | D33: =SUM(D21:D32) -> 305223.3 | E33: =SUM(E21:E32) -> 550893.74
A36: Base del resumen: 2026 incluye septiembre estimado en exportación; 2027 nacional/Canarias aplica +10 % y exportación usa el importe del archivo adjunto.
A37: La oferta de Canarias no fija T-3 embarque ni gastos de destino; los importes mostrados no los incluyen.

Sheet Nacional 2026
A2: Presupuesto transporte nacional 2026
A3: Septiembre a diciembre · Campillo y Canarias separados · importe sin T-3 ni gastos de destino
A6: Mes | B6: Resto kg | C6: Resto palets | D6: Campillo (€) | E6: Canarias kg | F6: Canarias palets | G6: Sealine (€) | H6: Total kg | I6: Total (€)
A7: Sep | B7: =SUMIFS('Nacional · base'!$E$1074:$E$1473,'Nacional · base'!$A$1074:$A$1473,2026,'Nacional · base'!$B$1074:$B$1473,9,'Nacional · base'!$D$1074:$D$1473,"Resto nacional") -> 72566.526 | C7: =SUMIFS('Nacional · base'!$G$1074:$G$1473,'Nacional · base'!$A$1074:$A$1473,2026,'Nacional · base'!$B$1074:$B$1473,9,'Nacional · base'!$D$1074:$D$1473,"Resto nacional") -> 97 | D7: =SUMIFS('Nacional · base'!$Q$1074:$Q$1473,'Nacional · base'!$A$1074:$A$1473,2026,'Nacional · base'!$B$1074:$B$1473,9,'Nacional · base'!$D$1074:$D$1473,"Resto nacional") -> 6434.5324 | E7: =SUMIFS('Nacional · base'!$E$1074:$E$1473,'Nacional · base'!$A$1074:$A$1473,2026,'Nacional · base'!$B$1074:$B$1473,9,'Nacional · base'!$D$1074:$D$1473,"Canarias") -> 9089.387 | F7: =SUMIFS('Nacional · base'!$G$1074:$G$1473,'Nacional · base'!$A$1074:$A$1473,2026,'Nacional · base'!$B$1074:$B$1473,9,'Nacional · base'!$D$1074:$D$1473,"Canarias") -> 13 | G7: =SUMIFS('Nacional · base'!$R$1074:$R$1473,'Nacional · base'!$A$1074:$A$1473,2026,'Nacional · base'!$B$1074:$B$1473,9,'Nacional · base'!$D$1074:$D$1473,"Canarias") -> 2450.109 | H7: =B7+E7 -> 81655.913 | I7: =D7+G7 -> 8884.6414
A8: Oct | B8: =SUMIFS('Nacional · base'!$E$1074:$E$1473,'Nacional · base'!$A$1074:$A$1473,2026,'Nacional · base'!$B$1074:$B$1473,10,'Nacional · base'!$D$1074:$D$1473,"Resto nacional") -> 118404.53 | C8: =SUMIFS('Nacional · base'!$G$1074:$G$1473,'Nacional · base'!$A$1074:$A$1473,2026,'Nacional · base'!$B$1074:$B$1473,10,'Nacional · base'!$D$1074:$D$1473,"Resto nacional") -> 151 | D8: =SUMIFS('Nacional · base'!$Q$1074:$Q$1473,'Nacional · base'!$A$1074:$A$1473,2026,'Nacional · base'!$B$1074:$B$1473,10,'Nacional · base'!$D$1074:$D$1473,"Resto nacional") -> 10499.025 | E8: =SUMIFS('Nacional · base'!$E$1074:$E$1473,'Nacional · base'!$A$1074:$A$1473,2026,'Nacional · base'!$B$1074:$B$1473,10,'Nacional · base'!$D$1074:$D$1473,"Canarias") -> 35824.774 | F8: =SUMIFS('Nacional · base'!$G$1074:$G$1473,'Nacional · base'!$A$1074:$A$1473,2026,'Nacional · base'!$B$1074:$B$1473,10,'Nacional · base'!$D$1074:$D$1473,"Canarias") -> 41 | G8: =SUMIFS('Nacional · base'!$R$1074:$R$1473,'Nacional · base'!$A$1074:$A$1473,2026,'Nacional · base'!$B$1074:$B$1473,10,'Nacional · base'!$D$1074:$D$1473,"Canarias") -> 7990.591 | H8: =B8+E8 -> 154229.3 | I8: =D8+G8 -> 18489.616
A9: Nov | B9: =SUMIFS('Nacional · base'!$E$1074:$E$1473,'Nacional · base'!$A$1074:$A$1473,2026,'Nacional · base'!$B$1074:$B$1473,11,'Nacional · base'!$D$1074:$D$1473,"Resto nacional") -> 115171.44 | C9: =SUMIFS('Nacional · base'!$G$1074:$G$1473,'Nacional · base'!$A$1074:$A$1473,2026,'Nacional · base'!$B$1074:$B$1473,11,'Nacional · base'!$D$1074:$D$1473,"Resto nacional") -> 139 | D9: =SUMIFS('Nacional · base'!$Q$1074:$Q$1473,'Nacional · base'!$A$1074:$A$1473,2026,'Nacional · base'!$B$1074:$B$1473,11,'Nacional · base'!$D$1074:$D$1473,"Resto nacional") -> 10212.345 | E9: =SUMIFS('Nacional · base'!$E$1074:$E$1473,'Nacional · base'!$A$1074:$A$1473,2026,'Nacional · base'!$B$1074:$B$1473,11,'Nacional · base'!$D$1074:$D$1473,"Canarias") -> 47468.442 | F9: =SUMIFS('Nacional · base'!$G$1074:$G$1473,'Nacional · base'!$A$1074:$A$1473,2026,'Nacional · base'!$B$1074:$B$1473,11,'Nacional · base'!$D$1074:$D$1473,"Canarias") -> 57 | G9: =SUMIFS('Nacional · base'!$R$1074:$R$1473,'Nacional · base'!$A$1074:$A$1473,2026,'Nacional · base'!$B$1074:$B$1473,11,'Nacional · base'!$D$1074:$D$1473,"Canarias") -> 11300.379 | H9: =B9+E9 -> 162639.89 | I9: =D9+G9 -> 21512.724
A10: Dic | B10: =SUMIFS('Nacional · base'!$E$1074:$E$1473,'Nacional · base'!$A$1074:$A$1473,2026,'Nacional · base'!$B$1074:$B$1473,12,'Nacional · base'!$D$1074:$D$1473,"Resto nacional") -> 45718.934 | C10: =SUMIFS('Nacional · base'!$G$1074:$G$1473,'Nacional · base'!$A$1074:$A$1473,2026,'Nacional · base'!$B$1074:$B$1473,12,'Nacional · base'!$D$1074:$D$1473,"Resto nacional") -> 66 | D10: =SUMIFS('Nacional · base'!$Q$1074:$Q$1473,'Nacional · base'!$A$1074:$A$1473,2026,'Nacional · base'!$B$1074:$B$1473,12,'Nacional · base'!$D$1074:$D$1473,"Resto nacional") -> 4053.9348 | E10: =SUMIFS('Nacional · base'!$E$1074:$E$1473,'Nacional · base'!$A$1074:$A$1473,2026,'Nacional · base'!$B$1074:$B$1473,12,'Nacional · base'!$D$1074:$D$1473,"Canarias") -> 2505.7434 | F10: =SUMIFS('Nacional · base'!$G$1074:$G$1473,'Nacional · base'!$A$1074:$A$1473,2026,'Nacional · base'!$B$1074:$B$1473,12,'Nacional · base'!$D$1074:$D$1473,"Canarias") -> 3 | G10: =SUMIFS('Nacional · base'!$R$1074:$R$1473,'Nacional · base'!$A$1074:$A$1473,2026,'Nacional · base'!$B$1074:$B$1473,12,'Nacional · base'!$D$1074:$D$1473,"Canarias") -> 534.13573 | H10: =B10+E10 -> 48224.677 | I10: =D10+G10 -> 4588.0705
A11: TOTAL | B11: =SUM(B7:B10) -> 351861.43 | C11: =SUM(C7:C10) -> 453 | D11: =SUM(D7:D10) -> 31199.837 | E11: =SUM(E7:E10) -> 94888.346 | F11: =SUM(F7:F10) -> 114 | G11: =SUM(G7:G10) -> 22275.215 | H11: =SUM(H7:H10) -> 446749.78 | I11: =SUM(I7:I10) -> 53475.052
A15: Canarias · coste por cliente y mes
A16: Mes | B16: Cliente / destino | C16: Kilos | D16: Palets | E16: Sealine (€)
A17: Sep | B17: AGROQUIMICAS DRAGO S.L. · La Montañeta, El Calero | C17: =SUMIFS('Nacional · base'!$E$1074:$E$1473,'Nacional · base'!$A$1074:$A$1473,2026,'Nacional · base'!$B$1074:$B$1473,9,'Nacional · base'!$C$1074:$C$1473,"AGROQUIMICAS DRAGO S.L.") -> 2832.6125 | D17: =SUMIFS('Nacional · base'!$G$1074:$G$1473,'Nacional · base'!$A$1074:$A$1473,2026,'Nacional · base'!$B$1074:$B$1473,9,'Nacional · base'!$C$1074:$C$1473,"AGROQUIMICAS DRAGO S.L.") -> 4 | E17: =SUMIFS('Nacional · base'!$R$1074:$R$1473,'Nacional · base'!$A$1074:$A$1473,2026,'Nacional · base'!$B$1074:$B$1473,9,'Nacional · base'!$C$1074:$C$1473,"AGROQUIMICAS DRAGO S.L.") -> 597.13574
A18: Sep | B18: FITOSANITARIOS DRAGO S.L.U · Santa Cruz de Tenerife | C18: =SUMIFS('Nacional · base'!$E$1074:$E$1473,'Nacional · base'!$A$1074:$A$1473,2026,'Nacional · base'!$B$1074:$B$1473,9,'Nacional · base'!$C$1074:$C$1473,"FITOSANITARIOS DRAGO S.L.U") -> 0 | D18: =SUMIFS('Nacional · base'!$G$1074:$G$1473,'Nacional · base'!$A$1074:$A$1473,2026,'Nacional · base'!$B$1074:$B$1473,9,'Nacional · base'!$C$1074:$C$1473,"FITOSANITARIOS DRAGO S.L.U") -> 0 | E18: =SUMIFS('Nacional · base'!$R$1074:$R$1473,'Nacional · base'!$A$1074:$A$1473,2026,'Nacional · base'!$B$1074:$B$1473,9,'Nacional · base'!$C$1074:$C$1473,"FITOSANITARIOS DRAGO S.L.U") -> 0
A19: Sep | B19: CABRERA MORALES FRANCISCO · Santa Cruz de La Palma | C19: =SUMIFS('Nacional · base'!$E$1074:$E$1473,'Nacional · base'!$A$1074:$A$1473,2026,'Nacional · base'!$B$1074:$B$1473,9,'Nacional · base'!$C$1074:$C$1473,"CABRERA MORALES FRANCISCO") -> 6256.7745 | D19: =SUMIFS('Nacional · base'!$G$1074:$G$1473,'Nacional · base'!$A$1074:$A$1473,2026,'Nacional · base'!$B$1074:$B$1473,9,'Nacional · base'!$C$1074:$C$1473,"CABRERA MORALES FRANCISCO") -> 9 | E19: =SUMIFS('Nacional · base'!$R$1074:$R$1473,'Nacional · base'!$A$1074:$A$1473,2026,'Nacional · base'!$B$1074:$B$1473,9,'Nacional · base'!$C$1074:$C$1473,"CABRERA MORALES FRANCISCO") -> 1852.9732
A20: Oct | B20: AGROQUIMICAS DRAGO S.L. · La Montañeta, El Calero | C20: =SUMIFS('Nacional · base'!$E$1074:$E$1473,'Nacional · base'!$A$1074:$A$1473,2026,'Nacional · base'!$B$1074:$B$1473,10,'Nacional · base'!$C$1074:$C$1473,"AGROQUIMICAS DRAGO S.L.") -> 12645.51 | D20: =SUMIFS('Nacional · base'!$G$1074:$G$1473,'Nacional · base'!$A$1074:$A$1473,2026,'Nacional · base'!$B$1074:$B$1473,10,'Nacional · base'!$C$1074:$C$1473,"AGROQUIMICAS DRAGO S.L.") -> 15 | E20: =SUMIFS('Nacional · base'!$R$1074:$R$1473,'Nacional · base'!$A$1074:$A$1473,2026,'Nacional · base'!$B$1074:$B$1473,10,'Nacional · base'!$C$1074:$C$1473,"AGROQUIMICAS DRAGO S.L.") -> 2553.3303
A21: Oct | B21: FITOSANITARIOS DRAGO S.L.U · Santa Cruz de Tenerife | C21: =SUMIFS('Nacional · base'!$E$1074:$E$1473,'Nacional · base'!$A$1074:$A$1473,2026,'Nacional · base'!$B$1074:$B$1473,10,'Nacional · base'!$C$1074:$C$1473,"FITOSANITARIOS DRAGO S.L.U") -> 15191.069 | D21: =SUMIFS('Nacional · base'!$G$1074:$G$1473,'Nacional · base'!$A$1074:$A$1473,2026,'Nacional · base'!$B$1074:$B$1473,10,'Nacional · base'!$C$1074:$C$1473,"FITOSANITARIOS DRAGO S.L.U") -> 15 | E21: =SUMIFS('Nacional · base'!$R$1074:$R$1473,'Nacional · base'!$A$1074:$A$1473,2026,'Nacional · base'!$B$1074:$B$1473,10,'Nacional · base'!$C$1074:$C$1473,"FITOSANITARIOS DRAGO S.L.U") -> 3076.529
A22: Oct | B22: CABRERA MORALES FRANCISCO · Santa Cruz de La Palma | C22: =SUMIFS('Nacional · base'!$E$1074:$E$1473,'Nacional · base'!$A$1074:$A$1473,2026,'Nacional · base'!$B$1074:$B$1473,10,'Nacional · base'!$C$1074:$C$1473,"CABRERA MORALES FRANCISCO") -> 7988.1947 | D22: =SUMIFS('Nacional · base'!$G$1074:$G$1473,'Nacional · base'!$A$1074:$A$1473,2026,'Nacional · base'!$B$1074:$B$1473,10,'Nacional · base'!$C$1074:$C$1473,"CABRERA MORALES FRANCISCO") -> 11 | E22: =SUMIFS('Nacional · base'!$R$1074:$R$1473,'Nacional · base'!$A$1074:$A$1473,2026,'Nacional · base'!$B$1074:$B$1473,10,'Nacional · base'!$C$1074:$C$1473,"CABRERA MORALES FRANCISCO") -> 2360.7317
A23: Nov | B23: AGROQUIMICAS DRAGO S.L. · La Montañeta, El Calero | C23: =SUMIFS('Nacional · base'!$E$1074:$E$1473,'Nacional · base'!$A$1074:$A$1473,2026,'Nacional · base'!$B$1074:$B$1473,11,'Nacional · base'!$C$1074:$C$1473,"AGROQUIMICAS DRAGO S.L.") -> 14119.075 | D23: =SUMIFS('Nacional · base'!$G$1074:$G$1473,'Nacional · base'!$A$1074:$A$1473,2026,'Nacional · base'!$B$1074:$B$1473,11,'Nacional · base'!$C$1074:$C$1473,"AGROQUIMICAS DRAGO S.L.") -> 17 | E23: =SUMIFS('Nacional · base'!$R$1074:$R$1473,'Nacional · base'!$A$1074:$A$1473,2026,'Nacional · base'!$B$1074:$B$1473,11,'Nacional · base'!$C$1074:$C$1473,"AGROQUIMICAS DRAGO S.L.") -> 2855.2046
A24: Nov | B24: FITOSANITARIOS DRAGO S.L.U · Santa Cruz de Tenerife | C24: =SUMIFS('Nacional · base'!$E$1074:$E$1473,'Nacional · base'!$A$1074:$A$1473,2026,'Nacional · base'!$B$1074:$B$1473,11,'Nacional · base'!$C$1074:$C$1473,"FITOSANITARIOS DRAGO S.L.U") -> 15459.542 | D24: =SUMIFS('Nacional · base'!$G$1074:$G$1473,'Nacional · base'!$A$1074:$A$1473,2026,'Nacional · base'!$B$1074:$B$1473,11,'Nacional · base'!$C$1074:$C$1473,"FITOSANITARIOS DRAGO S.L.U") -> 16 | E24: =SUMIFS('Nacional · base'!$R$1074:$R$1473,'Nacional · base'!$A$1074:$A$1473,2026,'Nacional · base'!$B$1074:$B$1473,11,'Nacional · base'!$C$1074:$C$1473,"FITOSANITARIOS DRAGO S.L.U") -> 3130.9249
A25: Nov | B25: CABRERA MORALES FRANCISCO · Santa Cruz de La Palma | C25: =SUMIFS('Nacional · base'!$E$1074:$E$1473,'Nacional · base'!$A$1074:$A$1473,2026,'Nacional · base'!$B$1074:$B$1473,11,'Nacional · base'!$C$1074:$C$1473,"CABRERA MORALES FRANCISCO") -> 17889.825 | D25: =SUMIFS('Nacional · base'!$G$1074:$G$1473,'Nacional · base'!$A$1074:$A$1473,2026,'Nacional · base'!$B$1074:$B$1473,11,'Nacional · base'!$C$1074:$C$1473,"CABRERA MORALES FRANCISCO") -> 24 | E25: =SUMIFS('Nacional · base'!$R$1074:$R$1473,'Nacional · base'!$A$1074:$A$1473,2026,'Nacional · base'!$B$1074:$B$1473,11,'Nacional · base'!$C$1074:$C$1473,"CABRERA MORALES FRANCISCO") -> 5314.2496
A26: Dic | B26: AGROQUIMICAS DRAGO S.L. · La Montañeta, El Calero | C26: =SUMIFS('Nacional · base'!$E$1074:$E$1473,'Nacional · base'!$A$1074:$A$1473,2026,'Nacional · base'!$B$1074:$B$1473,12,'Nacional · base'!$C$1074:$C$1473,"AGROQUIMICAS DRAGO S.L.") -> 2505.7434 | D26: =SUMIFS('Nacional · base'!$G$1074:$G$1473,'Nacional · base'!$A$1074:$A$1473,2026,'Nacional · base'!$B$1074:$B$1473,12,'Nacional · base'!$C$1074:$C$1473,"AGROQUIMICAS DRAGO S.L.") -> 3 | E26: =SUMIFS('Nacional · base'!$R$1074:$R$1473,'Nacional · base'!$A$1074:$A$1473,2026,'Nacional · base'!$B$1074:$B$1473,12,'Nacional · base'!$C$1074:$C$1473,"AGROQUIMICAS DRAGO S.L.") -> 534.13573
A27: Dic | B27: FITOSANITARIOS DRAGO S.L.U · Santa Cruz de Tenerife | C27: =SUMIFS('Nacional · base'!$E$1074:$E$1473,'Nacional · base'!$A$1074:$A$1473,2026,'Nacional · base'!$B$1074:$B$1473,12,'Nacional · base'!$C$1074:$C$1473,"FITOSANITARIOS DRAGO S.L.U") -> 0 | D27: =SUMIFS('Nacional · base'!$G$1074:$G$1473,'Nacional · base'!$A$1074:$A$1473,2026,'Nacional · base'!$B$1074:$B$1473,12,'Nacional · base'!$C$1074:$C$1473,"FITOSANITARIOS DRAGO S.L.U") -> 0 | E27: =SUMIFS('Nacional · base'!$R$1074:$R$1473,'Nacional · base'!$A$1074:$A$1473,2026,'Nacional · base'!$B$1074:$B$1473,12,'Nacional · base'!$C$1074:$C$1473,"FITOSANITARIOS DRAGO S.L.U") -> 0
A28: Dic | B28: CABRERA MORALES FRANCISCO · Santa Cruz de La Palma | C28: =SUMIFS('Nacional · base'!$E$1074:$E$1473,'Nacional · base'!$A$1074:$A$1473,2026,'Nacional · base'!$B$1074:$B$1473,12,'Nacional · base'!$C$1074:$C$1473,"CABRERA MORALES FRANCISCO") -> 0 | D28: =SUMIFS('Nacional · base'!$G$1074:$G$1473,'Nacional · base'!$A$1074:$A$1473,2026,'Nacional · base'!$B$1074:$B$1473,12,'Nacional · base'!$C$1074:$C$1473,"CABRERA MORALES FRANCISCO") -> 0 | E28: =SUMIFS('Nacional · base'!$R$1074:$R$1473,'Nacional · base'!$A$1074:$A$1473,2026,'Nacional · base'!$B$1074:$B$1473,12,'Nacional · base'!$C$1074:$C$1473,"CABRERA MORALES FRANCISCO") -> 0

Sheet Nacional 2027
A2: Presupuesto transporte nacional 2027
A3: Enero a diciembre · tarifas 2026 + 10 % (4,5 % IPC y 5,5 % combustible) · sin T-3 ni destino
A6: Mes | B6: Resto kg | C6: Resto palets | D6: Campillo (€) | E6: Canarias kg | F6: Canarias palets | G6: Sealine (€) | H6: Total kg | I6: Total (€)
A7: Ene | B7: =SUMIFS('Nacional · base'!$E$1074:$E$1473,'Nacional · base'!$A$1074:$A$1473,2027,'Nacional · base'!$B$1074:$B$1473,1,'Nacional · base'!$D$1074:$D$1473,"Resto nacional") -> 71939.78 | C7: =SUMIFS('Nacional · base'!$G$1074:$G$1473,'Nacional · base'!$A$1074:$A$1473,2027,'Nacional · base'!$B$1074:$B$1473,1,'Nacional · base'!$D$1074:$D$1473,"Resto nacional") -> 103 | D7: =SUMIFS('Nacional · base'!$Q$1074:$Q$1473,'Nacional · base'!$A$1074:$A$1473,2027,'Nacional · base'!$B$1074:$B$1473,1,'Nacional · base'!$D$1074:$D$1473,"Resto nacional") -> 7016.8542 | E7: =SUMIFS('Nacional · base'!$E$1074:$E$1473,'Nacional · base'!$A$1074:$A$1473,2027,'Nacional · base'!$B$1074:$B$1473,1,'Nacional · base'!$D$1074:$D$1473,"Canarias") -> 21809.84 | F7: =SUMIFS('Nacional · base'!$G$1074:$G$1473,'Nacional · base'!$A$1074:$A$1473,2027,'Nacional · base'!$B$1074:$B$1473,1,'Nacional · base'!$D$1074:$D$1473,"Canarias") -> 28 | G7: =SUMIFS('Nacional · base'!$R$1074:$R$1473,'Nacional · base'!$A$1074:$A$1473,2027,'Nacional · base'!$B$1074:$B$1473,1,'Nacional · base'!$D$1074:$D$1473,"Canarias") -> 6088.1813 | H7: =B7+E7 -> 93749.62 | I7: =D7+G7 -> 13105.035
A8: Feb | B8: =SUMIFS('Nacional · base'!$E$1074:$E$1473,'Nacional · base'!$A$1074:$A$1473,2027,'Nacional · base'!$B$1074:$B$1473,2,'Nacional · base'!$D$1074:$D$1473,"Resto nacional") -> 139637.04 | C8: =SUMIFS('Nacional · base'!$G$1074:$G$1473,'Nacional · base'!$A$1074:$A$1473,2027,'Nacional · base'!$B$1074:$B$1473,2,'Nacional · base'!$D$1074:$D$1473,"Resto nacional") -> 184 | D8: =SUMIFS('Nacional · base'!$Q$1074:$Q$1473,'Nacional · base'!$A$1074:$A$1473,2027,'Nacional · base'!$B$1074:$B$1473,2,'Nacional · base'!$D$1074:$D$1473,"Resto nacional") -> 13619.902 | E8: =SUMIFS('Nacional · base'!$E$1074:$E$1473,'Nacional · base'!$A$1074:$A$1473,2027,'Nacional · base'!$B$1074:$B$1473,2,'Nacional · base'!$D$1074:$D$1473,"Canarias") -> 19473.88 | F8: =SUMIFS('Nacional · base'!$G$1074:$G$1473,'Nacional · base'!$A$1074:$A$1473,2027,'Nacional · base'!$B$1074:$B$1473,2,'Nacional · base'!$D$1074:$D$1473,"Canarias") -> 25 | G8: =SUMIFS('Nacional · base'!$R$1074:$R$1473,'Nacional · base'!$A$1074:$A$1473,2027,'Nacional · base'!$B$1074:$B$1473,2,'Nacional · base'!$D$1074:$D$1473,"Canarias") -> 5367.2581 | H8: =B8+E8 -> 159110.92 | I8: =D8+G8 -> 18987.16
A9: Mar | B9: =SUMIFS('Nacional · base'!$E$1074:$E$1473,'Nacional · base'!$A$1074:$A$1473,2027,'Nacional · base'!$B$1074:$B$1473,3,'Nacional · base'!$D$1074:$D$1473,"Resto nacional") -> 190772.44 | C9: =SUMIFS('Nacional · base'!$G$1074:$G$1473,'Nacional · base'!$A$1074:$A$1473,2027,'Nacional · base'!$B$1074:$B$1473,3,'Nacional · base'!$D$1074:$D$1473,"Resto nacional") -> 246 | D9: =SUMIFS('Nacional · base'!$Q$1074:$Q$1473,'Nacional · base'!$A$1074:$A$1473,2027,'Nacional · base'!$B$1074:$B$1473,3,'Nacional · base'!$D$1074:$D$1473,"Resto nacional") -> 18607.541 | E9: =SUMIFS('Nacional · base'!$E$1074:$E$1473,'Nacional · base'!$A$1074:$A$1473,2027,'Nacional · base'!$B$1074:$B$1473,3,'Nacional · base'!$D$1074:$D$1473,"Canarias") -> 27761.06 | F9: =SUMIFS('Nacional · base'!$G$1074:$G$1473,'Nacional · base'!$A$1074:$A$1473,2027,'Nacional · base'!$B$1074:$B$1473,3,'Nacional · base'!$D$1074:$D$1473,"Canarias") -> 34 | G9: =SUMIFS('Nacional · base'!$R$1074:$R$1473,'Nacional · base'!$A$1074:$A$1473,2027,'Nacional · base'!$B$1074:$B$1473,3,'Nacional · base'!$D$1074:$D$1473,"Canarias") -> 7224.7247 | H9: =B9+E9 -> 218533.5 | I9: =D9+G9 -> 25832.266
A10: Abr | B10: =SUMIFS('Nacional · base'!$E$1074:$E$1473,'Nacional · base'!$A$1074:$A$1473,2027,'Nacional · base'!$B$1074:$B$1473,4,'Nacional · base'!$D$1074:$D$1473,"Resto nacional") -> 226121.76 | C10: =SUMIFS('Nacional · base'!$G$1074:$G$1473,'Nacional · base'!$A$1074:$A$1473,2027,'Nacional · base'!$B$1074:$B$1473,4,'Nacional · base'!$D$1074:$D$1473,"Resto nacional") -> 296 | D10: =SUMIFS('Nacional · base'!$Q$1074:$Q$1473,'Nacional · base'!$A$1074:$A$1473,2027,'Nacional · base'!$B$1074:$B$1473,4,'Nacional · base'!$D$1074:$D$1473,"Resto nacional") -> 22055.439 | E10: =SUMIFS('Nacional · base'!$E$1074:$E$1473,'Nacional · base'!$A$1074:$A$1473,2027,'Nacional · base'!$B$1074:$B$1473,4,'Nacional · base'!$D$1074:$D$1473,"Canarias") -> 13650.64 | F10: =SUMIFS('Nacional · base'!$G$1074:$G$1473,'Nacional · base'!$A$1074:$A$1473,2027,'Nacional · base'!$B$1074:$B$1473,4,'Nacional · base'!$D$1074:$D$1473,"Canarias") -> 18 | G10: =SUMIFS('Nacional · base'!$R$1074:$R$1473,'Nacional · base'!$A$1074:$A$1473,2027,'Nacional · base'!$B$1074:$B$1473,4,'Nacional · base'!$D$1074:$D$1473,"Canarias") -> 3712.0421 | H10: =B10+E10 -> 239772.4 | I10: =D10+G10 -> 25767.481
A11: May | B11: =SUMIFS('Nacional · base'!$E$1074:$E$1473,'Nacional · base'!$A$1074:$A$1473,2027,'Nacional · base'!$B$1074:$B$1473,5,'Nacional · base'!$D$1074:$D$1473,"Resto nacional") -> 191162.96 | C11: =SUMIFS('Nacional · base'!$G$1074:$G$1473,'Nacional · base'!$A$1074:$A$1473,2027,'Nacional · base'!$B$1074:$B$1473,5,'Nacional · base'!$D$1074:$D$1473,"Resto nacional") -> 250 | D11: =SUMIFS('Nacional · base'!$Q$1074:$Q$1473,'Nacional · base'!$A$1074:$A$1473,2027,'Nacional · base'!$B$1074:$B$1473,5,'Nacional · base'!$D$1074:$D$1473,"Resto nacional") -> 18645.631 | E11: =SUMIFS('Nacional · base'!$E$1074:$E$1473,'Nacional · base'!$A$1074:$A$1473,2027,'Nacional · base'!$B$1074:$B$1473,5,'Nacional · base'!$D$1074:$D$1473,"Canarias") -> 50703.5 | F11: =SUMIFS('Nacional · base'!$G$1074:$G$1473,'Nacional · base'!$A$1074:$A$1473,2027,'Nacional · base'!$B$1074:$B$1473,5,'Nacional · base'!$D$1074:$D$1473,"Canarias") -> 63 | G11: =SUMIFS('Nacional · base'!$R$1074:$R$1473,'Nacional · base'!$A$1074:$A$1473,2027,'Nacional · base'!$B$1074:$B$1473,5,'Nacional · base'!$D$1074:$D$1473,"Canarias") -> 14028.954 | H11: =B11+E11 -> 241866.46 | I11: =D11+G11 -> 32674.585
A12: Jun | B12: =SUMIFS('Nacional · base'!$E$1074:$E$1473,'Nacional · base'!$A$1074:$A$1473,2027,'Nacional · base'!$B$1074:$B$1473,6,'Nacional · base'!$D$1074:$D$1473,"Resto nacional") -> 209112.66 | C12: =SUMIFS('Nacional · base'!$G$1074:$G$1473,'Nacional · base'!$A$1074:$A$1473,2027,'Nacional · base'!$B$1074:$B$1473,6,'Nacional · base'!$D$1074:$D$1473,"Resto nacional") -> 270 | D12: =SUMIFS('Nacional · base'!$Q$1074:$Q$1473,'Nacional · base'!$A$1074:$A$1473,2027,'Nacional · base'!$B$1074:$B$1473,6,'Nacional · base'!$D$1074:$D$1473,"Resto nacional") -> 20396.407 | E12: =SUMIFS('Nacional · base'!$E$1074:$E$1473,'Nacional · base'!$A$1074:$A$1473,2027,'Nacional · base'!$B$1074:$B$1473,6,'Nacional · base'!$D$1074:$D$1473,"Canarias") -> 8591.18 | F12: =SUMIFS('Nacional · base'!$G$1074:$G$1473,'Nacional · base'!$A$1074:$A$1473,2027,'Nacional · base'!$B$1074:$B$1473,6,'Nacional · base'!$D$1074:$D$1473,"Canarias") -> 13 | G12: =SUMIFS('Nacional · base'!$R$1074:$R$1473,'Nacional · base'!$A$1074:$A$1473,2027,'Nacional · base'!$B$1074:$B$1473,6,'Nacional · base'!$D$1074:$D$1473,"Canarias") -> 2584.44 | H12: =B12+E12 -> 217703.84 | I12: =D12+G12 -> 22980.847
A13: Jul | B13: =SUMIFS('Nacional · base'!$E$1074:$E$1473,'Nacional · base'!$A$1074:$A$1473,2027,'Nacional · base'!$B$1074:$B$1473,7,'Nacional · base'!$D$1074:$D$1473,"Resto nacional") -> 151201.88 | C13: =SUMIFS('Nacional · base'!$G$1074:$G$1473,'Nacional · base'!$A$1074:$A$1473,2027,'Nacional · base'!$B$1074:$B$1473,7,'Nacional · base'!$D$1074:$D$1473,"Resto nacional") -> 199 | D13: =SUMIFS('Nacional · base'!$Q$1074:$Q$1473,'Nacional · base'!$A$1074:$A$1473,2027,'Nacional · base'!$B$1074:$B$1473,7,'Nacional · base'!$D$1074:$D$1473,"Resto nacional") -> 14747.912 | E13: =SUMIFS('Nacional · base'!$E$1074:$E$1473,'Nacional · base'!$A$1074:$A$1473,2027,'Nacional · base'!$B$1074:$B$1473,7,'Nacional · base'!$D$1074:$D$1473,"Canarias") -> 16143.1 | F13: =SUMIFS('Nacional · base'!$G$1074:$G$1473,'Nacional · base'!$A$1074:$A$1473,2027,'Nacional · base'!$B$1074:$B$1473,7,'Nacional · base'!$D$1074:$D$1473,"Canarias") -> 23 | G13: =SUMIFS('Nacional · base'!$R$1074:$R$1473,'Nacional · base'!$A$1074:$A$1473,2027,'Nacional · base'!$B$1074:$B$1473,7,'Nacional · base'!$D$1074:$D$1473,"Canarias") -> 4588.2983 | H13: =B13+E13 -> 167344.98 | I13: =D13+G13 -> 19336.21
A14: Ago | B14: =SUMIFS('Nacional · base'!$E$1074:$E$1473,'Nacional · base'!$A$1074:$A$1473,2027,'Nacional · base'!$B$1074:$B$1473,8,'Nacional · base'!$D$1074:$D$1473,"Resto nacional") -> 136751.46 | C14: =SUMIFS('Nacional · base'!$G$1074:$G$1473,'Nacional · base'!$A$1074:$A$1473,2027,'Nacional · base'!$B$1074:$B$1473,8,'Nacional · base'!$D$1074:$D$1473,"Resto nacional") -> 167 | D14: =SUMIFS('Nacional · base'!$Q$1074:$Q$1473,'Nacional · base'!$A$1074:$A$1473,2027,'Nacional · base'!$B$1074:$B$1473,8,'Nacional · base'!$D$1074:$D$1473,"Resto nacional") -> 13338.449 | E14: =SUMIFS('Nacional · base'!$E$1074:$E$1473,'Nacional · base'!$A$1074:$A$1473,2027,'Nacional · base'!$B$1074:$B$1473,8,'Nacional · base'!$D$1074:$D$1473,"Canarias") -> 27209.98 | F14: =SUMIFS('Nacional · base'!$G$1074:$G$1473,'Nacional · base'!$A$1074:$A$1473,2027,'Nacional · base'!$B$1074:$B$1473,8,'Nacional · base'!$D$1074:$D$1473,"Canarias") -> 37 | G14: =SUMIFS('Nacional · base'!$R$1074:$R$1473,'Nacional · base'!$A$1074:$A$1473,2027,'Nacional · base'!$B$1074:$B$1473,8,'Nacional · base'!$D$1074:$D$1473,"Canarias") -> 8667.6855 | H14: =B14+E14 -> 163961.44 | I14: =D14+G14 -> 22006.134
A15: Sep | B15: =SUMIFS('Nacional · base'!$E$1074:$E$1473,'Nacional · base'!$A$1074:$A$1473,2027,'Nacional · base'!$B$1074:$B$1473,9,'Nacional · base'!$D$1074:$D$1473,"Resto nacional") -> 80234.04 | C15: =SUMIFS('Nacional · base'!$G$1074:$G$1473,'Nacional · base'!$A$1074:$A$1473,2027,'Nacional · base'!$B$1074:$B$1473,9,'Nacional · base'!$D$1074:$D$1473,"Resto nacional") -> 102 | D15: =SUMIFS('Nacional · base'!$Q$1074:$Q$1473,'Nacional · base'!$A$1074:$A$1473,2027,'Nacional · base'!$B$1074:$B$1473,9,'Nacional · base'!$D$1074:$D$1473,"Resto nacional") -> 7825.8588 | E15: =SUMIFS('Nacional · base'!$E$1074:$E$1473,'Nacional · base'!$A$1074:$A$1473,2027,'Nacional · base'!$B$1074:$B$1473,9,'Nacional · base'!$D$1074:$D$1473,"Canarias") -> 9928 | F15: =SUMIFS('Nacional · base'!$G$1074:$G$1473,'Nacional · base'!$A$1074:$A$1473,2027,'Nacional · base'!$B$1074:$B$1473,9,'Nacional · base'!$D$1074:$D$1473,"Canarias") -> 14 | G15: =SUMIFS('Nacional · base'!$R$1074:$R$1473,'Nacional · base'!$A$1074:$A$1473,2027,'Nacional · base'!$B$1074:$B$1473,9,'Nacional · base'!$D$1074:$D$1473,"Canarias") -> 2950.8535 | H15: =B15+E15 -> 90162.04 | I15: =D15+G15 -> 10776.712
A16: Oct | B16: =SUMIFS('Nacional · base'!$E$1074:$E$1473,'Nacional · base'!$A$1074:$A$1473,2027,'Nacional · base'!$B$1074:$B$1473,10,'Nacional · base'!$D$1074:$D$1473,"Resto nacional") -> 130207 | C16: =SUMIFS('Nacional · base'!$G$1074:$G$1473,'Nacional · base'!$A$1074:$A$1473,2027,'Nacional · base'!$B$1074:$B$1473,10,'Nacional · base'!$D$1074:$D$1473,"Resto nacional") -> 165 | D16: =SUMIFS('Nacional · base'!$Q$1074:$Q$1473,'Nacional · base'!$A$1074:$A$1473,2027,'Nacional · base'!$B$1074:$B$1473,10,'Nacional · base'!$D$1074:$D$1473,"Resto nacional") -> 12700.116 | E16: =SUMIFS('Nacional · base'!$E$1074:$E$1473,'Nacional · base'!$A$1074:$A$1473,2027,'Nacional · base'!$B$1074:$B$1473,10,'Nacional · base'!$D$1074:$D$1473,"Canarias") -> 39003.2 | F16: =SUMIFS('Nacional · base'!$G$1074:$G$1473,'Nacional · base'!$A$1074:$A$1473,2027,'Nacional · base'!$B$1074:$B$1473,10,'Nacional · base'!$D$1074:$D$1473,"Canarias") -> 45 | G16: =SUMIFS('Nacional · base'!$R$1074:$R$1473,'Nacional · base'!$A$1074:$A$1473,2027,'Nacional · base'!$B$1074:$B$1473,10,'Nacional · base'!$D$1074:$D$1473,"Canarias") -> 9635.0411 | H16: =B16+E16 -> 169210.2 | I16: =D16+G16 -> 22335.157
A17: Nov | B17: =SUMIFS('Nacional · base'!$E$1074:$E$1473,'Nacional · base'!$A$1074:$A$1473,2027,'Nacional · base'!$B$1074:$B$1473,11,'Nacional · base'!$D$1074:$D$1473,"Resto nacional") -> 128444.36 | C17: =SUMIFS('Nacional · base'!$G$1074:$G$1473,'Nacional · base'!$A$1074:$A$1473,2027,'Nacional · base'!$B$1074:$B$1473,11,'Nacional · base'!$D$1074:$D$1473,"Resto nacional") -> 155 | D17: =SUMIFS('Nacional · base'!$Q$1074:$Q$1473,'Nacional · base'!$A$1074:$A$1473,2027,'Nacional · base'!$B$1074:$B$1473,11,'Nacional · base'!$D$1074:$D$1473,"Resto nacional") -> 12528.192 | E17: =SUMIFS('Nacional · base'!$E$1074:$E$1473,'Nacional · base'!$A$1074:$A$1473,2027,'Nacional · base'!$B$1074:$B$1473,11,'Nacional · base'!$D$1074:$D$1473,"Canarias") -> 52107.9 | F17: =SUMIFS('Nacional · base'!$G$1074:$G$1473,'Nacional · base'!$A$1074:$A$1473,2027,'Nacional · base'!$B$1074:$B$1473,11,'Nacional · base'!$D$1074:$D$1473,"Canarias") -> 62 | G17: =SUMIFS('Nacional · base'!$R$1074:$R$1473,'Nacional · base'!$A$1074:$A$1473,2027,'Nacional · base'!$B$1074:$B$1473,11,'Nacional · base'!$D$1074:$D$1473,"Canarias") -> 13725.162 | H17: =B17+E17 -> 180552.26 | I17: =D17+G17 -> 26253.353
A18: Dic | B18: =SUMIFS('Nacional · base'!$E$1074:$E$1473,'Nacional · base'!$A$1074:$A$1473,2027,'Nacional · base'!$B$1074:$B$1473,12,'Nacional · base'!$D$1074:$D$1473,"Resto nacional") -> 51158.06 | C18: =SUMIFS('Nacional · base'!$G$1074:$G$1473,'Nacional · base'!$A$1074:$A$1473,2027,'Nacional · base'!$B$1074:$B$1473,12,'Nacional · base'!$D$1074:$D$1473,"Resto nacional") -> 74 | D18: =SUMIFS('Nacional · base'!$Q$1074:$Q$1473,'Nacional · base'!$A$1074:$A$1473,2027,'Nacional · base'!$B$1074:$B$1473,12,'Nacional · base'!$D$1074:$D$1473,"Resto nacional") -> 4989.8491 | E18: =SUMIFS('Nacional · base'!$E$1074:$E$1473,'Nacional · base'!$A$1074:$A$1473,2027,'Nacional · base'!$B$1074:$B$1473,12,'Nacional · base'!$D$1074:$D$1473,"Canarias") -> 2666.8 | F18: =SUMIFS('Nacional · base'!$G$1074:$G$1473,'Nacional · base'!$A$1074:$A$1473,2027,'Nacional · base'!$B$1074:$B$1473,12,'Nacional · base'!$D$1074:$D$1473,"Canarias") -> 4 | G18: =SUMIFS('Nacional · base'!$R$1074:$R$1473,'Nacional · base'!$A$1074:$A$1473,2027,'Nacional · base'!$B$1074:$B$1473,12,'Nacional · base'!$D$1074:$D$1473,"Canarias") -> 625.65144 | H18: =B18+E18 -> 53824.86 | I18: =D18+G18 -> 5615.5006
A19: TOTAL | B19: =SUM(B7:B18) -> 1706743.4 | C19: =SUM(C7:C18) -> 2211 | D19: =SUM(D7:D18) -> 166472.15 | E19: =SUM(E7:E18) -> 289049.08 | F19: =SUM(F7:F18) -> 366 | G19: =SUM(G7:G18) -> 79198.291 | H19: =SUM(H7:H18) -> 1995792.5 | I19: =SUM(I7:I18) -> 245670.44
A23: Canarias · coste por cliente y mes
A24: Mes | B24: Cliente / destino | C24: Kilos | D24: Palets | E24: Sealine (€)
A25: Ene | B25: AGROQUIMICAS DRAGO S.L. · La Montañeta, El Calero | C25: =SUMIFS('Nacional · base'!$E$1074:$E$1473,'Nacional · base'!$A$1074:$A$1473,2027,'Nacional · base'!$B$1074:$B$1473,1,'Nacional · base'!$C$1074:$C$1473,"AGROQUIMICAS DRAGO S.L.") -> 8598.06 | D25: =SUMIFS('Nacional · base'!$G$1074:$G$1473,'Nacional · base'!$A$1074:$A$1473,2027,'Nacional · base'!$B$1074:$B$1473,1,'Nacional · base'!$C$1074:$C$1473,"AGROQUIMICAS DRAGO S.L.") -> 10 | E25: =SUMIFS('Nacional · base'!$R$1074:$R$1473,'Nacional · base'!$A$1074:$A$1473,2027,'Nacional · base'!$B$1074:$B$1473,1,'Nacional · base'!$C$1074:$C$1473,"AGROQUIMICAS DRAGO S.L.") -> 1934.4507
A26: Ene | B26: FITOSANITARIOS DRAGO S.L.U · Santa Cruz de Tenerife | C26: =SUMIFS('Nacional · base'!$E$1074:$E$1473,'Nacional · base'!$A$1074:$A$1473,2027,'Nacional · base'!$B$1074:$B$1473,1,'Nacional · base'!$C$1074:$C$1473,"FITOSANITARIOS DRAGO S.L.U") -> 1959.74 | D26: =SUMIFS('Nacional · base'!$G$1074:$G$1473,'Nacional · base'!$A$1074:$A$1473,2027,'Nacional · base'!$B$1074:$B$1473,1,'Nacional · base'!$C$1074:$C$1473,"FITOSANITARIOS DRAGO S.L.U") -> 3 | E26: =SUMIFS('Nacional · base'!$R$1074:$R$1473,'Nacional · base'!$A$1074:$A$1473,2027,'Nacional · base'!$B$1074:$B$1473,1,'Nacional · base'!$C$1074:$C$1473,"FITOSANITARIOS DRAGO S.L.U") -> 479.17655
A27: Ene | B27: CABRERA MORALES FRANCISCO · Santa Cruz de La Palma | C27: =SUMIFS('Nacional · base'!$E$1074:$E$1473,'Nacional · base'!$A$1074:$A$1473,2027,'Nacional · base'!$B$1074:$B$1473,1,'Nacional · base'!$C$1074:$C$1473,"CABRERA MORALES FRANCISCO") -> 11252.04 | D27: =SUMIFS('Nacional · base'!$G$1074:$G$1473,'Nacional · base'!$A$1074:$A$1473,2027,'Nacional · base'!$B$1074:$B$1473,1,'Nacional · base'!$C$1074:$C$1473,"CABRERA MORALES FRANCISCO") -> 15 | E27: =SUMIFS('Nacional · base'!$R$1074:$R$1473,'Nacional · base'!$A$1074:$A$1473,2027,'Nacional · base'!$B$1074:$B$1473,1,'Nacional · base'!$C$1074:$C$1473,"CABRERA MORALES FRANCISCO") -> 3674.554
A28: Feb | B28: AGROQUIMICAS DRAGO S.L. · La Montañeta, El Calero | C28: =SUMIFS('Nacional · base'!$E$1074:$E$1473,'Nacional · base'!$A$1074:$A$1473,2027,'Nacional · base'!$B$1074:$B$1473,2,'Nacional · base'!$C$1074:$C$1473,"AGROQUIMICAS DRAGO S.L.") -> 4192.54 | D28: =SUMIFS('Nacional · base'!$G$1074:$G$1473,'Nacional · base'!$A$1074:$A$1473,2027,'Nacional · base'!$B$1074:$B$1473,2,'Nacional · base'!$C$1074:$C$1473,"AGROQUIMICAS DRAGO S.L.") -> 6 | E28: =SUMIFS('Nacional · base'!$R$1074:$R$1473,'Nacional · base'!$A$1074:$A$1473,2027,'Nacional · base'!$B$1074:$B$1473,2,'Nacional · base'!$C$1074:$C$1473,"AGROQUIMICAS DRAGO S.L.") -> 970.08255
A29: Feb | B29: FITOSANITARIOS DRAGO S.L.U · Santa Cruz de Tenerife | C29: =SUMIFS('Nacional · base'!$E$1074:$E$1473,'Nacional · base'!$A$1074:$A$1473,2027,'Nacional · base'!$B$1074:$B$1473,2,'Nacional · base'!$C$1074:$C$1473,"FITOSANITARIOS DRAGO S.L.U") -> 5785.54 | D29: =SUMIFS('Nacional · base'!$G$1074:$G$1473,'Nacional · base'!$A$1074:$A$1473,2027,'Nacional · base'!$B$1074:$B$1473,2,'Nacional · base'!$C$1074:$C$1473,"FITOSANITARIOS DRAGO S.L.U") -> 6 | E29: =SUMIFS('Nacional · base'!$R$1074:$R$1473,'Nacional · base'!$A$1074:$A$1473,2027,'Nacional · base'!$B$1074:$B$1473,2,'Nacional · base'!$C$1074:$C$1473,"FITOSANITARIOS DRAGO S.L.U") -> 1278.6532
A30: Feb | B30: CABRERA MORALES FRANCISCO · Santa Cruz de La Palma | C30: =SUMIFS('Nacional · base'!$E$1074:$E$1473,'Nacional · base'!$A$1074:$A$1473,2027,'Nacional · base'!$B$1074:$B$1473,2,'Nacional · base'!$C$1074:$C$1473,"CABRERA MORALES FRANCISCO") -> 9495.8 | D30: =SUMIFS('Nacional · base'!$G$1074:$G$1473,'Nacional · base'!$A$1074:$A$1473,2027,'Nacional · base'!$B$1074:$B$1473,2,'Nacional · base'!$C$1074:$C$1473,"CABRERA MORALES FRANCISCO") -> 13 | E30: =SUMIFS('Nacional · base'!$R$1074:$R$1473,'Nacional · base'!$A$1074:$A$1473,2027,'Nacional · base'!$B$1074:$B$1473,2,'Nacional · base'!$C$1074:$C$1473,"CABRERA MORALES FRANCISCO") -> 3118.5224
A31: Mar | B31: AGROQUIMICAS DRAGO S.L. · La Montañeta, El Calero | C31: =SUMIFS('Nacional · base'!$E$1074:$E$1473,'Nacional · base'!$A$1074:$A$1473,2027,'Nacional · base'!$B$1074:$B$1473,3,'Nacional · base'!$C$1074:$C$1473,"AGROQUIMICAS DRAGO S.L.") -> 11280.2 | D31: =SUMIFS('Nacional · base'!$G$1074:$G$1473,'Nacional · base'!$A$1074:$A$1473,2027,'Nacional · base'!$B$1074:$B$1473,3,'Nacional · base'!$C$1074:$C$1473,"AGROQUIMICAS DRAGO S.L.") -> 14 | E31: =SUMIFS('Nacional · base'!$R$1074:$R$1473,'Nacional · base'!$A$1074:$A$1473,2027,'Nacional · base'!$B$1074:$B$1473,3,'Nacional · base'!$C$1074:$C$1473,"AGROQUIMICAS DRAGO S.L.") -> 2537.6171
A32: Mar | B32: FITOSANITARIOS DRAGO S.L.U · Santa Cruz de Tenerife | C32: =SUMIFS('Nacional · base'!$E$1074:$E$1473,'Nacional · base'!$A$1074:$A$1473,2027,'Nacional · base'!$B$1074:$B$1473,3,'Nacional · base'!$C$1074:$C$1473,"FITOSANITARIOS DRAGO S.L.U") -> 6819.44 | D32: =SUMIFS('Nacional · base'!$G$1074:$G$1473,'Nacional · base'!$A$1074:$A$1473,2027,'Nacional · base'!$B$1074:$B$1473,3,'Nacional · base'!$C$1074:$C$1473,"FITOSANITARIOS DRAGO S.L.U") -> 7 | E32: =SUMIFS('Nacional · base'!$R$1074:$R$1473,'Nacional · base'!$A$1074:$A$1473,2027,'Nacional · base'!$B$1074:$B$1473,3,'Nacional · base'!$C$1074:$C$1473,"FITOSANITARIOS DRAGO S.L.U") -> 1541.2203
A33: Mar | B33: CABRERA MORALES FRANCISCO · Santa Cruz de La Palma | C33: =SUMIFS('Nacional · base'!$E$1074:$E$1473,'Nacional · base'!$A$1074:$A$1473,2027,'Nacional · base'!$B$1074:$B$1473,3,'Nacional · base'!$C$1074:$C$1473,"CABRERA MORALES FRANCISCO") -> 9661.42 | D33: =SUMIFS('Nacional · base'!$G$1074:$G$1473,'Nacional · base'!$A$1074:$A$1473,2027,'Nacional · base'!$B$1074:$B$1473,3,'Nacional · base'!$C$1074:$C$1473,"CABRERA MORALES FRANCISCO") -> 13 | E33: =SUMIFS('Nacional · base'!$R$1074:$R$1473,'Nacional · base'!$A$1074:$A$1473,2027,'Nacional · base'!$B$1074:$B$1473,3,'Nacional · base'!$C$1074:$C$1473,"CABRERA MORALES FRANCISCO") -> 3145.8873
A34: Abr | B34: AGROQUIMICAS DRAGO S.L. · La Montañeta, El Calero | C34: =SUMIFS('Nacional · base'!$E$1074:$E$1473,'Nacional · base'!$A$1074:$A$1473,2027,'Nacional · base'!$B$1074:$B$1473,4,'Nacional · base'!$C$1074:$C$1473,"AGROQUIMICAS DRAGO S.L.") -> 4948.84 | D34: =SUMIFS('Nacional · base'!$G$1074:$G$1473,'Nacional · base'!$A$1074:$A$1473,2027,'Nacional · base'!$B$1074:$B$1473,4,'Nacional · base'!$C$1074:$C$1473,"AGROQUIMICAS DRAGO S.L.") -> 7 | E34: =SUMIFS('Nacional · base'!$R$1074:$R$1473,'Nacional · base'!$A$1074:$A$1473,2027,'Nacional · base'!$B$1074:$B$1473,4,'Nacional · base'!$C$1074:$C$1473,"AGROQUIMICAS DRAGO S.L.") -> 1142.1143
A35: Abr | B35: FITOSANITARIOS DRAGO S.L.U · Santa Cruz de Tenerife | C35: =SUMIFS('Nacional · base'!$E$1074:$E$1473,'Nacional · base'!$A$1074:$A$1473,2027,'Nacional · base'!$B$1074:$B$1473,4,'Nacional · base'!$C$1074:$C$1473,"FITOSANITARIOS DRAGO S.L.U") -> 3009 | D35: =SUMIFS('Nacional · base'!$G$1074:$G$1473,'Nacional · base'!$A$1074:$A$1473,2027,'Nacional · base'!$B$1074:$B$1473,4,'Nacional · base'!$C$1074:$C$1473,"FITOSANITARIOS DRAGO S.L.U") -> 3 | E35: =SUMIFS('Nacional · base'!$R$1074:$R$1473,'Nacional · base'!$A$1074:$A$1473,2027,'Nacional · base'!$B$1074:$B$1473,4,'Nacional · base'!$C$1074:$C$1473,"FITOSANITARIOS DRAGO S.L.U") -> 702.69258
A36: Abr | B36: CABRERA MORALES FRANCISCO · Santa Cruz de La Palma | C36: =SUMIFS('Nacional · base'!$E$1074:$E$1473,'Nacional · base'!$A$1074:$A$1473,2027,'Nacional · base'!$B$1074:$B$1473,4,'Nacional · base'!$C$1074:$C$1473,"CABRERA MORALES FRANCISCO") -> 5692.8 | D36: =SUMIFS('Nacional · base'!$G$1074:$G$1473,'Nacional · base'!$A$1074:$A$1473,2027,'Nacional · base'!$B$1074:$B$1473,4,'Nacional · base'!$C$1074:$C$1473,"CABRERA MORALES FRANCISCO") -> 8 | E36: =SUMIFS('Nacional · base'!$R$1074:$R$1473,'Nacional · base'!$A$1074:$A$1473,2027,'Nacional · base'!$B$1074:$B$1473,4,'Nacional · base'!$C$1074:$C$1473,"CABRERA MORALES FRANCISCO") -> 1867.2352
A37: May | B37: AGROQUIMICAS DRAGO S.L. · La Montañeta, El Calero | C37: =SUMIFS('Nacional · base'!$E$1074:$E$1473,'Nacional · base'!$A$1074:$A$1473,2027,'Nacional · base'!$B$1074:$B$1473,5,'Nacional · base'!$C$1074:$C$1473,"AGROQUIMICAS DRAGO S.L.") -> 4124.1 | D37: =SUMIFS('Nacional · base'!$G$1074:$G$1473,'Nacional · base'!$A$1074:$A$1473,2027,'Nacional · base'!$B$1074:$B$1473,5,'Nacional · base'!$C$1074:$C$1473,"AGROQUIMICAS DRAGO S.L.") -> 6 | E37: =SUMIFS('Nacional · base'!$R$1074:$R$1473,'Nacional · base'!$A$1074:$A$1473,2027,'Nacional · base'!$B$1074:$B$1473,5,'Nacional · base'!$C$1074:$C$1473,"AGROQUIMICAS DRAGO S.L.") -> 956.64325
A38: May | B38: FITOSANITARIOS DRAGO S.L.U · Santa Cruz de Tenerife | C38: =SUMIFS('Nacional · base'!$E$1074:$E$1473,'Nacional · base'!$A$1074:$A$1473,2027,'Nacional · base'!$B$1074:$B$1473,5,'Nacional · base'!$C$1074:$C$1473,"FITOSANITARIOS DRAGO S.L.U") -> 20681.5 | D38: =SUMIFS('Nacional · base'!$G$1074:$G$1473,'Nacional · base'!$A$1074:$A$1473,2027,'Nacional · base'!$B$1074:$B$1473,5,'Nacional · base'!$C$1074:$C$1473,"FITOSANITARIOS DRAGO S.L.U") -> 22 | E38: =SUMIFS('Nacional · base'!$R$1074:$R$1473,'Nacional · base'!$A$1074:$A$1473,2027,'Nacional · base'!$B$1074:$B$1473,5,'Nacional · base'!$C$1074:$C$1473,"FITOSANITARIOS DRAGO S.L.U") -> 4621.9335
A39: May | B39: CABRERA MORALES FRANCISCO · Santa Cruz de La Palma | C39: =SUMIFS('Nacional · base'!$E$1074:$E$1473,'Nacional · base'!$A$1074:$A$1473,2027,'Nacional · base'!$B$1074:$B$1473,5,'Nacional · base'!$C$1074:$C$1473,"CABRERA MORALES FRANCISCO") -> 25897.9 | D39: =SUMIFS('Nacional · base'!$G$1074:$G$1473,'Nacional · base'!$A$1074:$A$1473,2027,'Nacional · base'!$B$1074:$B$1473,5,'Nacional · base'!$C$1074:$C$1473,"CABRERA MORALES FRANCISCO") -> 35 | E39: =SUMIFS('Nacional · base'!$R$1074:$R$1473,'Nacional · base'!$A$1074:$A$1473,2027,'Nacional · base'!$B$1074:$B$1473,5,'Nacional · base'!$C$1074:$C$1473,"CABRERA MORALES FRANCISCO") -> 8450.3769
A40: Jun | B40: AGROQUIMICAS DRAGO S.L. · La Montañeta, El Calero | C40: =SUMIFS('Nacional · base'!$E$1074:$E$1473,'Nacional · base'!$A$1074:$A$1473,2027,'Nacional · base'!$B$1074:$B$1473,6,'Nacional · base'!$C$1074:$C$1473,"AGROQUIMICAS DRAGO S.L.") -> 2573.28 | D40: =SUMIFS('Nacional · base'!$G$1074:$G$1473,'Nacional · base'!$A$1074:$A$1473,2027,'Nacional · base'!$B$1074:$B$1473,6,'Nacional · base'!$C$1074:$C$1473,"AGROQUIMICAS DRAGO S.L.") -> 4 | E40: =SUMIFS('Nacional · base'!$R$1074:$R$1473,'Nacional · base'!$A$1074:$A$1473,2027,'Nacional · base'!$B$1074:$B$1473,6,'Nacional · base'!$C$1074:$C$1473,"AGROQUIMICAS DRAGO S.L.") -> 602.49977
A41: Jun | B41: FITOSANITARIOS DRAGO S.L.U · Santa Cruz de Tenerife | C41: =SUMIFS('Nacional · base'!$E$1074:$E$1473,'Nacional · base'!$A$1074:$A$1473,2027,'Nacional · base'!$B$1074:$B$1473,6,'Nacional · base'!$C$1074:$C$1473,"FITOSANITARIOS DRAGO S.L.U") -> 0 | D41: =SUMIFS('Nacional · base'!$G$1074:$G$1473,'Nacional · base'!$A$1074:$A$1473,2027,'Nacional · base'!$B$1074:$B$1473,6,'Nacional · base'!$C$1074:$C$1473,"FITOSANITARIOS DRAGO S.L.U") -> 0 | E41: =SUMIFS('Nacional · base'!$R$1074:$R$1473,'Nacional · base'!$A$1074:$A$1473,2027,'Nacional · base'!$B$1074:$B$1473,6,'Nacional · base'!$C$1074:$C$1473,"FITOSANITARIOS DRAGO S.L.U") -> 0
A42: Jun | B42: CABRERA MORALES FRANCISCO · Santa Cruz de La Palma | C42: =SUMIFS('Nacional · base'!$E$1074:$E$1473,'Nacional · base'!$A$1074:$A$1473,2027,'Nacional · base'!$B$1074:$B$1473,6,'Nacional · base'!$C$1074:$C$1473,"CABRERA MORALES FRANCISCO") -> 6017.9 | D42: =SUMIFS('Nacional · base'!$G$1074:$G$1473,'Nacional · base'!$A$1074:$A$1473,2027,'Nacional · base'!$B$1074:$B$1473,6,'Nacional · base'!$C$1074:$C$1473,"CABRERA MORALES FRANCISCO") -> 9 | E42: =SUMIFS('Nacional · base'!$R$1074:$R$1473,'Nacional · base'!$A$1074:$A$1473,2027,'Nacional · base'!$B$1074:$B$1473,6,'Nacional · base'!$C$1074:$C$1473,"CABRERA MORALES FRANCISCO") -> 1981.9402
A43: Jul | B43: AGROQUIMICAS DRAGO S.L. · La Montañeta, El Calero | C43: =SUMIFS('Nacional · base'!$E$1074:$E$1473,'Nacional · base'!$A$1074:$A$1473,2027,'Nacional · base'!$B$1074:$B$1473,7,'Nacional · base'!$C$1074:$C$1473,"AGROQUIMICAS DRAGO S.L.") -> 4913.1 | D43: =SUMIFS('Nacional · base'!$G$1074:$G$1473,'Nacional · base'!$A$1074:$A$1473,2027,'Nacional · base'!$B$1074:$B$1473,7,'Nacional · base'!$C$1074:$C$1473,"AGROQUIMICAS DRAGO S.L.") -> 7 | E43: =SUMIFS('Nacional · base'!$R$1074:$R$1473,'Nacional · base'!$A$1074:$A$1473,2027,'Nacional · base'!$B$1074:$B$1473,7,'Nacional · base'!$C$1074:$C$1473,"AGROQUIMICAS DRAGO S.L.") -> 1139.6776
A44: Jul | B44: FITOSANITARIOS DRAGO S.L.U · Santa Cruz de Tenerife | C44: =SUMIFS('Nacional · base'!$E$1074:$E$1473,'Nacional · base'!$A$1074:$A$1473,2027,'Nacional · base'!$B$1074:$B$1473,7,'Nacional · base'!$C$1074:$C$1473,"FITOSANITARIOS DRAGO S.L.U") -> 2407.2 | D44: =SUMIFS('Nacional · base'!$G$1074:$G$1473,'Nacional · base'!$A$1074:$A$1473,2027,'Nacional · base'!$B$1074:$B$1473,7,'Nacional · base'!$C$1074:$C$1473,"FITOSANITARIOS DRAGO S.L.U") -> 4 | E44: =SUMIFS('Nacional · base'!$R$1074:$R$1473,'Nacional · base'!$A$1074:$A$1473,2027,'Nacional · base'!$B$1074:$B$1473,7,'Nacional · base'!$C$1074:$C$1473,"FITOSANITARIOS DRAGO S.L.U") -> 563.70181
A45: Jul | B45: CABRERA MORALES FRANCISCO · Santa Cruz de La Palma | C45: =SUMIFS('Nacional · base'!$E$1074:$E$1473,'Nacional · base'!$A$1074:$A$1473,2027,'Nacional · base'!$B$1074:$B$1473,7,'Nacional · base'!$C$1074:$C$1473,"CABRERA MORALES FRANCISCO") -> 8822.8 | D45: =SUMIFS('Nacional · base'!$G$1074:$G$1473,'Nacional · base'!$A$1074:$A$1473,2027,'Nacional · base'!$B$1074:$B$1473,7,'Nacional · base'!$C$1074:$C$1473,"CABRERA MORALES FRANCISCO") -> 12 | E45: =SUMIFS('Nacional · base'!$R$1074:$R$1473,'Nacional · base'!$A$1074:$A$1473,2027,'Nacional · base'!$B$1074:$B$1473,7,'Nacional · base'!$C$1074:$C$1473,"CABRERA MORALES FRANCISCO") -> 2884.9188
A46: Ago | B46: AGROQUIMICAS DRAGO S.L. · La Montañeta, El Calero | C46: =SUMIFS('Nacional · base'!$E$1074:$E$1473,'Nacional · base'!$A$1074:$A$1473,2027,'Nacional · base'!$B$1074:$B$1473,8,'Nacional · base'!$C$1074:$C$1473,"AGROQUIMICAS DRAGO S.L.") -> 3001.96 | D46: =SUMIFS('Nacional · base'!$G$1074:$G$1473,'Nacional · base'!$A$1074:$A$1473,2027,'Nacional · base'!$B$1074:$B$1473,8,'Nacional · base'!$C$1074:$C$1473,"AGROQUIMICAS DRAGO S.L.") -> 4 | E46: =SUMIFS('Nacional · base'!$R$1074:$R$1473,'Nacional · base'!$A$1074:$A$1473,2027,'Nacional · base'!$B$1074:$B$1473,8,'Nacional · base'!$C$1074:$C$1473,"AGROQUIMICAS DRAGO S.L.") -> 697.07145
...

Sheet Export · costes
A2: Costes mensuales de exportación
A3: Septiembre de 2026 añadido desde previsión de ventas; el resto se distribuye según coste anual por país del archivo adjunto.
A4: La documentación fija de 54 € de Arabia Saudí se asigna a octubre para reconciliar el total 2026 del origen.
A6: Año | B6: Mes | C6: Coste (€)
A7: 2026 | B7: Sep | C7: =SUMIFS($F$32:$F$207,$A$32:$A$207,2026,$B$32:$B$207,"Sep") -> 16253
A8: 2026 | B8: Oct | C8: =SUMIFS($F$32:$F$207,$A$32:$A$207,2026,$B$32:$B$207,"Oct")+'Export · países'!F7 -> 21379
A9: 2026 | B9: Nov | C9: =SUMIFS($F$32:$F$207,$A$32:$A$207,2026,$B$32:$B$207,"Nov") -> 32454
A10: 2026 | B10: Dic | C10: =SUMIFS($F$32:$F$207,$A$32:$A$207,2026,$B$32:$B$207,"Dic") -> 27150
A11: TOTAL 2026 | C11: =SUM(C7:C10) -> 97236
A14: Año | B14: Mes | C14: Coste (€)
A15: 2027 | B15: Ene | C15: =SUMIFS($F$32:$F$207,$A$32:$A$207,2027,$B$32:$B$207,"Ene") -> 29809.2
A16: 2027 | B16: Feb | C16: =SUMIFS($F$32:$F$207,$A$32:$A$207,2027,$B$32:$B$207,"Feb") -> 21246.7
A17: 2027 | B17: Mar | C17: =SUMIFS($F$32:$F$207,$A$32:$A$207,2027,$B$32:$B$207,"Mar") -> 19638.3
A18: 2027 | B18: Abr | C18: =SUMIFS($F$32:$F$207,$A$32:$A$207,2027,$B$32:$B$207,"Abr") -> 8004.2
A19: 2027 | B19: May | C19: =SUMIFS($F$32:$F$207,$A$32:$A$207,2027,$B$32:$B$207,"May") -> 38718.8
A20: 2027 | B20: Jun | C20: =SUMIFS($F$32:$F$207,$A$32:$A$207,2027,$B$32:$B$207,"Jun") -> 33492
A21: 2027 | B21: Jul | C21: =SUMIFS($F$32:$F$207,$A$32:$A$207,2027,$B$32:$B$207,"Jul") -> 13212.8
A22: 2027 | B22: Ago | C22: =SUMIFS($F$32:$F$207,$A$32:$A$207,2027,$B$32:$B$207,"Ago") -> 18509.6
A23: 2027 | B23: Sep | C23: =SUMIFS($F$32:$F$207,$A$32:$A$207,2027,$B$32:$B$207,"Sep") -> 24148.9
A24: 2027 | B24: Oct | C24: =SUMIFS($F$32:$F$207,$A$32:$A$207,2027,$B$32:$B$207,"Oct") -> 23411.3
A25: 2027 | B25: Nov | C25: =SUMIFS($F$32:$F$207,$A$32:$A$207,2027,$B$32:$B$207,"Nov") -> 40650.7
A26: 2027 | B26: Dic | C26: =SUMIFS($F$32:$F$207,$A$32:$A$207,2027,$B$32:$B$207,"Dic") -> 34380.8
A27: TOTAL 2027 | C27: =SUM(C15:C26) -> 305223.3
A31: Año | B31: Mes | C31: País | D31: Envíos | E31: Coste/envío (€) | F31: Coste (€)
A32: 2026 | B32: Sep | C32: ARABIA SAUDÍ | D32: =0 -> 0 | E32: =IFERROR('Export · países'!F7/'Export · países'!C7,0) -> 0 | F32: =D32*E32 -> 0
A33: 2026 | B33: Sep | C33: AZERBAIYÁN | D33: =0 -> 0 | E33: =IFERROR('Export · países'!F8/'Export · países'!C8,0) -> 1701 | F33: =D33*E33 -> 0
A34: 2026 | B34: Sep | C34: COSTA RICA | D34: =1 -> 1 | E34: =IFERROR('Export · países'!F11/'Export · países'!C11,0) -> 3850 | F34: =D34*E34 -> 3850
A35: 2026 | B35: Sep | C35: DOMINICANA, REPÚBLICA | D35: =0 -> 0 | E35: =IFERROR('Export · países'!F12/'Export · países'!C12,0) -> 3675 | F35: =D35*E35 -> 0
A36: 2026 | B36: Sep | C36: ECUADOR (incluidas las Islas Galápagos) | D36: =0 -> 0 | E36: =IFERROR('Export · países'!F13/'Export · países'!C13,0) -> 104 | F36: =D36*E36 -> 0
A37: 2026 | B37: Sep | C37: EGIPTO | D37: =1 -> 1 | E37: =IFERROR('Export · países'!F14/'Export · países'!C14,0) -> 179 | F37: =D37*E37 -> 179
A38: 2026 | B38: Sep | C38: ITALIA | D38: =0 -> 0 | E38: =IFERROR('Export · países'!F17/'Export · países'!C17,0) -> 487 | F38: =D38*E38 -> 0
A39: 2026 | B39: Sep | C39: LÍBANO | D39: =0 -> 0 | E39: =IFERROR('Export · países'!F18/'Export · países'!C18,0) -> 1579 | F39: =D39*E39 -> 0
A40: 2026 | B40: Sep | C40: NETHERLANS | D40: =2 -> 2 | E40: =IFERROR('Export · países'!F20/'Export · países'!C20,0) -> 4413 | F40: =D40*E40 -> 8826
A41: 2026 | B41: Sep | C41: PANAMÁ | D41: =0 -> 0 | E41: =IFERROR('Export · países'!F21/'Export · países'!C21,0) -> 3449 | F41: =D41*E41 -> 0
A42: 2026 | B42: Sep | C42: TURQUÍA | D42: =2 -> 2 | E42: =IFERROR('Export · países'!F25/'Export · países'!C25,0) -> 1699 | F42: =D42*E42 -> 3398
A43: 2026 | B43: Oct | C43: ARABIA SAUDÍ | D43: ='Export · detalle'!B7 -> 0 | E43: =IFERROR('Export · países'!F7/'Export · países'!C7,0) -> 0 | F43: =D43*E43 -> 0
A44: 2026 | B44: Oct | C44: AZERBAIYÁN | D44: ='Export · detalle'!B8 -> 0 | E44: =IFERROR('Export · países'!F8/'Export · países'!C8,0) -> 1701 | F44: =D44*E44 -> 0
A45: 2026 | B45: Oct | C45: COSTA RICA | D45: ='Export · detalle'!B11 -> 3 | E45: =IFERROR('Export · países'!F11/'Export · países'!C11,0) -> 3850 | F45: =D45*E45 -> 11550
A46: 2026 | B46: Oct | C46: DOMINICANA, REPÚBLICA | D46: ='Export · detalle'!B12 -> 0 | E46: =IFERROR('Export · países'!F12/'Export · países'!C12,0) -> 3675 | F46: =D46*E46 -> 0
A47: 2026 | B47: Oct | C47: ECUADOR (incluidas las Islas Galápagos) | D47: ='Export · detalle'!B13 -> 1 | E47: =IFERROR('Export · países'!F13/'Export · países'!C13,0) -> 104 | F47: =D47*E47 -> 104
...

Sheet Export · detalle
A2: Envíos previstos de exportación
A3: Por país y mes · máximo 21 palets por envío · España excluida
A5: 2026 · octubre a diciembre
A6: País | B6: Oct | C6: Nov | D6: Dic | E6: Total 2026
A7: ARABIA SAUDÍ | B7: =ROUNDUP(SUMIFS('Export · base'!$H$7:$H$408,'Export · base'!$A$7:$A$408,2026,'Export · base'!$B$7:$B$408,10,'Export · base'!$C$7:$C$408,$A7)/'Export · supuestos'!$B$5,0) -> 0 | C7: =ROUNDUP(SUMIFS('Export · base'!$H$7:$H$408,'Export · base'!$A$7:$A$408,2026,'Export · base'!$B$7:$B$408,11,'Export · base'!$C$7:$C$408,$A7)/'Export · supuestos'!$B$5,0) -> 0 | D7: =ROUNDUP(SUMIFS('Export · base'!$H$7:$H$408,'Export · base'!$A$7:$A$408,2026,'Export · base'!$B$7:$B$408,12,'Export · base'!$C$7:$C$408,$A7)/'Export · supuestos'!$B$5,0) -> 0 | E7: =SUM(B7:D7) -> 0
A8: AZERBAIYÁN | B8: =ROUNDUP(SUMIFS('Export · base'!$H$7:$H$408,'Export · base'!$A$7:$A$408,2026,'Export · base'!$B$7:$B$408,10,'Export · base'!$C$7:$C$408,$A8)/'Export · supuestos'!$B$5,0) -> 0 | C8: =ROUNDUP(SUMIFS('Export · base'!$H$7:$H$408,'Export · base'!$A$7:$A$408,2026,'Export · base'!$B$7:$B$408,11,'Export · base'!$C$7:$C$408,$A8)/'Export · supuestos'!$B$5,0) -> 0 | D8: =ROUNDUP(SUMIFS('Export · base'!$H$7:$H$408,'Export · base'!$A$7:$A$408,2026,'Export · base'!$B$7:$B$408,12,'Export · base'!$C$7:$C$408,$A8)/'Export · supuestos'!$B$5,0) -> 2 | E8: =SUM(B8:D8) -> 2
A9: CHILE | B9: =ROUNDUP(SUMIFS('Export · base'!$H$7:$H$408,'Export · base'!$A$7:$A$408,2026,'Export · base'!$B$7:$B$408,10,'Export · base'!$C$7:$C$408,$A9)/'Export · supuestos'!$B$5,0) -> 0 | C9: =ROUNDUP(SUMIFS('Export · base'!$H$7:$H$408,'Export · base'!$A$7:$A$408,2026,'Export · base'!$B$7:$B$408,11,'Export · base'!$C$7:$C$408,$A9)/'Export · supuestos'!$B$5,0) -> 0 | D9: =ROUNDUP(SUMIFS('Export · base'!$H$7:$H$408,'Export · base'!$A$7:$A$408,2026,'Export · base'!$B$7:$B$408,12,'Export · base'!$C$7:$C$408,$A9)/'Export · supuestos'!$B$5,0) -> 10 | E9: =SUM(B9:D9) -> 10
A10: COLOMBIA | B10: =ROUNDUP(SUMIFS('Export · base'!$H$7:$H$408,'Export · base'!$A$7:$A$408,2026,'Export · base'!$B$7:$B$408,10,'Export · base'!$C$7:$C$408,$A10)/'Export · supuestos'!$B$5,0) -> 0 | C10: =ROUNDUP(SUMIFS('Export · base'!$H$7:$H$408,'Export · base'!$A$7:$A$408,2026,'Export · base'!$B$7:$B$408,11,'Export · base'!$C$7:$C$408,$A10)/'Export · supuestos'!$B$5,0) -> 2 | D10: =ROUNDUP(SUMIFS('Export · base'!$H$7:$H$408,'Export · base'!$A$7:$A$408,2026,'Export · base'!$B$7:$B$408,12,'Export · base'!$C$7:$C$408,$A10)/'Export · supuestos'!$B$5,0) -> 0 | E10: =SUM(B10:D10) -> 2
A11: COSTA RICA | B11: =ROUNDUP(SUMIFS('Export · base'!$H$7:$H$408,'Export · base'!$A$7:$A$408,2026,'Export · base'!$B$7:$B$408,10,'Export · base'!$C$7:$C$408,$A11)/'Export · supuestos'!$B$5,0) -> 3 | C11: =ROUNDUP(SUMIFS('Export · base'!$H$7:$H$408,'Export · base'!$A$7:$A$408,2026,'Export · base'!$B$7:$B$408,11,'Export · base'!$C$7:$C$408,$A11)/'Export · supuestos'!$B$5,0) -> 2 | D11: =ROUNDUP(SUMIFS('Export · base'!$H$7:$H$408,'Export · base'!$A$7:$A$408,2026,'Export · base'!$B$7:$B$408,12,'Export · base'!$C$7:$C$408,$A11)/'Export · supuestos'!$B$5,0) -> 2 | E11: =SUM(B11:D11) -> 7
A12: DOMINICANA, REPÚBLICA | B12: =ROUNDUP(SUMIFS('Export · base'!$H$7:$H$408,'Export · base'!$A$7:$A$408,2026,'Export · base'!$B$7:$B$408,10,'Export · base'!$C$7:$C$408,$A12)/'Export · supuestos'!$B$5,0) -> 0 | C12: =ROUNDUP(SUMIFS('Export · base'!$H$7:$H$408,'Export · base'!$A$7:$A$408,2026,'Export · base'!$B$7:$B$408,11,'Export · base'!$C$7:$C$408,$A12)/'Export · supuestos'!$B$5,0) -> 2 | D12: =ROUNDUP(SUMIFS('Export · base'!$H$7:$H$408,'Export · base'!$A$7:$A$408,2026,'Export · base'!$B$7:$B$408,12,'Export · base'!$C$7:$C$408,$A12)/'Export · supuestos'!$B$5,0) -> 0 | E12: =SUM(B12:D12) -> 2
A13: ECUADOR (incluidas las Islas Galápagos) | B13: =ROUNDUP(SUMIFS('Export · base'!$H$7:$H$408,'Export · base'!$A$7:$A$408,2026,'Export · base'!$B$7:$B$408,10,'Export · base'!$C$7:$C$408,$A13)/'Export · supuestos'!$B$5,0) -> 1 | C13: =ROUNDUP(SUMIFS('Export · base'!$H$7:$H$408,'Export · base'!$A$7:$A$408,2026,'Export · base'!$B$7:$B$408,11,'Export · base'!$C$7:$C$408,$A13)/'Export · supuestos'!$B$5,0) -> 0 | D13: =ROUNDUP(SUMIFS('Export · base'!$H$7:$H$408,'Export · base'!$A$7:$A$408,2026,'Export · base'!$B$7:$B$408,12,'Export · base'!$C$7:$C$408,$A13)/'Export · supuestos'!$B$5,0) -> 0 | E13: =SUM(B13:D13) -> 1
A14: EGIPTO | B14: =ROUNDUP(SUMIFS('Export · base'!$H$7:$H$408,'Export · base'!$A$7:$A$408,2026,'Export · base'!$B$7:$B$408,10,'Export · base'!$C$7:$C$408,$A14)/'Export · supuestos'!$B$5,0) -> 2 | C14: =ROUNDUP(SUMIFS('Export · base'!$H$7:$H$408,'Export · base'!$A$7:$A$408,2026,'Export · base'!$B$7:$B$408,11,'Export · base'!$C$7:$C$408,$A14)/'Export · supuestos'!$B$5,0) -> 4 | D14: =ROUNDUP(SUMIFS('Export · base'!$H$7:$H$408,'Export · base'!$A$7:$A$408,2026,'Export · base'!$B$7:$B$408,12,'Export · base'!$C$7:$C$408,$A14)/'Export · supuestos'!$B$5,0) -> 1 | E14: =SUM(B14:D14) -> 7
A15: GEORGIA | B15: =ROUNDUP(SUMIFS('Export · base'!$H$7:$H$408,'Export · base'!$A$7:$A$408,2026,'Export · base'!$B$7:$B$408,10,'Export · base'!$C$7:$C$408,$A15)/'Export · supuestos'!$B$5,0) -> 0 | C15: =ROUNDUP(SUMIFS('Export · base'!$H$7:$H$408,'Export · base'!$A$7:$A$408,2026,'Export · base'!$B$7:$B$408,11,'Export · base'!$C$7:$C$408,$A15)/'Export · supuestos'!$B$5,0) -> 0 | D15: =ROUNDUP(SUMIFS('Export · base'!$H$7:$H$408,'Export · base'!$A$7:$A$408,2026,'Export · base'!$B$7:$B$408,12,'Export · base'!$C$7:$C$408,$A15)/'Export · supuestos'!$B$5,0) -> 3 | E15: =SUM(B15:D15) -> 3
A16: GRECIA | B16: =ROUNDUP(SUMIFS('Export · base'!$H$7:$H$408,'Export · base'!$A$7:$A$408,2026,'Export · base'!$B$7:$B$408,10,'Export · base'!$C$7:$C$408,$A16)/'Export · supuestos'!$B$5,0) -> 0 | C16: =ROUNDUP(SUMIFS('Export · base'!$H$7:$H$408,'Export · base'!$A$7:$A$408,2026,'Export · base'!$B$7:$B$408,11,'Export · base'!$C$7:$C$408,$A16)/'Export · supuestos'!$B$5,0) -> 0 | D16: =ROUNDUP(SUMIFS('Export · base'!$H$7:$H$408,'Export · base'!$A$7:$A$408,2026,'Export · base'!$B$7:$B$408,12,'Export · base'!$C$7:$C$408,$A16)/'Export · supuestos'!$B$5,0) -> 2 | E16: =SUM(B16:D16) -> 2
A17: ITALIA | B17: =ROUNDUP(SUMIFS('Export · base'!$H$7:$H$408,'Export · base'!$A$7:$A$408,2026,'Export · base'!$B$7:$B$408,10,'Export · base'!$C$7:$C$408,$A17)/'Export · supuestos'!$B$5,0) -> 1 | C17: =ROUNDUP(SUMIFS('Export · base'!$H$7:$H$408,'Export · base'!$A$7:$A$408,2026,'Export · base'!$B$7:$B$408,11,'Export · base'!$C$7:$C$408,$A17)/'Export · supuestos'!$B$5,0) -> 0 | D17: =ROUNDUP(SUMIFS('Export · base'!$H$7:$H$408,'Export · base'!$A$7:$A$408,2026,'Export · base'!$B$7:$B$408,12,'Export · base'!$C$7:$C$408,$A17)/'Export · supuestos'!$B$5,0) -> 1 | E17: =SUM(B17:D17) -> 2
A18: LÍBANO | B18: =ROUNDUP(SUMIFS('Export · base'!$H$7:$H$408,'Export · base'!$A$7:$A$408,2026,'Export · base'!$B$7:$B$408,10,'Export · base'!$C$7:$C$408,$A18)/'Export · supuestos'!$B$5,0) -> 0 | C18: =ROUNDUP(SUMIFS('Export · base'!$H$7:$H$408,'Export · base'!$A$7:$A$408,2026,'Export · base'!$B$7:$B$408,11,'Export · base'!$C$7:$C$408,$A18)/'Export · supuestos'!$B$5,0) -> 0 | D18: =ROUNDUP(SUMIFS('Export · base'!$H$7:$H$408,'Export · base'!$A$7:$A$408,2026,'Export · base'!$B$7:$B$408,12,'Export · base'!$C$7:$C$408,$A18)/'Export · supuestos'!$B$5,0) -> 2 | E18: =SUM(B18:D18) -> 2
... A25: TURQUÍA | B25: =ROUNDUP(SUMIFS('Export · base'!$H$7:$H$408,'Export · base'!$A$7:$A$408,2026,'Export · base'!$B$7:$B$408,10,'Export · base'!$C$7:$C$408,$A25)/'Export · supuestos'!$B$5,0) -> 0 | C25: =ROUNDUP(SUMIFS('Export · base'!$H$7:$H$408,'Export · base'!$A$7:$A$408,2026,'Export · base'!$B$7:$B$408,11,'Export · base'!$C$7:$C$408,$A25)/'Export · supuestos'!$B$5,0) -> 0 | D25: =ROUNDUP(SUMIFS('Export · base'!$H$7:$H$408,'Export · base'!$A$7:$A$408,2026,'Export · base'!$B$7:$B$408,12,'Export · base'!$C$7:$C$408,$A25)/'Export · supuestos'!$B$5,0) -> 2 | E25: =SUM(B25:D25) -> 2
A26: TOTAL | B26: =SUM(B7:B25) -> 10 | C26: =SUM(C7:C25) -> 16 | D26: =SUM(D7:D25) -> 30 | E26: =SUM(E7:E25) -> 56
A29: 2027 · enero a diciembre
A30: País | B30: Ene | C30: Feb | D30: Mar | E30: Abr | F30: May | G30: Jun | H30: Jul | I30: Ago | J30: Sep | K30: Oct | L30: Nov | M30: Dic | N30: Total 2027
